2025-09-11 02:34:38.443 INFO (MainThread) [homeassistant.setup] Setup of domain system_log took 0.09 seconds
2025-09-11 02:34:38.444 INFO (MainThread) [homeassistant.setup] Setup of domain http took 0.09 seconds
2025-09-11 02:34:38.444 INFO (MainThread) [homeassistant.setup] Setup of domain logger took 0.09 seconds
2025-09-11 02:34:38.444 INFO (MainThread) [homeassistant.setup] Setting up websocket_api
2025-09-11 02:34:38.445 INFO (MainThread) [homeassistant.setup] Setup of domain websocket_api took 0.00 seconds
2025-09-11 02:34:38.451 INFO (MainThread) [homeassistant.setup] Setting up network
2025-09-11 02:34:38.454 INFO (MainThread) [homeassistant.setup] Setup of domain network took 0.00 seconds
2025-09-11 02:34:38.454 INFO (MainThread) [homeassistant.bootstrap] Setting up stage frontend: {'frontend'}; already set up: {}
Dependencies: {'onboarding', 'search', 'repairs', 'file_upload', 'config', 'auth', 'lovelace', 'diagnostics', 'device_automation', 'api'}; already set up: {'system_log', 'http', 'websocket_api'}
2025-09-11 02:34:38.455 INFO (MainThread) [homeassistant.setup] Setting up auth
2025-09-11 02:34:38.456 INFO (MainThread) [homeassistant.setup] Setup of domain auth took 0.00 seconds
2025-09-11 02:34:38.456 INFO (MainThread) [homeassistant.setup] Setting up onboarding
2025-09-11 02:34:38.456 INFO (MainThread) [homeassistant.setup] Setup of domain onboarding took 0.00 seconds
2025-09-11 02:34:38.457 INFO (MainThread) [homeassistant.setup] Setting up search
2025-09-11 02:34:38.457 INFO (MainThread) [homeassistant.setup] Setup of domain search took 0.00 seconds
2025-09-11 02:34:38.457 INFO (MainThread) [homeassistant.setup] Setting up repairs
2025-09-11 02:34:38.458 INFO (MainThread) [homeassistant.setup] Setup of domain repairs took 0.00 seconds
2025-09-11 02:34:38.458 INFO (MainThread) [homeassistant.setup] Setting up file_upload
2025-09-11 02:34:38.459 INFO (MainThread) [homeassistant.setup] Setup of domain file_upload took 0.00 seconds
2025-09-11 02:34:38.459 INFO (MainThread) [homeassistant.setup] Setting up config
2025-09-11 02:34:38.462 INFO (MainThread) [homeassistant.setup] Setup of domain config took 0.00 seconds
2025-09-11 02:34:38.463 INFO (MainThread) [homeassistant.setup] Setting up lovelace
2025-09-11 02:34:38.464 INFO (MainThread) [homeassistant.setup] Setting up diagnostics
2025-09-11 02:34:38.465 INFO (MainThread) [homeassistant.setup] Setup of domain diagnostics took 0.00 seconds
2025-09-11 02:34:38.465 INFO (MainThread) [homeassistant.setup] Setting up device_automation
2025-09-11 02:34:38.465 INFO (MainThread) [homeassistant.setup] Setup of domain device_automation took 0.00 seconds
2025-09-11 02:34:38.466 INFO (MainThread) [homeassistant.setup] Setting up api
2025-09-11 02:34:38.467 INFO (MainThread) [homeassistant.setup] Setup of domain api took 0.00 seconds
2025-09-11 02:34:38.468 INFO (MainThread) [homeassistant.setup] Setup of domain lovelace took 0.01 seconds
2025-09-11 02:34:38.479 INFO (MainThread) [homeassistant.setup] Setting up frontend
2025-09-11 02:34:38.487 INFO (MainThread) [homeassistant.setup] Setup of domain frontend took 0.01 seconds
2025-09-11 02:34:38.487 INFO (MainThread) [homeassistant.bootstrap] Setting up stage recorder: {'recorder'}; already set up: {}
Dependencies: {}; already set up: {}
2025-09-11 02:34:38.489 INFO (MainThread) [homeassistant.setup] Setup of domain http took 0.00 seconds
2025-09-11 02:34:38.503 INFO (MainThread) [homeassistant.setup] Setting up recorder
2025-09-11 02:34:38.534 ERROR (Recorder) [homeassistant.components.recorder.core] Error during connection setup: (retrying in 3 seconds)
Traceback (most recent call last):
  File "/usr/local/lib/python3.13/site-packages/sqlalchemy/engine/base.py", line 145, in __init__
    self._dbapi_connection = engine.raw_connection()
                             ~~~~~~~~~~~~~~~~~~~~~^^
  File "/usr/local/lib/python3.13/site-packages/sqlalchemy/engine/base.py", line 3297, in raw_connection
    return self.pool.connect()
           ~~~~~~~~~~~~~~~~~^^
  File "/usr/local/lib/python3.13/site-packages/sqlalchemy/pool/base.py", line 449, in connect
    return _ConnectionFairy._checkout(self)
           ~~~~~~~~~~~~~~~~~~~~~~~~~~^^^^^^
  File "/usr/local/lib/python3.13/site-packages/sqlalchemy/pool/base.py", line 1264, in _checkout
    fairy = _ConnectionRecord.checkout(pool)
  File "/usr/local/lib/python3.13/site-packages/sqlalchemy/pool/base.py", line 713, in checkout
    rec = pool._do_get()
  File "/usr/local/lib/python3.13/site-packages/sqlalchemy/pool/impl.py", line 179, in _do_get
    with util.safe_reraise():
         ~~~~~~~~~~~~~~~~~^^
  File "/usr/local/lib/python3.13/site-packages/sqlalchemy/util/langhelpers.py", line 224, in __exit__
    raise exc_value.with_traceback(exc_tb)
  File "/usr/local/lib/python3.13/site-packages/sqlalchemy/pool/impl.py", line 177, in _do_get
    return self._create_connection()
           ~~~~~~~~~~~~~~~~~~~~~~~^^
  File "/usr/local/lib/python3.13/site-packages/sqlalchemy/pool/base.py", line 390, in _create_connection
    return _ConnectionRecord(self)
  File "/usr/local/lib/python3.13/site-packages/sqlalchemy/pool/base.py", line 675, in __init__
    self.__connect()
    ~~~~~~~~~~~~~~^^
  File "/usr/local/lib/python3.13/site-packages/sqlalchemy/pool/base.py", line 901, in __connect
    with util.safe_reraise():
         ~~~~~~~~~~~~~~~~~^^
  File "/usr/local/lib/python3.13/site-packages/sqlalchemy/util/langhelpers.py", line 224, in __exit__
    raise exc_value.with_traceback(exc_tb)
  File "/usr/local/lib/python3.13/site-packages/sqlalchemy/pool/base.py", line 897, in __connect
    self.dbapi_connection = connection = pool._invoke_creator(self)
                                         ~~~~~~~~~~~~~~~~~~~~^^^^^^
  File "/usr/local/lib/python3.13/site-packages/sqlalchemy/engine/create.py", line 646, in connect
    return dialect.connect(*cargs, **cparams)
           ~~~~~~~~~~~~~~~^^^^^^^^^^^^^^^^^^^
  File "/usr/local/lib/python3.13/site-packages/sqlalchemy/engine/default.py", line 625, in connect
    return self.loaded_dbapi.connect(*cargs, **cparams)  # type: ignore[no-any-return]  # NOQA: E501
           ~~~~~~~~~~~~~~~~~~~~~~~~~^^^^^^^^^^^^^^^^^^^
  File "/usr/local/lib/python3.13/site-packages/psycopg2/__init__.py", line 122, in connect
    conn = _connect(dsn, connection_factory=connection_factory, **kwasync)
psycopg2.OperationalError: connection to server at "172.21.0.3", port 5432 failed: Connection refused
	Is the server running on that host and accepting TCP/IP connections?


The above exception was the direct cause of the following exception:

Traceback (most recent call last):
  File "/usr/src/homeassistant/homeassistant/components/recorder/core.py", line 927, in _setup_recorder
    self._setup_connection()
    ~~~~~~~~~~~~~~~~~~~~~~^^
  File "/usr/src/homeassistant/homeassistant/components/recorder/core.py", line 1448, in _setup_connection
    migration.pre_migrate_schema(self.engine)
    ~~~~~~~~~~~~~~~~~~~~~~~~~~~~^^^^^^^^^^^^^
  File "/usr/src/homeassistant/homeassistant/components/recorder/migration.py", line 331, in pre_migrate_schema
    inspector = sqlalchemy.inspect(engine)
  File "/usr/local/lib/python3.13/site-packages/sqlalchemy/inspection.py", line 140, in inspect
    ret = reg(subject)
  File "/usr/local/lib/python3.13/site-packages/sqlalchemy/engine/reflection.py", line 313, in _engine_insp
    return Inspector._construct(Inspector._init_engine, bind)
           ~~~~~~~~~~~~~~~~~~~~^^^^^^^^^^^^^^^^^^^^^^^^^^^^^^
  File "/usr/local/lib/python3.13/site-packages/sqlalchemy/engine/reflection.py", line 246, in _construct
    init(self, bind)
    ~~~~^^^^^^^^^^^^
  File "/usr/local/lib/python3.13/site-packages/sqlalchemy/engine/reflection.py", line 257, in _init_engine
    engine.connect().close()
    ~~~~~~~~~~~~~~^^
  File "/usr/local/lib/python3.13/site-packages/sqlalchemy/engine/base.py", line 3273, in connect
    return self._connection_cls(self)
           ~~~~~~~~~~~~~~~~~~~~^^^^^^
  File "/usr/local/lib/python3.13/site-packages/sqlalchemy/engine/base.py", line 147, in __init__
    Connection._handle_dbapi_exception_noconnection(
    ~~~~~~~~~~~~~~~~~~~~~~~~~~~~~~~~~~~~~~~~~~~~~~~^
        err, dialect, engine
        ^^^^^^^^^^^^^^^^^^^^
    )
    ^
  File "/usr/local/lib/python3.13/site-packages/sqlalchemy/engine/base.py", line 2436, in _handle_dbapi_exception_noconnection
    raise sqlalchemy_exception.with_traceback(exc_info[2]) from e
  File "/usr/local/lib/python3.13/site-packages/sqlalchemy/engine/base.py", line 145, in __init__
    self._dbapi_connection = engine.raw_connection()
                             ~~~~~~~~~~~~~~~~~~~~~^^
  File "/usr/local/lib/python3.13/site-packages/sqlalchemy/engine/base.py", line 3297, in raw_connection
    return self.pool.connect()
           ~~~~~~~~~~~~~~~~~^^
  File "/usr/local/lib/python3.13/site-packages/sqlalchemy/pool/base.py", line 449, in connect
    return _ConnectionFairy._checkout(self)
           ~~~~~~~~~~~~~~~~~~~~~~~~~~^^^^^^
  File "/usr/local/lib/python3.13/site-packages/sqlalchemy/pool/base.py", line 1264, in _checkout
    fairy = _ConnectionRecord.checkout(pool)
  File "/usr/local/lib/python3.13/site-packages/sqlalchemy/pool/base.py", line 713, in checkout
    rec = pool._do_get()
  File "/usr/local/lib/python3.13/site-packages/sqlalchemy/pool/impl.py", line 179, in _do_get
    with util.safe_reraise():
         ~~~~~~~~~~~~~~~~~^^
  File "/usr/local/lib/python3.13/site-packages/sqlalchemy/util/langhelpers.py", line 224, in __exit__
    raise exc_value.with_traceback(exc_tb)
  File "/usr/local/lib/python3.13/site-packages/sqlalchemy/pool/impl.py", line 177, in _do_get
    return self._create_connection()
           ~~~~~~~~~~~~~~~~~~~~~~~^^
  File "/usr/local/lib/python3.13/site-packages/sqlalchemy/pool/base.py", line 390, in _create_connection
    return _ConnectionRecord(self)
  File "/usr/local/lib/python3.13/site-packages/sqlalchemy/pool/base.py", line 675, in __init__
    self.__connect()
    ~~~~~~~~~~~~~~^^
  File "/usr/local/lib/python3.13/site-packages/sqlalchemy/pool/base.py", line 901, in __connect
    with util.safe_reraise():
         ~~~~~~~~~~~~~~~~~^^
  File "/usr/local/lib/python3.13/site-packages/sqlalchemy/util/langhelpers.py", line 224, in __exit__
    raise exc_value.with_traceback(exc_tb)
  File "/usr/local/lib/python3.13/site-packages/sqlalchemy/pool/base.py", line 897, in __connect
    self.dbapi_connection = connection = pool._invoke_creator(self)
                                         ~~~~~~~~~~~~~~~~~~~~^^^^^^
  File "/usr/local/lib/python3.13/site-packages/sqlalchemy/engine/create.py", line 646, in connect
    return dialect.connect(*cargs, **cparams)
           ~~~~~~~~~~~~~~~^^^^^^^^^^^^^^^^^^^
  File "/usr/local/lib/python3.13/site-packages/sqlalchemy/engine/default.py", line 625, in connect
    return self.loaded_dbapi.connect(*cargs, **cparams)  # type: ignore[no-any-return]  # NOQA: E501
           ~~~~~~~~~~~~~~~~~~~~~~~~~^^^^^^^^^^^^^^^^^^^
  File "/usr/local/lib/python3.13/site-packages/psycopg2/__init__.py", line 122, in connect
    conn = _connect(dsn, connection_factory=connection_factory, **kwasync)
sqlalchemy.exc.OperationalError: (psycopg2.OperationalError) connection to server at "172.21.0.3", port 5432 failed: Connection refused
	Is the server running on that host and accepting TCP/IP connections?

(Background on this error at: https://sqlalche.me/e/20/e3q8)
2025-09-11 02:34:41.542 ERROR (Recorder) [homeassistant.components.recorder.core] Error during connection setup: (retrying in 3 seconds)
Traceback (most recent call last):
  File "/usr/local/lib/python3.13/site-packages/sqlalchemy/engine/base.py", line 145, in __init__
    self._dbapi_connection = engine.raw_connection()
                             ~~~~~~~~~~~~~~~~~~~~~^^
  File "/usr/local/lib/python3.13/site-packages/sqlalchemy/engine/base.py", line 3297, in raw_connection
    return self.pool.connect()
           ~~~~~~~~~~~~~~~~~^^
  File "/usr/local/lib/python3.13/site-packages/sqlalchemy/pool/base.py", line 449, in connect
    return _ConnectionFairy._checkout(self)
           ~~~~~~~~~~~~~~~~~~~~~~~~~~^^^^^^
  File "/usr/local/lib/python3.13/site-packages/sqlalchemy/pool/base.py", line 1264, in _checkout
    fairy = _ConnectionRecord.checkout(pool)
  File "/usr/local/lib/python3.13/site-packages/sqlalchemy/pool/base.py", line 713, in checkout
    rec = pool._do_get()
  File "/usr/local/lib/python3.13/site-packages/sqlalchemy/pool/impl.py", line 179, in _do_get
    with util.safe_reraise():
         ~~~~~~~~~~~~~~~~~^^
  File "/usr/local/lib/python3.13/site-packages/sqlalchemy/util/langhelpers.py", line 224, in __exit__
    raise exc_value.with_traceback(exc_tb)
  File "/usr/local/lib/python3.13/site-packages/sqlalchemy/pool/impl.py", line 177, in _do_get
    return self._create_connection()
           ~~~~~~~~~~~~~~~~~~~~~~~^^
  File "/usr/local/lib/python3.13/site-packages/sqlalchemy/pool/base.py", line 390, in _create_connection
    return _ConnectionRecord(self)
  File "/usr/local/lib/python3.13/site-packages/sqlalchemy/pool/base.py", line 675, in __init__
    self.__connect()
    ~~~~~~~~~~~~~~^^
  File "/usr/local/lib/python3.13/site-packages/sqlalchemy/pool/base.py", line 901, in __connect
    with util.safe_reraise():
         ~~~~~~~~~~~~~~~~~^^
  File "/usr/local/lib/python3.13/site-packages/sqlalchemy/util/langhelpers.py", line 224, in __exit__
    raise exc_value.with_traceback(exc_tb)
  File "/usr/local/lib/python3.13/site-packages/sqlalchemy/pool/base.py", line 897, in __connect
    self.dbapi_connection = connection = pool._invoke_creator(self)
                                         ~~~~~~~~~~~~~~~~~~~~^^^^^^
  File "/usr/local/lib/python3.13/site-packages/sqlalchemy/engine/create.py", line 646, in connect
    return dialect.connect(*cargs, **cparams)
           ~~~~~~~~~~~~~~~^^^^^^^^^^^^^^^^^^^
  File "/usr/local/lib/python3.13/site-packages/sqlalchemy/engine/default.py", line 625, in connect
    return self.loaded_dbapi.connect(*cargs, **cparams)  # type: ignore[no-any-return]  # NOQA: E501
           ~~~~~~~~~~~~~~~~~~~~~~~~~^^^^^^^^^^^^^^^^^^^
  File "/usr/local/lib/python3.13/site-packages/psycopg2/__init__.py", line 122, in connect
    conn = _connect(dsn, connection_factory=connection_factory, **kwasync)
psycopg2.OperationalError: connection to server at "172.21.0.3", port 5432 failed: Connection refused
	Is the server running on that host and accepting TCP/IP connections?


The above exception was the direct cause of the following exception:

Traceback (most recent call last):
  File "/usr/src/homeassistant/homeassistant/components/recorder/core.py", line 927, in _setup_recorder
    self._setup_connection()
    ~~~~~~~~~~~~~~~~~~~~~~^^
  File "/usr/src/homeassistant/homeassistant/components/recorder/core.py", line 1448, in _setup_connection
    migration.pre_migrate_schema(self.engine)
    ~~~~~~~~~~~~~~~~~~~~~~~~~~~~^^^^^^^^^^^^^
  File "/usr/src/homeassistant/homeassistant/components/recorder/migration.py", line 331, in pre_migrate_schema
    inspector = sqlalchemy.inspect(engine)
  File "/usr/local/lib/python3.13/site-packages/sqlalchemy/inspection.py", line 140, in inspect
    ret = reg(subject)
  File "/usr/local/lib/python3.13/site-packages/sqlalchemy/engine/reflection.py", line 313, in _engine_insp
    return Inspector._construct(Inspector._init_engine, bind)
           ~~~~~~~~~~~~~~~~~~~~^^^^^^^^^^^^^^^^^^^^^^^^^^^^^^
  File "/usr/local/lib/python3.13/site-packages/sqlalchemy/engine/reflection.py", line 246, in _construct
    init(self, bind)
    ~~~~^^^^^^^^^^^^
  File "/usr/local/lib/python3.13/site-packages/sqlalchemy/engine/reflection.py", line 257, in _init_engine
    engine.connect().close()
    ~~~~~~~~~~~~~~^^
  File "/usr/local/lib/python3.13/site-packages/sqlalchemy/engine/base.py", line 3273, in connect
    return self._connection_cls(self)
           ~~~~~~~~~~~~~~~~~~~~^^^^^^
  File "/usr/local/lib/python3.13/site-packages/sqlalchemy/engine/base.py", line 147, in __init__
    Connection._handle_dbapi_exception_noconnection(
    ~~~~~~~~~~~~~~~~~~~~~~~~~~~~~~~~~~~~~~~~~~~~~~~^
        err, dialect, engine
        ^^^^^^^^^^^^^^^^^^^^
    )
    ^
  File "/usr/local/lib/python3.13/site-packages/sqlalchemy/engine/base.py", line 2436, in _handle_dbapi_exception_noconnection
    raise sqlalchemy_exception.with_traceback(exc_info[2]) from e
  File "/usr/local/lib/python3.13/site-packages/sqlalchemy/engine/base.py", line 145, in __init__
    self._dbapi_connection = engine.raw_connection()
                             ~~~~~~~~~~~~~~~~~~~~~^^
  File "/usr/local/lib/python3.13/site-packages/sqlalchemy/engine/base.py", line 3297, in raw_connection
    return self.pool.connect()
           ~~~~~~~~~~~~~~~~~^^
  File "/usr/local/lib/python3.13/site-packages/sqlalchemy/pool/base.py", line 449, in connect
    return _ConnectionFairy._checkout(self)
           ~~~~~~~~~~~~~~~~~~~~~~~~~~^^^^^^
  File "/usr/local/lib/python3.13/site-packages/sqlalchemy/pool/base.py", line 1264, in _checkout
    fairy = _ConnectionRecord.checkout(pool)
  File "/usr/local/lib/python3.13/site-packages/sqlalchemy/pool/base.py", line 713, in checkout
    rec = pool._do_get()
  File "/usr/local/lib/python3.13/site-packages/sqlalchemy/pool/impl.py", line 179, in _do_get
    with util.safe_reraise():
         ~~~~~~~~~~~~~~~~~^^
  File "/usr/local/lib/python3.13/site-packages/sqlalchemy/util/langhelpers.py", line 224, in __exit__
    raise exc_value.with_traceback(exc_tb)
  File "/usr/local/lib/python3.13/site-packages/sqlalchemy/pool/impl.py", line 177, in _do_get
    return self._create_connection()
           ~~~~~~~~~~~~~~~~~~~~~~~^^
  File "/usr/local/lib/python3.13/site-packages/sqlalchemy/pool/base.py", line 390, in _create_connection
    return _ConnectionRecord(self)
  File "/usr/local/lib/python3.13/site-packages/sqlalchemy/pool/base.py", line 675, in __init__
    self.__connect()
    ~~~~~~~~~~~~~~^^
  File "/usr/local/lib/python3.13/site-packages/sqlalchemy/pool/base.py", line 901, in __connect
    with util.safe_reraise():
         ~~~~~~~~~~~~~~~~~^^
  File "/usr/local/lib/python3.13/site-packages/sqlalchemy/util/langhelpers.py", line 224, in __exit__
    raise exc_value.with_traceback(exc_tb)
  File "/usr/local/lib/python3.13/site-packages/sqlalchemy/pool/base.py", line 897, in __connect
    self.dbapi_connection = connection = pool._invoke_creator(self)
                                         ~~~~~~~~~~~~~~~~~~~~^^^^^^
  File "/usr/local/lib/python3.13/site-packages/sqlalchemy/engine/create.py", line 646, in connect
    return dialect.connect(*cargs, **cparams)
           ~~~~~~~~~~~~~~~^^^^^^^^^^^^^^^^^^^
  File "/usr/local/lib/python3.13/site-packages/sqlalchemy/engine/default.py", line 625, in connect
    return self.loaded_dbapi.connect(*cargs, **cparams)  # type: ignore[no-any-return]  # NOQA: E501
           ~~~~~~~~~~~~~~~~~~~~~~~~~^^^^^^^^^^^^^^^^^^^
  File "/usr/local/lib/python3.13/site-packages/psycopg2/__init__.py", line 122, in connect
    conn = _connect(dsn, connection_factory=connection_factory, **kwasync)
sqlalchemy.exc.OperationalError: (psycopg2.OperationalError) connection to server at "172.21.0.3", port 5432 failed: Connection refused
	Is the server running on that host and accepting TCP/IP connections?

(Background on this error at: https://sqlalche.me/e/20/e3q8)
2025-09-11 02:34:44.549 ERROR (Recorder) [homeassistant.components.recorder.core] Error during connection setup: (retrying in 3 seconds)
Traceback (most recent call last):
  File "/usr/local/lib/python3.13/site-packages/sqlalchemy/engine/base.py", line 145, in __init__
    self._dbapi_connection = engine.raw_connection()
                             ~~~~~~~~~~~~~~~~~~~~~^^
  File "/usr/local/lib/python3.13/site-packages/sqlalchemy/engine/base.py", line 3297, in raw_connection
    return self.pool.connect()
           ~~~~~~~~~~~~~~~~~^^
  File "/usr/local/lib/python3.13/site-packages/sqlalchemy/pool/base.py", line 449, in connect
    return _ConnectionFairy._checkout(self)
           ~~~~~~~~~~~~~~~~~~~~~~~~~~^^^^^^
  File "/usr/local/lib/python3.13/site-packages/sqlalchemy/pool/base.py", line 1264, in _checkout
    fairy = _ConnectionRecord.checkout(pool)
  File "/usr/local/lib/python3.13/site-packages/sqlalchemy/pool/base.py", line 713, in checkout
    rec = pool._do_get()
  File "/usr/local/lib/python3.13/site-packages/sqlalchemy/pool/impl.py", line 179, in _do_get
    with util.safe_reraise():
         ~~~~~~~~~~~~~~~~~^^
  File "/usr/local/lib/python3.13/site-packages/sqlalchemy/util/langhelpers.py", line 224, in __exit__
    raise exc_value.with_traceback(exc_tb)
  File "/usr/local/lib/python3.13/site-packages/sqlalchemy/pool/impl.py", line 177, in _do_get
    return self._create_connection()
           ~~~~~~~~~~~~~~~~~~~~~~~^^
  File "/usr/local/lib/python3.13/site-packages/sqlalchemy/pool/base.py", line 390, in _create_connection
    return _ConnectionRecord(self)
  File "/usr/local/lib/python3.13/site-packages/sqlalchemy/pool/base.py", line 675, in __init__
    self.__connect()
    ~~~~~~~~~~~~~~^^
  File "/usr/local/lib/python3.13/site-packages/sqlalchemy/pool/base.py", line 901, in __connect
    with util.safe_reraise():
         ~~~~~~~~~~~~~~~~~^^
  File "/usr/local/lib/python3.13/site-packages/sqlalchemy/util/langhelpers.py", line 224, in __exit__
    raise exc_value.with_traceback(exc_tb)
  File "/usr/local/lib/python3.13/site-packages/sqlalchemy/pool/base.py", line 897, in __connect
    self.dbapi_connection = connection = pool._invoke_creator(self)
                                         ~~~~~~~~~~~~~~~~~~~~^^^^^^
  File "/usr/local/lib/python3.13/site-packages/sqlalchemy/engine/create.py", line 646, in connect
    return dialect.connect(*cargs, **cparams)
           ~~~~~~~~~~~~~~~^^^^^^^^^^^^^^^^^^^
  File "/usr/local/lib/python3.13/site-packages/sqlalchemy/engine/default.py", line 625, in connect
    return self.loaded_dbapi.connect(*cargs, **cparams)  # type: ignore[no-any-return]  # NOQA: E501
           ~~~~~~~~~~~~~~~~~~~~~~~~~^^^^^^^^^^^^^^^^^^^
  File "/usr/local/lib/python3.13/site-packages/psycopg2/__init__.py", line 122, in connect
    conn = _connect(dsn, connection_factory=connection_factory, **kwasync)
psycopg2.OperationalError: connection to server at "172.21.0.3", port 5432 failed: Connection refused
	Is the server running on that host and accepting TCP/IP connections?


The above exception was the direct cause of the following exception:

Traceback (most recent call last):
  File "/usr/src/homeassistant/homeassistant/components/recorder/core.py", line 927, in _setup_recorder
    self._setup_connection()
    ~~~~~~~~~~~~~~~~~~~~~~^^
  File "/usr/src/homeassistant/homeassistant/components/recorder/core.py", line 1448, in _setup_connection
    migration.pre_migrate_schema(self.engine)
    ~~~~~~~~~~~~~~~~~~~~~~~~~~~~^^^^^^^^^^^^^
  File "/usr/src/homeassistant/homeassistant/components/recorder/migration.py", line 331, in pre_migrate_schema
    inspector = sqlalchemy.inspect(engine)
  File "/usr/local/lib/python3.13/site-packages/sqlalchemy/inspection.py", line 140, in inspect
    ret = reg(subject)
  File "/usr/local/lib/python3.13/site-packages/sqlalchemy/engine/reflection.py", line 313, in _engine_insp
    return Inspector._construct(Inspector._init_engine, bind)
           ~~~~~~~~~~~~~~~~~~~~^^^^^^^^^^^^^^^^^^^^^^^^^^^^^^
  File "/usr/local/lib/python3.13/site-packages/sqlalchemy/engine/reflection.py", line 246, in _construct
    init(self, bind)
    ~~~~^^^^^^^^^^^^
  File "/usr/local/lib/python3.13/site-packages/sqlalchemy/engine/reflection.py", line 257, in _init_engine
    engine.connect().close()
    ~~~~~~~~~~~~~~^^
  File "/usr/local/lib/python3.13/site-packages/sqlalchemy/engine/base.py", line 3273, in connect
    return self._connection_cls(self)
           ~~~~~~~~~~~~~~~~~~~~^^^^^^
  File "/usr/local/lib/python3.13/site-packages/sqlalchemy/engine/base.py", line 147, in __init__
    Connection._handle_dbapi_exception_noconnection(
    ~~~~~~~~~~~~~~~~~~~~~~~~~~~~~~~~~~~~~~~~~~~~~~~^
        err, dialect, engine
        ^^^^^^^^^^^^^^^^^^^^
    )
    ^
  File "/usr/local/lib/python3.13/site-packages/sqlalchemy/engine/base.py", line 2436, in _handle_dbapi_exception_noconnection
    raise sqlalchemy_exception.with_traceback(exc_info[2]) from e
  File "/usr/local/lib/python3.13/site-packages/sqlalchemy/engine/base.py", line 145, in __init__
    self._dbapi_connection = engine.raw_connection()
                             ~~~~~~~~~~~~~~~~~~~~~^^
  File "/usr/local/lib/python3.13/site-packages/sqlalchemy/engine/base.py", line 3297, in raw_connection
    return self.pool.connect()
           ~~~~~~~~~~~~~~~~~^^
  File "/usr/local/lib/python3.13/site-packages/sqlalchemy/pool/base.py", line 449, in connect
    return _ConnectionFairy._checkout(self)
           ~~~~~~~~~~~~~~~~~~~~~~~~~~^^^^^^
  File "/usr/local/lib/python3.13/site-packages/sqlalchemy/pool/base.py", line 1264, in _checkout
    fairy = _ConnectionRecord.checkout(pool)
  File "/usr/local/lib/python3.13/site-packages/sqlalchemy/pool/base.py", line 713, in checkout
    rec = pool._do_get()
  File "/usr/local/lib/python3.13/site-packages/sqlalchemy/pool/impl.py", line 179, in _do_get
    with util.safe_reraise():
         ~~~~~~~~~~~~~~~~~^^
  File "/usr/local/lib/python3.13/site-packages/sqlalchemy/util/langhelpers.py", line 224, in __exit__
    raise exc_value.with_traceback(exc_tb)
  File "/usr/local/lib/python3.13/site-packages/sqlalchemy/pool/impl.py", line 177, in _do_get
    return self._create_connection()
           ~~~~~~~~~~~~~~~~~~~~~~~^^
  File "/usr/local/lib/python3.13/site-packages/sqlalchemy/pool/base.py", line 390, in _create_connection
    return _ConnectionRecord(self)
  File "/usr/local/lib/python3.13/site-packages/sqlalchemy/pool/base.py", line 675, in __init__
    self.__connect()
    ~~~~~~~~~~~~~~^^
  File "/usr/local/lib/python3.13/site-packages/sqlalchemy/pool/base.py", line 901, in __connect
    with util.safe_reraise():
         ~~~~~~~~~~~~~~~~~^^
  File "/usr/local/lib/python3.13/site-packages/sqlalchemy/util/langhelpers.py", line 224, in __exit__
    raise exc_value.with_traceback(exc_tb)
  File "/usr/local/lib/python3.13/site-packages/sqlalchemy/pool/base.py", line 897, in __connect
    self.dbapi_connection = connection = pool._invoke_creator(self)
                                         ~~~~~~~~~~~~~~~~~~~~^^^^^^
  File "/usr/local/lib/python3.13/site-packages/sqlalchemy/engine/create.py", line 646, in connect
    return dialect.connect(*cargs, **cparams)
           ~~~~~~~~~~~~~~~^^^^^^^^^^^^^^^^^^^
  File "/usr/local/lib/python3.13/site-packages/sqlalchemy/engine/default.py", line 625, in connect
    return self.loaded_dbapi.connect(*cargs, **cparams)  # type: ignore[no-any-return]  # NOQA: E501
           ~~~~~~~~~~~~~~~~~~~~~~~~~^^^^^^^^^^^^^^^^^^^
  File "/usr/local/lib/python3.13/site-packages/psycopg2/__init__.py", line 122, in connect
    conn = _connect(dsn, connection_factory=connection_factory, **kwasync)
sqlalchemy.exc.OperationalError: (psycopg2.OperationalError) connection to server at "172.21.0.3", port 5432 failed: Connection refused
	Is the server running on that host and accepting TCP/IP connections?

(Background on this error at: https://sqlalche.me/e/20/e3q8)
2025-09-11 02:34:47.559 ERROR (Recorder) [homeassistant.components.recorder.core] Error during connection setup: (retrying in 3 seconds)
Traceback (most recent call last):
  File "/usr/local/lib/python3.13/site-packages/sqlalchemy/engine/base.py", line 145, in __init__
    self._dbapi_connection = engine.raw_connection()
                             ~~~~~~~~~~~~~~~~~~~~~^^
  File "/usr/local/lib/python3.13/site-packages/sqlalchemy/engine/base.py", line 3297, in raw_connection
    return self.pool.connect()
           ~~~~~~~~~~~~~~~~~^^
  File "/usr/local/lib/python3.13/site-packages/sqlalchemy/pool/base.py", line 449, in connect
    return _ConnectionFairy._checkout(self)
           ~~~~~~~~~~~~~~~~~~~~~~~~~~^^^^^^
  File "/usr/local/lib/python3.13/site-packages/sqlalchemy/pool/base.py", line 1264, in _checkout
    fairy = _ConnectionRecord.checkout(pool)
  File "/usr/local/lib/python3.13/site-packages/sqlalchemy/pool/base.py", line 713, in checkout
    rec = pool._do_get()
  File "/usr/local/lib/python3.13/site-packages/sqlalchemy/pool/impl.py", line 179, in _do_get
    with util.safe_reraise():
         ~~~~~~~~~~~~~~~~~^^
  File "/usr/local/lib/python3.13/site-packages/sqlalchemy/util/langhelpers.py", line 224, in __exit__
    raise exc_value.with_traceback(exc_tb)
  File "/usr/local/lib/python3.13/site-packages/sqlalchemy/pool/impl.py", line 177, in _do_get
    return self._create_connection()
           ~~~~~~~~~~~~~~~~~~~~~~~^^
  File "/usr/local/lib/python3.13/site-packages/sqlalchemy/pool/base.py", line 390, in _create_connection
    return _ConnectionRecord(self)
  File "/usr/local/lib/python3.13/site-packages/sqlalchemy/pool/base.py", line 675, in __init__
    self.__connect()
    ~~~~~~~~~~~~~~^^
  File "/usr/local/lib/python3.13/site-packages/sqlalchemy/pool/base.py", line 901, in __connect
    with util.safe_reraise():
         ~~~~~~~~~~~~~~~~~^^
  File "/usr/local/lib/python3.13/site-packages/sqlalchemy/util/langhelpers.py", line 224, in __exit__
    raise exc_value.with_traceback(exc_tb)
  File "/usr/local/lib/python3.13/site-packages/sqlalchemy/pool/base.py", line 897, in __connect
    self.dbapi_connection = connection = pool._invoke_creator(self)
                                         ~~~~~~~~~~~~~~~~~~~~^^^^^^
  File "/usr/local/lib/python3.13/site-packages/sqlalchemy/engine/create.py", line 646, in connect
    return dialect.connect(*cargs, **cparams)
           ~~~~~~~~~~~~~~~^^^^^^^^^^^^^^^^^^^
  File "/usr/local/lib/python3.13/site-packages/sqlalchemy/engine/default.py", line 625, in connect
    return self.loaded_dbapi.connect(*cargs, **cparams)  # type: ignore[no-any-return]  # NOQA: E501
           ~~~~~~~~~~~~~~~~~~~~~~~~~^^^^^^^^^^^^^^^^^^^
  File "/usr/local/lib/python3.13/site-packages/psycopg2/__init__.py", line 122, in connect
    conn = _connect(dsn, connection_factory=connection_factory, **kwasync)
psycopg2.OperationalError: connection to server at "172.21.0.3", port 5432 failed: Connection refused
	Is the server running on that host and accepting TCP/IP connections?


The above exception was the direct cause of the following exception:

Traceback (most recent call last):
  File "/usr/src/homeassistant/homeassistant/components/recorder/core.py", line 927, in _setup_recorder
    self._setup_connection()
    ~~~~~~~~~~~~~~~~~~~~~~^^
  File "/usr/src/homeassistant/homeassistant/components/recorder/core.py", line 1448, in _setup_connection
    migration.pre_migrate_schema(self.engine)
    ~~~~~~~~~~~~~~~~~~~~~~~~~~~~^^^^^^^^^^^^^
  File "/usr/src/homeassistant/homeassistant/components/recorder/migration.py", line 331, in pre_migrate_schema
    inspector = sqlalchemy.inspect(engine)
  File "/usr/local/lib/python3.13/site-packages/sqlalchemy/inspection.py", line 140, in inspect
    ret = reg(subject)
  File "/usr/local/lib/python3.13/site-packages/sqlalchemy/engine/reflection.py", line 313, in _engine_insp
    return Inspector._construct(Inspector._init_engine, bind)
           ~~~~~~~~~~~~~~~~~~~~^^^^^^^^^^^^^^^^^^^^^^^^^^^^^^
  File "/usr/local/lib/python3.13/site-packages/sqlalchemy/engine/reflection.py", line 246, in _construct
    init(self, bind)
    ~~~~^^^^^^^^^^^^
  File "/usr/local/lib/python3.13/site-packages/sqlalchemy/engine/reflection.py", line 257, in _init_engine
    engine.connect().close()
    ~~~~~~~~~~~~~~^^
  File "/usr/local/lib/python3.13/site-packages/sqlalchemy/engine/base.py", line 3273, in connect
    return self._connection_cls(self)
           ~~~~~~~~~~~~~~~~~~~~^^^^^^
  File "/usr/local/lib/python3.13/site-packages/sqlalchemy/engine/base.py", line 147, in __init__
    Connection._handle_dbapi_exception_noconnection(
    ~~~~~~~~~~~~~~~~~~~~~~~~~~~~~~~~~~~~~~~~~~~~~~~^
        err, dialect, engine
        ^^^^^^^^^^^^^^^^^^^^
    )
    ^
  File "/usr/local/lib/python3.13/site-packages/sqlalchemy/engine/base.py", line 2436, in _handle_dbapi_exception_noconnection
    raise sqlalchemy_exception.with_traceback(exc_info[2]) from e
  File "/usr/local/lib/python3.13/site-packages/sqlalchemy/engine/base.py", line 145, in __init__
    self._dbapi_connection = engine.raw_connection()
                             ~~~~~~~~~~~~~~~~~~~~~^^
  File "/usr/local/lib/python3.13/site-packages/sqlalchemy/engine/base.py", line 3297, in raw_connection
    return self.pool.connect()
           ~~~~~~~~~~~~~~~~~^^
  File "/usr/local/lib/python3.13/site-packages/sqlalchemy/pool/base.py", line 449, in connect
    return _ConnectionFairy._checkout(self)
           ~~~~~~~~~~~~~~~~~~~~~~~~~~^^^^^^
  File "/usr/local/lib/python3.13/site-packages/sqlalchemy/pool/base.py", line 1264, in _checkout
    fairy = _ConnectionRecord.checkout(pool)
  File "/usr/local/lib/python3.13/site-packages/sqlalchemy/pool/base.py", line 713, in checkout
    rec = pool._do_get()
  File "/usr/local/lib/python3.13/site-packages/sqlalchemy/pool/impl.py", line 179, in _do_get
    with util.safe_reraise():
         ~~~~~~~~~~~~~~~~~^^
  File "/usr/local/lib/python3.13/site-packages/sqlalchemy/util/langhelpers.py", line 224, in __exit__
    raise exc_value.with_traceback(exc_tb)
  File "/usr/local/lib/python3.13/site-packages/sqlalchemy/pool/impl.py", line 177, in _do_get
    return self._create_connection()
           ~~~~~~~~~~~~~~~~~~~~~~~^^
  File "/usr/local/lib/python3.13/site-packages/sqlalchemy/pool/base.py", line 390, in _create_connection
    return _ConnectionRecord(self)
  File "/usr/local/lib/python3.13/site-packages/sqlalchemy/pool/base.py", line 675, in __init__
    self.__connect()
    ~~~~~~~~~~~~~~^^
  File "/usr/local/lib/python3.13/site-packages/sqlalchemy/pool/base.py", line 901, in __connect
    with util.safe_reraise():
         ~~~~~~~~~~~~~~~~~^^
  File "/usr/local/lib/python3.13/site-packages/sqlalchemy/util/langhelpers.py", line 224, in __exit__
    raise exc_value.with_traceback(exc_tb)
  File "/usr/local/lib/python3.13/site-packages/sqlalchemy/pool/base.py", line 897, in __connect
    self.dbapi_connection = connection = pool._invoke_creator(self)
                                         ~~~~~~~~~~~~~~~~~~~~^^^^^^
  File "/usr/local/lib/python3.13/site-packages/sqlalchemy/engine/create.py", line 646, in connect
    return dialect.connect(*cargs, **cparams)
           ~~~~~~~~~~~~~~~^^^^^^^^^^^^^^^^^^^
  File "/usr/local/lib/python3.13/site-packages/sqlalchemy/engine/default.py", line 625, in connect
    return self.loaded_dbapi.connect(*cargs, **cparams)  # type: ignore[no-any-return]  # NOQA: E501
           ~~~~~~~~~~~~~~~~~~~~~~~~~^^^^^^^^^^^^^^^^^^^
  File "/usr/local/lib/python3.13/site-packages/psycopg2/__init__.py", line 122, in connect
    conn = _connect(dsn, connection_factory=connection_factory, **kwasync)
sqlalchemy.exc.OperationalError: (psycopg2.OperationalError) connection to server at "172.21.0.3", port 5432 failed: Connection refused
	Is the server running on that host and accepting TCP/IP connections?

(Background on this error at: https://sqlalche.me/e/20/e3q8)
2025-09-11 02:34:48.487 WARNING (MainThread) [homeassistant.setup] Setup of recorder is taking over 10 seconds.
2025-09-11 02:34:50.566 ERROR (Recorder) [homeassistant.components.recorder.core] Error during connection setup: (retrying in 3 seconds)
Traceback (most recent call last):
  File "/usr/local/lib/python3.13/site-packages/sqlalchemy/engine/base.py", line 145, in __init__
    self._dbapi_connection = engine.raw_connection()
                             ~~~~~~~~~~~~~~~~~~~~~^^
  File "/usr/local/lib/python3.13/site-packages/sqlalchemy/engine/base.py", line 3297, in raw_connection
    return self.pool.connect()
           ~~~~~~~~~~~~~~~~~^^
  File "/usr/local/lib/python3.13/site-packages/sqlalchemy/pool/base.py", line 449, in connect
    return _ConnectionFairy._checkout(self)
           ~~~~~~~~~~~~~~~~~~~~~~~~~~^^^^^^
  File "/usr/local/lib/python3.13/site-packages/sqlalchemy/pool/base.py", line 1264, in _checkout
    fairy = _ConnectionRecord.checkout(pool)
  File "/usr/local/lib/python3.13/site-packages/sqlalchemy/pool/base.py", line 713, in checkout
    rec = pool._do_get()
  File "/usr/local/lib/python3.13/site-packages/sqlalchemy/pool/impl.py", line 179, in _do_get
    with util.safe_reraise():
         ~~~~~~~~~~~~~~~~~^^
  File "/usr/local/lib/python3.13/site-packages/sqlalchemy/util/langhelpers.py", line 224, in __exit__
    raise exc_value.with_traceback(exc_tb)
  File "/usr/local/lib/python3.13/site-packages/sqlalchemy/pool/impl.py", line 177, in _do_get
    return self._create_connection()
           ~~~~~~~~~~~~~~~~~~~~~~~^^
  File "/usr/local/lib/python3.13/site-packages/sqlalchemy/pool/base.py", line 390, in _create_connection
    return _ConnectionRecord(self)
  File "/usr/local/lib/python3.13/site-packages/sqlalchemy/pool/base.py", line 675, in __init__
    self.__connect()
    ~~~~~~~~~~~~~~^^
  File "/usr/local/lib/python3.13/site-packages/sqlalchemy/pool/base.py", line 901, in __connect
    with util.safe_reraise():
         ~~~~~~~~~~~~~~~~~^^
  File "/usr/local/lib/python3.13/site-packages/sqlalchemy/util/langhelpers.py", line 224, in __exit__
    raise exc_value.with_traceback(exc_tb)
  File "/usr/local/lib/python3.13/site-packages/sqlalchemy/pool/base.py", line 897, in __connect
    self.dbapi_connection = connection = pool._invoke_creator(self)
                                         ~~~~~~~~~~~~~~~~~~~~^^^^^^
  File "/usr/local/lib/python3.13/site-packages/sqlalchemy/engine/create.py", line 646, in connect
    return dialect.connect(*cargs, **cparams)
           ~~~~~~~~~~~~~~~^^^^^^^^^^^^^^^^^^^
  File "/usr/local/lib/python3.13/site-packages/sqlalchemy/engine/default.py", line 625, in connect
    return self.loaded_dbapi.connect(*cargs, **cparams)  # type: ignore[no-any-return]  # NOQA: E501
           ~~~~~~~~~~~~~~~~~~~~~~~~~^^^^^^^^^^^^^^^^^^^
  File "/usr/local/lib/python3.13/site-packages/psycopg2/__init__.py", line 122, in connect
    conn = _connect(dsn, connection_factory=connection_factory, **kwasync)
psycopg2.OperationalError: connection to server at "172.21.0.3", port 5432 failed: Connection refused
	Is the server running on that host and accepting TCP/IP connections?


The above exception was the direct cause of the following exception:

Traceback (most recent call last):
  File "/usr/src/homeassistant/homeassistant/components/recorder/core.py", line 927, in _setup_recorder
    self._setup_connection()
    ~~~~~~~~~~~~~~~~~~~~~~^^
  File "/usr/src/homeassistant/homeassistant/components/recorder/core.py", line 1448, in _setup_connection
    migration.pre_migrate_schema(self.engine)
    ~~~~~~~~~~~~~~~~~~~~~~~~~~~~^^^^^^^^^^^^^
  File "/usr/src/homeassistant/homeassistant/components/recorder/migration.py", line 331, in pre_migrate_schema
    inspector = sqlalchemy.inspect(engine)
  File "/usr/local/lib/python3.13/site-packages/sqlalchemy/inspection.py", line 140, in inspect
    ret = reg(subject)
  File "/usr/local/lib/python3.13/site-packages/sqlalchemy/engine/reflection.py", line 313, in _engine_insp
    return Inspector._construct(Inspector._init_engine, bind)
           ~~~~~~~~~~~~~~~~~~~~^^^^^^^^^^^^^^^^^^^^^^^^^^^^^^
  File "/usr/local/lib/python3.13/site-packages/sqlalchemy/engine/reflection.py", line 246, in _construct
    init(self, bind)
    ~~~~^^^^^^^^^^^^
  File "/usr/local/lib/python3.13/site-packages/sqlalchemy/engine/reflection.py", line 257, in _init_engine
    engine.connect().close()
    ~~~~~~~~~~~~~~^^
  File "/usr/local/lib/python3.13/site-packages/sqlalchemy/engine/base.py", line 3273, in connect
    return self._connection_cls(self)
           ~~~~~~~~~~~~~~~~~~~~^^^^^^
  File "/usr/local/lib/python3.13/site-packages/sqlalchemy/engine/base.py", line 147, in __init__
    Connection._handle_dbapi_exception_noconnection(
    ~~~~~~~~~~~~~~~~~~~~~~~~~~~~~~~~~~~~~~~~~~~~~~~^
        err, dialect, engine
        ^^^^^^^^^^^^^^^^^^^^
    )
    ^
  File "/usr/local/lib/python3.13/site-packages/sqlalchemy/engine/base.py", line 2436, in _handle_dbapi_exception_noconnection
    raise sqlalchemy_exception.with_traceback(exc_info[2]) from e
  File "/usr/local/lib/python3.13/site-packages/sqlalchemy/engine/base.py", line 145, in __init__
    self._dbapi_connection = engine.raw_connection()
                             ~~~~~~~~~~~~~~~~~~~~~^^
  File "/usr/local/lib/python3.13/site-packages/sqlalchemy/engine/base.py", line 3297, in raw_connection
    return self.pool.connect()
           ~~~~~~~~~~~~~~~~~^^
  File "/usr/local/lib/python3.13/site-packages/sqlalchemy/pool/base.py", line 449, in connect
    return _ConnectionFairy._checkout(self)
           ~~~~~~~~~~~~~~~~~~~~~~~~~~^^^^^^
  File "/usr/local/lib/python3.13/site-packages/sqlalchemy/pool/base.py", line 1264, in _checkout
    fairy = _ConnectionRecord.checkout(pool)
  File "/usr/local/lib/python3.13/site-packages/sqlalchemy/pool/base.py", line 713, in checkout
    rec = pool._do_get()
  File "/usr/local/lib/python3.13/site-packages/sqlalchemy/pool/impl.py", line 179, in _do_get
    with util.safe_reraise():
         ~~~~~~~~~~~~~~~~~^^
  File "/usr/local/lib/python3.13/site-packages/sqlalchemy/util/langhelpers.py", line 224, in __exit__
    raise exc_value.with_traceback(exc_tb)
  File "/usr/local/lib/python3.13/site-packages/sqlalchemy/pool/impl.py", line 177, in _do_get
    return self._create_connection()
           ~~~~~~~~~~~~~~~~~~~~~~~^^
  File "/usr/local/lib/python3.13/site-packages/sqlalchemy/pool/base.py", line 390, in _create_connection
    return _ConnectionRecord(self)
  File "/usr/local/lib/python3.13/site-packages/sqlalchemy/pool/base.py", line 675, in __init__
    self.__connect()
    ~~~~~~~~~~~~~~^^
  File "/usr/local/lib/python3.13/site-packages/sqlalchemy/pool/base.py", line 901, in __connect
    with util.safe_reraise():
         ~~~~~~~~~~~~~~~~~^^
  File "/usr/local/lib/python3.13/site-packages/sqlalchemy/util/langhelpers.py", line 224, in __exit__
    raise exc_value.with_traceback(exc_tb)
  File "/usr/local/lib/python3.13/site-packages/sqlalchemy/pool/base.py", line 897, in __connect
    self.dbapi_connection = connection = pool._invoke_creator(self)
                                         ~~~~~~~~~~~~~~~~~~~~^^^^^^
  File "/usr/local/lib/python3.13/site-packages/sqlalchemy/engine/create.py", line 646, in connect
    return dialect.connect(*cargs, **cparams)
           ~~~~~~~~~~~~~~~^^^^^^^^^^^^^^^^^^^
  File "/usr/local/lib/python3.13/site-packages/sqlalchemy/engine/default.py", line 625, in connect
    return self.loaded_dbapi.connect(*cargs, **cparams)  # type: ignore[no-any-return]  # NOQA: E501
           ~~~~~~~~~~~~~~~~~~~~~~~~~^^^^^^^^^^^^^^^^^^^
  File "/usr/local/lib/python3.13/site-packages/psycopg2/__init__.py", line 122, in connect
    conn = _connect(dsn, connection_factory=connection_factory, **kwasync)
sqlalchemy.exc.OperationalError: (psycopg2.OperationalError) connection to server at "172.21.0.3", port 5432 failed: Connection refused
	Is the server running on that host and accepting TCP/IP connections?

(Background on this error at: https://sqlalche.me/e/20/e3q8)
2025-09-11 02:34:53.576 ERROR (Recorder) [homeassistant.components.recorder.core] Error during connection setup: (retrying in 3 seconds)
Traceback (most recent call last):
  File "/usr/local/lib/python3.13/site-packages/sqlalchemy/engine/base.py", line 145, in __init__
    self._dbapi_connection = engine.raw_connection()
                             ~~~~~~~~~~~~~~~~~~~~~^^
  File "/usr/local/lib/python3.13/site-packages/sqlalchemy/engine/base.py", line 3297, in raw_connection
    return self.pool.connect()
           ~~~~~~~~~~~~~~~~~^^
  File "/usr/local/lib/python3.13/site-packages/sqlalchemy/pool/base.py", line 449, in connect
    return _ConnectionFairy._checkout(self)
           ~~~~~~~~~~~~~~~~~~~~~~~~~~^^^^^^
  File "/usr/local/lib/python3.13/site-packages/sqlalchemy/pool/base.py", line 1264, in _checkout
    fairy = _ConnectionRecord.checkout(pool)
  File "/usr/local/lib/python3.13/site-packages/sqlalchemy/pool/base.py", line 713, in checkout
    rec = pool._do_get()
  File "/usr/local/lib/python3.13/site-packages/sqlalchemy/pool/impl.py", line 179, in _do_get
    with util.safe_reraise():
         ~~~~~~~~~~~~~~~~~^^
  File "/usr/local/lib/python3.13/site-packages/sqlalchemy/util/langhelpers.py", line 224, in __exit__
    raise exc_value.with_traceback(exc_tb)
  File "/usr/local/lib/python3.13/site-packages/sqlalchemy/pool/impl.py", line 177, in _do_get
    return self._create_connection()
           ~~~~~~~~~~~~~~~~~~~~~~~^^
  File "/usr/local/lib/python3.13/site-packages/sqlalchemy/pool/base.py", line 390, in _create_connection
    return _ConnectionRecord(self)
  File "/usr/local/lib/python3.13/site-packages/sqlalchemy/pool/base.py", line 675, in __init__
    self.__connect()
    ~~~~~~~~~~~~~~^^
  File "/usr/local/lib/python3.13/site-packages/sqlalchemy/pool/base.py", line 901, in __connect
    with util.safe_reraise():
         ~~~~~~~~~~~~~~~~~^^
  File "/usr/local/lib/python3.13/site-packages/sqlalchemy/util/langhelpers.py", line 224, in __exit__
    raise exc_value.with_traceback(exc_tb)
  File "/usr/local/lib/python3.13/site-packages/sqlalchemy/pool/base.py", line 897, in __connect
    self.dbapi_connection = connection = pool._invoke_creator(self)
                                         ~~~~~~~~~~~~~~~~~~~~^^^^^^
  File "/usr/local/lib/python3.13/site-packages/sqlalchemy/engine/create.py", line 646, in connect
    return dialect.connect(*cargs, **cparams)
           ~~~~~~~~~~~~~~~^^^^^^^^^^^^^^^^^^^
  File "/usr/local/lib/python3.13/site-packages/sqlalchemy/engine/default.py", line 625, in connect
    return self.loaded_dbapi.connect(*cargs, **cparams)  # type: ignore[no-any-return]  # NOQA: E501
           ~~~~~~~~~~~~~~~~~~~~~~~~~^^^^^^^^^^^^^^^^^^^
  File "/usr/local/lib/python3.13/site-packages/psycopg2/__init__.py", line 122, in connect
    conn = _connect(dsn, connection_factory=connection_factory, **kwasync)
psycopg2.OperationalError: connection to server at "172.21.0.3", port 5432 failed: Connection refused
	Is the server running on that host and accepting TCP/IP connections?


The above exception was the direct cause of the following exception:

Traceback (most recent call last):
  File "/usr/src/homeassistant/homeassistant/components/recorder/core.py", line 927, in _setup_recorder
    self._setup_connection()
    ~~~~~~~~~~~~~~~~~~~~~~^^
  File "/usr/src/homeassistant/homeassistant/components/recorder/core.py", line 1448, in _setup_connection
    migration.pre_migrate_schema(self.engine)
    ~~~~~~~~~~~~~~~~~~~~~~~~~~~~^^^^^^^^^^^^^
  File "/usr/src/homeassistant/homeassistant/components/recorder/migration.py", line 331, in pre_migrate_schema
    inspector = sqlalchemy.inspect(engine)
  File "/usr/local/lib/python3.13/site-packages/sqlalchemy/inspection.py", line 140, in inspect
    ret = reg(subject)
  File "/usr/local/lib/python3.13/site-packages/sqlalchemy/engine/reflection.py", line 313, in _engine_insp
    return Inspector._construct(Inspector._init_engine, bind)
           ~~~~~~~~~~~~~~~~~~~~^^^^^^^^^^^^^^^^^^^^^^^^^^^^^^
  File "/usr/local/lib/python3.13/site-packages/sqlalchemy/engine/reflection.py", line 246, in _construct
    init(self, bind)
    ~~~~^^^^^^^^^^^^
  File "/usr/local/lib/python3.13/site-packages/sqlalchemy/engine/reflection.py", line 257, in _init_engine
    engine.connect().close()
    ~~~~~~~~~~~~~~^^
  File "/usr/local/lib/python3.13/site-packages/sqlalchemy/engine/base.py", line 3273, in connect
    return self._connection_cls(self)
           ~~~~~~~~~~~~~~~~~~~~^^^^^^
  File "/usr/local/lib/python3.13/site-packages/sqlalchemy/engine/base.py", line 147, in __init__
    Connection._handle_dbapi_exception_noconnection(
    ~~~~~~~~~~~~~~~~~~~~~~~~~~~~~~~~~~~~~~~~~~~~~~~^
        err, dialect, engine
        ^^^^^^^^^^^^^^^^^^^^
    )
    ^
  File "/usr/local/lib/python3.13/site-packages/sqlalchemy/engine/base.py", line 2436, in _handle_dbapi_exception_noconnection
    raise sqlalchemy_exception.with_traceback(exc_info[2]) from e
  File "/usr/local/lib/python3.13/site-packages/sqlalchemy/engine/base.py", line 145, in __init__
    self._dbapi_connection = engine.raw_connection()
                             ~~~~~~~~~~~~~~~~~~~~~^^
  File "/usr/local/lib/python3.13/site-packages/sqlalchemy/engine/base.py", line 3297, in raw_connection
    return self.pool.connect()
           ~~~~~~~~~~~~~~~~~^^
  File "/usr/local/lib/python3.13/site-packages/sqlalchemy/pool/base.py", line 449, in connect
    return _ConnectionFairy._checkout(self)
           ~~~~~~~~~~~~~~~~~~~~~~~~~~^^^^^^
  File "/usr/local/lib/python3.13/site-packages/sqlalchemy/pool/base.py", line 1264, in _checkout
    fairy = _ConnectionRecord.checkout(pool)
  File "/usr/local/lib/python3.13/site-packages/sqlalchemy/pool/base.py", line 713, in checkout
    rec = pool._do_get()
  File "/usr/local/lib/python3.13/site-packages/sqlalchemy/pool/impl.py", line 179, in _do_get
    with util.safe_reraise():
         ~~~~~~~~~~~~~~~~~^^
  File "/usr/local/lib/python3.13/site-packages/sqlalchemy/util/langhelpers.py", line 224, in __exit__
    raise exc_value.with_traceback(exc_tb)
  File "/usr/local/lib/python3.13/site-packages/sqlalchemy/pool/impl.py", line 177, in _do_get
    return self._create_connection()
           ~~~~~~~~~~~~~~~~~~~~~~~^^
  File "/usr/local/lib/python3.13/site-packages/sqlalchemy/pool/base.py", line 390, in _create_connection
    return _ConnectionRecord(self)
  File "/usr/local/lib/python3.13/site-packages/sqlalchemy/pool/base.py", line 675, in __init__
    self.__connect()
    ~~~~~~~~~~~~~~^^
  File "/usr/local/lib/python3.13/site-packages/sqlalchemy/pool/base.py", line 901, in __connect
    with util.safe_reraise():
         ~~~~~~~~~~~~~~~~~^^
  File "/usr/local/lib/python3.13/site-packages/sqlalchemy/util/langhelpers.py", line 224, in __exit__
    raise exc_value.with_traceback(exc_tb)
  File "/usr/local/lib/python3.13/site-packages/sqlalchemy/pool/base.py", line 897, in __connect
    self.dbapi_connection = connection = pool._invoke_creator(self)
                                         ~~~~~~~~~~~~~~~~~~~~^^^^^^
  File "/usr/local/lib/python3.13/site-packages/sqlalchemy/engine/create.py", line 646, in connect
    return dialect.connect(*cargs, **cparams)
           ~~~~~~~~~~~~~~~^^^^^^^^^^^^^^^^^^^
  File "/usr/local/lib/python3.13/site-packages/sqlalchemy/engine/default.py", line 625, in connect
    return self.loaded_dbapi.connect(*cargs, **cparams)  # type: ignore[no-any-return]  # NOQA: E501
           ~~~~~~~~~~~~~~~~~~~~~~~~~^^^^^^^^^^^^^^^^^^^
  File "/usr/local/lib/python3.13/site-packages/psycopg2/__init__.py", line 122, in connect
    conn = _connect(dsn, connection_factory=connection_factory, **kwasync)
sqlalchemy.exc.OperationalError: (psycopg2.OperationalError) connection to server at "172.21.0.3", port 5432 failed: Connection refused
	Is the server running on that host and accepting TCP/IP connections?

(Background on this error at: https://sqlalche.me/e/20/e3q8)
2025-09-11 02:34:56.587 ERROR (Recorder) [homeassistant.components.recorder.core] Error during connection setup: (retrying in 3 seconds)
Traceback (most recent call last):
  File "/usr/local/lib/python3.13/site-packages/sqlalchemy/engine/base.py", line 145, in __init__
    self._dbapi_connection = engine.raw_connection()
                             ~~~~~~~~~~~~~~~~~~~~~^^
  File "/usr/local/lib/python3.13/site-packages/sqlalchemy/engine/base.py", line 3297, in raw_connection
    return self.pool.connect()
           ~~~~~~~~~~~~~~~~~^^
  File "/usr/local/lib/python3.13/site-packages/sqlalchemy/pool/base.py", line 449, in connect
    return _ConnectionFairy._checkout(self)
           ~~~~~~~~~~~~~~~~~~~~~~~~~~^^^^^^
  File "/usr/local/lib/python3.13/site-packages/sqlalchemy/pool/base.py", line 1264, in _checkout
    fairy = _ConnectionRecord.checkout(pool)
  File "/usr/local/lib/python3.13/site-packages/sqlalchemy/pool/base.py", line 713, in checkout
    rec = pool._do_get()
  File "/usr/local/lib/python3.13/site-packages/sqlalchemy/pool/impl.py", line 179, in _do_get
    with util.safe_reraise():
         ~~~~~~~~~~~~~~~~~^^
  File "/usr/local/lib/python3.13/site-packages/sqlalchemy/util/langhelpers.py", line 224, in __exit__
    raise exc_value.with_traceback(exc_tb)
  File "/usr/local/lib/python3.13/site-packages/sqlalchemy/pool/impl.py", line 177, in _do_get
    return self._create_connection()
           ~~~~~~~~~~~~~~~~~~~~~~~^^
  File "/usr/local/lib/python3.13/site-packages/sqlalchemy/pool/base.py", line 390, in _create_connection
    return _ConnectionRecord(self)
  File "/usr/local/lib/python3.13/site-packages/sqlalchemy/pool/base.py", line 675, in __init__
    self.__connect()
    ~~~~~~~~~~~~~~^^
  File "/usr/local/lib/python3.13/site-packages/sqlalchemy/pool/base.py", line 901, in __connect
    with util.safe_reraise():
         ~~~~~~~~~~~~~~~~~^^
  File "/usr/local/lib/python3.13/site-packages/sqlalchemy/util/langhelpers.py", line 224, in __exit__
    raise exc_value.with_traceback(exc_tb)
  File "/usr/local/lib/python3.13/site-packages/sqlalchemy/pool/base.py", line 897, in __connect
    self.dbapi_connection = connection = pool._invoke_creator(self)
                                         ~~~~~~~~~~~~~~~~~~~~^^^^^^
  File "/usr/local/lib/python3.13/site-packages/sqlalchemy/engine/create.py", line 646, in connect
    return dialect.connect(*cargs, **cparams)
           ~~~~~~~~~~~~~~~^^^^^^^^^^^^^^^^^^^
  File "/usr/local/lib/python3.13/site-packages/sqlalchemy/engine/default.py", line 625, in connect
    return self.loaded_dbapi.connect(*cargs, **cparams)  # type: ignore[no-any-return]  # NOQA: E501
           ~~~~~~~~~~~~~~~~~~~~~~~~~^^^^^^^^^^^^^^^^^^^
  File "/usr/local/lib/python3.13/site-packages/psycopg2/__init__.py", line 122, in connect
    conn = _connect(dsn, connection_factory=connection_factory, **kwasync)
psycopg2.OperationalError: connection to server at "172.21.0.3", port 5432 failed: Connection refused
	Is the server running on that host and accepting TCP/IP connections?


The above exception was the direct cause of the following exception:

Traceback (most recent call last):
  File "/usr/src/homeassistant/homeassistant/components/recorder/core.py", line 927, in _setup_recorder
    self._setup_connection()
    ~~~~~~~~~~~~~~~~~~~~~~^^
  File "/usr/src/homeassistant/homeassistant/components/recorder/core.py", line 1448, in _setup_connection
    migration.pre_migrate_schema(self.engine)
    ~~~~~~~~~~~~~~~~~~~~~~~~~~~~^^^^^^^^^^^^^
  File "/usr/src/homeassistant/homeassistant/components/recorder/migration.py", line 331, in pre_migrate_schema
    inspector = sqlalchemy.inspect(engine)
  File "/usr/local/lib/python3.13/site-packages/sqlalchemy/inspection.py", line 140, in inspect
    ret = reg(subject)
  File "/usr/local/lib/python3.13/site-packages/sqlalchemy/engine/reflection.py", line 313, in _engine_insp
    return Inspector._construct(Inspector._init_engine, bind)
           ~~~~~~~~~~~~~~~~~~~~^^^^^^^^^^^^^^^^^^^^^^^^^^^^^^
  File "/usr/local/lib/python3.13/site-packages/sqlalchemy/engine/reflection.py", line 246, in _construct
    init(self, bind)
    ~~~~^^^^^^^^^^^^
  File "/usr/local/lib/python3.13/site-packages/sqlalchemy/engine/reflection.py", line 257, in _init_engine
    engine.connect().close()
    ~~~~~~~~~~~~~~^^
  File "/usr/local/lib/python3.13/site-packages/sqlalchemy/engine/base.py", line 3273, in connect
    return self._connection_cls(self)
           ~~~~~~~~~~~~~~~~~~~~^^^^^^
  File "/usr/local/lib/python3.13/site-packages/sqlalchemy/engine/base.py", line 147, in __init__
    Connection._handle_dbapi_exception_noconnection(
    ~~~~~~~~~~~~~~~~~~~~~~~~~~~~~~~~~~~~~~~~~~~~~~~^
        err, dialect, engine
        ^^^^^^^^^^^^^^^^^^^^
    )
    ^
  File "/usr/local/lib/python3.13/site-packages/sqlalchemy/engine/base.py", line 2436, in _handle_dbapi_exception_noconnection
    raise sqlalchemy_exception.with_traceback(exc_info[2]) from e
  File "/usr/local/lib/python3.13/site-packages/sqlalchemy/engine/base.py", line 145, in __init__
    self._dbapi_connection = engine.raw_connection()
                             ~~~~~~~~~~~~~~~~~~~~~^^
  File "/usr/local/lib/python3.13/site-packages/sqlalchemy/engine/base.py", line 3297, in raw_connection
    return self.pool.connect()
           ~~~~~~~~~~~~~~~~~^^
  File "/usr/local/lib/python3.13/site-packages/sqlalchemy/pool/base.py", line 449, in connect
    return _ConnectionFairy._checkout(self)
           ~~~~~~~~~~~~~~~~~~~~~~~~~~^^^^^^
  File "/usr/local/lib/python3.13/site-packages/sqlalchemy/pool/base.py", line 1264, in _checkout
    fairy = _ConnectionRecord.checkout(pool)
  File "/usr/local/lib/python3.13/site-packages/sqlalchemy/pool/base.py", line 713, in checkout
    rec = pool._do_get()
  File "/usr/local/lib/python3.13/site-packages/sqlalchemy/pool/impl.py", line 179, in _do_get
    with util.safe_reraise():
         ~~~~~~~~~~~~~~~~~^^
  File "/usr/local/lib/python3.13/site-packages/sqlalchemy/util/langhelpers.py", line 224, in __exit__
    raise exc_value.with_traceback(exc_tb)
  File "/usr/local/lib/python3.13/site-packages/sqlalchemy/pool/impl.py", line 177, in _do_get
    return self._create_connection()
           ~~~~~~~~~~~~~~~~~~~~~~~^^
  File "/usr/local/lib/python3.13/site-packages/sqlalchemy/pool/base.py", line 390, in _create_connection
    return _ConnectionRecord(self)
  File "/usr/local/lib/python3.13/site-packages/sqlalchemy/pool/base.py", line 675, in __init__
    self.__connect()
    ~~~~~~~~~~~~~~^^
  File "/usr/local/lib/python3.13/site-packages/sqlalchemy/pool/base.py", line 901, in __connect
    with util.safe_reraise():
         ~~~~~~~~~~~~~~~~~^^
  File "/usr/local/lib/python3.13/site-packages/sqlalchemy/util/langhelpers.py", line 224, in __exit__
    raise exc_value.with_traceback(exc_tb)
  File "/usr/local/lib/python3.13/site-packages/sqlalchemy/pool/base.py", line 897, in __connect
    self.dbapi_connection = connection = pool._invoke_creator(self)
                                         ~~~~~~~~~~~~~~~~~~~~^^^^^^
  File "/usr/local/lib/python3.13/site-packages/sqlalchemy/engine/create.py", line 646, in connect
    return dialect.connect(*cargs, **cparams)
           ~~~~~~~~~~~~~~~^^^^^^^^^^^^^^^^^^^
  File "/usr/local/lib/python3.13/site-packages/sqlalchemy/engine/default.py", line 625, in connect
    return self.loaded_dbapi.connect(*cargs, **cparams)  # type: ignore[no-any-return]  # NOQA: E501
           ~~~~~~~~~~~~~~~~~~~~~~~~~^^^^^^^^^^^^^^^^^^^
  File "/usr/local/lib/python3.13/site-packages/psycopg2/__init__.py", line 122, in connect
    conn = _connect(dsn, connection_factory=connection_factory, **kwasync)
sqlalchemy.exc.OperationalError: (psycopg2.OperationalError) connection to server at "172.21.0.3", port 5432 failed: Connection refused
	Is the server running on that host and accepting TCP/IP connections?

(Background on this error at: https://sqlalche.me/e/20/e3q8)
2025-09-11 02:34:59.602 ERROR (Recorder) [homeassistant.components.recorder.core] Error during connection setup: (retrying in 3 seconds)
Traceback (most recent call last):
  File "/usr/local/lib/python3.13/site-packages/sqlalchemy/engine/base.py", line 145, in __init__
    self._dbapi_connection = engine.raw_connection()
                             ~~~~~~~~~~~~~~~~~~~~~^^
  File "/usr/local/lib/python3.13/site-packages/sqlalchemy/engine/base.py", line 3297, in raw_connection
    return self.pool.connect()
           ~~~~~~~~~~~~~~~~~^^
  File "/usr/local/lib/python3.13/site-packages/sqlalchemy/pool/base.py", line 449, in connect
    return _ConnectionFairy._checkout(self)
           ~~~~~~~~~~~~~~~~~~~~~~~~~~^^^^^^
  File "/usr/local/lib/python3.13/site-packages/sqlalchemy/pool/base.py", line 1264, in _checkout
    fairy = _ConnectionRecord.checkout(pool)
  File "/usr/local/lib/python3.13/site-packages/sqlalchemy/pool/base.py", line 713, in checkout
    rec = pool._do_get()
  File "/usr/local/lib/python3.13/site-packages/sqlalchemy/pool/impl.py", line 179, in _do_get
    with util.safe_reraise():
         ~~~~~~~~~~~~~~~~~^^
  File "/usr/local/lib/python3.13/site-packages/sqlalchemy/util/langhelpers.py", line 224, in __exit__
    raise exc_value.with_traceback(exc_tb)
  File "/usr/local/lib/python3.13/site-packages/sqlalchemy/pool/impl.py", line 177, in _do_get
    return self._create_connection()
           ~~~~~~~~~~~~~~~~~~~~~~~^^
  File "/usr/local/lib/python3.13/site-packages/sqlalchemy/pool/base.py", line 390, in _create_connection
    return _ConnectionRecord(self)
  File "/usr/local/lib/python3.13/site-packages/sqlalchemy/pool/base.py", line 675, in __init__
    self.__connect()
    ~~~~~~~~~~~~~~^^
  File "/usr/local/lib/python3.13/site-packages/sqlalchemy/pool/base.py", line 901, in __connect
    with util.safe_reraise():
         ~~~~~~~~~~~~~~~~~^^
  File "/usr/local/lib/python3.13/site-packages/sqlalchemy/util/langhelpers.py", line 224, in __exit__
    raise exc_value.with_traceback(exc_tb)
  File "/usr/local/lib/python3.13/site-packages/sqlalchemy/pool/base.py", line 897, in __connect
    self.dbapi_connection = connection = pool._invoke_creator(self)
                                         ~~~~~~~~~~~~~~~~~~~~^^^^^^
  File "/usr/local/lib/python3.13/site-packages/sqlalchemy/engine/create.py", line 646, in connect
    return dialect.connect(*cargs, **cparams)
           ~~~~~~~~~~~~~~~^^^^^^^^^^^^^^^^^^^
  File "/usr/local/lib/python3.13/site-packages/sqlalchemy/engine/default.py", line 625, in connect
    return self.loaded_dbapi.connect(*cargs, **cparams)  # type: ignore[no-any-return]  # NOQA: E501
           ~~~~~~~~~~~~~~~~~~~~~~~~~^^^^^^^^^^^^^^^^^^^
  File "/usr/local/lib/python3.13/site-packages/psycopg2/__init__.py", line 122, in connect
    conn = _connect(dsn, connection_factory=connection_factory, **kwasync)
psycopg2.OperationalError: connection to server at "172.21.0.3", port 5432 failed: Connection refused
	Is the server running on that host and accepting TCP/IP connections?


The above exception was the direct cause of the following exception:

Traceback (most recent call last):
  File "/usr/src/homeassistant/homeassistant/components/recorder/core.py", line 927, in _setup_recorder
    self._setup_connection()
    ~~~~~~~~~~~~~~~~~~~~~~^^
  File "/usr/src/homeassistant/homeassistant/components/recorder/core.py", line 1448, in _setup_connection
    migration.pre_migrate_schema(self.engine)
    ~~~~~~~~~~~~~~~~~~~~~~~~~~~~^^^^^^^^^^^^^
  File "/usr/src/homeassistant/homeassistant/components/recorder/migration.py", line 331, in pre_migrate_schema
    inspector = sqlalchemy.inspect(engine)
  File "/usr/local/lib/python3.13/site-packages/sqlalchemy/inspection.py", line 140, in inspect
    ret = reg(subject)
  File "/usr/local/lib/python3.13/site-packages/sqlalchemy/engine/reflection.py", line 313, in _engine_insp
    return Inspector._construct(Inspector._init_engine, bind)
           ~~~~~~~~~~~~~~~~~~~~^^^^^^^^^^^^^^^^^^^^^^^^^^^^^^
  File "/usr/local/lib/python3.13/site-packages/sqlalchemy/engine/reflection.py", line 246, in _construct
    init(self, bind)
    ~~~~^^^^^^^^^^^^
  File "/usr/local/lib/python3.13/site-packages/sqlalchemy/engine/reflection.py", line 257, in _init_engine
    engine.connect().close()
    ~~~~~~~~~~~~~~^^
  File "/usr/local/lib/python3.13/site-packages/sqlalchemy/engine/base.py", line 3273, in connect
    return self._connection_cls(self)
           ~~~~~~~~~~~~~~~~~~~~^^^^^^
  File "/usr/local/lib/python3.13/site-packages/sqlalchemy/engine/base.py", line 147, in __init__
    Connection._handle_dbapi_exception_noconnection(
    ~~~~~~~~~~~~~~~~~~~~~~~~~~~~~~~~~~~~~~~~~~~~~~~^
        err, dialect, engine
        ^^^^^^^^^^^^^^^^^^^^
    )
    ^
  File "/usr/local/lib/python3.13/site-packages/sqlalchemy/engine/base.py", line 2436, in _handle_dbapi_exception_noconnection
    raise sqlalchemy_exception.with_traceback(exc_info[2]) from e
  File "/usr/local/lib/python3.13/site-packages/sqlalchemy/engine/base.py", line 145, in __init__
    self._dbapi_connection = engine.raw_connection()
                             ~~~~~~~~~~~~~~~~~~~~~^^
  File "/usr/local/lib/python3.13/site-packages/sqlalchemy/engine/base.py", line 3297, in raw_connection
    return self.pool.connect()
           ~~~~~~~~~~~~~~~~~^^
  File "/usr/local/lib/python3.13/site-packages/sqlalchemy/pool/base.py", line 449, in connect
    return _ConnectionFairy._checkout(self)
           ~~~~~~~~~~~~~~~~~~~~~~~~~~^^^^^^
  File "/usr/local/lib/python3.13/site-packages/sqlalchemy/pool/base.py", line 1264, in _checkout
    fairy = _ConnectionRecord.checkout(pool)
  File "/usr/local/lib/python3.13/site-packages/sqlalchemy/pool/base.py", line 713, in checkout
    rec = pool._do_get()
  File "/usr/local/lib/python3.13/site-packages/sqlalchemy/pool/impl.py", line 179, in _do_get
    with util.safe_reraise():
         ~~~~~~~~~~~~~~~~~^^
  File "/usr/local/lib/python3.13/site-packages/sqlalchemy/util/langhelpers.py", line 224, in __exit__
    raise exc_value.with_traceback(exc_tb)
  File "/usr/local/lib/python3.13/site-packages/sqlalchemy/pool/impl.py", line 177, in _do_get
    return self._create_connection()
           ~~~~~~~~~~~~~~~~~~~~~~~^^
  File "/usr/local/lib/python3.13/site-packages/sqlalchemy/pool/base.py", line 390, in _create_connection
    return _ConnectionRecord(self)
  File "/usr/local/lib/python3.13/site-packages/sqlalchemy/pool/base.py", line 675, in __init__
    self.__connect()
    ~~~~~~~~~~~~~~^^
  File "/usr/local/lib/python3.13/site-packages/sqlalchemy/pool/base.py", line 901, in __connect
    with util.safe_reraise():
         ~~~~~~~~~~~~~~~~~^^
  File "/usr/local/lib/python3.13/site-packages/sqlalchemy/util/langhelpers.py", line 224, in __exit__
    raise exc_value.with_traceback(exc_tb)
  File "/usr/local/lib/python3.13/site-packages/sqlalchemy/pool/base.py", line 897, in __connect
    self.dbapi_connection = connection = pool._invoke_creator(self)
                                         ~~~~~~~~~~~~~~~~~~~~^^^^^^
  File "/usr/local/lib/python3.13/site-packages/sqlalchemy/engine/create.py", line 646, in connect
    return dialect.connect(*cargs, **cparams)
           ~~~~~~~~~~~~~~~^^^^^^^^^^^^^^^^^^^
  File "/usr/local/lib/python3.13/site-packages/sqlalchemy/engine/default.py", line 625, in connect
    return self.loaded_dbapi.connect(*cargs, **cparams)  # type: ignore[no-any-return]  # NOQA: E501
           ~~~~~~~~~~~~~~~~~~~~~~~~~^^^^^^^^^^^^^^^^^^^
  File "/usr/local/lib/python3.13/site-packages/psycopg2/__init__.py", line 122, in connect
    conn = _connect(dsn, connection_factory=connection_factory, **kwasync)
sqlalchemy.exc.OperationalError: (psycopg2.OperationalError) connection to server at "172.21.0.3", port 5432 failed: Connection refused
	Is the server running on that host and accepting TCP/IP connections?

(Background on this error at: https://sqlalche.me/e/20/e3q8)
2025-09-11 02:35:02.612 ERROR (Recorder) [homeassistant.components.recorder.core] Error during connection setup: (retrying in 3 seconds)
Traceback (most recent call last):
  File "/usr/local/lib/python3.13/site-packages/sqlalchemy/engine/base.py", line 145, in __init__
    self._dbapi_connection = engine.raw_connection()
                             ~~~~~~~~~~~~~~~~~~~~~^^
  File "/usr/local/lib/python3.13/site-packages/sqlalchemy/engine/base.py", line 3297, in raw_connection
    return self.pool.connect()
           ~~~~~~~~~~~~~~~~~^^
  File "/usr/local/lib/python3.13/site-packages/sqlalchemy/pool/base.py", line 449, in connect
    return _ConnectionFairy._checkout(self)
           ~~~~~~~~~~~~~~~~~~~~~~~~~~^^^^^^
  File "/usr/local/lib/python3.13/site-packages/sqlalchemy/pool/base.py", line 1264, in _checkout
    fairy = _ConnectionRecord.checkout(pool)
  File "/usr/local/lib/python3.13/site-packages/sqlalchemy/pool/base.py", line 713, in checkout
    rec = pool._do_get()
  File "/usr/local/lib/python3.13/site-packages/sqlalchemy/pool/impl.py", line 179, in _do_get
    with util.safe_reraise():
         ~~~~~~~~~~~~~~~~~^^
  File "/usr/local/lib/python3.13/site-packages/sqlalchemy/util/langhelpers.py", line 224, in __exit__
    raise exc_value.with_traceback(exc_tb)
  File "/usr/local/lib/python3.13/site-packages/sqlalchemy/pool/impl.py", line 177, in _do_get
    return self._create_connection()
           ~~~~~~~~~~~~~~~~~~~~~~~^^
  File "/usr/local/lib/python3.13/site-packages/sqlalchemy/pool/base.py", line 390, in _create_connection
    return _ConnectionRecord(self)
  File "/usr/local/lib/python3.13/site-packages/sqlalchemy/pool/base.py", line 675, in __init__
    self.__connect()
    ~~~~~~~~~~~~~~^^
  File "/usr/local/lib/python3.13/site-packages/sqlalchemy/pool/base.py", line 901, in __connect
    with util.safe_reraise():
         ~~~~~~~~~~~~~~~~~^^
  File "/usr/local/lib/python3.13/site-packages/sqlalchemy/util/langhelpers.py", line 224, in __exit__
    raise exc_value.with_traceback(exc_tb)
  File "/usr/local/lib/python3.13/site-packages/sqlalchemy/pool/base.py", line 897, in __connect
    self.dbapi_connection = connection = pool._invoke_creator(self)
                                         ~~~~~~~~~~~~~~~~~~~~^^^^^^
  File "/usr/local/lib/python3.13/site-packages/sqlalchemy/engine/create.py", line 646, in connect
    return dialect.connect(*cargs, **cparams)
           ~~~~~~~~~~~~~~~^^^^^^^^^^^^^^^^^^^
  File "/usr/local/lib/python3.13/site-packages/sqlalchemy/engine/default.py", line 625, in connect
    return self.loaded_dbapi.connect(*cargs, **cparams)  # type: ignore[no-any-return]  # NOQA: E501
           ~~~~~~~~~~~~~~~~~~~~~~~~~^^^^^^^^^^^^^^^^^^^
  File "/usr/local/lib/python3.13/site-packages/psycopg2/__init__.py", line 122, in connect
    conn = _connect(dsn, connection_factory=connection_factory, **kwasync)
psycopg2.OperationalError: connection to server at "172.21.0.3", port 5432 failed: Connection refused
	Is the server running on that host and accepting TCP/IP connections?


The above exception was the direct cause of the following exception:

Traceback (most recent call last):
  File "/usr/src/homeassistant/homeassistant/components/recorder/core.py", line 927, in _setup_recorder
    self._setup_connection()
    ~~~~~~~~~~~~~~~~~~~~~~^^
  File "/usr/src/homeassistant/homeassistant/components/recorder/core.py", line 1448, in _setup_connection
    migration.pre_migrate_schema(self.engine)
    ~~~~~~~~~~~~~~~~~~~~~~~~~~~~^^^^^^^^^^^^^
  File "/usr/src/homeassistant/homeassistant/components/recorder/migration.py", line 331, in pre_migrate_schema
    inspector = sqlalchemy.inspect(engine)
  File "/usr/local/lib/python3.13/site-packages/sqlalchemy/inspection.py", line 140, in inspect
    ret = reg(subject)
  File "/usr/local/lib/python3.13/site-packages/sqlalchemy/engine/reflection.py", line 313, in _engine_insp
    return Inspector._construct(Inspector._init_engine, bind)
           ~~~~~~~~~~~~~~~~~~~~^^^^^^^^^^^^^^^^^^^^^^^^^^^^^^
  File "/usr/local/lib/python3.13/site-packages/sqlalchemy/engine/reflection.py", line 246, in _construct
    init(self, bind)
    ~~~~^^^^^^^^^^^^
  File "/usr/local/lib/python3.13/site-packages/sqlalchemy/engine/reflection.py", line 257, in _init_engine
    engine.connect().close()
    ~~~~~~~~~~~~~~^^
  File "/usr/local/lib/python3.13/site-packages/sqlalchemy/engine/base.py", line 3273, in connect
    return self._connection_cls(self)
           ~~~~~~~~~~~~~~~~~~~~^^^^^^
  File "/usr/local/lib/python3.13/site-packages/sqlalchemy/engine/base.py", line 147, in __init__
    Connection._handle_dbapi_exception_noconnection(
    ~~~~~~~~~~~~~~~~~~~~~~~~~~~~~~~~~~~~~~~~~~~~~~~^
        err, dialect, engine
        ^^^^^^^^^^^^^^^^^^^^
    )
    ^
  File "/usr/local/lib/python3.13/site-packages/sqlalchemy/engine/base.py", line 2436, in _handle_dbapi_exception_noconnection
    raise sqlalchemy_exception.with_traceback(exc_info[2]) from e
  File "/usr/local/lib/python3.13/site-packages/sqlalchemy/engine/base.py", line 145, in __init__
    self._dbapi_connection = engine.raw_connection()
                             ~~~~~~~~~~~~~~~~~~~~~^^
  File "/usr/local/lib/python3.13/site-packages/sqlalchemy/engine/base.py", line 3297, in raw_connection
    return self.pool.connect()
           ~~~~~~~~~~~~~~~~~^^
  File "/usr/local/lib/python3.13/site-packages/sqlalchemy/pool/base.py", line 449, in connect
    return _ConnectionFairy._checkout(self)
           ~~~~~~~~~~~~~~~~~~~~~~~~~~^^^^^^
  File "/usr/local/lib/python3.13/site-packages/sqlalchemy/pool/base.py", line 1264, in _checkout
    fairy = _ConnectionRecord.checkout(pool)
  File "/usr/local/lib/python3.13/site-packages/sqlalchemy/pool/base.py", line 713, in checkout
    rec = pool._do_get()
  File "/usr/local/lib/python3.13/site-packages/sqlalchemy/pool/impl.py", line 179, in _do_get
    with util.safe_reraise():
         ~~~~~~~~~~~~~~~~~^^
  File "/usr/local/lib/python3.13/site-packages/sqlalchemy/util/langhelpers.py", line 224, in __exit__
    raise exc_value.with_traceback(exc_tb)
  File "/usr/local/lib/python3.13/site-packages/sqlalchemy/pool/impl.py", line 177, in _do_get
    return self._create_connection()
           ~~~~~~~~~~~~~~~~~~~~~~~^^
  File "/usr/local/lib/python3.13/site-packages/sqlalchemy/pool/base.py", line 390, in _create_connection
    return _ConnectionRecord(self)
  File "/usr/local/lib/python3.13/site-packages/sqlalchemy/pool/base.py", line 675, in __init__
    self.__connect()
    ~~~~~~~~~~~~~~^^
  File "/usr/local/lib/python3.13/site-packages/sqlalchemy/pool/base.py", line 901, in __connect
    with util.safe_reraise():
         ~~~~~~~~~~~~~~~~~^^
  File "/usr/local/lib/python3.13/site-packages/sqlalchemy/util/langhelpers.py", line 224, in __exit__
    raise exc_value.with_traceback(exc_tb)
  File "/usr/local/lib/python3.13/site-packages/sqlalchemy/pool/base.py", line 897, in __connect
    self.dbapi_connection = connection = pool._invoke_creator(self)
                                         ~~~~~~~~~~~~~~~~~~~~^^^^^^
  File "/usr/local/lib/python3.13/site-packages/sqlalchemy/engine/create.py", line 646, in connect
    return dialect.connect(*cargs, **cparams)
           ~~~~~~~~~~~~~~~^^^^^^^^^^^^^^^^^^^
  File "/usr/local/lib/python3.13/site-packages/sqlalchemy/engine/default.py", line 625, in connect
    return self.loaded_dbapi.connect(*cargs, **cparams)  # type: ignore[no-any-return]  # NOQA: E501
           ~~~~~~~~~~~~~~~~~~~~~~~~~^^^^^^^^^^^^^^^^^^^
  File "/usr/local/lib/python3.13/site-packages/psycopg2/__init__.py", line 122, in connect
    conn = _connect(dsn, connection_factory=connection_factory, **kwasync)
sqlalchemy.exc.OperationalError: (psycopg2.OperationalError) connection to server at "172.21.0.3", port 5432 failed: Connection refused
	Is the server running on that host and accepting TCP/IP connections?

(Background on this error at: https://sqlalche.me/e/20/e3q8)
2025-09-11 02:35:05.621 ERROR (Recorder) [homeassistant.components.recorder.core] Error during connection setup: (retrying in 3 seconds)
Traceback (most recent call last):
  File "/usr/local/lib/python3.13/site-packages/sqlalchemy/engine/base.py", line 145, in __init__
    self._dbapi_connection = engine.raw_connection()
                             ~~~~~~~~~~~~~~~~~~~~~^^
  File "/usr/local/lib/python3.13/site-packages/sqlalchemy/engine/base.py", line 3297, in raw_connection
    return self.pool.connect()
           ~~~~~~~~~~~~~~~~~^^
  File "/usr/local/lib/python3.13/site-packages/sqlalchemy/pool/base.py", line 449, in connect
    return _ConnectionFairy._checkout(self)
           ~~~~~~~~~~~~~~~~~~~~~~~~~~^^^^^^
  File "/usr/local/lib/python3.13/site-packages/sqlalchemy/pool/base.py", line 1264, in _checkout
    fairy = _ConnectionRecord.checkout(pool)
  File "/usr/local/lib/python3.13/site-packages/sqlalchemy/pool/base.py", line 713, in checkout
    rec = pool._do_get()
  File "/usr/local/lib/python3.13/site-packages/sqlalchemy/pool/impl.py", line 179, in _do_get
    with util.safe_reraise():
         ~~~~~~~~~~~~~~~~~^^
  File "/usr/local/lib/python3.13/site-packages/sqlalchemy/util/langhelpers.py", line 224, in __exit__
    raise exc_value.with_traceback(exc_tb)
  File "/usr/local/lib/python3.13/site-packages/sqlalchemy/pool/impl.py", line 177, in _do_get
    return self._create_connection()
           ~~~~~~~~~~~~~~~~~~~~~~~^^
  File "/usr/local/lib/python3.13/site-packages/sqlalchemy/pool/base.py", line 390, in _create_connection
    return _ConnectionRecord(self)
  File "/usr/local/lib/python3.13/site-packages/sqlalchemy/pool/base.py", line 675, in __init__
    self.__connect()
    ~~~~~~~~~~~~~~^^
  File "/usr/local/lib/python3.13/site-packages/sqlalchemy/pool/base.py", line 901, in __connect
    with util.safe_reraise():
         ~~~~~~~~~~~~~~~~~^^
  File "/usr/local/lib/python3.13/site-packages/sqlalchemy/util/langhelpers.py", line 224, in __exit__
    raise exc_value.with_traceback(exc_tb)
  File "/usr/local/lib/python3.13/site-packages/sqlalchemy/pool/base.py", line 897, in __connect
    self.dbapi_connection = connection = pool._invoke_creator(self)
                                         ~~~~~~~~~~~~~~~~~~~~^^^^^^
  File "/usr/local/lib/python3.13/site-packages/sqlalchemy/engine/create.py", line 646, in connect
    return dialect.connect(*cargs, **cparams)
           ~~~~~~~~~~~~~~~^^^^^^^^^^^^^^^^^^^
  File "/usr/local/lib/python3.13/site-packages/sqlalchemy/engine/default.py", line 625, in connect
    return self.loaded_dbapi.connect(*cargs, **cparams)  # type: ignore[no-any-return]  # NOQA: E501
           ~~~~~~~~~~~~~~~~~~~~~~~~~^^^^^^^^^^^^^^^^^^^
  File "/usr/local/lib/python3.13/site-packages/psycopg2/__init__.py", line 122, in connect
    conn = _connect(dsn, connection_factory=connection_factory, **kwasync)
psycopg2.OperationalError: connection to server at "172.21.0.3", port 5432 failed: Connection refused
	Is the server running on that host and accepting TCP/IP connections?


The above exception was the direct cause of the following exception:

Traceback (most recent call last):
  File "/usr/src/homeassistant/homeassistant/components/recorder/core.py", line 927, in _setup_recorder
    self._setup_connection()
    ~~~~~~~~~~~~~~~~~~~~~~^^
  File "/usr/src/homeassistant/homeassistant/components/recorder/core.py", line 1448, in _setup_connection
    migration.pre_migrate_schema(self.engine)
    ~~~~~~~~~~~~~~~~~~~~~~~~~~~~^^^^^^^^^^^^^
  File "/usr/src/homeassistant/homeassistant/components/recorder/migration.py", line 331, in pre_migrate_schema
    inspector = sqlalchemy.inspect(engine)
  File "/usr/local/lib/python3.13/site-packages/sqlalchemy/inspection.py", line 140, in inspect
    ret = reg(subject)
  File "/usr/local/lib/python3.13/site-packages/sqlalchemy/engine/reflection.py", line 313, in _engine_insp
    return Inspector._construct(Inspector._init_engine, bind)
           ~~~~~~~~~~~~~~~~~~~~^^^^^^^^^^^^^^^^^^^^^^^^^^^^^^
  File "/usr/local/lib/python3.13/site-packages/sqlalchemy/engine/reflection.py", line 246, in _construct
    init(self, bind)
    ~~~~^^^^^^^^^^^^
  File "/usr/local/lib/python3.13/site-packages/sqlalchemy/engine/reflection.py", line 257, in _init_engine
    engine.connect().close()
    ~~~~~~~~~~~~~~^^
  File "/usr/local/lib/python3.13/site-packages/sqlalchemy/engine/base.py", line 3273, in connect
    return self._connection_cls(self)
           ~~~~~~~~~~~~~~~~~~~~^^^^^^
  File "/usr/local/lib/python3.13/site-packages/sqlalchemy/engine/base.py", line 147, in __init__
    Connection._handle_dbapi_exception_noconnection(
    ~~~~~~~~~~~~~~~~~~~~~~~~~~~~~~~~~~~~~~~~~~~~~~~^
        err, dialect, engine
        ^^^^^^^^^^^^^^^^^^^^
    )
    ^
  File "/usr/local/lib/python3.13/site-packages/sqlalchemy/engine/base.py", line 2436, in _handle_dbapi_exception_noconnection
    raise sqlalchemy_exception.with_traceback(exc_info[2]) from e
  File "/usr/local/lib/python3.13/site-packages/sqlalchemy/engine/base.py", line 145, in __init__
    self._dbapi_connection = engine.raw_connection()
                             ~~~~~~~~~~~~~~~~~~~~~^^
  File "/usr/local/lib/python3.13/site-packages/sqlalchemy/engine/base.py", line 3297, in raw_connection
    return self.pool.connect()
           ~~~~~~~~~~~~~~~~~^^
  File "/usr/local/lib/python3.13/site-packages/sqlalchemy/pool/base.py", line 449, in connect
    return _ConnectionFairy._checkout(self)
           ~~~~~~~~~~~~~~~~~~~~~~~~~~^^^^^^
  File "/usr/local/lib/python3.13/site-packages/sqlalchemy/pool/base.py", line 1264, in _checkout
    fairy = _ConnectionRecord.checkout(pool)
  File "/usr/local/lib/python3.13/site-packages/sqlalchemy/pool/base.py", line 713, in checkout
    rec = pool._do_get()
  File "/usr/local/lib/python3.13/site-packages/sqlalchemy/pool/impl.py", line 179, in _do_get
    with util.safe_reraise():
         ~~~~~~~~~~~~~~~~~^^
  File "/usr/local/lib/python3.13/site-packages/sqlalchemy/util/langhelpers.py", line 224, in __exit__
    raise exc_value.with_traceback(exc_tb)
  File "/usr/local/lib/python3.13/site-packages/sqlalchemy/pool/impl.py", line 177, in _do_get
    return self._create_connection()
           ~~~~~~~~~~~~~~~~~~~~~~~^^
  File "/usr/local/lib/python3.13/site-packages/sqlalchemy/pool/base.py", line 390, in _create_connection
    return _ConnectionRecord(self)
  File "/usr/local/lib/python3.13/site-packages/sqlalchemy/pool/base.py", line 675, in __init__
    self.__connect()
    ~~~~~~~~~~~~~~^^
  File "/usr/local/lib/python3.13/site-packages/sqlalchemy/pool/base.py", line 901, in __connect
    with util.safe_reraise():
         ~~~~~~~~~~~~~~~~~^^
  File "/usr/local/lib/python3.13/site-packages/sqlalchemy/util/langhelpers.py", line 224, in __exit__
    raise exc_value.with_traceback(exc_tb)
  File "/usr/local/lib/python3.13/site-packages/sqlalchemy/pool/base.py", line 897, in __connect
    self.dbapi_connection = connection = pool._invoke_creator(self)
                                         ~~~~~~~~~~~~~~~~~~~~^^^^^^
  File "/usr/local/lib/python3.13/site-packages/sqlalchemy/engine/create.py", line 646, in connect
    return dialect.connect(*cargs, **cparams)
           ~~~~~~~~~~~~~~~^^^^^^^^^^^^^^^^^^^
  File "/usr/local/lib/python3.13/site-packages/sqlalchemy/engine/default.py", line 625, in connect
    return self.loaded_dbapi.connect(*cargs, **cparams)  # type: ignore[no-any-return]  # NOQA: E501
           ~~~~~~~~~~~~~~~~~~~~~~~~~^^^^^^^^^^^^^^^^^^^
  File "/usr/local/lib/python3.13/site-packages/psycopg2/__init__.py", line 122, in connect
    conn = _connect(dsn, connection_factory=connection_factory, **kwasync)
sqlalchemy.exc.OperationalError: (psycopg2.OperationalError) connection to server at "172.21.0.3", port 5432 failed: Connection refused
	Is the server running on that host and accepting TCP/IP connections?

(Background on this error at: https://sqlalche.me/e/20/e3q8)
2025-09-11 02:35:05.630 ERROR (Recorder) [homeassistant.components.recorder.core] Recorder setup failed, recorder shutting down
2025-09-11 02:35:05.631 ERROR (MainThread) [homeassistant.setup] Setup failed for 'recorder': Integration failed to initialize.
2025-09-11 02:35:05.631 INFO (MainThread) [homeassistant.setup] Setup of domain recorder took 27.14 seconds
2025-09-11 02:35:05.631 INFO (MainThread) [homeassistant.bootstrap] Nothing to set up in stage debugger: {'debugpy'}
2025-09-11 02:35:05.631 INFO (MainThread) [homeassistant.bootstrap] Setting up stage zeroconf: {'zeroconf'}; already set up: {}
Dependencies: {}; already set up: {'http', 'websocket_api', 'network', 'api'}
2025-09-11 02:35:05.631 INFO (MainThread) [homeassistant.setup] Setting up zeroconf
2025-09-11 02:35:05.634 INFO (MainThread) [homeassistant.components.zeroconf] Starting Zeroconf broadcast
2025-09-11 02:35:05.634 INFO (MainThread) [homeassistant.setup] Setup of domain zeroconf took 0.00 seconds
2025-09-11 02:35:05.635 INFO (MainThread) [homeassistant.bootstrap] Setting up stage 1: {'ssdp'}; already set up: {}
Dependencies: {}; already set up: {'http', 'websocket_api', 'network'}
2025-09-11 02:35:05.683 INFO (MainThread) [homeassistant.setup] Setting up ssdp
2025-09-11 02:35:05.686 INFO (MainThread) [homeassistant.setup] Setup of domain ssdp took 0.00 seconds
2025-09-11 02:35:05.687 INFO (MainThread) [homeassistant.bootstrap] Setting up stage 2: {'timer', 'schedule', 'script', 'group', 'counter', 'sonos', 'input_button', 'application_credentials', 'input_select', 'media_source', 'input_datetime', 'input_text', 'scene', 'backup', 'input_number', 'hardware', 'zone', 'tts', 'automation', 'recorder', 'input_boolean', 'tag', 'person', 'mqtt', 'analytics', 'binary_sensor', 'system_health', 'logbook', 'history'}; already set up: {'network', 'homeassistant', 'ssdp', 'http', 'api', 'zeroconf', 'frontend', 'logger'}
Dependencies: {'blueprint', 'ffmpeg', 'trace', 'image_upload'}; already set up: {'onboarding', 'file_upload', 'websocket_api', 'ssdp', 'auth', 'lovelace', 'diagnostics', 'zeroconf', 'frontend', 'search', 'system_log', 'repairs', 'network', 'config', 'device_automation', 'api', 'http'}
2025-09-11 02:35:05.687 INFO (MainThread) [homeassistant.setup] Setting up binary_sensor
2025-09-11 02:35:05.688 INFO (MainThread) [homeassistant.setup] Setup of domain binary_sensor took 0.00 seconds
2025-09-11 02:35:05.688 INFO (MainThread) [homeassistant.setup] Setting up scene
2025-09-11 02:35:05.688 INFO (MainThread) [homeassistant.components.scene] Setting up homeassistant.scene
2025-09-11 02:35:05.690 INFO (MainThread) [homeassistant.setup] Setup of domain scene took 0.00 seconds
2025-09-11 02:35:05.691 INFO (MainThread) [homeassistant.setup] Setting up input_number
2025-09-11 02:35:05.692 INFO (MainThread) [homeassistant.setup] Setup of domain input_number took 0.00 seconds
2025-09-11 02:35:05.693 INFO (MainThread) [homeassistant.setup] Setting up blueprint
2025-09-11 02:35:05.693 INFO (MainThread) [homeassistant.setup] Setup of domain blueprint took 0.00 seconds
2025-09-11 02:35:05.693 INFO (MainThread) [homeassistant.setup] Setting up trace
2025-09-11 02:35:05.693 INFO (MainThread) [homeassistant.setup] Setup of domain trace took 0.00 seconds
2025-09-11 02:35:05.694 INFO (MainThread) [homeassistant.setup] Setting up script
2025-09-11 02:35:05.694 INFO (MainThread) [homeassistant.setup] Setup of domain script took 0.00 seconds
2025-09-11 02:35:05.694 INFO (MainThread) [homeassistant.setup] Setting up group
2025-09-11 02:35:05.695 INFO (MainThread) [homeassistant.setup] Setup of domain group took 0.00 seconds
2025-09-11 02:35:05.695 INFO (MainThread) [homeassistant.setup] Setting up zone
2025-09-11 02:35:05.697 INFO (MainThread) [homeassistant.setup] Setup of domain zone took 0.00 seconds
2025-09-11 02:35:05.714 INFO (MainThread) [homeassistant.setup] Setting up image_upload
2025-09-11 02:35:05.716 INFO (MainThread) [homeassistant.setup] Setup of domain image_upload took 0.00 seconds
2025-09-11 02:35:05.716 INFO (MainThread) [homeassistant.setup] Setting up person
2025-09-11 02:35:05.717 INFO (MainThread) [homeassistant.setup] Setting up system_health
2025-09-11 02:35:05.718 INFO (MainThread) [homeassistant.setup] Setup of domain system_health took 0.00 seconds
2025-09-11 02:35:05.718 ERROR (MainThread) [homeassistant.setup] Unable to set up dependencies of 'logbook'. Setup failed for dependencies: ['recorder']
2025-09-11 02:35:05.718 ERROR (MainThread) [homeassistant.setup] Setup failed for 'logbook': Could not setup dependencies: recorder
2025-09-11 02:35:05.718 INFO (MainThread) [homeassistant.setup] Setting up backup
2025-09-11 02:35:05.719 ERROR (MainThread) [homeassistant.setup] Unable to set up dependencies of 'history'. Setup failed for dependencies: ['recorder']
2025-09-11 02:35:05.719 ERROR (MainThread) [homeassistant.setup] Setup failed for 'history': Could not setup dependencies: recorder
2025-09-11 02:35:05.721 INFO (MainThread) [homeassistant.setup] Setup of domain person took 0.00 seconds
2025-09-11 02:35:05.724 INFO (MainThread) [homeassistant.setup] Setup of domain backup took 0.01 seconds
2025-09-11 02:35:05.730 INFO (MainThread) [homeassistant.setup] Setting up ffmpeg
2025-09-11 02:35:05.730 INFO (MainThread) [homeassistant.setup] Setup of domain ffmpeg took 0.00 seconds
2025-09-11 02:35:05.733 INFO (MainThread) [homeassistant.setup] Setting up timer
2025-09-11 02:35:05.735 INFO (MainThread) [homeassistant.setup] Setup of domain timer took 0.00 seconds
2025-09-11 02:35:05.740 INFO (MainThread) [homeassistant.setup] Setting up schedule
2025-09-11 02:35:05.742 INFO (MainThread) [homeassistant.setup] Setup of domain schedule took 0.00 seconds
2025-09-11 02:35:05.751 INFO (MainThread) [homeassistant.setup] Setting up hardware
2025-09-11 02:35:05.836 INFO (MainThread) [homeassistant.setup] Setup of domain hardware took 0.08 seconds
2025-09-11 02:35:05.874 INFO (MainThread) [homeassistant.setup] Setting up counter
2025-09-11 02:35:05.876 INFO (MainThread) [homeassistant.setup] Setup of domain counter took 0.00 seconds
2025-09-11 02:35:05.884 INFO (MainThread) [homeassistant.setup] Setting up media_source
2025-09-11 02:35:05.886 INFO (MainThread) [homeassistant.setup] Setup of domain media_source took 0.00 seconds
2025-09-11 02:35:05.889 INFO (MainThread) [homeassistant.setup] Setting up input_boolean
2025-09-11 02:35:05.891 INFO (MainThread) [homeassistant.setup] Setup of domain input_boolean took 0.00 seconds
2025-09-11 02:35:05.893 INFO (MainThread) [homeassistant.setup] Setting up input_button
2025-09-11 02:35:05.894 INFO (MainThread) [homeassistant.setup] Setup of domain input_button took 0.00 seconds
2025-09-11 02:35:05.899 INFO (MainThread) [homeassistant.setup] Setting up application_credentials
2025-09-11 02:35:05.900 INFO (MainThread) [homeassistant.setup] Setup of domain application_credentials took 0.00 seconds
2025-09-11 02:35:05.905 INFO (MainThread) [homeassistant.setup] Setting up input_select
2025-09-11 02:35:05.907 INFO (MainThread) [homeassistant.setup] Setup of domain input_select took 0.00 seconds
2025-09-11 02:35:05.910 INFO (MainThread) [homeassistant.setup] Setting up input_datetime
2025-09-11 02:35:05.911 INFO (MainThread) [homeassistant.setup] Setup of domain input_datetime took 0.00 seconds
2025-09-11 02:35:05.914 INFO (MainThread) [homeassistant.setup] Setting up input_text
2025-09-11 02:35:05.915 INFO (MainThread) [homeassistant.setup] Setup of domain input_text took 0.00 seconds
2025-09-11 02:35:05.928 INFO (MainThread) [homeassistant.setup] Setting up mqtt
2025-09-11 02:35:05.928 INFO (MainThread) [homeassistant.setup] Setup of domain mqtt took 0.00 seconds
2025-09-11 02:35:05.945 INFO (MainThread) [homeassistant.setup] Setting up analytics
2025-09-11 02:35:05.945 INFO (MainThread) [homeassistant.setup] Setup of domain analytics took 0.00 seconds
2025-09-11 02:35:05.951 INFO (MainThread) [homeassistant.setup] Setting up tag
2025-09-11 02:35:05.952 INFO (MainThread) [homeassistant.setup] Setup of domain tag took 0.00 seconds
2025-09-11 02:35:06.002 INFO (MainThread) [homeassistant.setup] Setting up automation
2025-09-11 02:35:06.004 INFO (MainThread) [homeassistant.setup] Setup of domain automation took 0.00 seconds
2025-09-11 02:35:06.086 INFO (MainThread) [homeassistant.setup] Setting up sonos
2025-09-11 02:35:06.086 INFO (MainThread) [homeassistant.setup] Setup of domain sonos took 0.00 seconds
2025-09-11 02:35:06.094 INFO (MainThread) [homeassistant.setup] Setting up event
2025-09-11 02:35:06.095 INFO (MainThread) [homeassistant.setup] Setup of domain event took 0.00 seconds
2025-09-11 02:35:06.095 INFO (MainThread) [homeassistant.setup] Setting up sensor
2025-09-11 02:35:06.096 INFO (MainThread) [homeassistant.setup] Setup of domain sensor took 0.00 seconds
2025-09-11 02:35:06.097 INFO (MainThread) [homeassistant.components.event] Setting up backup.event
2025-09-11 02:35:06.098 INFO (MainThread) [homeassistant.components.sensor] Setting up backup.sensor
2025-09-11 02:35:06.428 DEBUG (MainThread) [homeassistant.components.mqtt.client] mqtt: connection opened 24
2025-09-11 02:35:06.429 DEBUG (MainThread) [homeassistant.components.mqtt.client] mqtt: Starting client misc loop
2025-09-11 02:35:06.429 DEBUG (MainThread) [homeassistant.components.mqtt.client] mqtt: register write 24
2025-09-11 02:35:06.436 DEBUG (MainThread) [homeassistant.components.mqtt.client] mqtt: unregister write 24
2025-09-11 02:35:06.437 DEBUG (MainThread) [homeassistant.components.mqtt.client] Connected to MQTT server mqtt:1883 (Success)
2025-09-11 02:35:06.453 INFO (MainThread) [homeassistant.setup] Setting up tts
2025-09-11 02:35:06.460 INFO (MainThread) [homeassistant.setup] Setup of domain tts took 0.01 seconds
2025-09-11 02:35:06.939 DEBUG (MainThread) [homeassistant.components.mqtt.client] mqtt: register write 24
2025-09-11 02:35:06.939 DEBUG (MainThread) [homeassistant.components.mqtt.client] Subscribing with mid: 1 to topics with qos: [('homeassistant/alarm_control_panel/+/config', 0)]
2025-09-11 02:35:06.940 DEBUG (MainThread) [homeassistant.components.mqtt.client] mqtt: unregister write 24
2025-09-11 02:35:06.941 DEBUG (MainThread) [homeassistant.components.mqtt.client] mqtt: register write 24
2025-09-11 02:35:06.941 DEBUG (MainThread) [homeassistant.components.mqtt.client] Subscribing with mid: 2 to topics with qos: [('homeassistant/binary_sensor/+/config', 0)]
2025-09-11 02:35:06.941 DEBUG (MainThread) [homeassistant.components.mqtt.client] mqtt: unregister write 24
2025-09-11 02:35:06.941 DEBUG (MainThread) [homeassistant.components.mqtt.client] mqtt: register write 24
2025-09-11 02:35:06.941 DEBUG (MainThread) [homeassistant.components.mqtt.client] Subscribing with mid: 3 to topics with qos: [('homeassistant/button/+/config', 0)]
2025-09-11 02:35:06.942 DEBUG (MainThread) [homeassistant.components.mqtt.client] mqtt: unregister write 24
2025-09-11 02:35:06.942 DEBUG (MainThread) [homeassistant.components.mqtt.client] mqtt: register write 24
2025-09-11 02:35:06.942 DEBUG (MainThread) [homeassistant.components.mqtt.client] Subscribing with mid: 4 to topics with qos: [('homeassistant/camera/+/config', 0)]
2025-09-11 02:35:06.943 DEBUG (MainThread) [homeassistant.components.mqtt.client] mqtt: unregister write 24
2025-09-11 02:35:06.943 DEBUG (MainThread) [homeassistant.components.mqtt.client] mqtt: register write 24
2025-09-11 02:35:06.943 DEBUG (MainThread) [homeassistant.components.mqtt.client] Subscribing with mid: 5 to topics with qos: [('homeassistant/climate/+/config', 0)]
2025-09-11 02:35:06.944 DEBUG (MainThread) [homeassistant.components.mqtt.client] mqtt: unregister write 24
2025-09-11 02:35:06.944 DEBUG (MainThread) [homeassistant.components.mqtt.client] mqtt: register write 24
2025-09-11 02:35:06.945 DEBUG (MainThread) [homeassistant.components.mqtt.client] Subscribing with mid: 6 to topics with qos: [('homeassistant/cover/+/config', 0)]
2025-09-11 02:35:06.945 DEBUG (MainThread) [homeassistant.components.mqtt.client] mqtt: unregister write 24
2025-09-11 02:35:06.946 DEBUG (MainThread) [homeassistant.components.mqtt.client] mqtt: register write 24
2025-09-11 02:35:06.946 DEBUG (MainThread) [homeassistant.components.mqtt.client] Subscribing with mid: 7 to topics with qos: [('homeassistant/device_automation/+/config', 0)]
2025-09-11 02:35:06.946 DEBUG (MainThread) [homeassistant.components.mqtt.client] mqtt: unregister write 24
2025-09-11 02:35:06.947 DEBUG (MainThread) [homeassistant.components.mqtt.client] mqtt: register write 24
2025-09-11 02:35:06.947 DEBUG (MainThread) [homeassistant.components.mqtt.client] Subscribing with mid: 8 to topics with qos: [('homeassistant/device_tracker/+/config', 0)]
2025-09-11 02:35:06.949 DEBUG (MainThread) [homeassistant.components.mqtt.client] mqtt: unregister write 24
2025-09-11 02:35:06.950 DEBUG (MainThread) [homeassistant.components.mqtt.client] mqtt: register write 24
2025-09-11 02:35:06.950 DEBUG (MainThread) [homeassistant.components.mqtt.client] Subscribing with mid: 9 to topics with qos: [('homeassistant/event/+/config', 0)]
2025-09-11 02:35:06.950 DEBUG (MainThread) [homeassistant.components.mqtt.client] mqtt: unregister write 24
2025-09-11 02:35:06.950 DEBUG (MainThread) [homeassistant.components.mqtt.client] mqtt: register write 24
2025-09-11 02:35:06.951 DEBUG (MainThread) [homeassistant.components.mqtt.client] Subscribing with mid: 10 to topics with qos: [('homeassistant/fan/+/config', 0)]
2025-09-11 02:35:06.951 DEBUG (MainThread) [homeassistant.components.mqtt.client] mqtt: unregister write 24
2025-09-11 02:35:06.952 DEBUG (MainThread) [homeassistant.components.mqtt.client] mqtt: register write 24
2025-09-11 02:35:06.952 DEBUG (MainThread) [homeassistant.components.mqtt.client] Subscribing with mid: 11 to topics with qos: [('homeassistant/humidifier/+/config', 0)]
2025-09-11 02:35:06.952 DEBUG (MainThread) [homeassistant.components.mqtt.client] mqtt: unregister write 24
2025-09-11 02:35:06.953 DEBUG (MainThread) [homeassistant.components.mqtt.client] mqtt: register write 24
2025-09-11 02:35:06.953 DEBUG (MainThread) [homeassistant.components.mqtt.client] Subscribing with mid: 12 to topics with qos: [('homeassistant/image/+/config', 0)]
2025-09-11 02:35:06.953 DEBUG (MainThread) [homeassistant.components.mqtt.client] mqtt: unregister write 24
2025-09-11 02:35:06.954 DEBUG (MainThread) [homeassistant.components.mqtt.client] mqtt: register write 24
2025-09-11 02:35:06.954 DEBUG (MainThread) [homeassistant.components.mqtt.client] Subscribing with mid: 13 to topics with qos: [('homeassistant/lawn_mower/+/config', 0)]
2025-09-11 02:35:06.954 DEBUG (MainThread) [homeassistant.components.mqtt.client] mqtt: unregister write 24
2025-09-11 02:35:06.955 DEBUG (MainThread) [homeassistant.components.mqtt.client] mqtt: register write 24
2025-09-11 02:35:06.955 DEBUG (MainThread) [homeassistant.components.mqtt.client] Subscribing with mid: 14 to topics with qos: [('homeassistant/light/+/config', 0)]
2025-09-11 02:35:06.955 DEBUG (MainThread) [homeassistant.components.mqtt.client] mqtt: unregister write 24
2025-09-11 02:35:06.956 DEBUG (MainThread) [homeassistant.components.mqtt.client] mqtt: register write 24
2025-09-11 02:35:06.956 DEBUG (MainThread) [homeassistant.components.mqtt.client] Subscribing with mid: 15 to topics with qos: [('homeassistant/lock/+/config', 0)]
2025-09-11 02:35:06.956 DEBUG (MainThread) [homeassistant.components.mqtt.client] mqtt: unregister write 24
2025-09-11 02:35:06.957 DEBUG (MainThread) [homeassistant.components.mqtt.client] mqtt: register write 24
2025-09-11 02:35:06.957 DEBUG (MainThread) [homeassistant.components.mqtt.client] Subscribing with mid: 16 to topics with qos: [('homeassistant/notify/+/config', 0)]
2025-09-11 02:35:06.957 DEBUG (MainThread) [homeassistant.components.mqtt.client] mqtt: unregister write 24
2025-09-11 02:35:06.958 DEBUG (MainThread) [homeassistant.components.mqtt.client] mqtt: register write 24
2025-09-11 02:35:06.958 DEBUG (MainThread) [homeassistant.components.mqtt.client] Subscribing with mid: 17 to topics with qos: [('homeassistant/number/+/config', 0)]
2025-09-11 02:35:06.958 DEBUG (MainThread) [homeassistant.components.mqtt.client] mqtt: unregister write 24
2025-09-11 02:35:06.959 DEBUG (MainThread) [homeassistant.components.mqtt.client] mqtt: register write 24
2025-09-11 02:35:06.959 DEBUG (MainThread) [homeassistant.components.mqtt.client] Subscribing with mid: 18 to topics with qos: [('homeassistant/scene/+/config', 0)]
2025-09-11 02:35:06.960 DEBUG (MainThread) [homeassistant.components.mqtt.client] mqtt: unregister write 24
2025-09-11 02:35:06.961 DEBUG (MainThread) [homeassistant.components.mqtt.client] mqtt: register write 24
2025-09-11 02:35:06.961 DEBUG (MainThread) [homeassistant.components.mqtt.client] Subscribing with mid: 19 to topics with qos: [('homeassistant/siren/+/config', 0)]
2025-09-11 02:35:06.961 DEBUG (MainThread) [homeassistant.components.mqtt.client] mqtt: unregister write 24
2025-09-11 02:35:06.962 DEBUG (MainThread) [homeassistant.components.mqtt.client] mqtt: register write 24
2025-09-11 02:35:06.962 DEBUG (MainThread) [homeassistant.components.mqtt.client] Subscribing with mid: 20 to topics with qos: [('homeassistant/select/+/config', 0)]
2025-09-11 02:35:06.963 DEBUG (MainThread) [homeassistant.components.mqtt.client] mqtt: unregister write 24
2025-09-11 02:35:06.964 DEBUG (MainThread) [homeassistant.components.mqtt.client] mqtt: register write 24
2025-09-11 02:35:06.964 DEBUG (MainThread) [homeassistant.components.mqtt.client] Subscribing with mid: 21 to topics with qos: [('homeassistant/sensor/+/config', 0)]
2025-09-11 02:35:06.964 DEBUG (MainThread) [homeassistant.components.mqtt.client] mqtt: unregister write 24
2025-09-11 02:35:06.965 DEBUG (MainThread) [homeassistant.components.mqtt.client] mqtt: register write 24
2025-09-11 02:35:06.965 DEBUG (MainThread) [homeassistant.components.mqtt.client] Subscribing with mid: 22 to topics with qos: [('homeassistant/switch/+/config', 0)]
2025-09-11 02:35:06.966 DEBUG (MainThread) [homeassistant.components.mqtt.client] mqtt: unregister write 24
2025-09-11 02:35:06.966 DEBUG (MainThread) [homeassistant.components.mqtt.client] mqtt: register write 24
2025-09-11 02:35:06.966 DEBUG (MainThread) [homeassistant.components.mqtt.client] Subscribing with mid: 23 to topics with qos: [('homeassistant/tag/+/config', 0)]
2025-09-11 02:35:06.967 DEBUG (MainThread) [homeassistant.components.mqtt.client] mqtt: unregister write 24
2025-09-11 02:35:06.967 DEBUG (MainThread) [homeassistant.components.mqtt.client] mqtt: register write 24
2025-09-11 02:35:06.968 DEBUG (MainThread) [homeassistant.components.mqtt.client] Subscribing with mid: 24 to topics with qos: [('homeassistant/text/+/config', 0)]
2025-09-11 02:35:06.968 DEBUG (MainThread) [homeassistant.components.mqtt.client] mqtt: unregister write 24
2025-09-11 02:35:06.969 DEBUG (MainThread) [homeassistant.components.mqtt.client] mqtt: register write 24
2025-09-11 02:35:06.969 DEBUG (MainThread) [homeassistant.components.mqtt.client] Subscribing with mid: 25 to topics with qos: [('homeassistant/update/+/config', 0)]
2025-09-11 02:35:06.969 DEBUG (MainThread) [homeassistant.components.mqtt.client] mqtt: unregister write 24
2025-09-11 02:35:06.970 DEBUG (MainThread) [homeassistant.components.mqtt.client] mqtt: register write 24
2025-09-11 02:35:06.970 DEBUG (MainThread) [homeassistant.components.mqtt.client] Subscribing with mid: 26 to topics with qos: [('homeassistant/vacuum/+/config', 0)]
2025-09-11 02:35:06.970 DEBUG (MainThread) [homeassistant.components.mqtt.client] mqtt: unregister write 24
2025-09-11 02:35:06.971 DEBUG (MainThread) [homeassistant.components.mqtt.client] mqtt: register write 24
2025-09-11 02:35:06.971 DEBUG (MainThread) [homeassistant.components.mqtt.client] Subscribing with mid: 27 to topics with qos: [('homeassistant/valve/+/config', 0)]
2025-09-11 02:35:06.971 DEBUG (MainThread) [homeassistant.components.mqtt.client] mqtt: unregister write 24
2025-09-11 02:35:06.972 DEBUG (MainThread) [homeassistant.components.mqtt.client] mqtt: register write 24
2025-09-11 02:35:06.972 DEBUG (MainThread) [homeassistant.components.mqtt.client] Subscribing with mid: 28 to topics with qos: [('homeassistant/water_heater/+/config', 0)]
2025-09-11 02:35:06.972 DEBUG (MainThread) [homeassistant.components.mqtt.client] mqtt: unregister write 24
2025-09-11 02:35:06.973 DEBUG (MainThread) [homeassistant.components.mqtt.client] mqtt: register write 24
2025-09-11 02:35:06.973 DEBUG (MainThread) [homeassistant.components.mqtt.client] Subscribing with mid: 29 to topics with qos: [('homeassistant/alarm_control_panel/+/+/config', 0)]
2025-09-11 02:35:06.973 DEBUG (MainThread) [homeassistant.components.mqtt.client] mqtt: unregister write 24
2025-09-11 02:35:06.974 DEBUG (MainThread) [homeassistant.components.mqtt.client] mqtt: register write 24
2025-09-11 02:35:06.974 DEBUG (MainThread) [homeassistant.components.mqtt.client] Subscribing with mid: 30 to topics with qos: [('homeassistant/binary_sensor/+/+/config', 0)]
2025-09-11 02:35:06.975 DEBUG (MainThread) [homeassistant.components.mqtt.client] mqtt: unregister write 24
2025-09-11 02:35:06.975 DEBUG (MainThread) [homeassistant.components.mqtt.client] mqtt: register write 24
2025-09-11 02:35:06.975 DEBUG (MainThread) [homeassistant.components.mqtt.client] Subscribing with mid: 31 to topics with qos: [('homeassistant/button/+/+/config', 0)]
2025-09-11 02:35:06.976 DEBUG (MainThread) [homeassistant.components.mqtt.client] mqtt: unregister write 24
2025-09-11 02:35:06.976 DEBUG (MainThread) [homeassistant.components.mqtt.client] mqtt: register write 24
2025-09-11 02:35:06.977 DEBUG (MainThread) [homeassistant.components.mqtt.client] Subscribing with mid: 32 to topics with qos: [('homeassistant/camera/+/+/config', 0)]
2025-09-11 02:35:06.977 DEBUG (MainThread) [homeassistant.components.mqtt.client] mqtt: unregister write 24
2025-09-11 02:35:06.978 DEBUG (MainThread) [homeassistant.components.mqtt.client] mqtt: register write 24
2025-09-11 02:35:06.978 DEBUG (MainThread) [homeassistant.components.mqtt.client] Subscribing with mid: 33 to topics with qos: [('homeassistant/climate/+/+/config', 0)]
2025-09-11 02:35:06.979 DEBUG (MainThread) [homeassistant.components.mqtt.client] mqtt: unregister write 24
2025-09-11 02:35:06.979 DEBUG (MainThread) [homeassistant.components.mqtt.client] mqtt: register write 24
2025-09-11 02:35:06.980 DEBUG (MainThread) [homeassistant.components.mqtt.client] Subscribing with mid: 34 to topics with qos: [('homeassistant/cover/+/+/config', 0)]
2025-09-11 02:35:06.980 DEBUG (MainThread) [homeassistant.components.mqtt.client] mqtt: unregister write 24
2025-09-11 02:35:06.980 DEBUG (MainThread) [homeassistant.components.mqtt.client] mqtt: register write 24
2025-09-11 02:35:06.980 DEBUG (MainThread) [homeassistant.components.mqtt.client] Subscribing with mid: 35 to topics with qos: [('homeassistant/device_automation/+/+/config', 0)]
2025-09-11 02:35:06.981 DEBUG (MainThread) [homeassistant.components.mqtt.client] mqtt: unregister write 24
2025-09-11 02:35:06.982 DEBUG (MainThread) [homeassistant.components.mqtt.client] mqtt: register write 24
2025-09-11 02:35:06.982 DEBUG (MainThread) [homeassistant.components.mqtt.client] Subscribing with mid: 36 to topics with qos: [('homeassistant/device_tracker/+/+/config', 0)]
2025-09-11 02:35:06.982 DEBUG (MainThread) [homeassistant.components.mqtt.client] mqtt: unregister write 24
2025-09-11 02:35:06.983 DEBUG (MainThread) [homeassistant.components.mqtt.client] mqtt: register write 24
2025-09-11 02:35:06.983 DEBUG (MainThread) [homeassistant.components.mqtt.client] Subscribing with mid: 37 to topics with qos: [('homeassistant/event/+/+/config', 0)]
2025-09-11 02:35:06.983 DEBUG (MainThread) [homeassistant.components.mqtt.client] mqtt: unregister write 24
2025-09-11 02:35:06.984 DEBUG (MainThread) [homeassistant.components.mqtt.client] mqtt: register write 24
2025-09-11 02:35:06.984 DEBUG (MainThread) [homeassistant.components.mqtt.client] Subscribing with mid: 38 to topics with qos: [('homeassistant/fan/+/+/config', 0)]
2025-09-11 02:35:06.985 DEBUG (MainThread) [homeassistant.components.mqtt.client] mqtt: unregister write 24
2025-09-11 02:35:06.985 DEBUG (MainThread) [homeassistant.components.mqtt.client] mqtt: register write 24
2025-09-11 02:35:06.985 DEBUG (MainThread) [homeassistant.components.mqtt.client] Subscribing with mid: 39 to topics with qos: [('homeassistant/humidifier/+/+/config', 0)]
2025-09-11 02:35:06.986 DEBUG (MainThread) [homeassistant.components.mqtt.client] mqtt: unregister write 24
2025-09-11 02:35:06.986 DEBUG (MainThread) [homeassistant.components.mqtt.client] mqtt: register write 24
2025-09-11 02:35:06.986 DEBUG (MainThread) [homeassistant.components.mqtt.client] Subscribing with mid: 40 to topics with qos: [('homeassistant/image/+/+/config', 0)]
2025-09-11 02:35:06.987 DEBUG (MainThread) [homeassistant.components.mqtt.client] mqtt: unregister write 24
2025-09-11 02:35:06.988 DEBUG (MainThread) [homeassistant.components.mqtt.client] mqtt: register write 24
2025-09-11 02:35:06.988 DEBUG (MainThread) [homeassistant.components.mqtt.client] Subscribing with mid: 41 to topics with qos: [('homeassistant/lawn_mower/+/+/config', 0)]
2025-09-11 02:35:06.988 DEBUG (MainThread) [homeassistant.components.mqtt.client] mqtt: unregister write 24
2025-09-11 02:35:06.989 DEBUG (MainThread) [homeassistant.components.mqtt.client] mqtt: register write 24
2025-09-11 02:35:06.989 DEBUG (MainThread) [homeassistant.components.mqtt.client] Subscribing with mid: 42 to topics with qos: [('homeassistant/light/+/+/config', 0)]
2025-09-11 02:35:06.991 DEBUG (MainThread) [homeassistant.components.mqtt.client] mqtt: unregister write 24
2025-09-11 02:35:06.991 DEBUG (MainThread) [homeassistant.components.mqtt.client] mqtt: register write 24
2025-09-11 02:35:06.991 DEBUG (MainThread) [homeassistant.components.mqtt.client] Subscribing with mid: 43 to topics with qos: [('homeassistant/lock/+/+/config', 0)]
2025-09-11 02:35:06.992 DEBUG (MainThread) [homeassistant.components.mqtt.client] mqtt: unregister write 24
2025-09-11 02:35:06.993 DEBUG (MainThread) [homeassistant.components.mqtt.client] mqtt: register write 24
2025-09-11 02:35:06.994 DEBUG (MainThread) [homeassistant.components.mqtt.client] Subscribing with mid: 44 to topics with qos: [('homeassistant/notify/+/+/config', 0)]
2025-09-11 02:35:06.994 DEBUG (MainThread) [homeassistant.components.mqtt.client] mqtt: unregister write 24
2025-09-11 02:35:06.995 DEBUG (MainThread) [homeassistant.components.mqtt.client] mqtt: register write 24
2025-09-11 02:35:06.995 DEBUG (MainThread) [homeassistant.components.mqtt.client] Subscribing with mid: 45 to topics with qos: [('homeassistant/number/+/+/config', 0)]
2025-09-11 02:35:06.995 DEBUG (MainThread) [homeassistant.components.mqtt.client] mqtt: unregister write 24
2025-09-11 02:35:06.995 DEBUG (MainThread) [homeassistant.components.mqtt.client] mqtt: register write 24
2025-09-11 02:35:06.996 DEBUG (MainThread) [homeassistant.components.mqtt.client] Subscribing with mid: 46 to topics with qos: [('homeassistant/scene/+/+/config', 0)]
2025-09-11 02:35:06.997 DEBUG (MainThread) [homeassistant.components.mqtt.client] mqtt: unregister write 24
2025-09-11 02:35:06.997 DEBUG (MainThread) [homeassistant.components.mqtt.client] mqtt: register write 24
2025-09-11 02:35:06.997 DEBUG (MainThread) [homeassistant.components.mqtt.client] Subscribing with mid: 47 to topics with qos: [('homeassistant/siren/+/+/config', 0)]
2025-09-11 02:35:06.997 DEBUG (MainThread) [homeassistant.components.mqtt.client] mqtt: unregister write 24
2025-09-11 02:35:06.998 DEBUG (MainThread) [homeassistant.components.mqtt.client] mqtt: register write 24
2025-09-11 02:35:06.998 DEBUG (MainThread) [homeassistant.components.mqtt.client] Subscribing with mid: 48 to topics with qos: [('homeassistant/select/+/+/config', 0)]
2025-09-11 02:35:06.998 DEBUG (MainThread) [homeassistant.components.mqtt.client] mqtt: unregister write 24
2025-09-11 02:35:06.998 DEBUG (MainThread) [homeassistant.components.mqtt.client] mqtt: register write 24
2025-09-11 02:35:06.998 DEBUG (MainThread) [homeassistant.components.mqtt.client] Subscribing with mid: 49 to topics with qos: [('homeassistant/sensor/+/+/config', 0)]
2025-09-11 02:35:06.999 DEBUG (MainThread) [homeassistant.components.mqtt.client] mqtt: unregister write 24
2025-09-11 02:35:07.000 DEBUG (MainThread) [homeassistant.components.mqtt.client] mqtt: register write 24
2025-09-11 02:35:07.000 DEBUG (MainThread) [homeassistant.components.mqtt.client] Subscribing with mid: 50 to topics with qos: [('homeassistant/switch/+/+/config', 0)]
2025-09-11 02:35:07.000 DEBUG (MainThread) [homeassistant.components.mqtt.client] mqtt: unregister write 24
2025-09-11 02:35:07.001 DEBUG (MainThread) [homeassistant.components.mqtt.client] mqtt: register write 24
2025-09-11 02:35:07.001 DEBUG (MainThread) [homeassistant.components.mqtt.client] Subscribing with mid: 51 to topics with qos: [('homeassistant/tag/+/+/config', 0)]
2025-09-11 02:35:07.001 DEBUG (MainThread) [homeassistant.components.mqtt.client] mqtt: unregister write 24
2025-09-11 02:35:07.001 DEBUG (MainThread) [homeassistant.components.mqtt.client] mqtt: register write 24
2025-09-11 02:35:07.001 DEBUG (MainThread) [homeassistant.components.mqtt.client] Subscribing with mid: 52 to topics with qos: [('homeassistant/text/+/+/config', 0)]
2025-09-11 02:35:07.002 DEBUG (MainThread) [homeassistant.components.mqtt.client] mqtt: unregister write 24
2025-09-11 02:35:07.002 DEBUG (MainThread) [homeassistant.components.mqtt.client] mqtt: register write 24
2025-09-11 02:35:07.002 DEBUG (MainThread) [homeassistant.components.mqtt.client] Subscribing with mid: 53 to topics with qos: [('homeassistant/update/+/+/config', 0)]
2025-09-11 02:35:07.003 DEBUG (MainThread) [homeassistant.components.mqtt.client] mqtt: unregister write 24
2025-09-11 02:35:07.005 DEBUG (MainThread) [homeassistant.components.mqtt.client] mqtt: register write 24
2025-09-11 02:35:07.005 DEBUG (MainThread) [homeassistant.components.mqtt.client] Subscribing with mid: 54 to topics with qos: [('homeassistant/vacuum/+/+/config', 0)]
2025-09-11 02:35:07.005 DEBUG (MainThread) [homeassistant.components.mqtt.client] mqtt: unregister write 24
2025-09-11 02:35:07.006 DEBUG (MainThread) [homeassistant.components.mqtt.client] mqtt: register write 24
2025-09-11 02:35:07.006 DEBUG (MainThread) [homeassistant.components.mqtt.client] Subscribing with mid: 55 to topics with qos: [('homeassistant/valve/+/+/config', 0)]
2025-09-11 02:35:07.006 DEBUG (MainThread) [homeassistant.components.mqtt.client] mqtt: unregister write 24
2025-09-11 02:35:07.006 DEBUG (MainThread) [homeassistant.components.mqtt.client] mqtt: register write 24
2025-09-11 02:35:07.006 DEBUG (MainThread) [homeassistant.components.mqtt.client] Subscribing with mid: 56 to topics with qos: [('homeassistant/water_heater/+/+/config', 0)]
2025-09-11 02:35:07.007 DEBUG (MainThread) [homeassistant.components.mqtt.client] mqtt: unregister write 24
2025-09-11 02:35:07.007 DEBUG (MainThread) [homeassistant.components.mqtt.client] mqtt: register write 24
2025-09-11 02:35:07.007 DEBUG (MainThread) [homeassistant.components.mqtt.client] Subscribing with mid: 57 to topics with qos: [('homeassistant/device/+/config', 0)]
2025-09-11 02:35:07.009 DEBUG (MainThread) [homeassistant.components.mqtt.client] mqtt: unregister write 24
2025-09-11 02:35:07.010 DEBUG (MainThread) [homeassistant.components.mqtt.client] mqtt: register write 24
2025-09-11 02:35:07.010 DEBUG (MainThread) [homeassistant.components.mqtt.client] Subscribing with mid: 58 to topics with qos: [('homeassistant/device/+/+/config', 0)]
2025-09-11 02:35:07.010 DEBUG (MainThread) [homeassistant.components.mqtt.client] mqtt: unregister write 24
2025-09-11 02:35:07.010 DEBUG (MainThread) [homeassistant.components.mqtt.client] mqtt: register write 24
2025-09-11 02:35:07.011 DEBUG (MainThread) [homeassistant.components.mqtt.client] Subscribing with mid: 59 to topics with qos: [('drop_connect/discovery/#', 0)]
2025-09-11 02:35:07.011 DEBUG (MainThread) [homeassistant.components.mqtt.client] mqtt: unregister write 24
2025-09-11 02:35:07.012 DEBUG (MainThread) [homeassistant.components.mqtt.client] mqtt: register write 24
2025-09-11 02:35:07.012 DEBUG (MainThread) [homeassistant.components.mqtt.client] Subscribing with mid: 60 to topics with qos: [('dsmr/#', 0)]
2025-09-11 02:35:07.012 DEBUG (MainThread) [homeassistant.components.mqtt.client] mqtt: unregister write 24
2025-09-11 02:35:07.012 DEBUG (MainThread) [homeassistant.components.mqtt.client] mqtt: register write 24
2025-09-11 02:35:07.012 DEBUG (MainThread) [homeassistant.components.mqtt.client] Subscribing with mid: 61 to topics with qos: [('esphome/discover/#', 0)]
2025-09-11 02:35:07.013 DEBUG (MainThread) [homeassistant.components.mqtt.client] mqtt: unregister write 24
2025-09-11 02:35:07.013 DEBUG (MainThread) [homeassistant.components.mqtt.client] mqtt: register write 24
2025-09-11 02:35:07.013 DEBUG (MainThread) [homeassistant.components.mqtt.client] Subscribing with mid: 62 to topics with qos: [('fully/deviceInfo/+', 0)]
2025-09-11 02:35:07.014 DEBUG (MainThread) [homeassistant.components.mqtt.client] mqtt: unregister write 24
2025-09-11 02:35:07.014 DEBUG (MainThread) [homeassistant.components.mqtt.client] mqtt: register write 24
2025-09-11 02:35:07.014 DEBUG (MainThread) [homeassistant.components.mqtt.client] Subscribing with mid: 63 to topics with qos: [('pglab/discovery/#', 0)]
2025-09-11 02:35:07.014 DEBUG (MainThread) [homeassistant.components.mqtt.client] mqtt: unregister write 24
2025-09-11 02:35:07.015 DEBUG (MainThread) [homeassistant.components.mqtt.client] mqtt: register write 24
2025-09-11 02:35:07.015 DEBUG (MainThread) [homeassistant.components.mqtt.client] Subscribing with mid: 64 to topics with qos: [('cloudapp/QBUSMQTTGW/+/state', 0)]
2025-09-11 02:35:07.015 DEBUG (MainThread) [homeassistant.components.mqtt.client] mqtt: unregister write 24
2025-09-11 02:35:07.016 DEBUG (MainThread) [homeassistant.components.mqtt.client] mqtt: register write 24
2025-09-11 02:35:07.016 DEBUG (MainThread) [homeassistant.components.mqtt.client] Subscribing with mid: 65 to topics with qos: [('tasmota/discovery/#', 0)]
2025-09-11 02:35:07.017 DEBUG (MainThread) [homeassistant.components.mqtt.client] mqtt: unregister write 24
2025-09-11 02:35:07.018 DEBUG (MainThread) [homeassistant.components.mqtt.client] mqtt: register write 24
2025-09-11 02:35:07.018 DEBUG (MainThread) [homeassistant.components.mqtt.client] Subscribing with mid: 66 to topics with qos: [('cloudapp/QBUSMQTTGW/config', 0), ('cloudapp/QBUSMQTTGW/state', 0)]
2025-09-11 02:35:07.019 DEBUG (MainThread) [homeassistant.components.mqtt.client] mqtt: unregister write 24
2025-09-11 02:35:07.056 INFO (MainThread) [homeassistant.setup] Setting up media_player
2025-09-11 02:35:07.190 INFO (MainThread) [homeassistant.setup] Setup of domain media_player took 0.13 seconds
2025-09-11 02:35:07.190 INFO (MainThread) [homeassistant.setup] Setting up number
2025-09-11 02:35:07.191 INFO (MainThread) [homeassistant.setup] Setup of domain number took 0.00 seconds
2025-09-11 02:35:07.191 INFO (MainThread) [homeassistant.setup] Setting up select
2025-09-11 02:35:07.193 INFO (MainThread) [homeassistant.setup] Setup of domain select took 0.00 seconds
2025-09-11 02:35:07.194 INFO (MainThread) [homeassistant.setup] Setting up switch
2025-09-11 02:35:07.194 INFO (MainThread) [homeassistant.setup] Setup of domain switch took 0.00 seconds
2025-09-11 02:35:07.195 INFO (MainThread) [homeassistant.components.binary_sensor] Setting up sonos.binary_sensor
2025-09-11 02:35:07.196 INFO (MainThread) [homeassistant.components.media_player] Setting up sonos.media_player
2025-09-11 02:35:07.197 INFO (MainThread) [homeassistant.components.number] Setting up sonos.number
2025-09-11 02:35:07.197 INFO (MainThread) [homeassistant.components.select] Setting up sonos.select
2025-09-11 02:35:07.198 INFO (MainThread) [homeassistant.components.sensor] Setting up sonos.sensor
2025-09-11 02:35:07.198 INFO (MainThread) [homeassistant.components.switch] Setting up sonos.switch
2025-09-11 02:35:17.192 WARNING (MainThread) [homeassistant.components.sonos] Could not get visible Sonos devices from 192.168.1.103: HTTPConnectionPool(host='192.168.1.103', port=1400): Max retries exceeded with url: /xml/DeviceProperties1.xml (Caused by ConnectTimeoutError(<urllib3.connection.HTTPConnection object at 0x7562b1b4b770>, 'Connection to 192.168.1.103 timed out. (connect timeout=10)'))
2025-09-11 02:35:19.262 WARNING (MainThread) [homeassistant.components.sonos] Subscription to 192.168.1.102 failed, attempting to poll directly
2025-09-11 02:35:21.263 INFO (MainThread) [homeassistant.bootstrap] Home Assistant initialized in 44.09s
2025-09-11 02:35:21.263 INFO (MainThread) [homeassistant.core] Starting Home Assistant 2025.9.1
2025-09-11 02:35:21.273 DEBUG (MainThread) [homeassistant.components.mqtt.trigger] Attaching MQTT trigger for topic: 'alicia/tts/announce', payload: 'None'
2025-09-11 02:35:21.274 INFO (MainThread) [homeassistant.components.automation.sonos_tts_announcement] Initialized trigger Sonos TTS Announcement
2025-09-11 02:35:21.274 DEBUG (MainThread) [homeassistant.components.mqtt.trigger] Attaching MQTT trigger for topic: 'alicia/commands/sonos/group', payload: 'None'
2025-09-11 02:35:21.274 INFO (MainThread) [homeassistant.components.automation.sonos_multi_room_group_control] Initialized trigger Sonos Multi-Room Group Control
2025-09-11 02:35:21.274 DEBUG (MainThread) [homeassistant.components.mqtt.trigger] Attaching MQTT trigger for topic: 'alicia/commands/sonos/volume', payload: 'None'
2025-09-11 02:35:21.274 INFO (MainThread) [homeassistant.components.automation.sonos_volume_control] Initialized trigger Sonos Volume Control
2025-09-11 02:35:21.274 DEBUG (MainThread) [homeassistant.components.mqtt.trigger] Attaching MQTT trigger for topic: 'alicia/commands/sonos/playback', payload: 'None'
2025-09-11 02:35:21.274 INFO (MainThread) [homeassistant.components.automation.sonos_playback_control] Initialized trigger Sonos Playback Control
2025-09-11 02:35:21.274 INFO (MainThread) [homeassistant.components.automation.sonos_status_monitor] Initialized trigger Sonos Status Monitor
2025-09-11 02:35:21.775 DEBUG (MainThread) [homeassistant.components.mqtt.client] mqtt: register write 24
2025-09-11 02:35:21.776 DEBUG (MainThread) [homeassistant.components.mqtt.client] Subscribing with mid: 67 to topics with qos: [('alicia/tts/announce', 0), ('alicia/commands/sonos/group', 0), ('alicia/commands/sonos/volume', 0), ('alicia/commands/sonos/playback', 0)]
2025-09-11 02:35:21.776 DEBUG (MainThread) [homeassistant.components.mqtt.client] mqtt: unregister write 24
2025-09-11 02:35:26.777 DEBUG (MainThread) [homeassistant.components.mqtt.client] mqtt: register write 24
2025-09-11 02:35:26.778 DEBUG (MainThread) [homeassistant.components.mqtt.client] Transmitting message on homeassistant/status: 'online', mid: 68, qos: 0
2025-09-11 02:35:26.778 DEBUG (MainThread) [homeassistant.components.mqtt.client] mqtt: unregister write 24
2025-09-11 02:35:26.778 INFO (MainThread) [homeassistant.components.mqtt.client] MQTT client initialized, birth message sent
2025-09-11 02:36:06.467 DEBUG (MainThread) [homeassistant.components.mqtt.client] mqtt: register write 24
2025-09-11 02:36:06.467 DEBUG (MainThread) [homeassistant.components.mqtt.client] mqtt: unregister write 24
2025-09-11 02:37:06.508 DEBUG (MainThread) [homeassistant.components.mqtt.client] mqtt: register write 24
2025-09-11 02:37:06.509 DEBUG (MainThread) [homeassistant.components.mqtt.client] mqtt: unregister write 24
2025-09-11 02:38:06.539 DEBUG (MainThread) [homeassistant.components.mqtt.client] mqtt: register write 24
2025-09-11 02:38:06.539 DEBUG (MainThread) [homeassistant.components.mqtt.client] mqtt: unregister write 24
2025-09-11 02:39:06.568 DEBUG (MainThread) [homeassistant.components.mqtt.client] mqtt: register write 24
2025-09-11 02:39:06.569 DEBUG (MainThread) [homeassistant.components.mqtt.client] mqtt: unregister write 24
2025-09-11 02:40:00.425 INFO (MainThread) [homeassistant.components.automation.sonos_status_monitor] Sonos Status Monitor: Running automation actions
2025-09-11 02:40:00.425 INFO (MainThread) [homeassistant.components.automation.sonos_status_monitor] Sonos Status Monitor: Executing step call service
2025-09-11 02:40:00.428 ERROR (MainThread) [homeassistant.components.automation.sonos_status_monitor] Sonos Status Monitor: Error executing script. Invalid data for call_service at pos 1: extra keys not allowed @ data['payload_template']
2025-09-11 02:40:00.428 ERROR (MainThread) [homeassistant.components.automation.sonos_status_monitor] Error while executing automation automation.sonos_status_monitor: extra keys not allowed @ data['payload_template']
