2025-09-10 22:42:31.649 INFO (MainThread) [homeassistant.setup] Setting up system_log
2025-09-10 22:42:31.748 INFO (MainThread) [homeassistant.setup] Setup of domain http took 0.10 seconds
2025-09-10 22:42:31.748 INFO (MainThread) [homeassistant.setup] Setup of domain logger took 0.10 seconds
2025-09-10 22:42:31.748 INFO (MainThread) [homeassistant.setup] Setting up websocket_api
2025-09-10 22:42:31.749 INFO (MainThread) [homeassistant.setup] Setup of domain websocket_api took 0.00 seconds
2025-09-10 22:42:31.750 INFO (MainThread) [homeassistant.setup] Setup of domain system_log took 0.10 seconds
2025-09-10 22:42:31.755 INFO (MainThread) [homeassistant.setup] Setting up network
2025-09-10 22:42:31.757 INFO (MainThread) [homeassistant.setup] Setup of domain network took 0.00 seconds
2025-09-10 22:42:31.757 INFO (MainThread) [homeassistant.bootstrap] Setting up stage frontend: {'frontend'}; already set up: {}
Dependencies: {'api', 'search', 'device_automation', 'onboarding', 'lovelace', 'repairs', 'diagnostics', 'file_upload', 'auth', 'config'}; already set up: {'http', 'websocket_api', 'system_log'}
2025-09-10 22:42:31.757 INFO (MainThread) [homeassistant.setup] Setting up api
2025-09-10 22:42:31.758 INFO (MainThread) [homeassistant.setup] Setup of domain api took 0.00 seconds
2025-09-10 22:42:31.759 INFO (MainThread) [homeassistant.setup] Setting up search
2025-09-10 22:42:31.759 INFO (MainThread) [homeassistant.setup] Setup of domain search took 0.00 seconds
2025-09-10 22:42:31.759 INFO (MainThread) [homeassistant.setup] Setting up device_automation
2025-09-10 22:42:31.759 INFO (MainThread) [homeassistant.setup] Setup of domain device_automation took 0.00 seconds
2025-09-10 22:42:31.759 INFO (MainThread) [homeassistant.setup] Setting up auth
2025-09-10 22:42:31.760 INFO (MainThread) [homeassistant.setup] Setup of domain auth took 0.00 seconds
2025-09-10 22:42:31.760 INFO (MainThread) [homeassistant.setup] Setting up onboarding
2025-09-10 22:42:31.760 INFO (MainThread) [homeassistant.setup] Setup of domain onboarding took 0.00 seconds
2025-09-10 22:42:31.760 INFO (MainThread) [homeassistant.setup] Setting up lovelace
2025-09-10 22:42:31.760 INFO (MainThread) [homeassistant.setup] Setting up diagnostics
2025-09-10 22:42:31.761 INFO (MainThread) [homeassistant.setup] Setup of domain diagnostics took 0.00 seconds
2025-09-10 22:42:31.761 INFO (MainThread) [homeassistant.setup] Setting up config
2025-09-10 22:42:31.764 INFO (MainThread) [homeassistant.setup] Setup of domain config took 0.00 seconds
2025-09-10 22:42:31.764 INFO (MainThread) [homeassistant.setup] Setting up repairs
2025-09-10 22:42:31.764 INFO (MainThread) [homeassistant.setup] Setup of domain repairs took 0.00 seconds
2025-09-10 22:42:31.764 INFO (MainThread) [homeassistant.setup] Setting up file_upload
2025-09-10 22:42:31.764 INFO (MainThread) [homeassistant.setup] Setup of domain file_upload took 0.00 seconds
2025-09-10 22:42:31.765 INFO (MainThread) [homeassistant.setup] Setup of domain lovelace took 0.01 seconds
2025-09-10 22:42:31.771 INFO (MainThread) [homeassistant.setup] Setting up frontend
2025-09-10 22:42:31.778 INFO (MainThread) [homeassistant.setup] Setup of domain frontend took 0.01 seconds
2025-09-10 22:42:31.779 INFO (MainThread) [homeassistant.bootstrap] Setting up stage recorder: {'recorder'}; already set up: {}
Dependencies: {}; already set up: {}
2025-09-10 22:42:31.779 INFO (MainThread) [homeassistant.setup] Setting up recorder
2025-09-10 22:42:31.782 INFO (MainThread) [homeassistant.setup] Setup of domain http took 0.00 seconds
2025-09-10 22:42:31.802 ERROR (Recorder) [homeassistant.components.recorder.core] Error during connection setup: (retrying in 3 seconds)
Traceback (most recent call last):
  File "/usr/local/lib/python3.13/site-packages/sqlalchemy/engine/base.py", line 145, in __init__
    self._dbapi_connection = engine.raw_connection()
                             ~~~~~~~~~~~~~~~~~~~~~^^
  File "/usr/local/lib/python3.13/site-packages/sqlalchemy/engine/base.py", line 3297, in raw_connection
    return self.pool.connect()
           ~~~~~~~~~~~~~~~~~^^
  File "/usr/local/lib/python3.13/site-packages/sqlalchemy/pool/base.py", line 449, in connect
    return _ConnectionFairy._checkout(self)
           ~~~~~~~~~~~~~~~~~~~~~~~~~~^^^^^^
  File "/usr/local/lib/python3.13/site-packages/sqlalchemy/pool/base.py", line 1264, in _checkout
    fairy = _ConnectionRecord.checkout(pool)
  File "/usr/local/lib/python3.13/site-packages/sqlalchemy/pool/base.py", line 713, in checkout
    rec = pool._do_get()
  File "/usr/local/lib/python3.13/site-packages/sqlalchemy/pool/impl.py", line 179, in _do_get
    with util.safe_reraise():
         ~~~~~~~~~~~~~~~~~^^
  File "/usr/local/lib/python3.13/site-packages/sqlalchemy/util/langhelpers.py", line 224, in __exit__
    raise exc_value.with_traceback(exc_tb)
  File "/usr/local/lib/python3.13/site-packages/sqlalchemy/pool/impl.py", line 177, in _do_get
    return self._create_connection()
           ~~~~~~~~~~~~~~~~~~~~~~~^^
  File "/usr/local/lib/python3.13/site-packages/sqlalchemy/pool/base.py", line 390, in _create_connection
    return _ConnectionRecord(self)
  File "/usr/local/lib/python3.13/site-packages/sqlalchemy/pool/base.py", line 675, in __init__
    self.__connect()
    ~~~~~~~~~~~~~~^^
  File "/usr/local/lib/python3.13/site-packages/sqlalchemy/pool/base.py", line 901, in __connect
    with util.safe_reraise():
         ~~~~~~~~~~~~~~~~~^^
  File "/usr/local/lib/python3.13/site-packages/sqlalchemy/util/langhelpers.py", line 224, in __exit__
    raise exc_value.with_traceback(exc_tb)
  File "/usr/local/lib/python3.13/site-packages/sqlalchemy/pool/base.py", line 897, in __connect
    self.dbapi_connection = connection = pool._invoke_creator(self)
                                         ~~~~~~~~~~~~~~~~~~~~^^^^^^
  File "/usr/local/lib/python3.13/site-packages/sqlalchemy/engine/create.py", line 646, in connect
    return dialect.connect(*cargs, **cparams)
           ~~~~~~~~~~~~~~~^^^^^^^^^^^^^^^^^^^
  File "/usr/local/lib/python3.13/site-packages/sqlalchemy/engine/default.py", line 625, in connect
    return self.loaded_dbapi.connect(*cargs, **cparams)  # type: ignore[no-any-return]  # NOQA: E501
           ~~~~~~~~~~~~~~~~~~~~~~~~~^^^^^^^^^^^^^^^^^^^
  File "/usr/local/lib/python3.13/site-packages/psycopg2/__init__.py", line 122, in connect
    conn = _connect(dsn, connection_factory=connection_factory, **kwasync)
psycopg2.OperationalError: connection to server at "172.21.0.3", port 5432 failed: Connection refused
	Is the server running on that host and accepting TCP/IP connections?


The above exception was the direct cause of the following exception:

Traceback (most recent call last):
  File "/usr/src/homeassistant/homeassistant/components/recorder/core.py", line 927, in _setup_recorder
    self._setup_connection()
    ~~~~~~~~~~~~~~~~~~~~~~^^
  File "/usr/src/homeassistant/homeassistant/components/recorder/core.py", line 1448, in _setup_connection
    migration.pre_migrate_schema(self.engine)
    ~~~~~~~~~~~~~~~~~~~~~~~~~~~~^^^^^^^^^^^^^
  File "/usr/src/homeassistant/homeassistant/components/recorder/migration.py", line 331, in pre_migrate_schema
    inspector = sqlalchemy.inspect(engine)
  File "/usr/local/lib/python3.13/site-packages/sqlalchemy/inspection.py", line 140, in inspect
    ret = reg(subject)
  File "/usr/local/lib/python3.13/site-packages/sqlalchemy/engine/reflection.py", line 313, in _engine_insp
    return Inspector._construct(Inspector._init_engine, bind)
           ~~~~~~~~~~~~~~~~~~~~^^^^^^^^^^^^^^^^^^^^^^^^^^^^^^
  File "/usr/local/lib/python3.13/site-packages/sqlalchemy/engine/reflection.py", line 246, in _construct
    init(self, bind)
    ~~~~^^^^^^^^^^^^
  File "/usr/local/lib/python3.13/site-packages/sqlalchemy/engine/reflection.py", line 257, in _init_engine
    engine.connect().close()
    ~~~~~~~~~~~~~~^^
  File "/usr/local/lib/python3.13/site-packages/sqlalchemy/engine/base.py", line 3273, in connect
    return self._connection_cls(self)
           ~~~~~~~~~~~~~~~~~~~~^^^^^^
  File "/usr/local/lib/python3.13/site-packages/sqlalchemy/engine/base.py", line 147, in __init__
    Connection._handle_dbapi_exception_noconnection(
    ~~~~~~~~~~~~~~~~~~~~~~~~~~~~~~~~~~~~~~~~~~~~~~~^
        err, dialect, engine
        ^^^^^^^^^^^^^^^^^^^^
    )
    ^
  File "/usr/local/lib/python3.13/site-packages/sqlalchemy/engine/base.py", line 2436, in _handle_dbapi_exception_noconnection
    raise sqlalchemy_exception.with_traceback(exc_info[2]) from e
  File "/usr/local/lib/python3.13/site-packages/sqlalchemy/engine/base.py", line 145, in __init__
    self._dbapi_connection = engine.raw_connection()
                             ~~~~~~~~~~~~~~~~~~~~~^^
  File "/usr/local/lib/python3.13/site-packages/sqlalchemy/engine/base.py", line 3297, in raw_connection
    return self.pool.connect()
           ~~~~~~~~~~~~~~~~~^^
  File "/usr/local/lib/python3.13/site-packages/sqlalchemy/pool/base.py", line 449, in connect
    return _ConnectionFairy._checkout(self)
           ~~~~~~~~~~~~~~~~~~~~~~~~~~^^^^^^
  File "/usr/local/lib/python3.13/site-packages/sqlalchemy/pool/base.py", line 1264, in _checkout
    fairy = _ConnectionRecord.checkout(pool)
  File "/usr/local/lib/python3.13/site-packages/sqlalchemy/pool/base.py", line 713, in checkout
    rec = pool._do_get()
  File "/usr/local/lib/python3.13/site-packages/sqlalchemy/pool/impl.py", line 179, in _do_get
    with util.safe_reraise():
         ~~~~~~~~~~~~~~~~~^^
  File "/usr/local/lib/python3.13/site-packages/sqlalchemy/util/langhelpers.py", line 224, in __exit__
    raise exc_value.with_traceback(exc_tb)
  File "/usr/local/lib/python3.13/site-packages/sqlalchemy/pool/impl.py", line 177, in _do_get
    return self._create_connection()
           ~~~~~~~~~~~~~~~~~~~~~~~^^
  File "/usr/local/lib/python3.13/site-packages/sqlalchemy/pool/base.py", line 390, in _create_connection
    return _ConnectionRecord(self)
  File "/usr/local/lib/python3.13/site-packages/sqlalchemy/pool/base.py", line 675, in __init__
    self.__connect()
    ~~~~~~~~~~~~~~^^
  File "/usr/local/lib/python3.13/site-packages/sqlalchemy/pool/base.py", line 901, in __connect
    with util.safe_reraise():
         ~~~~~~~~~~~~~~~~~^^
  File "/usr/local/lib/python3.13/site-packages/sqlalchemy/util/langhelpers.py", line 224, in __exit__
    raise exc_value.with_traceback(exc_tb)
  File "/usr/local/lib/python3.13/site-packages/sqlalchemy/pool/base.py", line 897, in __connect
    self.dbapi_connection = connection = pool._invoke_creator(self)
                                         ~~~~~~~~~~~~~~~~~~~~^^^^^^
  File "/usr/local/lib/python3.13/site-packages/sqlalchemy/engine/create.py", line 646, in connect
    return dialect.connect(*cargs, **cparams)
           ~~~~~~~~~~~~~~~^^^^^^^^^^^^^^^^^^^
  File "/usr/local/lib/python3.13/site-packages/sqlalchemy/engine/default.py", line 625, in connect
    return self.loaded_dbapi.connect(*cargs, **cparams)  # type: ignore[no-any-return]  # NOQA: E501
           ~~~~~~~~~~~~~~~~~~~~~~~~~^^^^^^^^^^^^^^^^^^^
  File "/usr/local/lib/python3.13/site-packages/psycopg2/__init__.py", line 122, in connect
    conn = _connect(dsn, connection_factory=connection_factory, **kwasync)
sqlalchemy.exc.OperationalError: (psycopg2.OperationalError) connection to server at "172.21.0.3", port 5432 failed: Connection refused
	Is the server running on that host and accepting TCP/IP connections?

(Background on this error at: https://sqlalche.me/e/20/e3q8)
2025-09-10 22:42:34.818 ERROR (Recorder) [homeassistant.components.recorder.core] Error during connection setup: (retrying in 3 seconds)
Traceback (most recent call last):
  File "/usr/local/lib/python3.13/site-packages/sqlalchemy/engine/base.py", line 145, in __init__
    self._dbapi_connection = engine.raw_connection()
                             ~~~~~~~~~~~~~~~~~~~~~^^
  File "/usr/local/lib/python3.13/site-packages/sqlalchemy/engine/base.py", line 3297, in raw_connection
    return self.pool.connect()
           ~~~~~~~~~~~~~~~~~^^
  File "/usr/local/lib/python3.13/site-packages/sqlalchemy/pool/base.py", line 449, in connect
    return _ConnectionFairy._checkout(self)
           ~~~~~~~~~~~~~~~~~~~~~~~~~~^^^^^^
  File "/usr/local/lib/python3.13/site-packages/sqlalchemy/pool/base.py", line 1264, in _checkout
    fairy = _ConnectionRecord.checkout(pool)
  File "/usr/local/lib/python3.13/site-packages/sqlalchemy/pool/base.py", line 713, in checkout
    rec = pool._do_get()
  File "/usr/local/lib/python3.13/site-packages/sqlalchemy/pool/impl.py", line 179, in _do_get
    with util.safe_reraise():
         ~~~~~~~~~~~~~~~~~^^
  File "/usr/local/lib/python3.13/site-packages/sqlalchemy/util/langhelpers.py", line 224, in __exit__
    raise exc_value.with_traceback(exc_tb)
  File "/usr/local/lib/python3.13/site-packages/sqlalchemy/pool/impl.py", line 177, in _do_get
    return self._create_connection()
           ~~~~~~~~~~~~~~~~~~~~~~~^^
  File "/usr/local/lib/python3.13/site-packages/sqlalchemy/pool/base.py", line 390, in _create_connection
    return _ConnectionRecord(self)
  File "/usr/local/lib/python3.13/site-packages/sqlalchemy/pool/base.py", line 675, in __init__
    self.__connect()
    ~~~~~~~~~~~~~~^^
  File "/usr/local/lib/python3.13/site-packages/sqlalchemy/pool/base.py", line 901, in __connect
    with util.safe_reraise():
         ~~~~~~~~~~~~~~~~~^^
  File "/usr/local/lib/python3.13/site-packages/sqlalchemy/util/langhelpers.py", line 224, in __exit__
    raise exc_value.with_traceback(exc_tb)
  File "/usr/local/lib/python3.13/site-packages/sqlalchemy/pool/base.py", line 897, in __connect
    self.dbapi_connection = connection = pool._invoke_creator(self)
                                         ~~~~~~~~~~~~~~~~~~~~^^^^^^
  File "/usr/local/lib/python3.13/site-packages/sqlalchemy/engine/create.py", line 646, in connect
    return dialect.connect(*cargs, **cparams)
           ~~~~~~~~~~~~~~~^^^^^^^^^^^^^^^^^^^
  File "/usr/local/lib/python3.13/site-packages/sqlalchemy/engine/default.py", line 625, in connect
    return self.loaded_dbapi.connect(*cargs, **cparams)  # type: ignore[no-any-return]  # NOQA: E501
           ~~~~~~~~~~~~~~~~~~~~~~~~~^^^^^^^^^^^^^^^^^^^
  File "/usr/local/lib/python3.13/site-packages/psycopg2/__init__.py", line 122, in connect
    conn = _connect(dsn, connection_factory=connection_factory, **kwasync)
psycopg2.OperationalError: connection to server at "172.21.0.3", port 5432 failed: Connection refused
	Is the server running on that host and accepting TCP/IP connections?


The above exception was the direct cause of the following exception:

Traceback (most recent call last):
  File "/usr/src/homeassistant/homeassistant/components/recorder/core.py", line 927, in _setup_recorder
    self._setup_connection()
    ~~~~~~~~~~~~~~~~~~~~~~^^
  File "/usr/src/homeassistant/homeassistant/components/recorder/core.py", line 1448, in _setup_connection
    migration.pre_migrate_schema(self.engine)
    ~~~~~~~~~~~~~~~~~~~~~~~~~~~~^^^^^^^^^^^^^
  File "/usr/src/homeassistant/homeassistant/components/recorder/migration.py", line 331, in pre_migrate_schema
    inspector = sqlalchemy.inspect(engine)
  File "/usr/local/lib/python3.13/site-packages/sqlalchemy/inspection.py", line 140, in inspect
    ret = reg(subject)
  File "/usr/local/lib/python3.13/site-packages/sqlalchemy/engine/reflection.py", line 313, in _engine_insp
    return Inspector._construct(Inspector._init_engine, bind)
           ~~~~~~~~~~~~~~~~~~~~^^^^^^^^^^^^^^^^^^^^^^^^^^^^^^
  File "/usr/local/lib/python3.13/site-packages/sqlalchemy/engine/reflection.py", line 246, in _construct
    init(self, bind)
    ~~~~^^^^^^^^^^^^
  File "/usr/local/lib/python3.13/site-packages/sqlalchemy/engine/reflection.py", line 257, in _init_engine
    engine.connect().close()
    ~~~~~~~~~~~~~~^^
  File "/usr/local/lib/python3.13/site-packages/sqlalchemy/engine/base.py", line 3273, in connect
    return self._connection_cls(self)
           ~~~~~~~~~~~~~~~~~~~~^^^^^^
  File "/usr/local/lib/python3.13/site-packages/sqlalchemy/engine/base.py", line 147, in __init__
    Connection._handle_dbapi_exception_noconnection(
    ~~~~~~~~~~~~~~~~~~~~~~~~~~~~~~~~~~~~~~~~~~~~~~~^
        err, dialect, engine
        ^^^^^^^^^^^^^^^^^^^^
    )
    ^
  File "/usr/local/lib/python3.13/site-packages/sqlalchemy/engine/base.py", line 2436, in _handle_dbapi_exception_noconnection
    raise sqlalchemy_exception.with_traceback(exc_info[2]) from e
  File "/usr/local/lib/python3.13/site-packages/sqlalchemy/engine/base.py", line 145, in __init__
    self._dbapi_connection = engine.raw_connection()
                             ~~~~~~~~~~~~~~~~~~~~~^^
  File "/usr/local/lib/python3.13/site-packages/sqlalchemy/engine/base.py", line 3297, in raw_connection
    return self.pool.connect()
           ~~~~~~~~~~~~~~~~~^^
  File "/usr/local/lib/python3.13/site-packages/sqlalchemy/pool/base.py", line 449, in connect
    return _ConnectionFairy._checkout(self)
           ~~~~~~~~~~~~~~~~~~~~~~~~~~^^^^^^
  File "/usr/local/lib/python3.13/site-packages/sqlalchemy/pool/base.py", line 1264, in _checkout
    fairy = _ConnectionRecord.checkout(pool)
  File "/usr/local/lib/python3.13/site-packages/sqlalchemy/pool/base.py", line 713, in checkout
    rec = pool._do_get()
  File "/usr/local/lib/python3.13/site-packages/sqlalchemy/pool/impl.py", line 179, in _do_get
    with util.safe_reraise():
         ~~~~~~~~~~~~~~~~~^^
  File "/usr/local/lib/python3.13/site-packages/sqlalchemy/util/langhelpers.py", line 224, in __exit__
    raise exc_value.with_traceback(exc_tb)
  File "/usr/local/lib/python3.13/site-packages/sqlalchemy/pool/impl.py", line 177, in _do_get
    return self._create_connection()
           ~~~~~~~~~~~~~~~~~~~~~~~^^
  File "/usr/local/lib/python3.13/site-packages/sqlalchemy/pool/base.py", line 390, in _create_connection
    return _ConnectionRecord(self)
  File "/usr/local/lib/python3.13/site-packages/sqlalchemy/pool/base.py", line 675, in __init__
    self.__connect()
    ~~~~~~~~~~~~~~^^
  File "/usr/local/lib/python3.13/site-packages/sqlalchemy/pool/base.py", line 901, in __connect
    with util.safe_reraise():
         ~~~~~~~~~~~~~~~~~^^
  File "/usr/local/lib/python3.13/site-packages/sqlalchemy/util/langhelpers.py", line 224, in __exit__
    raise exc_value.with_traceback(exc_tb)
  File "/usr/local/lib/python3.13/site-packages/sqlalchemy/pool/base.py", line 897, in __connect
    self.dbapi_connection = connection = pool._invoke_creator(self)
                                         ~~~~~~~~~~~~~~~~~~~~^^^^^^
  File "/usr/local/lib/python3.13/site-packages/sqlalchemy/engine/create.py", line 646, in connect
    return dialect.connect(*cargs, **cparams)
           ~~~~~~~~~~~~~~~^^^^^^^^^^^^^^^^^^^
  File "/usr/local/lib/python3.13/site-packages/sqlalchemy/engine/default.py", line 625, in connect
    return self.loaded_dbapi.connect(*cargs, **cparams)  # type: ignore[no-any-return]  # NOQA: E501
           ~~~~~~~~~~~~~~~~~~~~~~~~~^^^^^^^^^^^^^^^^^^^
  File "/usr/local/lib/python3.13/site-packages/psycopg2/__init__.py", line 122, in connect
    conn = _connect(dsn, connection_factory=connection_factory, **kwasync)
sqlalchemy.exc.OperationalError: (psycopg2.OperationalError) connection to server at "172.21.0.3", port 5432 failed: Connection refused
	Is the server running on that host and accepting TCP/IP connections?

(Background on this error at: https://sqlalche.me/e/20/e3q8)
2025-09-10 22:42:37.827 ERROR (Recorder) [homeassistant.components.recorder.core] Error during connection setup: (retrying in 3 seconds)
Traceback (most recent call last):
  File "/usr/local/lib/python3.13/site-packages/sqlalchemy/engine/base.py", line 145, in __init__
    self._dbapi_connection = engine.raw_connection()
                             ~~~~~~~~~~~~~~~~~~~~~^^
  File "/usr/local/lib/python3.13/site-packages/sqlalchemy/engine/base.py", line 3297, in raw_connection
    return self.pool.connect()
           ~~~~~~~~~~~~~~~~~^^
  File "/usr/local/lib/python3.13/site-packages/sqlalchemy/pool/base.py", line 449, in connect
    return _ConnectionFairy._checkout(self)
           ~~~~~~~~~~~~~~~~~~~~~~~~~~^^^^^^
  File "/usr/local/lib/python3.13/site-packages/sqlalchemy/pool/base.py", line 1264, in _checkout
    fairy = _ConnectionRecord.checkout(pool)
  File "/usr/local/lib/python3.13/site-packages/sqlalchemy/pool/base.py", line 713, in checkout
    rec = pool._do_get()
  File "/usr/local/lib/python3.13/site-packages/sqlalchemy/pool/impl.py", line 179, in _do_get
    with util.safe_reraise():
         ~~~~~~~~~~~~~~~~~^^
  File "/usr/local/lib/python3.13/site-packages/sqlalchemy/util/langhelpers.py", line 224, in __exit__
    raise exc_value.with_traceback(exc_tb)
  File "/usr/local/lib/python3.13/site-packages/sqlalchemy/pool/impl.py", line 177, in _do_get
    return self._create_connection()
           ~~~~~~~~~~~~~~~~~~~~~~~^^
  File "/usr/local/lib/python3.13/site-packages/sqlalchemy/pool/base.py", line 390, in _create_connection
    return _ConnectionRecord(self)
  File "/usr/local/lib/python3.13/site-packages/sqlalchemy/pool/base.py", line 675, in __init__
    self.__connect()
    ~~~~~~~~~~~~~~^^
  File "/usr/local/lib/python3.13/site-packages/sqlalchemy/pool/base.py", line 901, in __connect
    with util.safe_reraise():
         ~~~~~~~~~~~~~~~~~^^
  File "/usr/local/lib/python3.13/site-packages/sqlalchemy/util/langhelpers.py", line 224, in __exit__
    raise exc_value.with_traceback(exc_tb)
  File "/usr/local/lib/python3.13/site-packages/sqlalchemy/pool/base.py", line 897, in __connect
    self.dbapi_connection = connection = pool._invoke_creator(self)
                                         ~~~~~~~~~~~~~~~~~~~~^^^^^^
  File "/usr/local/lib/python3.13/site-packages/sqlalchemy/engine/create.py", line 646, in connect
    return dialect.connect(*cargs, **cparams)
           ~~~~~~~~~~~~~~~^^^^^^^^^^^^^^^^^^^
  File "/usr/local/lib/python3.13/site-packages/sqlalchemy/engine/default.py", line 625, in connect
    return self.loaded_dbapi.connect(*cargs, **cparams)  # type: ignore[no-any-return]  # NOQA: E501
           ~~~~~~~~~~~~~~~~~~~~~~~~~^^^^^^^^^^^^^^^^^^^
  File "/usr/local/lib/python3.13/site-packages/psycopg2/__init__.py", line 122, in connect
    conn = _connect(dsn, connection_factory=connection_factory, **kwasync)
psycopg2.OperationalError: connection to server at "172.21.0.3", port 5432 failed: Connection refused
	Is the server running on that host and accepting TCP/IP connections?


The above exception was the direct cause of the following exception:

Traceback (most recent call last):
  File "/usr/src/homeassistant/homeassistant/components/recorder/core.py", line 927, in _setup_recorder
    self._setup_connection()
    ~~~~~~~~~~~~~~~~~~~~~~^^
  File "/usr/src/homeassistant/homeassistant/components/recorder/core.py", line 1448, in _setup_connection
    migration.pre_migrate_schema(self.engine)
    ~~~~~~~~~~~~~~~~~~~~~~~~~~~~^^^^^^^^^^^^^
  File "/usr/src/homeassistant/homeassistant/components/recorder/migration.py", line 331, in pre_migrate_schema
    inspector = sqlalchemy.inspect(engine)
  File "/usr/local/lib/python3.13/site-packages/sqlalchemy/inspection.py", line 140, in inspect
    ret = reg(subject)
  File "/usr/local/lib/python3.13/site-packages/sqlalchemy/engine/reflection.py", line 313, in _engine_insp
    return Inspector._construct(Inspector._init_engine, bind)
           ~~~~~~~~~~~~~~~~~~~~^^^^^^^^^^^^^^^^^^^^^^^^^^^^^^
  File "/usr/local/lib/python3.13/site-packages/sqlalchemy/engine/reflection.py", line 246, in _construct
    init(self, bind)
    ~~~~^^^^^^^^^^^^
  File "/usr/local/lib/python3.13/site-packages/sqlalchemy/engine/reflection.py", line 257, in _init_engine
    engine.connect().close()
    ~~~~~~~~~~~~~~^^
  File "/usr/local/lib/python3.13/site-packages/sqlalchemy/engine/base.py", line 3273, in connect
    return self._connection_cls(self)
           ~~~~~~~~~~~~~~~~~~~~^^^^^^
  File "/usr/local/lib/python3.13/site-packages/sqlalchemy/engine/base.py", line 147, in __init__
    Connection._handle_dbapi_exception_noconnection(
    ~~~~~~~~~~~~~~~~~~~~~~~~~~~~~~~~~~~~~~~~~~~~~~~^
        err, dialect, engine
        ^^^^^^^^^^^^^^^^^^^^
    )
    ^
  File "/usr/local/lib/python3.13/site-packages/sqlalchemy/engine/base.py", line 2436, in _handle_dbapi_exception_noconnection
    raise sqlalchemy_exception.with_traceback(exc_info[2]) from e
  File "/usr/local/lib/python3.13/site-packages/sqlalchemy/engine/base.py", line 145, in __init__
    self._dbapi_connection = engine.raw_connection()
                             ~~~~~~~~~~~~~~~~~~~~~^^
  File "/usr/local/lib/python3.13/site-packages/sqlalchemy/engine/base.py", line 3297, in raw_connection
    return self.pool.connect()
           ~~~~~~~~~~~~~~~~~^^
  File "/usr/local/lib/python3.13/site-packages/sqlalchemy/pool/base.py", line 449, in connect
    return _ConnectionFairy._checkout(self)
           ~~~~~~~~~~~~~~~~~~~~~~~~~~^^^^^^
  File "/usr/local/lib/python3.13/site-packages/sqlalchemy/pool/base.py", line 1264, in _checkout
    fairy = _ConnectionRecord.checkout(pool)
  File "/usr/local/lib/python3.13/site-packages/sqlalchemy/pool/base.py", line 713, in checkout
    rec = pool._do_get()
  File "/usr/local/lib/python3.13/site-packages/sqlalchemy/pool/impl.py", line 179, in _do_get
    with util.safe_reraise():
         ~~~~~~~~~~~~~~~~~^^
  File "/usr/local/lib/python3.13/site-packages/sqlalchemy/util/langhelpers.py", line 224, in __exit__
    raise exc_value.with_traceback(exc_tb)
  File "/usr/local/lib/python3.13/site-packages/sqlalchemy/pool/impl.py", line 177, in _do_get
    return self._create_connection()
           ~~~~~~~~~~~~~~~~~~~~~~~^^
  File "/usr/local/lib/python3.13/site-packages/sqlalchemy/pool/base.py", line 390, in _create_connection
    return _ConnectionRecord(self)
  File "/usr/local/lib/python3.13/site-packages/sqlalchemy/pool/base.py", line 675, in __init__
    self.__connect()
    ~~~~~~~~~~~~~~^^
  File "/usr/local/lib/python3.13/site-packages/sqlalchemy/pool/base.py", line 901, in __connect
    with util.safe_reraise():
         ~~~~~~~~~~~~~~~~~^^
  File "/usr/local/lib/python3.13/site-packages/sqlalchemy/util/langhelpers.py", line 224, in __exit__
    raise exc_value.with_traceback(exc_tb)
  File "/usr/local/lib/python3.13/site-packages/sqlalchemy/pool/base.py", line 897, in __connect
    self.dbapi_connection = connection = pool._invoke_creator(self)
                                         ~~~~~~~~~~~~~~~~~~~~^^^^^^
  File "/usr/local/lib/python3.13/site-packages/sqlalchemy/engine/create.py", line 646, in connect
    return dialect.connect(*cargs, **cparams)
           ~~~~~~~~~~~~~~~^^^^^^^^^^^^^^^^^^^
  File "/usr/local/lib/python3.13/site-packages/sqlalchemy/engine/default.py", line 625, in connect
    return self.loaded_dbapi.connect(*cargs, **cparams)  # type: ignore[no-any-return]  # NOQA: E501
           ~~~~~~~~~~~~~~~~~~~~~~~~~^^^^^^^^^^^^^^^^^^^
  File "/usr/local/lib/python3.13/site-packages/psycopg2/__init__.py", line 122, in connect
    conn = _connect(dsn, connection_factory=connection_factory, **kwasync)
sqlalchemy.exc.OperationalError: (psycopg2.OperationalError) connection to server at "172.21.0.3", port 5432 failed: Connection refused
	Is the server running on that host and accepting TCP/IP connections?

(Background on this error at: https://sqlalche.me/e/20/e3q8)
2025-09-10 22:42:40.836 ERROR (Recorder) [homeassistant.components.recorder.core] Error during connection setup: (retrying in 3 seconds)
Traceback (most recent call last):
  File "/usr/local/lib/python3.13/site-packages/sqlalchemy/engine/base.py", line 145, in __init__
    self._dbapi_connection = engine.raw_connection()
                             ~~~~~~~~~~~~~~~~~~~~~^^
  File "/usr/local/lib/python3.13/site-packages/sqlalchemy/engine/base.py", line 3297, in raw_connection
    return self.pool.connect()
           ~~~~~~~~~~~~~~~~~^^
  File "/usr/local/lib/python3.13/site-packages/sqlalchemy/pool/base.py", line 449, in connect
    return _ConnectionFairy._checkout(self)
           ~~~~~~~~~~~~~~~~~~~~~~~~~~^^^^^^
  File "/usr/local/lib/python3.13/site-packages/sqlalchemy/pool/base.py", line 1264, in _checkout
    fairy = _ConnectionRecord.checkout(pool)
  File "/usr/local/lib/python3.13/site-packages/sqlalchemy/pool/base.py", line 713, in checkout
    rec = pool._do_get()
  File "/usr/local/lib/python3.13/site-packages/sqlalchemy/pool/impl.py", line 179, in _do_get
    with util.safe_reraise():
         ~~~~~~~~~~~~~~~~~^^
  File "/usr/local/lib/python3.13/site-packages/sqlalchemy/util/langhelpers.py", line 224, in __exit__
    raise exc_value.with_traceback(exc_tb)
  File "/usr/local/lib/python3.13/site-packages/sqlalchemy/pool/impl.py", line 177, in _do_get
    return self._create_connection()
           ~~~~~~~~~~~~~~~~~~~~~~~^^
  File "/usr/local/lib/python3.13/site-packages/sqlalchemy/pool/base.py", line 390, in _create_connection
    return _ConnectionRecord(self)
  File "/usr/local/lib/python3.13/site-packages/sqlalchemy/pool/base.py", line 675, in __init__
    self.__connect()
    ~~~~~~~~~~~~~~^^
  File "/usr/local/lib/python3.13/site-packages/sqlalchemy/pool/base.py", line 901, in __connect
    with util.safe_reraise():
         ~~~~~~~~~~~~~~~~~^^
  File "/usr/local/lib/python3.13/site-packages/sqlalchemy/util/langhelpers.py", line 224, in __exit__
    raise exc_value.with_traceback(exc_tb)
  File "/usr/local/lib/python3.13/site-packages/sqlalchemy/pool/base.py", line 897, in __connect
    self.dbapi_connection = connection = pool._invoke_creator(self)
                                         ~~~~~~~~~~~~~~~~~~~~^^^^^^
  File "/usr/local/lib/python3.13/site-packages/sqlalchemy/engine/create.py", line 646, in connect
    return dialect.connect(*cargs, **cparams)
           ~~~~~~~~~~~~~~~^^^^^^^^^^^^^^^^^^^
  File "/usr/local/lib/python3.13/site-packages/sqlalchemy/engine/default.py", line 625, in connect
    return self.loaded_dbapi.connect(*cargs, **cparams)  # type: ignore[no-any-return]  # NOQA: E501
           ~~~~~~~~~~~~~~~~~~~~~~~~~^^^^^^^^^^^^^^^^^^^
  File "/usr/local/lib/python3.13/site-packages/psycopg2/__init__.py", line 122, in connect
    conn = _connect(dsn, connection_factory=connection_factory, **kwasync)
psycopg2.OperationalError: connection to server at "172.21.0.3", port 5432 failed: Connection refused
	Is the server running on that host and accepting TCP/IP connections?


The above exception was the direct cause of the following exception:

Traceback (most recent call last):
  File "/usr/src/homeassistant/homeassistant/components/recorder/core.py", line 927, in _setup_recorder
    self._setup_connection()
    ~~~~~~~~~~~~~~~~~~~~~~^^
  File "/usr/src/homeassistant/homeassistant/components/recorder/core.py", line 1448, in _setup_connection
    migration.pre_migrate_schema(self.engine)
    ~~~~~~~~~~~~~~~~~~~~~~~~~~~~^^^^^^^^^^^^^
  File "/usr/src/homeassistant/homeassistant/components/recorder/migration.py", line 331, in pre_migrate_schema
    inspector = sqlalchemy.inspect(engine)
  File "/usr/local/lib/python3.13/site-packages/sqlalchemy/inspection.py", line 140, in inspect
    ret = reg(subject)
  File "/usr/local/lib/python3.13/site-packages/sqlalchemy/engine/reflection.py", line 313, in _engine_insp
    return Inspector._construct(Inspector._init_engine, bind)
           ~~~~~~~~~~~~~~~~~~~~^^^^^^^^^^^^^^^^^^^^^^^^^^^^^^
  File "/usr/local/lib/python3.13/site-packages/sqlalchemy/engine/reflection.py", line 246, in _construct
    init(self, bind)
    ~~~~^^^^^^^^^^^^
  File "/usr/local/lib/python3.13/site-packages/sqlalchemy/engine/reflection.py", line 257, in _init_engine
    engine.connect().close()
    ~~~~~~~~~~~~~~^^
  File "/usr/local/lib/python3.13/site-packages/sqlalchemy/engine/base.py", line 3273, in connect
    return self._connection_cls(self)
           ~~~~~~~~~~~~~~~~~~~~^^^^^^
  File "/usr/local/lib/python3.13/site-packages/sqlalchemy/engine/base.py", line 147, in __init__
    Connection._handle_dbapi_exception_noconnection(
    ~~~~~~~~~~~~~~~~~~~~~~~~~~~~~~~~~~~~~~~~~~~~~~~^
        err, dialect, engine
        ^^^^^^^^^^^^^^^^^^^^
    )
    ^
  File "/usr/local/lib/python3.13/site-packages/sqlalchemy/engine/base.py", line 2436, in _handle_dbapi_exception_noconnection
    raise sqlalchemy_exception.with_traceback(exc_info[2]) from e
  File "/usr/local/lib/python3.13/site-packages/sqlalchemy/engine/base.py", line 145, in __init__
    self._dbapi_connection = engine.raw_connection()
                             ~~~~~~~~~~~~~~~~~~~~~^^
  File "/usr/local/lib/python3.13/site-packages/sqlalchemy/engine/base.py", line 3297, in raw_connection
    return self.pool.connect()
           ~~~~~~~~~~~~~~~~~^^
  File "/usr/local/lib/python3.13/site-packages/sqlalchemy/pool/base.py", line 449, in connect
    return _ConnectionFairy._checkout(self)
           ~~~~~~~~~~~~~~~~~~~~~~~~~~^^^^^^
  File "/usr/local/lib/python3.13/site-packages/sqlalchemy/pool/base.py", line 1264, in _checkout
    fairy = _ConnectionRecord.checkout(pool)
  File "/usr/local/lib/python3.13/site-packages/sqlalchemy/pool/base.py", line 713, in checkout
    rec = pool._do_get()
  File "/usr/local/lib/python3.13/site-packages/sqlalchemy/pool/impl.py", line 179, in _do_get
    with util.safe_reraise():
         ~~~~~~~~~~~~~~~~~^^
  File "/usr/local/lib/python3.13/site-packages/sqlalchemy/util/langhelpers.py", line 224, in __exit__
    raise exc_value.with_traceback(exc_tb)
  File "/usr/local/lib/python3.13/site-packages/sqlalchemy/pool/impl.py", line 177, in _do_get
    return self._create_connection()
           ~~~~~~~~~~~~~~~~~~~~~~~^^
  File "/usr/local/lib/python3.13/site-packages/sqlalchemy/pool/base.py", line 390, in _create_connection
    return _ConnectionRecord(self)
  File "/usr/local/lib/python3.13/site-packages/sqlalchemy/pool/base.py", line 675, in __init__
    self.__connect()
    ~~~~~~~~~~~~~~^^
  File "/usr/local/lib/python3.13/site-packages/sqlalchemy/pool/base.py", line 901, in __connect
    with util.safe_reraise():
         ~~~~~~~~~~~~~~~~~^^
  File "/usr/local/lib/python3.13/site-packages/sqlalchemy/util/langhelpers.py", line 224, in __exit__
    raise exc_value.with_traceback(exc_tb)
  File "/usr/local/lib/python3.13/site-packages/sqlalchemy/pool/base.py", line 897, in __connect
    self.dbapi_connection = connection = pool._invoke_creator(self)
                                         ~~~~~~~~~~~~~~~~~~~~^^^^^^
  File "/usr/local/lib/python3.13/site-packages/sqlalchemy/engine/create.py", line 646, in connect
    return dialect.connect(*cargs, **cparams)
           ~~~~~~~~~~~~~~~^^^^^^^^^^^^^^^^^^^
  File "/usr/local/lib/python3.13/site-packages/sqlalchemy/engine/default.py", line 625, in connect
    return self.loaded_dbapi.connect(*cargs, **cparams)  # type: ignore[no-any-return]  # NOQA: E501
           ~~~~~~~~~~~~~~~~~~~~~~~~~^^^^^^^^^^^^^^^^^^^
  File "/usr/local/lib/python3.13/site-packages/psycopg2/__init__.py", line 122, in connect
    conn = _connect(dsn, connection_factory=connection_factory, **kwasync)
sqlalchemy.exc.OperationalError: (psycopg2.OperationalError) connection to server at "172.21.0.3", port 5432 failed: Connection refused
	Is the server running on that host and accepting TCP/IP connections?

(Background on this error at: https://sqlalche.me/e/20/e3q8)
2025-09-10 22:42:41.780 WARNING (MainThread) [homeassistant.setup] Setup of recorder is taking over 10 seconds.
2025-09-10 22:42:43.843 ERROR (Recorder) [homeassistant.components.recorder.core] Error during connection setup: (retrying in 3 seconds)
Traceback (most recent call last):
  File "/usr/local/lib/python3.13/site-packages/sqlalchemy/engine/base.py", line 145, in __init__
    self._dbapi_connection = engine.raw_connection()
                             ~~~~~~~~~~~~~~~~~~~~~^^
  File "/usr/local/lib/python3.13/site-packages/sqlalchemy/engine/base.py", line 3297, in raw_connection
    return self.pool.connect()
           ~~~~~~~~~~~~~~~~~^^
  File "/usr/local/lib/python3.13/site-packages/sqlalchemy/pool/base.py", line 449, in connect
    return _ConnectionFairy._checkout(self)
           ~~~~~~~~~~~~~~~~~~~~~~~~~~^^^^^^
  File "/usr/local/lib/python3.13/site-packages/sqlalchemy/pool/base.py", line 1264, in _checkout
    fairy = _ConnectionRecord.checkout(pool)
  File "/usr/local/lib/python3.13/site-packages/sqlalchemy/pool/base.py", line 713, in checkout
    rec = pool._do_get()
  File "/usr/local/lib/python3.13/site-packages/sqlalchemy/pool/impl.py", line 179, in _do_get
    with util.safe_reraise():
         ~~~~~~~~~~~~~~~~~^^
  File "/usr/local/lib/python3.13/site-packages/sqlalchemy/util/langhelpers.py", line 224, in __exit__
    raise exc_value.with_traceback(exc_tb)
  File "/usr/local/lib/python3.13/site-packages/sqlalchemy/pool/impl.py", line 177, in _do_get
    return self._create_connection()
           ~~~~~~~~~~~~~~~~~~~~~~~^^
  File "/usr/local/lib/python3.13/site-packages/sqlalchemy/pool/base.py", line 390, in _create_connection
    return _ConnectionRecord(self)
  File "/usr/local/lib/python3.13/site-packages/sqlalchemy/pool/base.py", line 675, in __init__
    self.__connect()
    ~~~~~~~~~~~~~~^^
  File "/usr/local/lib/python3.13/site-packages/sqlalchemy/pool/base.py", line 901, in __connect
    with util.safe_reraise():
         ~~~~~~~~~~~~~~~~~^^
  File "/usr/local/lib/python3.13/site-packages/sqlalchemy/util/langhelpers.py", line 224, in __exit__
    raise exc_value.with_traceback(exc_tb)
  File "/usr/local/lib/python3.13/site-packages/sqlalchemy/pool/base.py", line 897, in __connect
    self.dbapi_connection = connection = pool._invoke_creator(self)
                                         ~~~~~~~~~~~~~~~~~~~~^^^^^^
  File "/usr/local/lib/python3.13/site-packages/sqlalchemy/engine/create.py", line 646, in connect
    return dialect.connect(*cargs, **cparams)
           ~~~~~~~~~~~~~~~^^^^^^^^^^^^^^^^^^^
  File "/usr/local/lib/python3.13/site-packages/sqlalchemy/engine/default.py", line 625, in connect
    return self.loaded_dbapi.connect(*cargs, **cparams)  # type: ignore[no-any-return]  # NOQA: E501
           ~~~~~~~~~~~~~~~~~~~~~~~~~^^^^^^^^^^^^^^^^^^^
  File "/usr/local/lib/python3.13/site-packages/psycopg2/__init__.py", line 122, in connect
    conn = _connect(dsn, connection_factory=connection_factory, **kwasync)
psycopg2.OperationalError: connection to server at "172.21.0.3", port 5432 failed: Connection refused
	Is the server running on that host and accepting TCP/IP connections?


The above exception was the direct cause of the following exception:

Traceback (most recent call last):
  File "/usr/src/homeassistant/homeassistant/components/recorder/core.py", line 927, in _setup_recorder
    self._setup_connection()
    ~~~~~~~~~~~~~~~~~~~~~~^^
  File "/usr/src/homeassistant/homeassistant/components/recorder/core.py", line 1448, in _setup_connection
    migration.pre_migrate_schema(self.engine)
    ~~~~~~~~~~~~~~~~~~~~~~~~~~~~^^^^^^^^^^^^^
  File "/usr/src/homeassistant/homeassistant/components/recorder/migration.py", line 331, in pre_migrate_schema
    inspector = sqlalchemy.inspect(engine)
  File "/usr/local/lib/python3.13/site-packages/sqlalchemy/inspection.py", line 140, in inspect
    ret = reg(subject)
  File "/usr/local/lib/python3.13/site-packages/sqlalchemy/engine/reflection.py", line 313, in _engine_insp
    return Inspector._construct(Inspector._init_engine, bind)
           ~~~~~~~~~~~~~~~~~~~~^^^^^^^^^^^^^^^^^^^^^^^^^^^^^^
  File "/usr/local/lib/python3.13/site-packages/sqlalchemy/engine/reflection.py", line 246, in _construct
    init(self, bind)
    ~~~~^^^^^^^^^^^^
  File "/usr/local/lib/python3.13/site-packages/sqlalchemy/engine/reflection.py", line 257, in _init_engine
    engine.connect().close()
    ~~~~~~~~~~~~~~^^
  File "/usr/local/lib/python3.13/site-packages/sqlalchemy/engine/base.py", line 3273, in connect
    return self._connection_cls(self)
           ~~~~~~~~~~~~~~~~~~~~^^^^^^
  File "/usr/local/lib/python3.13/site-packages/sqlalchemy/engine/base.py", line 147, in __init__
    Connection._handle_dbapi_exception_noconnection(
    ~~~~~~~~~~~~~~~~~~~~~~~~~~~~~~~~~~~~~~~~~~~~~~~^
        err, dialect, engine
        ^^^^^^^^^^^^^^^^^^^^
    )
    ^
  File "/usr/local/lib/python3.13/site-packages/sqlalchemy/engine/base.py", line 2436, in _handle_dbapi_exception_noconnection
    raise sqlalchemy_exception.with_traceback(exc_info[2]) from e
  File "/usr/local/lib/python3.13/site-packages/sqlalchemy/engine/base.py", line 145, in __init__
    self._dbapi_connection = engine.raw_connection()
                             ~~~~~~~~~~~~~~~~~~~~~^^
  File "/usr/local/lib/python3.13/site-packages/sqlalchemy/engine/base.py", line 3297, in raw_connection
    return self.pool.connect()
           ~~~~~~~~~~~~~~~~~^^
  File "/usr/local/lib/python3.13/site-packages/sqlalchemy/pool/base.py", line 449, in connect
    return _ConnectionFairy._checkout(self)
           ~~~~~~~~~~~~~~~~~~~~~~~~~~^^^^^^
  File "/usr/local/lib/python3.13/site-packages/sqlalchemy/pool/base.py", line 1264, in _checkout
    fairy = _ConnectionRecord.checkout(pool)
  File "/usr/local/lib/python3.13/site-packages/sqlalchemy/pool/base.py", line 713, in checkout
    rec = pool._do_get()
  File "/usr/local/lib/python3.13/site-packages/sqlalchemy/pool/impl.py", line 179, in _do_get
    with util.safe_reraise():
         ~~~~~~~~~~~~~~~~~^^
  File "/usr/local/lib/python3.13/site-packages/sqlalchemy/util/langhelpers.py", line 224, in __exit__
    raise exc_value.with_traceback(exc_tb)
  File "/usr/local/lib/python3.13/site-packages/sqlalchemy/pool/impl.py", line 177, in _do_get
    return self._create_connection()
           ~~~~~~~~~~~~~~~~~~~~~~~^^
  File "/usr/local/lib/python3.13/site-packages/sqlalchemy/pool/base.py", line 390, in _create_connection
    return _ConnectionRecord(self)
  File "/usr/local/lib/python3.13/site-packages/sqlalchemy/pool/base.py", line 675, in __init__
    self.__connect()
    ~~~~~~~~~~~~~~^^
  File "/usr/local/lib/python3.13/site-packages/sqlalchemy/pool/base.py", line 901, in __connect
    with util.safe_reraise():
         ~~~~~~~~~~~~~~~~~^^
  File "/usr/local/lib/python3.13/site-packages/sqlalchemy/util/langhelpers.py", line 224, in __exit__
    raise exc_value.with_traceback(exc_tb)
  File "/usr/local/lib/python3.13/site-packages/sqlalchemy/pool/base.py", line 897, in __connect
    self.dbapi_connection = connection = pool._invoke_creator(self)
                                         ~~~~~~~~~~~~~~~~~~~~^^^^^^
  File "/usr/local/lib/python3.13/site-packages/sqlalchemy/engine/create.py", line 646, in connect
    return dialect.connect(*cargs, **cparams)
           ~~~~~~~~~~~~~~~^^^^^^^^^^^^^^^^^^^
  File "/usr/local/lib/python3.13/site-packages/sqlalchemy/engine/default.py", line 625, in connect
    return self.loaded_dbapi.connect(*cargs, **cparams)  # type: ignore[no-any-return]  # NOQA: E501
           ~~~~~~~~~~~~~~~~~~~~~~~~~^^^^^^^^^^^^^^^^^^^
  File "/usr/local/lib/python3.13/site-packages/psycopg2/__init__.py", line 122, in connect
    conn = _connect(dsn, connection_factory=connection_factory, **kwasync)
sqlalchemy.exc.OperationalError: (psycopg2.OperationalError) connection to server at "172.21.0.3", port 5432 failed: Connection refused
	Is the server running on that host and accepting TCP/IP connections?

(Background on this error at: https://sqlalche.me/e/20/e3q8)
2025-09-10 22:42:46.852 ERROR (Recorder) [homeassistant.components.recorder.core] Error during connection setup: (retrying in 3 seconds)
Traceback (most recent call last):
  File "/usr/local/lib/python3.13/site-packages/sqlalchemy/engine/base.py", line 145, in __init__
    self._dbapi_connection = engine.raw_connection()
                             ~~~~~~~~~~~~~~~~~~~~~^^
  File "/usr/local/lib/python3.13/site-packages/sqlalchemy/engine/base.py", line 3297, in raw_connection
    return self.pool.connect()
           ~~~~~~~~~~~~~~~~~^^
  File "/usr/local/lib/python3.13/site-packages/sqlalchemy/pool/base.py", line 449, in connect
    return _ConnectionFairy._checkout(self)
           ~~~~~~~~~~~~~~~~~~~~~~~~~~^^^^^^
  File "/usr/local/lib/python3.13/site-packages/sqlalchemy/pool/base.py", line 1264, in _checkout
    fairy = _ConnectionRecord.checkout(pool)
  File "/usr/local/lib/python3.13/site-packages/sqlalchemy/pool/base.py", line 713, in checkout
    rec = pool._do_get()
  File "/usr/local/lib/python3.13/site-packages/sqlalchemy/pool/impl.py", line 179, in _do_get
    with util.safe_reraise():
         ~~~~~~~~~~~~~~~~~^^
  File "/usr/local/lib/python3.13/site-packages/sqlalchemy/util/langhelpers.py", line 224, in __exit__
    raise exc_value.with_traceback(exc_tb)
  File "/usr/local/lib/python3.13/site-packages/sqlalchemy/pool/impl.py", line 177, in _do_get
    return self._create_connection()
           ~~~~~~~~~~~~~~~~~~~~~~~^^
  File "/usr/local/lib/python3.13/site-packages/sqlalchemy/pool/base.py", line 390, in _create_connection
    return _ConnectionRecord(self)
  File "/usr/local/lib/python3.13/site-packages/sqlalchemy/pool/base.py", line 675, in __init__
    self.__connect()
    ~~~~~~~~~~~~~~^^
  File "/usr/local/lib/python3.13/site-packages/sqlalchemy/pool/base.py", line 901, in __connect
    with util.safe_reraise():
         ~~~~~~~~~~~~~~~~~^^
  File "/usr/local/lib/python3.13/site-packages/sqlalchemy/util/langhelpers.py", line 224, in __exit__
    raise exc_value.with_traceback(exc_tb)
  File "/usr/local/lib/python3.13/site-packages/sqlalchemy/pool/base.py", line 897, in __connect
    self.dbapi_connection = connection = pool._invoke_creator(self)
                                         ~~~~~~~~~~~~~~~~~~~~^^^^^^
  File "/usr/local/lib/python3.13/site-packages/sqlalchemy/engine/create.py", line 646, in connect
    return dialect.connect(*cargs, **cparams)
           ~~~~~~~~~~~~~~~^^^^^^^^^^^^^^^^^^^
  File "/usr/local/lib/python3.13/site-packages/sqlalchemy/engine/default.py", line 625, in connect
    return self.loaded_dbapi.connect(*cargs, **cparams)  # type: ignore[no-any-return]  # NOQA: E501
           ~~~~~~~~~~~~~~~~~~~~~~~~~^^^^^^^^^^^^^^^^^^^
  File "/usr/local/lib/python3.13/site-packages/psycopg2/__init__.py", line 122, in connect
    conn = _connect(dsn, connection_factory=connection_factory, **kwasync)
psycopg2.OperationalError: connection to server at "172.21.0.3", port 5432 failed: Connection refused
	Is the server running on that host and accepting TCP/IP connections?


The above exception was the direct cause of the following exception:

Traceback (most recent call last):
  File "/usr/src/homeassistant/homeassistant/components/recorder/core.py", line 927, in _setup_recorder
    self._setup_connection()
    ~~~~~~~~~~~~~~~~~~~~~~^^
  File "/usr/src/homeassistant/homeassistant/components/recorder/core.py", line 1448, in _setup_connection
    migration.pre_migrate_schema(self.engine)
    ~~~~~~~~~~~~~~~~~~~~~~~~~~~~^^^^^^^^^^^^^
  File "/usr/src/homeassistant/homeassistant/components/recorder/migration.py", line 331, in pre_migrate_schema
    inspector = sqlalchemy.inspect(engine)
  File "/usr/local/lib/python3.13/site-packages/sqlalchemy/inspection.py", line 140, in inspect
    ret = reg(subject)
  File "/usr/local/lib/python3.13/site-packages/sqlalchemy/engine/reflection.py", line 313, in _engine_insp
    return Inspector._construct(Inspector._init_engine, bind)
           ~~~~~~~~~~~~~~~~~~~~^^^^^^^^^^^^^^^^^^^^^^^^^^^^^^
  File "/usr/local/lib/python3.13/site-packages/sqlalchemy/engine/reflection.py", line 246, in _construct
    init(self, bind)
    ~~~~^^^^^^^^^^^^
  File "/usr/local/lib/python3.13/site-packages/sqlalchemy/engine/reflection.py", line 257, in _init_engine
    engine.connect().close()
    ~~~~~~~~~~~~~~^^
  File "/usr/local/lib/python3.13/site-packages/sqlalchemy/engine/base.py", line 3273, in connect
    return self._connection_cls(self)
           ~~~~~~~~~~~~~~~~~~~~^^^^^^
  File "/usr/local/lib/python3.13/site-packages/sqlalchemy/engine/base.py", line 147, in __init__
    Connection._handle_dbapi_exception_noconnection(
    ~~~~~~~~~~~~~~~~~~~~~~~~~~~~~~~~~~~~~~~~~~~~~~~^
        err, dialect, engine
        ^^^^^^^^^^^^^^^^^^^^
    )
    ^
  File "/usr/local/lib/python3.13/site-packages/sqlalchemy/engine/base.py", line 2436, in _handle_dbapi_exception_noconnection
    raise sqlalchemy_exception.with_traceback(exc_info[2]) from e
  File "/usr/local/lib/python3.13/site-packages/sqlalchemy/engine/base.py", line 145, in __init__
    self._dbapi_connection = engine.raw_connection()
                             ~~~~~~~~~~~~~~~~~~~~~^^
  File "/usr/local/lib/python3.13/site-packages/sqlalchemy/engine/base.py", line 3297, in raw_connection
    return self.pool.connect()
           ~~~~~~~~~~~~~~~~~^^
  File "/usr/local/lib/python3.13/site-packages/sqlalchemy/pool/base.py", line 449, in connect
    return _ConnectionFairy._checkout(self)
           ~~~~~~~~~~~~~~~~~~~~~~~~~~^^^^^^
  File "/usr/local/lib/python3.13/site-packages/sqlalchemy/pool/base.py", line 1264, in _checkout
    fairy = _ConnectionRecord.checkout(pool)
  File "/usr/local/lib/python3.13/site-packages/sqlalchemy/pool/base.py", line 713, in checkout
    rec = pool._do_get()
  File "/usr/local/lib/python3.13/site-packages/sqlalchemy/pool/impl.py", line 179, in _do_get
    with util.safe_reraise():
         ~~~~~~~~~~~~~~~~~^^
  File "/usr/local/lib/python3.13/site-packages/sqlalchemy/util/langhelpers.py", line 224, in __exit__
    raise exc_value.with_traceback(exc_tb)
  File "/usr/local/lib/python3.13/site-packages/sqlalchemy/pool/impl.py", line 177, in _do_get
    return self._create_connection()
           ~~~~~~~~~~~~~~~~~~~~~~~^^
  File "/usr/local/lib/python3.13/site-packages/sqlalchemy/pool/base.py", line 390, in _create_connection
    return _ConnectionRecord(self)
  File "/usr/local/lib/python3.13/site-packages/sqlalchemy/pool/base.py", line 675, in __init__
    self.__connect()
    ~~~~~~~~~~~~~~^^
  File "/usr/local/lib/python3.13/site-packages/sqlalchemy/pool/base.py", line 901, in __connect
    with util.safe_reraise():
         ~~~~~~~~~~~~~~~~~^^
  File "/usr/local/lib/python3.13/site-packages/sqlalchemy/util/langhelpers.py", line 224, in __exit__
    raise exc_value.with_traceback(exc_tb)
  File "/usr/local/lib/python3.13/site-packages/sqlalchemy/pool/base.py", line 897, in __connect
    self.dbapi_connection = connection = pool._invoke_creator(self)
                                         ~~~~~~~~~~~~~~~~~~~~^^^^^^
  File "/usr/local/lib/python3.13/site-packages/sqlalchemy/engine/create.py", line 646, in connect
    return dialect.connect(*cargs, **cparams)
           ~~~~~~~~~~~~~~~^^^^^^^^^^^^^^^^^^^
  File "/usr/local/lib/python3.13/site-packages/sqlalchemy/engine/default.py", line 625, in connect
    return self.loaded_dbapi.connect(*cargs, **cparams)  # type: ignore[no-any-return]  # NOQA: E501
           ~~~~~~~~~~~~~~~~~~~~~~~~~^^^^^^^^^^^^^^^^^^^
  File "/usr/local/lib/python3.13/site-packages/psycopg2/__init__.py", line 122, in connect
    conn = _connect(dsn, connection_factory=connection_factory, **kwasync)
sqlalchemy.exc.OperationalError: (psycopg2.OperationalError) connection to server at "172.21.0.3", port 5432 failed: Connection refused
	Is the server running on that host and accepting TCP/IP connections?

(Background on this error at: https://sqlalche.me/e/20/e3q8)
2025-09-10 22:42:49.975 ERROR (Recorder) [homeassistant.components.recorder.core] Error during connection setup: (retrying in 3 seconds)
Traceback (most recent call last):
  File "/usr/local/lib/python3.13/site-packages/sqlalchemy/engine/base.py", line 145, in __init__
    self._dbapi_connection = engine.raw_connection()
                             ~~~~~~~~~~~~~~~~~~~~~^^
  File "/usr/local/lib/python3.13/site-packages/sqlalchemy/engine/base.py", line 3297, in raw_connection
    return self.pool.connect()
           ~~~~~~~~~~~~~~~~~^^
  File "/usr/local/lib/python3.13/site-packages/sqlalchemy/pool/base.py", line 449, in connect
    return _ConnectionFairy._checkout(self)
           ~~~~~~~~~~~~~~~~~~~~~~~~~~^^^^^^
  File "/usr/local/lib/python3.13/site-packages/sqlalchemy/pool/base.py", line 1264, in _checkout
    fairy = _ConnectionRecord.checkout(pool)
  File "/usr/local/lib/python3.13/site-packages/sqlalchemy/pool/base.py", line 713, in checkout
    rec = pool._do_get()
  File "/usr/local/lib/python3.13/site-packages/sqlalchemy/pool/impl.py", line 179, in _do_get
    with util.safe_reraise():
         ~~~~~~~~~~~~~~~~~^^
  File "/usr/local/lib/python3.13/site-packages/sqlalchemy/util/langhelpers.py", line 224, in __exit__
    raise exc_value.with_traceback(exc_tb)
  File "/usr/local/lib/python3.13/site-packages/sqlalchemy/pool/impl.py", line 177, in _do_get
    return self._create_connection()
           ~~~~~~~~~~~~~~~~~~~~~~~^^
  File "/usr/local/lib/python3.13/site-packages/sqlalchemy/pool/base.py", line 390, in _create_connection
    return _ConnectionRecord(self)
  File "/usr/local/lib/python3.13/site-packages/sqlalchemy/pool/base.py", line 675, in __init__
    self.__connect()
    ~~~~~~~~~~~~~~^^
  File "/usr/local/lib/python3.13/site-packages/sqlalchemy/pool/base.py", line 901, in __connect
    with util.safe_reraise():
         ~~~~~~~~~~~~~~~~~^^
  File "/usr/local/lib/python3.13/site-packages/sqlalchemy/util/langhelpers.py", line 224, in __exit__
    raise exc_value.with_traceback(exc_tb)
  File "/usr/local/lib/python3.13/site-packages/sqlalchemy/pool/base.py", line 897, in __connect
    self.dbapi_connection = connection = pool._invoke_creator(self)
                                         ~~~~~~~~~~~~~~~~~~~~^^^^^^
  File "/usr/local/lib/python3.13/site-packages/sqlalchemy/engine/create.py", line 646, in connect
    return dialect.connect(*cargs, **cparams)
           ~~~~~~~~~~~~~~~^^^^^^^^^^^^^^^^^^^
  File "/usr/local/lib/python3.13/site-packages/sqlalchemy/engine/default.py", line 625, in connect
    return self.loaded_dbapi.connect(*cargs, **cparams)  # type: ignore[no-any-return]  # NOQA: E501
           ~~~~~~~~~~~~~~~~~~~~~~~~~^^^^^^^^^^^^^^^^^^^
  File "/usr/local/lib/python3.13/site-packages/psycopg2/__init__.py", line 122, in connect
    conn = _connect(dsn, connection_factory=connection_factory, **kwasync)
psycopg2.OperationalError: connection to server at "172.21.0.3", port 5432 failed: Connection refused
	Is the server running on that host and accepting TCP/IP connections?


The above exception was the direct cause of the following exception:

Traceback (most recent call last):
  File "/usr/src/homeassistant/homeassistant/components/recorder/core.py", line 927, in _setup_recorder
    self._setup_connection()
    ~~~~~~~~~~~~~~~~~~~~~~^^
  File "/usr/src/homeassistant/homeassistant/components/recorder/core.py", line 1448, in _setup_connection
    migration.pre_migrate_schema(self.engine)
    ~~~~~~~~~~~~~~~~~~~~~~~~~~~~^^^^^^^^^^^^^
  File "/usr/src/homeassistant/homeassistant/components/recorder/migration.py", line 331, in pre_migrate_schema
    inspector = sqlalchemy.inspect(engine)
  File "/usr/local/lib/python3.13/site-packages/sqlalchemy/inspection.py", line 140, in inspect
    ret = reg(subject)
  File "/usr/local/lib/python3.13/site-packages/sqlalchemy/engine/reflection.py", line 313, in _engine_insp
    return Inspector._construct(Inspector._init_engine, bind)
           ~~~~~~~~~~~~~~~~~~~~^^^^^^^^^^^^^^^^^^^^^^^^^^^^^^
  File "/usr/local/lib/python3.13/site-packages/sqlalchemy/engine/reflection.py", line 246, in _construct
    init(self, bind)
    ~~~~^^^^^^^^^^^^
  File "/usr/local/lib/python3.13/site-packages/sqlalchemy/engine/reflection.py", line 257, in _init_engine
    engine.connect().close()
    ~~~~~~~~~~~~~~^^
  File "/usr/local/lib/python3.13/site-packages/sqlalchemy/engine/base.py", line 3273, in connect
    return self._connection_cls(self)
           ~~~~~~~~~~~~~~~~~~~~^^^^^^
  File "/usr/local/lib/python3.13/site-packages/sqlalchemy/engine/base.py", line 147, in __init__
    Connection._handle_dbapi_exception_noconnection(
    ~~~~~~~~~~~~~~~~~~~~~~~~~~~~~~~~~~~~~~~~~~~~~~~^
        err, dialect, engine
        ^^^^^^^^^^^^^^^^^^^^
    )
    ^
  File "/usr/local/lib/python3.13/site-packages/sqlalchemy/engine/base.py", line 2436, in _handle_dbapi_exception_noconnection
    raise sqlalchemy_exception.with_traceback(exc_info[2]) from e
  File "/usr/local/lib/python3.13/site-packages/sqlalchemy/engine/base.py", line 145, in __init__
    self._dbapi_connection = engine.raw_connection()
                             ~~~~~~~~~~~~~~~~~~~~~^^
  File "/usr/local/lib/python3.13/site-packages/sqlalchemy/engine/base.py", line 3297, in raw_connection
    return self.pool.connect()
           ~~~~~~~~~~~~~~~~~^^
  File "/usr/local/lib/python3.13/site-packages/sqlalchemy/pool/base.py", line 449, in connect
    return _ConnectionFairy._checkout(self)
           ~~~~~~~~~~~~~~~~~~~~~~~~~~^^^^^^
  File "/usr/local/lib/python3.13/site-packages/sqlalchemy/pool/base.py", line 1264, in _checkout
    fairy = _ConnectionRecord.checkout(pool)
  File "/usr/local/lib/python3.13/site-packages/sqlalchemy/pool/base.py", line 713, in checkout
    rec = pool._do_get()
  File "/usr/local/lib/python3.13/site-packages/sqlalchemy/pool/impl.py", line 179, in _do_get
    with util.safe_reraise():
         ~~~~~~~~~~~~~~~~~^^
  File "/usr/local/lib/python3.13/site-packages/sqlalchemy/util/langhelpers.py", line 224, in __exit__
    raise exc_value.with_traceback(exc_tb)
  File "/usr/local/lib/python3.13/site-packages/sqlalchemy/pool/impl.py", line 177, in _do_get
    return self._create_connection()
           ~~~~~~~~~~~~~~~~~~~~~~~^^
  File "/usr/local/lib/python3.13/site-packages/sqlalchemy/pool/base.py", line 390, in _create_connection
    return _ConnectionRecord(self)
  File "/usr/local/lib/python3.13/site-packages/sqlalchemy/pool/base.py", line 675, in __init__
    self.__connect()
    ~~~~~~~~~~~~~~^^
  File "/usr/local/lib/python3.13/site-packages/sqlalchemy/pool/base.py", line 901, in __connect
    with util.safe_reraise():
         ~~~~~~~~~~~~~~~~~^^
  File "/usr/local/lib/python3.13/site-packages/sqlalchemy/util/langhelpers.py", line 224, in __exit__
    raise exc_value.with_traceback(exc_tb)
  File "/usr/local/lib/python3.13/site-packages/sqlalchemy/pool/base.py", line 897, in __connect
    self.dbapi_connection = connection = pool._invoke_creator(self)
                                         ~~~~~~~~~~~~~~~~~~~~^^^^^^
  File "/usr/local/lib/python3.13/site-packages/sqlalchemy/engine/create.py", line 646, in connect
    return dialect.connect(*cargs, **cparams)
           ~~~~~~~~~~~~~~~^^^^^^^^^^^^^^^^^^^
  File "/usr/local/lib/python3.13/site-packages/sqlalchemy/engine/default.py", line 625, in connect
    return self.loaded_dbapi.connect(*cargs, **cparams)  # type: ignore[no-any-return]  # NOQA: E501
           ~~~~~~~~~~~~~~~~~~~~~~~~~^^^^^^^^^^^^^^^^^^^
  File "/usr/local/lib/python3.13/site-packages/psycopg2/__init__.py", line 122, in connect
    conn = _connect(dsn, connection_factory=connection_factory, **kwasync)
sqlalchemy.exc.OperationalError: (psycopg2.OperationalError) connection to server at "172.21.0.3", port 5432 failed: Connection refused
	Is the server running on that host and accepting TCP/IP connections?

(Background on this error at: https://sqlalche.me/e/20/e3q8)
2025-09-10 22:42:52.983 ERROR (Recorder) [homeassistant.components.recorder.core] Error during connection setup: (retrying in 3 seconds)
Traceback (most recent call last):
  File "/usr/local/lib/python3.13/site-packages/sqlalchemy/engine/base.py", line 145, in __init__
    self._dbapi_connection = engine.raw_connection()
                             ~~~~~~~~~~~~~~~~~~~~~^^
  File "/usr/local/lib/python3.13/site-packages/sqlalchemy/engine/base.py", line 3297, in raw_connection
    return self.pool.connect()
           ~~~~~~~~~~~~~~~~~^^
  File "/usr/local/lib/python3.13/site-packages/sqlalchemy/pool/base.py", line 449, in connect
    return _ConnectionFairy._checkout(self)
           ~~~~~~~~~~~~~~~~~~~~~~~~~~^^^^^^
  File "/usr/local/lib/python3.13/site-packages/sqlalchemy/pool/base.py", line 1264, in _checkout
    fairy = _ConnectionRecord.checkout(pool)
  File "/usr/local/lib/python3.13/site-packages/sqlalchemy/pool/base.py", line 713, in checkout
    rec = pool._do_get()
  File "/usr/local/lib/python3.13/site-packages/sqlalchemy/pool/impl.py", line 179, in _do_get
    with util.safe_reraise():
         ~~~~~~~~~~~~~~~~~^^
  File "/usr/local/lib/python3.13/site-packages/sqlalchemy/util/langhelpers.py", line 224, in __exit__
    raise exc_value.with_traceback(exc_tb)
  File "/usr/local/lib/python3.13/site-packages/sqlalchemy/pool/impl.py", line 177, in _do_get
    return self._create_connection()
           ~~~~~~~~~~~~~~~~~~~~~~~^^
  File "/usr/local/lib/python3.13/site-packages/sqlalchemy/pool/base.py", line 390, in _create_connection
    return _ConnectionRecord(self)
  File "/usr/local/lib/python3.13/site-packages/sqlalchemy/pool/base.py", line 675, in __init__
    self.__connect()
    ~~~~~~~~~~~~~~^^
  File "/usr/local/lib/python3.13/site-packages/sqlalchemy/pool/base.py", line 901, in __connect
    with util.safe_reraise():
         ~~~~~~~~~~~~~~~~~^^
  File "/usr/local/lib/python3.13/site-packages/sqlalchemy/util/langhelpers.py", line 224, in __exit__
    raise exc_value.with_traceback(exc_tb)
  File "/usr/local/lib/python3.13/site-packages/sqlalchemy/pool/base.py", line 897, in __connect
    self.dbapi_connection = connection = pool._invoke_creator(self)
                                         ~~~~~~~~~~~~~~~~~~~~^^^^^^
  File "/usr/local/lib/python3.13/site-packages/sqlalchemy/engine/create.py", line 646, in connect
    return dialect.connect(*cargs, **cparams)
           ~~~~~~~~~~~~~~~^^^^^^^^^^^^^^^^^^^
  File "/usr/local/lib/python3.13/site-packages/sqlalchemy/engine/default.py", line 625, in connect
    return self.loaded_dbapi.connect(*cargs, **cparams)  # type: ignore[no-any-return]  # NOQA: E501
           ~~~~~~~~~~~~~~~~~~~~~~~~~^^^^^^^^^^^^^^^^^^^
  File "/usr/local/lib/python3.13/site-packages/psycopg2/__init__.py", line 122, in connect
    conn = _connect(dsn, connection_factory=connection_factory, **kwasync)
psycopg2.OperationalError: connection to server at "172.21.0.3", port 5432 failed: Connection refused
	Is the server running on that host and accepting TCP/IP connections?


The above exception was the direct cause of the following exception:

Traceback (most recent call last):
  File "/usr/src/homeassistant/homeassistant/components/recorder/core.py", line 927, in _setup_recorder
    self._setup_connection()
    ~~~~~~~~~~~~~~~~~~~~~~^^
  File "/usr/src/homeassistant/homeassistant/components/recorder/core.py", line 1448, in _setup_connection
    migration.pre_migrate_schema(self.engine)
    ~~~~~~~~~~~~~~~~~~~~~~~~~~~~^^^^^^^^^^^^^
  File "/usr/src/homeassistant/homeassistant/components/recorder/migration.py", line 331, in pre_migrate_schema
    inspector = sqlalchemy.inspect(engine)
  File "/usr/local/lib/python3.13/site-packages/sqlalchemy/inspection.py", line 140, in inspect
    ret = reg(subject)
  File "/usr/local/lib/python3.13/site-packages/sqlalchemy/engine/reflection.py", line 313, in _engine_insp
    return Inspector._construct(Inspector._init_engine, bind)
           ~~~~~~~~~~~~~~~~~~~~^^^^^^^^^^^^^^^^^^^^^^^^^^^^^^
  File "/usr/local/lib/python3.13/site-packages/sqlalchemy/engine/reflection.py", line 246, in _construct
    init(self, bind)
    ~~~~^^^^^^^^^^^^
  File "/usr/local/lib/python3.13/site-packages/sqlalchemy/engine/reflection.py", line 257, in _init_engine
    engine.connect().close()
    ~~~~~~~~~~~~~~^^
  File "/usr/local/lib/python3.13/site-packages/sqlalchemy/engine/base.py", line 3273, in connect
    return self._connection_cls(self)
           ~~~~~~~~~~~~~~~~~~~~^^^^^^
  File "/usr/local/lib/python3.13/site-packages/sqlalchemy/engine/base.py", line 147, in __init__
    Connection._handle_dbapi_exception_noconnection(
    ~~~~~~~~~~~~~~~~~~~~~~~~~~~~~~~~~~~~~~~~~~~~~~~^
        err, dialect, engine
        ^^^^^^^^^^^^^^^^^^^^
    )
    ^
  File "/usr/local/lib/python3.13/site-packages/sqlalchemy/engine/base.py", line 2436, in _handle_dbapi_exception_noconnection
    raise sqlalchemy_exception.with_traceback(exc_info[2]) from e
  File "/usr/local/lib/python3.13/site-packages/sqlalchemy/engine/base.py", line 145, in __init__
    self._dbapi_connection = engine.raw_connection()
                             ~~~~~~~~~~~~~~~~~~~~~^^
  File "/usr/local/lib/python3.13/site-packages/sqlalchemy/engine/base.py", line 3297, in raw_connection
    return self.pool.connect()
           ~~~~~~~~~~~~~~~~~^^
  File "/usr/local/lib/python3.13/site-packages/sqlalchemy/pool/base.py", line 449, in connect
    return _ConnectionFairy._checkout(self)
           ~~~~~~~~~~~~~~~~~~~~~~~~~~^^^^^^
  File "/usr/local/lib/python3.13/site-packages/sqlalchemy/pool/base.py", line 1264, in _checkout
    fairy = _ConnectionRecord.checkout(pool)
  File "/usr/local/lib/python3.13/site-packages/sqlalchemy/pool/base.py", line 713, in checkout
    rec = pool._do_get()
  File "/usr/local/lib/python3.13/site-packages/sqlalchemy/pool/impl.py", line 179, in _do_get
    with util.safe_reraise():
         ~~~~~~~~~~~~~~~~~^^
  File "/usr/local/lib/python3.13/site-packages/sqlalchemy/util/langhelpers.py", line 224, in __exit__
    raise exc_value.with_traceback(exc_tb)
  File "/usr/local/lib/python3.13/site-packages/sqlalchemy/pool/impl.py", line 177, in _do_get
    return self._create_connection()
           ~~~~~~~~~~~~~~~~~~~~~~~^^
  File "/usr/local/lib/python3.13/site-packages/sqlalchemy/pool/base.py", line 390, in _create_connection
    return _ConnectionRecord(self)
  File "/usr/local/lib/python3.13/site-packages/sqlalchemy/pool/base.py", line 675, in __init__
    self.__connect()
    ~~~~~~~~~~~~~~^^
  File "/usr/local/lib/python3.13/site-packages/sqlalchemy/pool/base.py", line 901, in __connect
    with util.safe_reraise():
         ~~~~~~~~~~~~~~~~~^^
  File "/usr/local/lib/python3.13/site-packages/sqlalchemy/util/langhelpers.py", line 224, in __exit__
    raise exc_value.with_traceback(exc_tb)
  File "/usr/local/lib/python3.13/site-packages/sqlalchemy/pool/base.py", line 897, in __connect
    self.dbapi_connection = connection = pool._invoke_creator(self)
                                         ~~~~~~~~~~~~~~~~~~~~^^^^^^
  File "/usr/local/lib/python3.13/site-packages/sqlalchemy/engine/create.py", line 646, in connect
    return dialect.connect(*cargs, **cparams)
           ~~~~~~~~~~~~~~~^^^^^^^^^^^^^^^^^^^
  File "/usr/local/lib/python3.13/site-packages/sqlalchemy/engine/default.py", line 625, in connect
    return self.loaded_dbapi.connect(*cargs, **cparams)  # type: ignore[no-any-return]  # NOQA: E501
           ~~~~~~~~~~~~~~~~~~~~~~~~~^^^^^^^^^^^^^^^^^^^
  File "/usr/local/lib/python3.13/site-packages/psycopg2/__init__.py", line 122, in connect
    conn = _connect(dsn, connection_factory=connection_factory, **kwasync)
sqlalchemy.exc.OperationalError: (psycopg2.OperationalError) connection to server at "172.21.0.3", port 5432 failed: Connection refused
	Is the server running on that host and accepting TCP/IP connections?

(Background on this error at: https://sqlalche.me/e/20/e3q8)
2025-09-10 22:42:55.991 ERROR (Recorder) [homeassistant.components.recorder.core] Error during connection setup: (retrying in 3 seconds)
Traceback (most recent call last):
  File "/usr/local/lib/python3.13/site-packages/sqlalchemy/engine/base.py", line 145, in __init__
    self._dbapi_connection = engine.raw_connection()
                             ~~~~~~~~~~~~~~~~~~~~~^^
  File "/usr/local/lib/python3.13/site-packages/sqlalchemy/engine/base.py", line 3297, in raw_connection
    return self.pool.connect()
           ~~~~~~~~~~~~~~~~~^^
  File "/usr/local/lib/python3.13/site-packages/sqlalchemy/pool/base.py", line 449, in connect
    return _ConnectionFairy._checkout(self)
           ~~~~~~~~~~~~~~~~~~~~~~~~~~^^^^^^
  File "/usr/local/lib/python3.13/site-packages/sqlalchemy/pool/base.py", line 1264, in _checkout
    fairy = _ConnectionRecord.checkout(pool)
  File "/usr/local/lib/python3.13/site-packages/sqlalchemy/pool/base.py", line 713, in checkout
    rec = pool._do_get()
  File "/usr/local/lib/python3.13/site-packages/sqlalchemy/pool/impl.py", line 179, in _do_get
    with util.safe_reraise():
         ~~~~~~~~~~~~~~~~~^^
  File "/usr/local/lib/python3.13/site-packages/sqlalchemy/util/langhelpers.py", line 224, in __exit__
    raise exc_value.with_traceback(exc_tb)
  File "/usr/local/lib/python3.13/site-packages/sqlalchemy/pool/impl.py", line 177, in _do_get
    return self._create_connection()
           ~~~~~~~~~~~~~~~~~~~~~~~^^
  File "/usr/local/lib/python3.13/site-packages/sqlalchemy/pool/base.py", line 390, in _create_connection
    return _ConnectionRecord(self)
  File "/usr/local/lib/python3.13/site-packages/sqlalchemy/pool/base.py", line 675, in __init__
    self.__connect()
    ~~~~~~~~~~~~~~^^
  File "/usr/local/lib/python3.13/site-packages/sqlalchemy/pool/base.py", line 901, in __connect
    with util.safe_reraise():
         ~~~~~~~~~~~~~~~~~^^
  File "/usr/local/lib/python3.13/site-packages/sqlalchemy/util/langhelpers.py", line 224, in __exit__
    raise exc_value.with_traceback(exc_tb)
  File "/usr/local/lib/python3.13/site-packages/sqlalchemy/pool/base.py", line 897, in __connect
    self.dbapi_connection = connection = pool._invoke_creator(self)
                                         ~~~~~~~~~~~~~~~~~~~~^^^^^^
  File "/usr/local/lib/python3.13/site-packages/sqlalchemy/engine/create.py", line 646, in connect
    return dialect.connect(*cargs, **cparams)
           ~~~~~~~~~~~~~~~^^^^^^^^^^^^^^^^^^^
  File "/usr/local/lib/python3.13/site-packages/sqlalchemy/engine/default.py", line 625, in connect
    return self.loaded_dbapi.connect(*cargs, **cparams)  # type: ignore[no-any-return]  # NOQA: E501
           ~~~~~~~~~~~~~~~~~~~~~~~~~^^^^^^^^^^^^^^^^^^^
  File "/usr/local/lib/python3.13/site-packages/psycopg2/__init__.py", line 122, in connect
    conn = _connect(dsn, connection_factory=connection_factory, **kwasync)
psycopg2.OperationalError: connection to server at "172.21.0.3", port 5432 failed: Connection refused
	Is the server running on that host and accepting TCP/IP connections?


The above exception was the direct cause of the following exception:

Traceback (most recent call last):
  File "/usr/src/homeassistant/homeassistant/components/recorder/core.py", line 927, in _setup_recorder
    self._setup_connection()
    ~~~~~~~~~~~~~~~~~~~~~~^^
  File "/usr/src/homeassistant/homeassistant/components/recorder/core.py", line 1448, in _setup_connection
    migration.pre_migrate_schema(self.engine)
    ~~~~~~~~~~~~~~~~~~~~~~~~~~~~^^^^^^^^^^^^^
  File "/usr/src/homeassistant/homeassistant/components/recorder/migration.py", line 331, in pre_migrate_schema
    inspector = sqlalchemy.inspect(engine)
  File "/usr/local/lib/python3.13/site-packages/sqlalchemy/inspection.py", line 140, in inspect
    ret = reg(subject)
  File "/usr/local/lib/python3.13/site-packages/sqlalchemy/engine/reflection.py", line 313, in _engine_insp
    return Inspector._construct(Inspector._init_engine, bind)
           ~~~~~~~~~~~~~~~~~~~~^^^^^^^^^^^^^^^^^^^^^^^^^^^^^^
  File "/usr/local/lib/python3.13/site-packages/sqlalchemy/engine/reflection.py", line 246, in _construct
    init(self, bind)
    ~~~~^^^^^^^^^^^^
  File "/usr/local/lib/python3.13/site-packages/sqlalchemy/engine/reflection.py", line 257, in _init_engine
    engine.connect().close()
    ~~~~~~~~~~~~~~^^
  File "/usr/local/lib/python3.13/site-packages/sqlalchemy/engine/base.py", line 3273, in connect
    return self._connection_cls(self)
           ~~~~~~~~~~~~~~~~~~~~^^^^^^
  File "/usr/local/lib/python3.13/site-packages/sqlalchemy/engine/base.py", line 147, in __init__
    Connection._handle_dbapi_exception_noconnection(
    ~~~~~~~~~~~~~~~~~~~~~~~~~~~~~~~~~~~~~~~~~~~~~~~^
        err, dialect, engine
        ^^^^^^^^^^^^^^^^^^^^
    )
    ^
  File "/usr/local/lib/python3.13/site-packages/sqlalchemy/engine/base.py", line 2436, in _handle_dbapi_exception_noconnection
    raise sqlalchemy_exception.with_traceback(exc_info[2]) from e
  File "/usr/local/lib/python3.13/site-packages/sqlalchemy/engine/base.py", line 145, in __init__
    self._dbapi_connection = engine.raw_connection()
                             ~~~~~~~~~~~~~~~~~~~~~^^
  File "/usr/local/lib/python3.13/site-packages/sqlalchemy/engine/base.py", line 3297, in raw_connection
    return self.pool.connect()
           ~~~~~~~~~~~~~~~~~^^
  File "/usr/local/lib/python3.13/site-packages/sqlalchemy/pool/base.py", line 449, in connect
    return _ConnectionFairy._checkout(self)
           ~~~~~~~~~~~~~~~~~~~~~~~~~~^^^^^^
  File "/usr/local/lib/python3.13/site-packages/sqlalchemy/pool/base.py", line 1264, in _checkout
    fairy = _ConnectionRecord.checkout(pool)
  File "/usr/local/lib/python3.13/site-packages/sqlalchemy/pool/base.py", line 713, in checkout
    rec = pool._do_get()
  File "/usr/local/lib/python3.13/site-packages/sqlalchemy/pool/impl.py", line 179, in _do_get
    with util.safe_reraise():
         ~~~~~~~~~~~~~~~~~^^
  File "/usr/local/lib/python3.13/site-packages/sqlalchemy/util/langhelpers.py", line 224, in __exit__
    raise exc_value.with_traceback(exc_tb)
  File "/usr/local/lib/python3.13/site-packages/sqlalchemy/pool/impl.py", line 177, in _do_get
    return self._create_connection()
           ~~~~~~~~~~~~~~~~~~~~~~~^^
  File "/usr/local/lib/python3.13/site-packages/sqlalchemy/pool/base.py", line 390, in _create_connection
    return _ConnectionRecord(self)
  File "/usr/local/lib/python3.13/site-packages/sqlalchemy/pool/base.py", line 675, in __init__
    self.__connect()
    ~~~~~~~~~~~~~~^^
  File "/usr/local/lib/python3.13/site-packages/sqlalchemy/pool/base.py", line 901, in __connect
    with util.safe_reraise():
         ~~~~~~~~~~~~~~~~~^^
  File "/usr/local/lib/python3.13/site-packages/sqlalchemy/util/langhelpers.py", line 224, in __exit__
    raise exc_value.with_traceback(exc_tb)
  File "/usr/local/lib/python3.13/site-packages/sqlalchemy/pool/base.py", line 897, in __connect
    self.dbapi_connection = connection = pool._invoke_creator(self)
                                         ~~~~~~~~~~~~~~~~~~~~^^^^^^
  File "/usr/local/lib/python3.13/site-packages/sqlalchemy/engine/create.py", line 646, in connect
    return dialect.connect(*cargs, **cparams)
           ~~~~~~~~~~~~~~~^^^^^^^^^^^^^^^^^^^
  File "/usr/local/lib/python3.13/site-packages/sqlalchemy/engine/default.py", line 625, in connect
    return self.loaded_dbapi.connect(*cargs, **cparams)  # type: ignore[no-any-return]  # NOQA: E501
           ~~~~~~~~~~~~~~~~~~~~~~~~~^^^^^^^^^^^^^^^^^^^
  File "/usr/local/lib/python3.13/site-packages/psycopg2/__init__.py", line 122, in connect
    conn = _connect(dsn, connection_factory=connection_factory, **kwasync)
sqlalchemy.exc.OperationalError: (psycopg2.OperationalError) connection to server at "172.21.0.3", port 5432 failed: Connection refused
	Is the server running on that host and accepting TCP/IP connections?

(Background on this error at: https://sqlalche.me/e/20/e3q8)
2025-09-10 22:42:58.999 ERROR (Recorder) [homeassistant.components.recorder.core] Error during connection setup: (retrying in 3 seconds)
Traceback (most recent call last):
  File "/usr/local/lib/python3.13/site-packages/sqlalchemy/engine/base.py", line 145, in __init__
    self._dbapi_connection = engine.raw_connection()
                             ~~~~~~~~~~~~~~~~~~~~~^^
  File "/usr/local/lib/python3.13/site-packages/sqlalchemy/engine/base.py", line 3297, in raw_connection
    return self.pool.connect()
           ~~~~~~~~~~~~~~~~~^^
  File "/usr/local/lib/python3.13/site-packages/sqlalchemy/pool/base.py", line 449, in connect
    return _ConnectionFairy._checkout(self)
           ~~~~~~~~~~~~~~~~~~~~~~~~~~^^^^^^
  File "/usr/local/lib/python3.13/site-packages/sqlalchemy/pool/base.py", line 1264, in _checkout
    fairy = _ConnectionRecord.checkout(pool)
  File "/usr/local/lib/python3.13/site-packages/sqlalchemy/pool/base.py", line 713, in checkout
    rec = pool._do_get()
  File "/usr/local/lib/python3.13/site-packages/sqlalchemy/pool/impl.py", line 179, in _do_get
    with util.safe_reraise():
         ~~~~~~~~~~~~~~~~~^^
  File "/usr/local/lib/python3.13/site-packages/sqlalchemy/util/langhelpers.py", line 224, in __exit__
    raise exc_value.with_traceback(exc_tb)
  File "/usr/local/lib/python3.13/site-packages/sqlalchemy/pool/impl.py", line 177, in _do_get
    return self._create_connection()
           ~~~~~~~~~~~~~~~~~~~~~~~^^
  File "/usr/local/lib/python3.13/site-packages/sqlalchemy/pool/base.py", line 390, in _create_connection
    return _ConnectionRecord(self)
  File "/usr/local/lib/python3.13/site-packages/sqlalchemy/pool/base.py", line 675, in __init__
    self.__connect()
    ~~~~~~~~~~~~~~^^
  File "/usr/local/lib/python3.13/site-packages/sqlalchemy/pool/base.py", line 901, in __connect
    with util.safe_reraise():
         ~~~~~~~~~~~~~~~~~^^
  File "/usr/local/lib/python3.13/site-packages/sqlalchemy/util/langhelpers.py", line 224, in __exit__
    raise exc_value.with_traceback(exc_tb)
  File "/usr/local/lib/python3.13/site-packages/sqlalchemy/pool/base.py", line 897, in __connect
    self.dbapi_connection = connection = pool._invoke_creator(self)
                                         ~~~~~~~~~~~~~~~~~~~~^^^^^^
  File "/usr/local/lib/python3.13/site-packages/sqlalchemy/engine/create.py", line 646, in connect
    return dialect.connect(*cargs, **cparams)
           ~~~~~~~~~~~~~~~^^^^^^^^^^^^^^^^^^^
  File "/usr/local/lib/python3.13/site-packages/sqlalchemy/engine/default.py", line 625, in connect
    return self.loaded_dbapi.connect(*cargs, **cparams)  # type: ignore[no-any-return]  # NOQA: E501
           ~~~~~~~~~~~~~~~~~~~~~~~~~^^^^^^^^^^^^^^^^^^^
  File "/usr/local/lib/python3.13/site-packages/psycopg2/__init__.py", line 122, in connect
    conn = _connect(dsn, connection_factory=connection_factory, **kwasync)
psycopg2.OperationalError: connection to server at "172.21.0.3", port 5432 failed: Connection refused
	Is the server running on that host and accepting TCP/IP connections?


The above exception was the direct cause of the following exception:

Traceback (most recent call last):
  File "/usr/src/homeassistant/homeassistant/components/recorder/core.py", line 927, in _setup_recorder
    self._setup_connection()
    ~~~~~~~~~~~~~~~~~~~~~~^^
  File "/usr/src/homeassistant/homeassistant/components/recorder/core.py", line 1448, in _setup_connection
    migration.pre_migrate_schema(self.engine)
    ~~~~~~~~~~~~~~~~~~~~~~~~~~~~^^^^^^^^^^^^^
  File "/usr/src/homeassistant/homeassistant/components/recorder/migration.py", line 331, in pre_migrate_schema
    inspector = sqlalchemy.inspect(engine)
  File "/usr/local/lib/python3.13/site-packages/sqlalchemy/inspection.py", line 140, in inspect
    ret = reg(subject)
  File "/usr/local/lib/python3.13/site-packages/sqlalchemy/engine/reflection.py", line 313, in _engine_insp
    return Inspector._construct(Inspector._init_engine, bind)
           ~~~~~~~~~~~~~~~~~~~~^^^^^^^^^^^^^^^^^^^^^^^^^^^^^^
  File "/usr/local/lib/python3.13/site-packages/sqlalchemy/engine/reflection.py", line 246, in _construct
    init(self, bind)
    ~~~~^^^^^^^^^^^^
  File "/usr/local/lib/python3.13/site-packages/sqlalchemy/engine/reflection.py", line 257, in _init_engine
    engine.connect().close()
    ~~~~~~~~~~~~~~^^
  File "/usr/local/lib/python3.13/site-packages/sqlalchemy/engine/base.py", line 3273, in connect
    return self._connection_cls(self)
           ~~~~~~~~~~~~~~~~~~~~^^^^^^
  File "/usr/local/lib/python3.13/site-packages/sqlalchemy/engine/base.py", line 147, in __init__
    Connection._handle_dbapi_exception_noconnection(
    ~~~~~~~~~~~~~~~~~~~~~~~~~~~~~~~~~~~~~~~~~~~~~~~^
        err, dialect, engine
        ^^^^^^^^^^^^^^^^^^^^
    )
    ^
  File "/usr/local/lib/python3.13/site-packages/sqlalchemy/engine/base.py", line 2436, in _handle_dbapi_exception_noconnection
    raise sqlalchemy_exception.with_traceback(exc_info[2]) from e
  File "/usr/local/lib/python3.13/site-packages/sqlalchemy/engine/base.py", line 145, in __init__
    self._dbapi_connection = engine.raw_connection()
                             ~~~~~~~~~~~~~~~~~~~~~^^
  File "/usr/local/lib/python3.13/site-packages/sqlalchemy/engine/base.py", line 3297, in raw_connection
    return self.pool.connect()
           ~~~~~~~~~~~~~~~~~^^
  File "/usr/local/lib/python3.13/site-packages/sqlalchemy/pool/base.py", line 449, in connect
    return _ConnectionFairy._checkout(self)
           ~~~~~~~~~~~~~~~~~~~~~~~~~~^^^^^^
  File "/usr/local/lib/python3.13/site-packages/sqlalchemy/pool/base.py", line 1264, in _checkout
    fairy = _ConnectionRecord.checkout(pool)
  File "/usr/local/lib/python3.13/site-packages/sqlalchemy/pool/base.py", line 713, in checkout
    rec = pool._do_get()
  File "/usr/local/lib/python3.13/site-packages/sqlalchemy/pool/impl.py", line 179, in _do_get
    with util.safe_reraise():
         ~~~~~~~~~~~~~~~~~^^
  File "/usr/local/lib/python3.13/site-packages/sqlalchemy/util/langhelpers.py", line 224, in __exit__
    raise exc_value.with_traceback(exc_tb)
  File "/usr/local/lib/python3.13/site-packages/sqlalchemy/pool/impl.py", line 177, in _do_get
    return self._create_connection()
           ~~~~~~~~~~~~~~~~~~~~~~~^^
  File "/usr/local/lib/python3.13/site-packages/sqlalchemy/pool/base.py", line 390, in _create_connection
    return _ConnectionRecord(self)
  File "/usr/local/lib/python3.13/site-packages/sqlalchemy/pool/base.py", line 675, in __init__
    self.__connect()
    ~~~~~~~~~~~~~~^^
  File "/usr/local/lib/python3.13/site-packages/sqlalchemy/pool/base.py", line 901, in __connect
    with util.safe_reraise():
         ~~~~~~~~~~~~~~~~~^^
  File "/usr/local/lib/python3.13/site-packages/sqlalchemy/util/langhelpers.py", line 224, in __exit__
    raise exc_value.with_traceback(exc_tb)
  File "/usr/local/lib/python3.13/site-packages/sqlalchemy/pool/base.py", line 897, in __connect
    self.dbapi_connection = connection = pool._invoke_creator(self)
                                         ~~~~~~~~~~~~~~~~~~~~^^^^^^
  File "/usr/local/lib/python3.13/site-packages/sqlalchemy/engine/create.py", line 646, in connect
    return dialect.connect(*cargs, **cparams)
           ~~~~~~~~~~~~~~~^^^^^^^^^^^^^^^^^^^
  File "/usr/local/lib/python3.13/site-packages/sqlalchemy/engine/default.py", line 625, in connect
    return self.loaded_dbapi.connect(*cargs, **cparams)  # type: ignore[no-any-return]  # NOQA: E501
           ~~~~~~~~~~~~~~~~~~~~~~~~~^^^^^^^^^^^^^^^^^^^
  File "/usr/local/lib/python3.13/site-packages/psycopg2/__init__.py", line 122, in connect
    conn = _connect(dsn, connection_factory=connection_factory, **kwasync)
sqlalchemy.exc.OperationalError: (psycopg2.OperationalError) connection to server at "172.21.0.3", port 5432 failed: Connection refused
	Is the server running on that host and accepting TCP/IP connections?

(Background on this error at: https://sqlalche.me/e/20/e3q8)
2025-09-10 22:42:59.005 ERROR (Recorder) [homeassistant.components.recorder.core] Recorder setup failed, recorder shutting down
2025-09-10 22:42:59.006 ERROR (MainThread) [homeassistant.setup] Setup failed for 'recorder': Integration failed to initialize.
2025-09-10 22:42:59.006 INFO (MainThread) [homeassistant.setup] Setup of domain recorder took 27.11 seconds
2025-09-10 22:42:59.006 INFO (MainThread) [homeassistant.bootstrap] Nothing to set up in stage debugger: {'debugpy'}
2025-09-10 22:42:59.006 INFO (MainThread) [homeassistant.bootstrap] Setting up stage zeroconf: {'zeroconf'}; already set up: {}
Dependencies: {}; already set up: {'api', 'http', 'websocket_api', 'network'}
2025-09-10 22:42:59.006 INFO (MainThread) [homeassistant.setup] Setting up zeroconf
2025-09-10 22:42:59.008 INFO (MainThread) [homeassistant.components.zeroconf] Starting Zeroconf broadcast
2025-09-10 22:42:59.008 INFO (MainThread) [homeassistant.setup] Setup of domain zeroconf took 0.00 seconds
2025-09-10 22:42:59.009 INFO (MainThread) [homeassistant.bootstrap] Setting up stage 1: {'ssdp'}; already set up: {}
Dependencies: {}; already set up: {'http', 'websocket_api', 'network'}
2025-09-10 22:42:59.043 INFO (MainThread) [homeassistant.setup] Setting up ssdp
2025-09-10 22:42:59.045 INFO (MainThread) [homeassistant.setup] Setup of domain ssdp took 0.00 seconds
2025-09-10 22:42:59.046 INFO (MainThread) [homeassistant.bootstrap] Setting up stage 2: {'system_health', 'sonos', 'zone', 'person', 'application_credentials', 'tts', 'input_text', 'input_number', 'scene', 'tag', 'timer', 'group', 'script', 'recorder', 'automation', 'media_source', 'schedule', 'logbook', 'binary_sensor', 'analytics', 'input_button', 'history', 'backup', 'counter', 'hardware', 'input_datetime', 'input_select', 'input_boolean', 'mqtt'}; already set up: {'api', 'logger', 'network', 'ssdp', 'homeassistant', 'zeroconf', 'http', 'frontend'}
Dependencies: {'image_upload', 'trace', 'blueprint', 'ffmpeg'}; already set up: {'search', 'device_automation', 'onboarding', 'lovelace', 'http', 'config', 'api', 'network', 'ssdp', 'system_log', 'zeroconf', 'repairs', 'diagnostics', 'websocket_api', 'file_upload', 'frontend', 'auth'}
2025-09-10 22:42:59.046 INFO (MainThread) [homeassistant.setup] Setting up binary_sensor
2025-09-10 22:42:59.046 INFO (MainThread) [homeassistant.setup] Setup of domain binary_sensor took 0.00 seconds
2025-09-10 22:42:59.046 INFO (MainThread) [homeassistant.setup] Setting up scene
2025-09-10 22:42:59.046 INFO (MainThread) [homeassistant.components.scene] Setting up homeassistant.scene
2025-09-10 22:42:59.047 INFO (MainThread) [homeassistant.setup] Setup of domain scene took 0.00 seconds
2025-09-10 22:42:59.047 INFO (MainThread) [homeassistant.setup] Setting up system_health
2025-09-10 22:42:59.047 INFO (MainThread) [homeassistant.setup] Setup of domain system_health took 0.00 seconds
2025-09-10 22:42:59.048 ERROR (MainThread) [homeassistant.setup] Unable to set up dependencies of 'logbook'. Setup failed for dependencies: ['recorder']
2025-09-10 22:42:59.048 ERROR (MainThread) [homeassistant.setup] Setup failed for 'logbook': Could not setup dependencies: recorder
2025-09-10 22:42:59.048 INFO (MainThread) [homeassistant.setup] Setting up blueprint
2025-09-10 22:42:59.048 INFO (MainThread) [homeassistant.setup] Setup of domain blueprint took 0.00 seconds
2025-09-10 22:42:59.048 INFO (MainThread) [homeassistant.setup] Setting up zone
2025-09-10 22:42:59.050 INFO (MainThread) [homeassistant.setup] Setup of domain zone took 0.00 seconds
2025-09-10 22:42:59.050 INFO (MainThread) [homeassistant.setup] Setting up image_upload
2025-09-10 22:42:59.050 INFO (MainThread) [homeassistant.setup] Setup of domain image_upload took 0.00 seconds
2025-09-10 22:42:59.051 INFO (MainThread) [homeassistant.setup] Setting up person
2025-09-10 22:42:59.051 INFO (MainThread) [homeassistant.setup] Setting up trace
2025-09-10 22:42:59.052 INFO (MainThread) [homeassistant.setup] Setup of domain trace took 0.00 seconds
2025-09-10 22:42:59.052 INFO (MainThread) [homeassistant.setup] Setting up backup
2025-09-10 22:42:59.052 INFO (MainThread) [homeassistant.setup] Setting up input_number
2025-09-10 22:42:59.053 INFO (MainThread) [homeassistant.setup] Setup of domain input_number took 0.00 seconds
2025-09-10 22:42:59.054 INFO (MainThread) [homeassistant.setup] Setting up group
2025-09-10 22:42:59.055 INFO (MainThread) [homeassistant.setup] Setup of domain group took 0.00 seconds
2025-09-10 22:42:59.055 INFO (MainThread) [homeassistant.setup] Setting up script
2025-09-10 22:42:59.055 INFO (MainThread) [homeassistant.setup] Setup of domain script took 0.00 seconds
2025-09-10 22:42:59.055 ERROR (MainThread) [homeassistant.setup] Unable to set up dependencies of 'history'. Setup failed for dependencies: ['recorder']
2025-09-10 22:42:59.056 ERROR (MainThread) [homeassistant.setup] Setup failed for 'history': Could not setup dependencies: recorder
2025-09-10 22:42:59.066 INFO (MainThread) [homeassistant.setup] Setup of domain backup took 0.01 seconds
2025-09-10 22:42:59.067 INFO (MainThread) [homeassistant.setup] Setup of domain person took 0.02 seconds
2025-09-10 22:42:59.074 INFO (MainThread) [homeassistant.setup] Setting up ffmpeg
2025-09-10 22:42:59.074 INFO (MainThread) [homeassistant.setup] Setup of domain ffmpeg took 0.00 seconds
2025-09-10 22:42:59.082 INFO (MainThread) [homeassistant.setup] Setting up media_source
2025-09-10 22:42:59.083 INFO (MainThread) [homeassistant.setup] Setup of domain media_source took 0.00 seconds
2025-09-10 22:42:59.084 INFO (MainThread) [homeassistant.setup] Setting up input_boolean
2025-09-10 22:42:59.086 INFO (MainThread) [homeassistant.setup] Setup of domain input_boolean took 0.00 seconds
2025-09-10 22:42:59.090 INFO (MainThread) [homeassistant.setup] Setting up application_credentials
2025-09-10 22:42:59.091 INFO (MainThread) [homeassistant.setup] Setup of domain application_credentials took 0.00 seconds
2025-09-10 22:42:59.102 INFO (MainThread) [homeassistant.setup] Setting up analytics
2025-09-10 22:42:59.102 INFO (MainThread) [homeassistant.setup] Setup of domain analytics took 0.00 seconds
2025-09-10 22:42:59.104 INFO (MainThread) [homeassistant.setup] Setting up input_button
2025-09-10 22:42:59.105 INFO (MainThread) [homeassistant.setup] Setup of domain input_button took 0.00 seconds
2025-09-10 22:42:59.107 INFO (MainThread) [homeassistant.setup] Setting up input_text
2025-09-10 22:42:59.108 INFO (MainThread) [homeassistant.setup] Setup of domain input_text took 0.00 seconds
2025-09-10 22:42:59.115 INFO (MainThread) [homeassistant.setup] Setting up schedule
2025-09-10 22:42:59.116 INFO (MainThread) [homeassistant.setup] Setup of domain schedule took 0.00 seconds
2025-09-10 22:42:59.120 INFO (MainThread) [homeassistant.setup] Setting up tag
2025-09-10 22:42:59.121 INFO (MainThread) [homeassistant.setup] Setup of domain tag took 0.00 seconds
2025-09-10 22:42:59.122 INFO (MainThread) [homeassistant.setup] Setting up timer
2025-09-10 22:42:59.124 INFO (MainThread) [homeassistant.setup] Setup of domain timer took 0.00 seconds
2025-09-10 22:42:59.126 INFO (MainThread) [homeassistant.setup] Setting up counter
2025-09-10 22:42:59.127 INFO (MainThread) [homeassistant.setup] Setup of domain counter took 0.00 seconds
2025-09-10 22:42:59.134 INFO (MainThread) [homeassistant.setup] Setting up hardware
2025-09-10 22:42:59.136 INFO (MainThread) [homeassistant.setup] Setting up input_datetime
2025-09-10 22:42:59.137 INFO (MainThread) [homeassistant.setup] Setup of domain input_datetime took 0.00 seconds
2025-09-10 22:42:59.149 INFO (MainThread) [homeassistant.setup] Setting up input_select
2025-09-10 22:42:59.150 INFO (MainThread) [homeassistant.setup] Setup of domain input_select took 0.00 seconds
2025-09-10 22:42:59.159 INFO (MainThread) [homeassistant.setup] Setup of domain hardware took 0.03 seconds
2025-09-10 22:42:59.197 INFO (MainThread) [homeassistant.setup] Setting up mqtt
2025-09-10 22:42:59.197 INFO (MainThread) [homeassistant.setup] Setup of domain mqtt took 0.00 seconds
2025-09-10 22:42:59.284 INFO (MainThread) [homeassistant.setup] Setting up sonos
2025-09-10 22:42:59.285 INFO (MainThread) [homeassistant.setup] Setup of domain sonos took 0.00 seconds
2025-09-10 22:42:59.289 INFO (MainThread) [homeassistant.setup] Setting up automation
2025-09-10 22:42:59.291 INFO (MainThread) [homeassistant.setup] Setup of domain automation took 0.00 seconds
2025-09-10 22:42:59.296 INFO (MainThread) [homeassistant.setup] Setting up event
2025-09-10 22:42:59.297 INFO (MainThread) [homeassistant.setup] Setup of domain event took 0.00 seconds
2025-09-10 22:42:59.297 INFO (MainThread) [homeassistant.setup] Setting up sensor
2025-09-10 22:42:59.297 INFO (MainThread) [homeassistant.setup] Setup of domain sensor took 0.00 seconds
2025-09-10 22:42:59.299 INFO (MainThread) [homeassistant.components.event] Setting up backup.event
2025-09-10 22:42:59.300 INFO (MainThread) [homeassistant.components.sensor] Setting up backup.sensor
2025-09-10 22:42:59.606 DEBUG (MainThread) [homeassistant.components.mqtt.client] mqtt: connection opened 25
2025-09-10 22:42:59.606 DEBUG (MainThread) [homeassistant.components.mqtt.client] mqtt: Starting client misc loop
2025-09-10 22:42:59.606 DEBUG (MainThread) [homeassistant.components.mqtt.client] mqtt: register write 25
2025-09-10 22:42:59.608 DEBUG (MainThread) [homeassistant.components.mqtt.client] mqtt: unregister write 25
2025-09-10 22:42:59.608 DEBUG (MainThread) [homeassistant.components.mqtt.client] Connected to MQTT server mqtt:1883 (Success)
2025-09-10 22:42:59.620 INFO (MainThread) [homeassistant.setup] Setting up tts
2025-09-10 22:42:59.625 INFO (MainThread) [homeassistant.setup] Setup of domain tts took 0.00 seconds
2025-09-10 22:43:00.109 DEBUG (MainThread) [homeassistant.components.mqtt.client] mqtt: register write 25
2025-09-10 22:43:00.109 DEBUG (MainThread) [homeassistant.components.mqtt.client] Subscribing with mid: 1 to topics with qos: [('homeassistant/alarm_control_panel/+/config', 0)]
2025-09-10 22:43:00.109 DEBUG (MainThread) [homeassistant.components.mqtt.client] mqtt: unregister write 25
2025-09-10 22:43:00.110 DEBUG (MainThread) [homeassistant.components.mqtt.client] mqtt: register write 25
2025-09-10 22:43:00.110 DEBUG (MainThread) [homeassistant.components.mqtt.client] Subscribing with mid: 2 to topics with qos: [('homeassistant/binary_sensor/+/config', 0)]
2025-09-10 22:43:00.110 DEBUG (MainThread) [homeassistant.components.mqtt.client] mqtt: unregister write 25
2025-09-10 22:43:00.111 DEBUG (MainThread) [homeassistant.components.mqtt.client] mqtt: register write 25
2025-09-10 22:43:00.111 DEBUG (MainThread) [homeassistant.components.mqtt.client] Subscribing with mid: 3 to topics with qos: [('homeassistant/button/+/config', 0)]
2025-09-10 22:43:00.111 DEBUG (MainThread) [homeassistant.components.mqtt.client] mqtt: unregister write 25
2025-09-10 22:43:00.112 DEBUG (MainThread) [homeassistant.components.mqtt.client] mqtt: register write 25
2025-09-10 22:43:00.112 DEBUG (MainThread) [homeassistant.components.mqtt.client] Subscribing with mid: 4 to topics with qos: [('homeassistant/camera/+/config', 0)]
2025-09-10 22:43:00.112 DEBUG (MainThread) [homeassistant.components.mqtt.client] mqtt: unregister write 25
2025-09-10 22:43:00.113 DEBUG (MainThread) [homeassistant.components.mqtt.client] mqtt: register write 25
2025-09-10 22:43:00.113 DEBUG (MainThread) [homeassistant.components.mqtt.client] Subscribing with mid: 5 to topics with qos: [('homeassistant/climate/+/config', 0)]
2025-09-10 22:43:00.113 DEBUG (MainThread) [homeassistant.components.mqtt.client] mqtt: unregister write 25
2025-09-10 22:43:00.114 DEBUG (MainThread) [homeassistant.components.mqtt.client] mqtt: register write 25
2025-09-10 22:43:00.114 DEBUG (MainThread) [homeassistant.components.mqtt.client] Subscribing with mid: 6 to topics with qos: [('homeassistant/cover/+/config', 0)]
2025-09-10 22:43:00.114 DEBUG (MainThread) [homeassistant.components.mqtt.client] mqtt: unregister write 25
2025-09-10 22:43:00.114 DEBUG (MainThread) [homeassistant.components.mqtt.client] mqtt: register write 25
2025-09-10 22:43:00.115 DEBUG (MainThread) [homeassistant.components.mqtt.client] Subscribing with mid: 7 to topics with qos: [('homeassistant/device_automation/+/config', 0)]
2025-09-10 22:43:00.115 DEBUG (MainThread) [homeassistant.components.mqtt.client] mqtt: unregister write 25
2025-09-10 22:43:00.115 DEBUG (MainThread) [homeassistant.components.mqtt.client] mqtt: register write 25
2025-09-10 22:43:00.115 DEBUG (MainThread) [homeassistant.components.mqtt.client] Subscribing with mid: 8 to topics with qos: [('homeassistant/device_tracker/+/config', 0)]
2025-09-10 22:43:00.116 DEBUG (MainThread) [homeassistant.components.mqtt.client] mqtt: unregister write 25
2025-09-10 22:43:00.116 DEBUG (MainThread) [homeassistant.components.mqtt.client] mqtt: register write 25
2025-09-10 22:43:00.116 DEBUG (MainThread) [homeassistant.components.mqtt.client] Subscribing with mid: 9 to topics with qos: [('homeassistant/event/+/config', 0)]
2025-09-10 22:43:00.117 DEBUG (MainThread) [homeassistant.components.mqtt.client] mqtt: unregister write 25
2025-09-10 22:43:00.117 DEBUG (MainThread) [homeassistant.components.mqtt.client] mqtt: register write 25
2025-09-10 22:43:00.117 DEBUG (MainThread) [homeassistant.components.mqtt.client] Subscribing with mid: 10 to topics with qos: [('homeassistant/fan/+/config', 0)]
2025-09-10 22:43:00.117 DEBUG (MainThread) [homeassistant.components.mqtt.client] mqtt: unregister write 25
2025-09-10 22:43:00.121 DEBUG (MainThread) [homeassistant.components.mqtt.client] mqtt: register write 25
2025-09-10 22:43:00.121 DEBUG (MainThread) [homeassistant.components.mqtt.client] Subscribing with mid: 11 to topics with qos: [('homeassistant/humidifier/+/config', 0)]
2025-09-10 22:43:00.121 DEBUG (MainThread) [homeassistant.components.mqtt.client] mqtt: unregister write 25
2025-09-10 22:43:00.122 DEBUG (MainThread) [homeassistant.components.mqtt.client] mqtt: register write 25
2025-09-10 22:43:00.122 DEBUG (MainThread) [homeassistant.components.mqtt.client] Subscribing with mid: 12 to topics with qos: [('homeassistant/image/+/config', 0)]
2025-09-10 22:43:00.122 DEBUG (MainThread) [homeassistant.components.mqtt.client] mqtt: unregister write 25
2025-09-10 22:43:00.122 DEBUG (MainThread) [homeassistant.components.mqtt.client] mqtt: register write 25
2025-09-10 22:43:00.122 DEBUG (MainThread) [homeassistant.components.mqtt.client] Subscribing with mid: 13 to topics with qos: [('homeassistant/lawn_mower/+/config', 0)]
2025-09-10 22:43:00.123 DEBUG (MainThread) [homeassistant.components.mqtt.client] mqtt: unregister write 25
2025-09-10 22:43:00.124 DEBUG (MainThread) [homeassistant.components.mqtt.client] mqtt: register write 25
2025-09-10 22:43:00.124 DEBUG (MainThread) [homeassistant.components.mqtt.client] Subscribing with mid: 14 to topics with qos: [('homeassistant/light/+/config', 0)]
2025-09-10 22:43:00.124 DEBUG (MainThread) [homeassistant.components.mqtt.client] mqtt: unregister write 25
2025-09-10 22:43:00.125 DEBUG (MainThread) [homeassistant.components.mqtt.client] mqtt: register write 25
2025-09-10 22:43:00.125 DEBUG (MainThread) [homeassistant.components.mqtt.client] Subscribing with mid: 15 to topics with qos: [('homeassistant/lock/+/config', 0)]
2025-09-10 22:43:00.125 DEBUG (MainThread) [homeassistant.components.mqtt.client] mqtt: unregister write 25
2025-09-10 22:43:00.126 DEBUG (MainThread) [homeassistant.components.mqtt.client] mqtt: register write 25
2025-09-10 22:43:00.126 DEBUG (MainThread) [homeassistant.components.mqtt.client] Subscribing with mid: 16 to topics with qos: [('homeassistant/notify/+/config', 0)]
2025-09-10 22:43:00.126 DEBUG (MainThread) [homeassistant.components.mqtt.client] mqtt: unregister write 25
2025-09-10 22:43:00.126 DEBUG (MainThread) [homeassistant.components.mqtt.client] mqtt: register write 25
2025-09-10 22:43:00.126 DEBUG (MainThread) [homeassistant.components.mqtt.client] Subscribing with mid: 17 to topics with qos: [('homeassistant/number/+/config', 0)]
2025-09-10 22:43:00.127 DEBUG (MainThread) [homeassistant.components.mqtt.client] mqtt: unregister write 25
2025-09-10 22:43:00.127 DEBUG (MainThread) [homeassistant.components.mqtt.client] mqtt: register write 25
2025-09-10 22:43:00.127 DEBUG (MainThread) [homeassistant.components.mqtt.client] Subscribing with mid: 18 to topics with qos: [('homeassistant/scene/+/config', 0)]
2025-09-10 22:43:00.128 DEBUG (MainThread) [homeassistant.components.mqtt.client] mqtt: unregister write 25
2025-09-10 22:43:00.129 DEBUG (MainThread) [homeassistant.components.mqtt.client] mqtt: register write 25
2025-09-10 22:43:00.129 DEBUG (MainThread) [homeassistant.components.mqtt.client] Subscribing with mid: 19 to topics with qos: [('homeassistant/siren/+/config', 0)]
2025-09-10 22:43:00.130 DEBUG (MainThread) [homeassistant.components.mqtt.client] mqtt: unregister write 25
2025-09-10 22:43:00.130 DEBUG (MainThread) [homeassistant.components.mqtt.client] mqtt: register write 25
2025-09-10 22:43:00.130 DEBUG (MainThread) [homeassistant.components.mqtt.client] Subscribing with mid: 20 to topics with qos: [('homeassistant/select/+/config', 0)]
2025-09-10 22:43:00.130 DEBUG (MainThread) [homeassistant.components.mqtt.client] mqtt: unregister write 25
2025-09-10 22:43:00.131 DEBUG (MainThread) [homeassistant.components.mqtt.client] mqtt: register write 25
2025-09-10 22:43:00.131 DEBUG (MainThread) [homeassistant.components.mqtt.client] Subscribing with mid: 21 to topics with qos: [('homeassistant/sensor/+/config', 0)]
2025-09-10 22:43:00.132 DEBUG (MainThread) [homeassistant.components.mqtt.client] mqtt: unregister write 25
2025-09-10 22:43:00.132 DEBUG (MainThread) [homeassistant.components.mqtt.client] mqtt: register write 25
2025-09-10 22:43:00.132 DEBUG (MainThread) [homeassistant.components.mqtt.client] Subscribing with mid: 22 to topics with qos: [('homeassistant/switch/+/config', 0)]
2025-09-10 22:43:00.133 DEBUG (MainThread) [homeassistant.components.mqtt.client] mqtt: unregister write 25
2025-09-10 22:43:00.133 DEBUG (MainThread) [homeassistant.components.mqtt.client] mqtt: register write 25
2025-09-10 22:43:00.133 DEBUG (MainThread) [homeassistant.components.mqtt.client] Subscribing with mid: 23 to topics with qos: [('homeassistant/tag/+/config', 0)]
2025-09-10 22:43:00.134 DEBUG (MainThread) [homeassistant.components.mqtt.client] mqtt: unregister write 25
2025-09-10 22:43:00.134 DEBUG (MainThread) [homeassistant.components.mqtt.client] mqtt: register write 25
2025-09-10 22:43:00.134 DEBUG (MainThread) [homeassistant.components.mqtt.client] Subscribing with mid: 24 to topics with qos: [('homeassistant/text/+/config', 0)]
2025-09-10 22:43:00.135 DEBUG (MainThread) [homeassistant.components.mqtt.client] mqtt: unregister write 25
2025-09-10 22:43:00.135 DEBUG (MainThread) [homeassistant.components.mqtt.client] mqtt: register write 25
2025-09-10 22:43:00.135 DEBUG (MainThread) [homeassistant.components.mqtt.client] Subscribing with mid: 25 to topics with qos: [('homeassistant/update/+/config', 0)]
2025-09-10 22:43:00.135 DEBUG (MainThread) [homeassistant.components.mqtt.client] mqtt: unregister write 25
2025-09-10 22:43:00.136 DEBUG (MainThread) [homeassistant.components.mqtt.client] mqtt: register write 25
2025-09-10 22:43:00.136 DEBUG (MainThread) [homeassistant.components.mqtt.client] Subscribing with mid: 26 to topics with qos: [('homeassistant/vacuum/+/config', 0)]
2025-09-10 22:43:00.136 DEBUG (MainThread) [homeassistant.components.mqtt.client] mqtt: unregister write 25
2025-09-10 22:43:00.137 DEBUG (MainThread) [homeassistant.components.mqtt.client] mqtt: register write 25
2025-09-10 22:43:00.137 DEBUG (MainThread) [homeassistant.components.mqtt.client] Subscribing with mid: 27 to topics with qos: [('homeassistant/valve/+/config', 0)]
2025-09-10 22:43:00.137 DEBUG (MainThread) [homeassistant.components.mqtt.client] mqtt: unregister write 25
2025-09-10 22:43:00.138 DEBUG (MainThread) [homeassistant.components.mqtt.client] mqtt: register write 25
2025-09-10 22:43:00.138 DEBUG (MainThread) [homeassistant.components.mqtt.client] Subscribing with mid: 28 to topics with qos: [('homeassistant/water_heater/+/config', 0)]
2025-09-10 22:43:00.139 DEBUG (MainThread) [homeassistant.components.mqtt.client] mqtt: unregister write 25
2025-09-10 22:43:00.140 DEBUG (MainThread) [homeassistant.components.mqtt.client] mqtt: register write 25
2025-09-10 22:43:00.140 DEBUG (MainThread) [homeassistant.components.mqtt.client] Subscribing with mid: 29 to topics with qos: [('homeassistant/alarm_control_panel/+/+/config', 0)]
2025-09-10 22:43:00.140 DEBUG (MainThread) [homeassistant.components.mqtt.client] mqtt: unregister write 25
2025-09-10 22:43:00.141 DEBUG (MainThread) [homeassistant.components.mqtt.client] mqtt: register write 25
2025-09-10 22:43:00.141 DEBUG (MainThread) [homeassistant.components.mqtt.client] Subscribing with mid: 30 to topics with qos: [('homeassistant/binary_sensor/+/+/config', 0)]
2025-09-10 22:43:00.142 DEBUG (MainThread) [homeassistant.components.mqtt.client] mqtt: unregister write 25
2025-09-10 22:43:00.142 DEBUG (MainThread) [homeassistant.components.mqtt.client] mqtt: register write 25
2025-09-10 22:43:00.142 DEBUG (MainThread) [homeassistant.components.mqtt.client] Subscribing with mid: 31 to topics with qos: [('homeassistant/button/+/+/config', 0)]
2025-09-10 22:43:00.143 DEBUG (MainThread) [homeassistant.components.mqtt.client] mqtt: unregister write 25
2025-09-10 22:43:00.143 DEBUG (MainThread) [homeassistant.components.mqtt.client] mqtt: register write 25
2025-09-10 22:43:00.143 DEBUG (MainThread) [homeassistant.components.mqtt.client] Subscribing with mid: 32 to topics with qos: [('homeassistant/camera/+/+/config', 0)]
2025-09-10 22:43:00.144 DEBUG (MainThread) [homeassistant.components.mqtt.client] mqtt: unregister write 25
2025-09-10 22:43:00.144 DEBUG (MainThread) [homeassistant.components.mqtt.client] mqtt: register write 25
2025-09-10 22:43:00.145 DEBUG (MainThread) [homeassistant.components.mqtt.client] Subscribing with mid: 33 to topics with qos: [('homeassistant/climate/+/+/config', 0)]
2025-09-10 22:43:00.145 DEBUG (MainThread) [homeassistant.components.mqtt.client] mqtt: unregister write 25
2025-09-10 22:43:00.145 DEBUG (MainThread) [homeassistant.components.mqtt.client] mqtt: register write 25
2025-09-10 22:43:00.146 DEBUG (MainThread) [homeassistant.components.mqtt.client] Subscribing with mid: 34 to topics with qos: [('homeassistant/cover/+/+/config', 0)]
2025-09-10 22:43:00.146 DEBUG (MainThread) [homeassistant.components.mqtt.client] mqtt: unregister write 25
2025-09-10 22:43:00.146 DEBUG (MainThread) [homeassistant.components.mqtt.client] mqtt: register write 25
2025-09-10 22:43:00.146 DEBUG (MainThread) [homeassistant.components.mqtt.client] Subscribing with mid: 35 to topics with qos: [('homeassistant/device_automation/+/+/config', 0)]
2025-09-10 22:43:00.146 DEBUG (MainThread) [homeassistant.components.mqtt.client] mqtt: unregister write 25
2025-09-10 22:43:00.147 DEBUG (MainThread) [homeassistant.components.mqtt.client] mqtt: register write 25
2025-09-10 22:43:00.147 DEBUG (MainThread) [homeassistant.components.mqtt.client] Subscribing with mid: 36 to topics with qos: [('homeassistant/device_tracker/+/+/config', 0)]
2025-09-10 22:43:00.148 DEBUG (MainThread) [homeassistant.components.mqtt.client] mqtt: unregister write 25
2025-09-10 22:43:00.149 DEBUG (MainThread) [homeassistant.components.mqtt.client] mqtt: register write 25
2025-09-10 22:43:00.149 DEBUG (MainThread) [homeassistant.components.mqtt.client] Subscribing with mid: 37 to topics with qos: [('homeassistant/event/+/+/config', 0)]
2025-09-10 22:43:00.149 DEBUG (MainThread) [homeassistant.components.mqtt.client] mqtt: unregister write 25
2025-09-10 22:43:00.150 DEBUG (MainThread) [homeassistant.components.mqtt.client] mqtt: register write 25
2025-09-10 22:43:00.150 DEBUG (MainThread) [homeassistant.components.mqtt.client] Subscribing with mid: 38 to topics with qos: [('homeassistant/fan/+/+/config', 0)]
2025-09-10 22:43:00.151 DEBUG (MainThread) [homeassistant.components.mqtt.client] mqtt: unregister write 25
2025-09-10 22:43:00.151 DEBUG (MainThread) [homeassistant.components.mqtt.client] mqtt: register write 25
2025-09-10 22:43:00.151 DEBUG (MainThread) [homeassistant.components.mqtt.client] Subscribing with mid: 39 to topics with qos: [('homeassistant/humidifier/+/+/config', 0)]
2025-09-10 22:43:00.153 DEBUG (MainThread) [homeassistant.components.mqtt.client] mqtt: unregister write 25
2025-09-10 22:43:00.153 DEBUG (MainThread) [homeassistant.components.mqtt.client] mqtt: register write 25
2025-09-10 22:43:00.154 DEBUG (MainThread) [homeassistant.components.mqtt.client] Subscribing with mid: 40 to topics with qos: [('homeassistant/image/+/+/config', 0)]
2025-09-10 22:43:00.154 DEBUG (MainThread) [homeassistant.components.mqtt.client] mqtt: unregister write 25
2025-09-10 22:43:00.155 DEBUG (MainThread) [homeassistant.components.mqtt.client] mqtt: register write 25
2025-09-10 22:43:00.155 DEBUG (MainThread) [homeassistant.components.mqtt.client] Subscribing with mid: 41 to topics with qos: [('homeassistant/lawn_mower/+/+/config', 0)]
2025-09-10 22:43:00.155 DEBUG (MainThread) [homeassistant.components.mqtt.client] mqtt: unregister write 25
2025-09-10 22:43:00.156 DEBUG (MainThread) [homeassistant.components.mqtt.client] mqtt: register write 25
2025-09-10 22:43:00.156 DEBUG (MainThread) [homeassistant.components.mqtt.client] Subscribing with mid: 42 to topics with qos: [('homeassistant/light/+/+/config', 0)]
2025-09-10 22:43:00.156 DEBUG (MainThread) [homeassistant.components.mqtt.client] mqtt: unregister write 25
2025-09-10 22:43:00.157 DEBUG (MainThread) [homeassistant.components.mqtt.client] mqtt: register write 25
2025-09-10 22:43:00.157 DEBUG (MainThread) [homeassistant.components.mqtt.client] Subscribing with mid: 43 to topics with qos: [('homeassistant/lock/+/+/config', 0)]
2025-09-10 22:43:00.157 DEBUG (MainThread) [homeassistant.components.mqtt.client] mqtt: unregister write 25
2025-09-10 22:43:00.158 DEBUG (MainThread) [homeassistant.components.mqtt.client] mqtt: register write 25
2025-09-10 22:43:00.158 DEBUG (MainThread) [homeassistant.components.mqtt.client] Subscribing with mid: 44 to topics with qos: [('homeassistant/notify/+/+/config', 0)]
2025-09-10 22:43:00.158 DEBUG (MainThread) [homeassistant.components.mqtt.client] mqtt: unregister write 25
2025-09-10 22:43:00.159 DEBUG (MainThread) [homeassistant.components.mqtt.client] mqtt: register write 25
2025-09-10 22:43:00.159 DEBUG (MainThread) [homeassistant.components.mqtt.client] Subscribing with mid: 45 to topics with qos: [('homeassistant/number/+/+/config', 0)]
2025-09-10 22:43:00.159 DEBUG (MainThread) [homeassistant.components.mqtt.client] mqtt: unregister write 25
2025-09-10 22:43:00.160 DEBUG (MainThread) [homeassistant.components.mqtt.client] mqtt: register write 25
2025-09-10 22:43:00.160 DEBUG (MainThread) [homeassistant.components.mqtt.client] Subscribing with mid: 46 to topics with qos: [('homeassistant/scene/+/+/config', 0)]
2025-09-10 22:43:00.160 DEBUG (MainThread) [homeassistant.components.mqtt.client] mqtt: unregister write 25
2025-09-10 22:43:00.161 DEBUG (MainThread) [homeassistant.components.mqtt.client] mqtt: register write 25
2025-09-10 22:43:00.161 DEBUG (MainThread) [homeassistant.components.mqtt.client] Subscribing with mid: 47 to topics with qos: [('homeassistant/siren/+/+/config', 0)]
2025-09-10 22:43:00.161 DEBUG (MainThread) [homeassistant.components.mqtt.client] mqtt: unregister write 25
2025-09-10 22:43:00.162 DEBUG (MainThread) [homeassistant.components.mqtt.client] mqtt: register write 25
2025-09-10 22:43:00.162 DEBUG (MainThread) [homeassistant.components.mqtt.client] Subscribing with mid: 48 to topics with qos: [('homeassistant/select/+/+/config', 0)]
2025-09-10 22:43:00.163 DEBUG (MainThread) [homeassistant.components.mqtt.client] mqtt: unregister write 25
2025-09-10 22:43:00.163 DEBUG (MainThread) [homeassistant.components.mqtt.client] mqtt: register write 25
2025-09-10 22:43:00.163 DEBUG (MainThread) [homeassistant.components.mqtt.client] Subscribing with mid: 49 to topics with qos: [('homeassistant/sensor/+/+/config', 0)]
2025-09-10 22:43:00.164 DEBUG (MainThread) [homeassistant.components.mqtt.client] mqtt: unregister write 25
2025-09-10 22:43:00.164 DEBUG (MainThread) [homeassistant.components.mqtt.client] mqtt: register write 25
2025-09-10 22:43:00.164 DEBUG (MainThread) [homeassistant.components.mqtt.client] Subscribing with mid: 50 to topics with qos: [('homeassistant/switch/+/+/config', 0)]
2025-09-10 22:43:00.164 DEBUG (MainThread) [homeassistant.components.mqtt.client] mqtt: unregister write 25
2025-09-10 22:43:00.165 DEBUG (MainThread) [homeassistant.components.mqtt.client] mqtt: register write 25
2025-09-10 22:43:00.165 DEBUG (MainThread) [homeassistant.components.mqtt.client] Subscribing with mid: 51 to topics with qos: [('homeassistant/tag/+/+/config', 0)]
2025-09-10 22:43:00.165 DEBUG (MainThread) [homeassistant.components.mqtt.client] mqtt: unregister write 25
2025-09-10 22:43:00.166 DEBUG (MainThread) [homeassistant.components.mqtt.client] mqtt: register write 25
2025-09-10 22:43:00.166 DEBUG (MainThread) [homeassistant.components.mqtt.client] Subscribing with mid: 52 to topics with qos: [('homeassistant/text/+/+/config', 0)]
2025-09-10 22:43:00.166 DEBUG (MainThread) [homeassistant.components.mqtt.client] mqtt: unregister write 25
2025-09-10 22:43:00.167 DEBUG (MainThread) [homeassistant.components.mqtt.client] mqtt: register write 25
2025-09-10 22:43:00.167 DEBUG (MainThread) [homeassistant.components.mqtt.client] Subscribing with mid: 53 to topics with qos: [('homeassistant/update/+/+/config', 0)]
2025-09-10 22:43:00.167 DEBUG (MainThread) [homeassistant.components.mqtt.client] mqtt: unregister write 25
2025-09-10 22:43:00.168 DEBUG (MainThread) [homeassistant.components.mqtt.client] mqtt: register write 25
2025-09-10 22:43:00.168 DEBUG (MainThread) [homeassistant.components.mqtt.client] Subscribing with mid: 54 to topics with qos: [('homeassistant/vacuum/+/+/config', 0)]
2025-09-10 22:43:00.169 DEBUG (MainThread) [homeassistant.components.mqtt.client] mqtt: unregister write 25
2025-09-10 22:43:00.170 DEBUG (MainThread) [homeassistant.components.mqtt.client] mqtt: register write 25
2025-09-10 22:43:00.170 DEBUG (MainThread) [homeassistant.components.mqtt.client] Subscribing with mid: 55 to topics with qos: [('homeassistant/valve/+/+/config', 0)]
2025-09-10 22:43:00.171 DEBUG (MainThread) [homeassistant.components.mqtt.client] mqtt: unregister write 25
2025-09-10 22:43:00.171 DEBUG (MainThread) [homeassistant.components.mqtt.client] mqtt: register write 25
2025-09-10 22:43:00.171 DEBUG (MainThread) [homeassistant.components.mqtt.client] Subscribing with mid: 56 to topics with qos: [('homeassistant/water_heater/+/+/config', 0)]
2025-09-10 22:43:00.172 DEBUG (MainThread) [homeassistant.components.mqtt.client] mqtt: unregister write 25
2025-09-10 22:43:00.173 DEBUG (MainThread) [homeassistant.components.mqtt.client] mqtt: register write 25
2025-09-10 22:43:00.173 DEBUG (MainThread) [homeassistant.components.mqtt.client] Subscribing with mid: 57 to topics with qos: [('homeassistant/device/+/config', 0)]
2025-09-10 22:43:00.174 DEBUG (MainThread) [homeassistant.components.mqtt.client] mqtt: unregister write 25
2025-09-10 22:43:00.175 DEBUG (MainThread) [homeassistant.components.mqtt.client] mqtt: register write 25
2025-09-10 22:43:00.175 DEBUG (MainThread) [homeassistant.components.mqtt.client] Subscribing with mid: 58 to topics with qos: [('homeassistant/device/+/+/config', 0)]
2025-09-10 22:43:00.175 DEBUG (MainThread) [homeassistant.components.mqtt.client] mqtt: unregister write 25
2025-09-10 22:43:00.176 DEBUG (MainThread) [homeassistant.components.mqtt.client] mqtt: register write 25
2025-09-10 22:43:00.176 DEBUG (MainThread) [homeassistant.components.mqtt.client] Subscribing with mid: 59 to topics with qos: [('drop_connect/discovery/#', 0)]
2025-09-10 22:43:00.176 DEBUG (MainThread) [homeassistant.components.mqtt.client] mqtt: unregister write 25
2025-09-10 22:43:00.176 DEBUG (MainThread) [homeassistant.components.mqtt.client] mqtt: register write 25
2025-09-10 22:43:00.177 DEBUG (MainThread) [homeassistant.components.mqtt.client] Subscribing with mid: 60 to topics with qos: [('dsmr/#', 0)]
2025-09-10 22:43:00.177 DEBUG (MainThread) [homeassistant.components.mqtt.client] mqtt: unregister write 25
2025-09-10 22:43:00.178 DEBUG (MainThread) [homeassistant.components.mqtt.client] mqtt: register write 25
2025-09-10 22:43:00.178 DEBUG (MainThread) [homeassistant.components.mqtt.client] Subscribing with mid: 61 to topics with qos: [('esphome/discover/#', 0)]
2025-09-10 22:43:00.178 DEBUG (MainThread) [homeassistant.components.mqtt.client] mqtt: unregister write 25
2025-09-10 22:43:00.179 DEBUG (MainThread) [homeassistant.components.mqtt.client] mqtt: register write 25
2025-09-10 22:43:00.179 DEBUG (MainThread) [homeassistant.components.mqtt.client] Subscribing with mid: 62 to topics with qos: [('fully/deviceInfo/+', 0)]
2025-09-10 22:43:00.179 DEBUG (MainThread) [homeassistant.components.mqtt.client] mqtt: unregister write 25
2025-09-10 22:43:00.181 DEBUG (MainThread) [homeassistant.components.mqtt.client] mqtt: register write 25
2025-09-10 22:43:00.181 DEBUG (MainThread) [homeassistant.components.mqtt.client] Subscribing with mid: 63 to topics with qos: [('pglab/discovery/#', 0)]
2025-09-10 22:43:00.181 DEBUG (MainThread) [homeassistant.components.mqtt.client] mqtt: unregister write 25
2025-09-10 22:43:00.182 DEBUG (MainThread) [homeassistant.components.mqtt.client] mqtt: register write 25
2025-09-10 22:43:00.182 DEBUG (MainThread) [homeassistant.components.mqtt.client] Subscribing with mid: 64 to topics with qos: [('cloudapp/QBUSMQTTGW/+/state', 0)]
2025-09-10 22:43:00.182 DEBUG (MainThread) [homeassistant.components.mqtt.client] mqtt: unregister write 25
2025-09-10 22:43:00.183 DEBUG (MainThread) [homeassistant.components.mqtt.client] mqtt: register write 25
2025-09-10 22:43:00.183 DEBUG (MainThread) [homeassistant.components.mqtt.client] Subscribing with mid: 65 to topics with qos: [('tasmota/discovery/#', 0)]
2025-09-10 22:43:00.183 DEBUG (MainThread) [homeassistant.components.mqtt.client] mqtt: unregister write 25
2025-09-10 22:43:00.183 DEBUG (MainThread) [homeassistant.components.mqtt.client] mqtt: register write 25
2025-09-10 22:43:00.184 DEBUG (MainThread) [homeassistant.components.mqtt.client] Subscribing with mid: 66 to topics with qos: [('cloudapp/QBUSMQTTGW/config', 0), ('cloudapp/QBUSMQTTGW/state', 0)]
2025-09-10 22:43:00.184 DEBUG (MainThread) [homeassistant.components.mqtt.client] mqtt: unregister write 25
2025-09-10 22:43:00.374 INFO (MainThread) [homeassistant.setup] Setting up media_player
2025-09-10 22:43:00.378 INFO (MainThread) [homeassistant.setup] Setup of domain media_player took 0.00 seconds
2025-09-10 22:43:00.379 INFO (MainThread) [homeassistant.setup] Setting up number
2025-09-10 22:43:00.380 INFO (MainThread) [homeassistant.setup] Setup of domain number took 0.00 seconds
2025-09-10 22:43:00.380 INFO (MainThread) [homeassistant.setup] Setting up select
2025-09-10 22:43:00.381 INFO (MainThread) [homeassistant.setup] Setup of domain select took 0.00 seconds
2025-09-10 22:43:00.382 INFO (MainThread) [homeassistant.setup] Setting up switch
2025-09-10 22:43:00.382 INFO (MainThread) [homeassistant.setup] Setup of domain switch took 0.00 seconds
2025-09-10 22:43:00.384 INFO (MainThread) [homeassistant.components.binary_sensor] Setting up sonos.binary_sensor
2025-09-10 22:43:00.384 INFO (MainThread) [homeassistant.components.media_player] Setting up sonos.media_player
2025-09-10 22:43:00.385 INFO (MainThread) [homeassistant.components.number] Setting up sonos.number
2025-09-10 22:43:00.385 INFO (MainThread) [homeassistant.components.select] Setting up sonos.select
2025-09-10 22:43:00.386 INFO (MainThread) [homeassistant.components.sensor] Setting up sonos.sensor
2025-09-10 22:43:00.386 INFO (MainThread) [homeassistant.components.switch] Setting up sonos.switch
2025-09-10 22:43:10.391 WARNING (MainThread) [homeassistant.components.sonos] Could not get visible Sonos devices from 192.168.1.103: HTTPConnectionPool(host='192.168.1.103', port=1400): Max retries exceeded with url: /xml/DeviceProperties1.xml (Caused by ConnectTimeoutError(<urllib3.connection.HTTPConnection object at 0x732ec147f770>, 'Connection to 192.168.1.103 timed out. (connect timeout=10)'))
2025-09-10 22:43:12.458 WARNING (MainThread) [homeassistant.components.sonos] Subscription to 192.168.1.102 failed, attempting to poll directly
2025-09-10 22:43:14.458 INFO (MainThread) [homeassistant.bootstrap] Home Assistant initialized in 43.54s
2025-09-10 22:43:14.459 INFO (MainThread) [homeassistant.core] Starting Home Assistant 2025.9.1
2025-09-10 22:43:14.466 DEBUG (MainThread) [homeassistant.components.mqtt.trigger] Attaching MQTT trigger for topic: 'alicia/tts/announce', payload: 'None'
2025-09-10 22:43:14.466 INFO (MainThread) [homeassistant.components.automation.sonos_tts_announcement] Initialized trigger Sonos TTS Announcement
2025-09-10 22:43:14.466 DEBUG (MainThread) [homeassistant.components.mqtt.trigger] Attaching MQTT trigger for topic: 'alicia/commands/sonos/group', payload: 'None'
2025-09-10 22:43:14.466 INFO (MainThread) [homeassistant.components.automation.sonos_multi_room_group_control] Initialized trigger Sonos Multi-Room Group Control
2025-09-10 22:43:14.466 DEBUG (MainThread) [homeassistant.components.mqtt.trigger] Attaching MQTT trigger for topic: 'alicia/commands/sonos/volume', payload: 'None'
2025-09-10 22:43:14.467 INFO (MainThread) [homeassistant.components.automation.sonos_volume_control] Initialized trigger Sonos Volume Control
2025-09-10 22:43:14.467 DEBUG (MainThread) [homeassistant.components.mqtt.trigger] Attaching MQTT trigger for topic: 'alicia/commands/sonos/playback', payload: 'None'
2025-09-10 22:43:14.467 INFO (MainThread) [homeassistant.components.automation.sonos_playback_control] Initialized trigger Sonos Playback Control
2025-09-10 22:43:14.467 INFO (MainThread) [homeassistant.components.automation.sonos_status_monitor] Initialized trigger Sonos Status Monitor
2025-09-10 22:43:14.969 DEBUG (MainThread) [homeassistant.components.mqtt.client] mqtt: register write 25
2025-09-10 22:43:14.969 DEBUG (MainThread) [homeassistant.components.mqtt.client] Subscribing with mid: 67 to topics with qos: [('alicia/tts/announce', 0), ('alicia/commands/sonos/group', 0), ('alicia/commands/sonos/volume', 0), ('alicia/commands/sonos/playback', 0)]
2025-09-10 22:43:14.969 DEBUG (MainThread) [homeassistant.components.mqtt.client] mqtt: unregister write 25
2025-09-10 22:43:20.085 DEBUG (MainThread) [homeassistant.components.mqtt.client] mqtt: register write 25
2025-09-10 22:43:20.086 DEBUG (MainThread) [homeassistant.components.mqtt.client] Transmitting message on homeassistant/status: 'online', mid: 68, qos: 0
2025-09-10 22:43:20.086 DEBUG (MainThread) [homeassistant.components.mqtt.client] mqtt: unregister write 25
2025-09-10 22:43:20.086 INFO (MainThread) [homeassistant.components.mqtt.client] MQTT client initialized, birth message sent
2025-09-10 22:43:59.890 DEBUG (MainThread) [homeassistant.components.mqtt.client] mqtt: register write 25
2025-09-10 22:43:59.891 DEBUG (MainThread) [homeassistant.components.mqtt.client] mqtt: unregister write 25
2025-09-10 22:45:00.177 DEBUG (MainThread) [homeassistant.components.mqtt.client] mqtt: register write 25
2025-09-10 22:45:00.177 DEBUG (MainThread) [homeassistant.components.mqtt.client] mqtt: unregister write 25
2025-09-10 22:46:00.453 DEBUG (MainThread) [homeassistant.components.mqtt.client] mqtt: register write 25
2025-09-10 22:46:00.453 DEBUG (MainThread) [homeassistant.components.mqtt.client] mqtt: unregister write 25
2025-09-10 22:47:00.738 DEBUG (MainThread) [homeassistant.components.mqtt.client] mqtt: register write 25
2025-09-10 22:47:00.738 DEBUG (MainThread) [homeassistant.components.mqtt.client] mqtt: unregister write 25
