2025-09-10 22:20:21.489 INFO (MainThread) [homeassistant.setup] Setup of domain http took 0.05 seconds
2025-09-10 22:20:21.489 INFO (MainThread) [homeassistant.setup] Setup of domain system_log took 0.05 seconds
2025-09-10 22:20:21.489 INFO (MainThread) [homeassistant.setup] Setup of domain logger took 0.05 seconds
2025-09-10 22:20:21.489 INFO (MainThread) [homeassistant.setup] Setting up websocket_api
2025-09-10 22:20:21.490 INFO (MainThread) [homeassistant.setup] Setup of domain websocket_api took 0.00 seconds
2025-09-10 22:20:21.494 INFO (MainThread) [homeassistant.setup] Setting up network
2025-09-10 22:20:21.496 INFO (MainThread) [homeassistant.setup] Setup of domain network took 0.00 seconds
2025-09-10 22:20:21.496 INFO (MainThread) [homeassistant.bootstrap] Setting up stage frontend: {'frontend'}; already set up: {}
Dependencies: {'diagnostics', 'api', 'onboarding', 'config', 'auth', 'file_upload', 'search', 'repairs', 'device_automation', 'lovelace'}; already set up: {'http', 'websocket_api', 'system_log'}
2025-09-10 22:20:21.496 INFO (MainThread) [homeassistant.setup] Setting up diagnostics
2025-09-10 22:20:21.497 INFO (MainThread) [homeassistant.setup] Setup of domain diagnostics took 0.00 seconds
2025-09-10 22:20:21.497 INFO (MainThread) [homeassistant.setup] Setting up api
2025-09-10 22:20:21.498 INFO (MainThread) [homeassistant.setup] Setup of domain api took 0.00 seconds
2025-09-10 22:20:21.498 INFO (MainThread) [homeassistant.setup] Setting up auth
2025-09-10 22:20:21.499 INFO (MainThread) [homeassistant.setup] Setup of domain auth took 0.00 seconds
2025-09-10 22:20:21.499 INFO (MainThread) [homeassistant.setup] Setting up onboarding
2025-09-10 22:20:21.499 INFO (MainThread) [homeassistant.setup] Setup of domain onboarding took 0.00 seconds
2025-09-10 22:20:21.499 INFO (MainThread) [homeassistant.setup] Setting up config
2025-09-10 22:20:21.500 INFO (MainThread) [homeassistant.setup] Setup of domain config took 0.00 seconds
2025-09-10 22:20:21.500 INFO (MainThread) [homeassistant.setup] Setting up device_automation
2025-09-10 22:20:21.501 INFO (MainThread) [homeassistant.setup] Setup of domain device_automation took 0.00 seconds
2025-09-10 22:20:21.501 INFO (MainThread) [homeassistant.setup] Setting up file_upload
2025-09-10 22:20:21.501 INFO (MainThread) [homeassistant.setup] Setup of domain file_upload took 0.00 seconds
2025-09-10 22:20:21.501 INFO (MainThread) [homeassistant.setup] Setting up lovelace
2025-09-10 22:20:21.502 INFO (MainThread) [homeassistant.setup] Setting up repairs
2025-09-10 22:20:21.502 INFO (MainThread) [homeassistant.setup] Setup of domain repairs took 0.00 seconds
2025-09-10 22:20:21.502 INFO (MainThread) [homeassistant.setup] Setting up search
2025-09-10 22:20:21.502 INFO (MainThread) [homeassistant.setup] Setup of domain search took 0.00 seconds
2025-09-10 22:20:21.503 INFO (MainThread) [homeassistant.setup] Setup of domain lovelace took 0.00 seconds
2025-09-10 22:20:21.510 INFO (MainThread) [homeassistant.setup] Setting up frontend
2025-09-10 22:20:21.517 INFO (MainThread) [homeassistant.setup] Setup of domain frontend took 0.01 seconds
2025-09-10 22:20:21.517 INFO (MainThread) [homeassistant.bootstrap] Setting up stage recorder: {'recorder'}; already set up: {}
Dependencies: {}; already set up: {}
2025-09-10 22:20:21.519 INFO (MainThread) [homeassistant.setup] Setup of domain http took 0.00 seconds
2025-09-10 22:20:21.528 INFO (MainThread) [homeassistant.setup] Setting up recorder
2025-09-10 22:20:21.545 ERROR (Recorder) [homeassistant.components.recorder.core] Error during connection setup: (retrying in 3 seconds)
Traceback (most recent call last):
  File "/usr/local/lib/python3.13/site-packages/sqlalchemy/engine/base.py", line 145, in __init__
    self._dbapi_connection = engine.raw_connection()
                             ~~~~~~~~~~~~~~~~~~~~~^^
  File "/usr/local/lib/python3.13/site-packages/sqlalchemy/engine/base.py", line 3297, in raw_connection
    return self.pool.connect()
           ~~~~~~~~~~~~~~~~~^^
  File "/usr/local/lib/python3.13/site-packages/sqlalchemy/pool/base.py", line 449, in connect
    return _ConnectionFairy._checkout(self)
           ~~~~~~~~~~~~~~~~~~~~~~~~~~^^^^^^
  File "/usr/local/lib/python3.13/site-packages/sqlalchemy/pool/base.py", line 1264, in _checkout
    fairy = _ConnectionRecord.checkout(pool)
  File "/usr/local/lib/python3.13/site-packages/sqlalchemy/pool/base.py", line 713, in checkout
    rec = pool._do_get()
  File "/usr/local/lib/python3.13/site-packages/sqlalchemy/pool/impl.py", line 179, in _do_get
    with util.safe_reraise():
         ~~~~~~~~~~~~~~~~~^^
  File "/usr/local/lib/python3.13/site-packages/sqlalchemy/util/langhelpers.py", line 224, in __exit__
    raise exc_value.with_traceback(exc_tb)
  File "/usr/local/lib/python3.13/site-packages/sqlalchemy/pool/impl.py", line 177, in _do_get
    return self._create_connection()
           ~~~~~~~~~~~~~~~~~~~~~~~^^
  File "/usr/local/lib/python3.13/site-packages/sqlalchemy/pool/base.py", line 390, in _create_connection
    return _ConnectionRecord(self)
  File "/usr/local/lib/python3.13/site-packages/sqlalchemy/pool/base.py", line 675, in __init__
    self.__connect()
    ~~~~~~~~~~~~~~^^
  File "/usr/local/lib/python3.13/site-packages/sqlalchemy/pool/base.py", line 901, in __connect
    with util.safe_reraise():
         ~~~~~~~~~~~~~~~~~^^
  File "/usr/local/lib/python3.13/site-packages/sqlalchemy/util/langhelpers.py", line 224, in __exit__
    raise exc_value.with_traceback(exc_tb)
  File "/usr/local/lib/python3.13/site-packages/sqlalchemy/pool/base.py", line 897, in __connect
    self.dbapi_connection = connection = pool._invoke_creator(self)
                                         ~~~~~~~~~~~~~~~~~~~~^^^^^^
  File "/usr/local/lib/python3.13/site-packages/sqlalchemy/engine/create.py", line 646, in connect
    return dialect.connect(*cargs, **cparams)
           ~~~~~~~~~~~~~~~^^^^^^^^^^^^^^^^^^^
  File "/usr/local/lib/python3.13/site-packages/sqlalchemy/engine/default.py", line 625, in connect
    return self.loaded_dbapi.connect(*cargs, **cparams)  # type: ignore[no-any-return]  # NOQA: E501
           ~~~~~~~~~~~~~~~~~~~~~~~~~^^^^^^^^^^^^^^^^^^^
  File "/usr/local/lib/python3.13/site-packages/psycopg2/__init__.py", line 122, in connect
    conn = _connect(dsn, connection_factory=connection_factory, **kwasync)
psycopg2.OperationalError: connection to server at "172.21.0.3", port 5432 failed: Connection refused
	Is the server running on that host and accepting TCP/IP connections?


The above exception was the direct cause of the following exception:

Traceback (most recent call last):
  File "/usr/src/homeassistant/homeassistant/components/recorder/core.py", line 927, in _setup_recorder
    self._setup_connection()
    ~~~~~~~~~~~~~~~~~~~~~~^^
  File "/usr/src/homeassistant/homeassistant/components/recorder/core.py", line 1448, in _setup_connection
    migration.pre_migrate_schema(self.engine)
    ~~~~~~~~~~~~~~~~~~~~~~~~~~~~^^^^^^^^^^^^^
  File "/usr/src/homeassistant/homeassistant/components/recorder/migration.py", line 331, in pre_migrate_schema
    inspector = sqlalchemy.inspect(engine)
  File "/usr/local/lib/python3.13/site-packages/sqlalchemy/inspection.py", line 140, in inspect
    ret = reg(subject)
  File "/usr/local/lib/python3.13/site-packages/sqlalchemy/engine/reflection.py", line 313, in _engine_insp
    return Inspector._construct(Inspector._init_engine, bind)
           ~~~~~~~~~~~~~~~~~~~~^^^^^^^^^^^^^^^^^^^^^^^^^^^^^^
  File "/usr/local/lib/python3.13/site-packages/sqlalchemy/engine/reflection.py", line 246, in _construct
    init(self, bind)
    ~~~~^^^^^^^^^^^^
  File "/usr/local/lib/python3.13/site-packages/sqlalchemy/engine/reflection.py", line 257, in _init_engine
    engine.connect().close()
    ~~~~~~~~~~~~~~^^
  File "/usr/local/lib/python3.13/site-packages/sqlalchemy/engine/base.py", line 3273, in connect
    return self._connection_cls(self)
           ~~~~~~~~~~~~~~~~~~~~^^^^^^
  File "/usr/local/lib/python3.13/site-packages/sqlalchemy/engine/base.py", line 147, in __init__
    Connection._handle_dbapi_exception_noconnection(
    ~~~~~~~~~~~~~~~~~~~~~~~~~~~~~~~~~~~~~~~~~~~~~~~^
        err, dialect, engine
        ^^^^^^^^^^^^^^^^^^^^
    )
    ^
  File "/usr/local/lib/python3.13/site-packages/sqlalchemy/engine/base.py", line 2436, in _handle_dbapi_exception_noconnection
    raise sqlalchemy_exception.with_traceback(exc_info[2]) from e
  File "/usr/local/lib/python3.13/site-packages/sqlalchemy/engine/base.py", line 145, in __init__
    self._dbapi_connection = engine.raw_connection()
                             ~~~~~~~~~~~~~~~~~~~~~^^
  File "/usr/local/lib/python3.13/site-packages/sqlalchemy/engine/base.py", line 3297, in raw_connection
    return self.pool.connect()
           ~~~~~~~~~~~~~~~~~^^
  File "/usr/local/lib/python3.13/site-packages/sqlalchemy/pool/base.py", line 449, in connect
    return _ConnectionFairy._checkout(self)
           ~~~~~~~~~~~~~~~~~~~~~~~~~~^^^^^^
  File "/usr/local/lib/python3.13/site-packages/sqlalchemy/pool/base.py", line 1264, in _checkout
    fairy = _ConnectionRecord.checkout(pool)
  File "/usr/local/lib/python3.13/site-packages/sqlalchemy/pool/base.py", line 713, in checkout
    rec = pool._do_get()
  File "/usr/local/lib/python3.13/site-packages/sqlalchemy/pool/impl.py", line 179, in _do_get
    with util.safe_reraise():
         ~~~~~~~~~~~~~~~~~^^
  File "/usr/local/lib/python3.13/site-packages/sqlalchemy/util/langhelpers.py", line 224, in __exit__
    raise exc_value.with_traceback(exc_tb)
  File "/usr/local/lib/python3.13/site-packages/sqlalchemy/pool/impl.py", line 177, in _do_get
    return self._create_connection()
           ~~~~~~~~~~~~~~~~~~~~~~~^^
  File "/usr/local/lib/python3.13/site-packages/sqlalchemy/pool/base.py", line 390, in _create_connection
    return _ConnectionRecord(self)
  File "/usr/local/lib/python3.13/site-packages/sqlalchemy/pool/base.py", line 675, in __init__
    self.__connect()
    ~~~~~~~~~~~~~~^^
  File "/usr/local/lib/python3.13/site-packages/sqlalchemy/pool/base.py", line 901, in __connect
    with util.safe_reraise():
         ~~~~~~~~~~~~~~~~~^^
  File "/usr/local/lib/python3.13/site-packages/sqlalchemy/util/langhelpers.py", line 224, in __exit__
    raise exc_value.with_traceback(exc_tb)
  File "/usr/local/lib/python3.13/site-packages/sqlalchemy/pool/base.py", line 897, in __connect
    self.dbapi_connection = connection = pool._invoke_creator(self)
                                         ~~~~~~~~~~~~~~~~~~~~^^^^^^
  File "/usr/local/lib/python3.13/site-packages/sqlalchemy/engine/create.py", line 646, in connect
    return dialect.connect(*cargs, **cparams)
           ~~~~~~~~~~~~~~~^^^^^^^^^^^^^^^^^^^
  File "/usr/local/lib/python3.13/site-packages/sqlalchemy/engine/default.py", line 625, in connect
    return self.loaded_dbapi.connect(*cargs, **cparams)  # type: ignore[no-any-return]  # NOQA: E501
           ~~~~~~~~~~~~~~~~~~~~~~~~~^^^^^^^^^^^^^^^^^^^
  File "/usr/local/lib/python3.13/site-packages/psycopg2/__init__.py", line 122, in connect
    conn = _connect(dsn, connection_factory=connection_factory, **kwasync)
sqlalchemy.exc.OperationalError: (psycopg2.OperationalError) connection to server at "172.21.0.3", port 5432 failed: Connection refused
	Is the server running on that host and accepting TCP/IP connections?

(Background on this error at: https://sqlalche.me/e/20/e3q8)
2025-09-10 22:20:24.567 ERROR (Recorder) [homeassistant.components.recorder.core] Error during connection setup: (retrying in 3 seconds)
Traceback (most recent call last):
  File "/usr/local/lib/python3.13/site-packages/sqlalchemy/engine/base.py", line 145, in __init__
    self._dbapi_connection = engine.raw_connection()
                             ~~~~~~~~~~~~~~~~~~~~~^^
  File "/usr/local/lib/python3.13/site-packages/sqlalchemy/engine/base.py", line 3297, in raw_connection
    return self.pool.connect()
           ~~~~~~~~~~~~~~~~~^^
  File "/usr/local/lib/python3.13/site-packages/sqlalchemy/pool/base.py", line 449, in connect
    return _ConnectionFairy._checkout(self)
           ~~~~~~~~~~~~~~~~~~~~~~~~~~^^^^^^
  File "/usr/local/lib/python3.13/site-packages/sqlalchemy/pool/base.py", line 1264, in _checkout
    fairy = _ConnectionRecord.checkout(pool)
  File "/usr/local/lib/python3.13/site-packages/sqlalchemy/pool/base.py", line 713, in checkout
    rec = pool._do_get()
  File "/usr/local/lib/python3.13/site-packages/sqlalchemy/pool/impl.py", line 179, in _do_get
    with util.safe_reraise():
         ~~~~~~~~~~~~~~~~~^^
  File "/usr/local/lib/python3.13/site-packages/sqlalchemy/util/langhelpers.py", line 224, in __exit__
    raise exc_value.with_traceback(exc_tb)
  File "/usr/local/lib/python3.13/site-packages/sqlalchemy/pool/impl.py", line 177, in _do_get
    return self._create_connection()
           ~~~~~~~~~~~~~~~~~~~~~~~^^
  File "/usr/local/lib/python3.13/site-packages/sqlalchemy/pool/base.py", line 390, in _create_connection
    return _ConnectionRecord(self)
  File "/usr/local/lib/python3.13/site-packages/sqlalchemy/pool/base.py", line 675, in __init__
    self.__connect()
    ~~~~~~~~~~~~~~^^
  File "/usr/local/lib/python3.13/site-packages/sqlalchemy/pool/base.py", line 901, in __connect
    with util.safe_reraise():
         ~~~~~~~~~~~~~~~~~^^
  File "/usr/local/lib/python3.13/site-packages/sqlalchemy/util/langhelpers.py", line 224, in __exit__
    raise exc_value.with_traceback(exc_tb)
  File "/usr/local/lib/python3.13/site-packages/sqlalchemy/pool/base.py", line 897, in __connect
    self.dbapi_connection = connection = pool._invoke_creator(self)
                                         ~~~~~~~~~~~~~~~~~~~~^^^^^^
  File "/usr/local/lib/python3.13/site-packages/sqlalchemy/engine/create.py", line 646, in connect
    return dialect.connect(*cargs, **cparams)
           ~~~~~~~~~~~~~~~^^^^^^^^^^^^^^^^^^^
  File "/usr/local/lib/python3.13/site-packages/sqlalchemy/engine/default.py", line 625, in connect
    return self.loaded_dbapi.connect(*cargs, **cparams)  # type: ignore[no-any-return]  # NOQA: E501
           ~~~~~~~~~~~~~~~~~~~~~~~~~^^^^^^^^^^^^^^^^^^^
  File "/usr/local/lib/python3.13/site-packages/psycopg2/__init__.py", line 122, in connect
    conn = _connect(dsn, connection_factory=connection_factory, **kwasync)
psycopg2.OperationalError: connection to server at "172.21.0.3", port 5432 failed: Connection refused
	Is the server running on that host and accepting TCP/IP connections?


The above exception was the direct cause of the following exception:

Traceback (most recent call last):
  File "/usr/src/homeassistant/homeassistant/components/recorder/core.py", line 927, in _setup_recorder
    self._setup_connection()
    ~~~~~~~~~~~~~~~~~~~~~~^^
  File "/usr/src/homeassistant/homeassistant/components/recorder/core.py", line 1448, in _setup_connection
    migration.pre_migrate_schema(self.engine)
    ~~~~~~~~~~~~~~~~~~~~~~~~~~~~^^^^^^^^^^^^^
  File "/usr/src/homeassistant/homeassistant/components/recorder/migration.py", line 331, in pre_migrate_schema
    inspector = sqlalchemy.inspect(engine)
  File "/usr/local/lib/python3.13/site-packages/sqlalchemy/inspection.py", line 140, in inspect
    ret = reg(subject)
  File "/usr/local/lib/python3.13/site-packages/sqlalchemy/engine/reflection.py", line 313, in _engine_insp
    return Inspector._construct(Inspector._init_engine, bind)
           ~~~~~~~~~~~~~~~~~~~~^^^^^^^^^^^^^^^^^^^^^^^^^^^^^^
  File "/usr/local/lib/python3.13/site-packages/sqlalchemy/engine/reflection.py", line 246, in _construct
    init(self, bind)
    ~~~~^^^^^^^^^^^^
  File "/usr/local/lib/python3.13/site-packages/sqlalchemy/engine/reflection.py", line 257, in _init_engine
    engine.connect().close()
    ~~~~~~~~~~~~~~^^
  File "/usr/local/lib/python3.13/site-packages/sqlalchemy/engine/base.py", line 3273, in connect
    return self._connection_cls(self)
           ~~~~~~~~~~~~~~~~~~~~^^^^^^
  File "/usr/local/lib/python3.13/site-packages/sqlalchemy/engine/base.py", line 147, in __init__
    Connection._handle_dbapi_exception_noconnection(
    ~~~~~~~~~~~~~~~~~~~~~~~~~~~~~~~~~~~~~~~~~~~~~~~^
        err, dialect, engine
        ^^^^^^^^^^^^^^^^^^^^
    )
    ^
  File "/usr/local/lib/python3.13/site-packages/sqlalchemy/engine/base.py", line 2436, in _handle_dbapi_exception_noconnection
    raise sqlalchemy_exception.with_traceback(exc_info[2]) from e
  File "/usr/local/lib/python3.13/site-packages/sqlalchemy/engine/base.py", line 145, in __init__
    self._dbapi_connection = engine.raw_connection()
                             ~~~~~~~~~~~~~~~~~~~~~^^
  File "/usr/local/lib/python3.13/site-packages/sqlalchemy/engine/base.py", line 3297, in raw_connection
    return self.pool.connect()
           ~~~~~~~~~~~~~~~~~^^
  File "/usr/local/lib/python3.13/site-packages/sqlalchemy/pool/base.py", line 449, in connect
    return _ConnectionFairy._checkout(self)
           ~~~~~~~~~~~~~~~~~~~~~~~~~~^^^^^^
  File "/usr/local/lib/python3.13/site-packages/sqlalchemy/pool/base.py", line 1264, in _checkout
    fairy = _ConnectionRecord.checkout(pool)
  File "/usr/local/lib/python3.13/site-packages/sqlalchemy/pool/base.py", line 713, in checkout
    rec = pool._do_get()
  File "/usr/local/lib/python3.13/site-packages/sqlalchemy/pool/impl.py", line 179, in _do_get
    with util.safe_reraise():
         ~~~~~~~~~~~~~~~~~^^
  File "/usr/local/lib/python3.13/site-packages/sqlalchemy/util/langhelpers.py", line 224, in __exit__
    raise exc_value.with_traceback(exc_tb)
  File "/usr/local/lib/python3.13/site-packages/sqlalchemy/pool/impl.py", line 177, in _do_get
    return self._create_connection()
           ~~~~~~~~~~~~~~~~~~~~~~~^^
  File "/usr/local/lib/python3.13/site-packages/sqlalchemy/pool/base.py", line 390, in _create_connection
    return _ConnectionRecord(self)
  File "/usr/local/lib/python3.13/site-packages/sqlalchemy/pool/base.py", line 675, in __init__
    self.__connect()
    ~~~~~~~~~~~~~~^^
  File "/usr/local/lib/python3.13/site-packages/sqlalchemy/pool/base.py", line 901, in __connect
    with util.safe_reraise():
         ~~~~~~~~~~~~~~~~~^^
  File "/usr/local/lib/python3.13/site-packages/sqlalchemy/util/langhelpers.py", line 224, in __exit__
    raise exc_value.with_traceback(exc_tb)
  File "/usr/local/lib/python3.13/site-packages/sqlalchemy/pool/base.py", line 897, in __connect
    self.dbapi_connection = connection = pool._invoke_creator(self)
                                         ~~~~~~~~~~~~~~~~~~~~^^^^^^
  File "/usr/local/lib/python3.13/site-packages/sqlalchemy/engine/create.py", line 646, in connect
    return dialect.connect(*cargs, **cparams)
           ~~~~~~~~~~~~~~~^^^^^^^^^^^^^^^^^^^
  File "/usr/local/lib/python3.13/site-packages/sqlalchemy/engine/default.py", line 625, in connect
    return self.loaded_dbapi.connect(*cargs, **cparams)  # type: ignore[no-any-return]  # NOQA: E501
           ~~~~~~~~~~~~~~~~~~~~~~~~~^^^^^^^^^^^^^^^^^^^
  File "/usr/local/lib/python3.13/site-packages/psycopg2/__init__.py", line 122, in connect
    conn = _connect(dsn, connection_factory=connection_factory, **kwasync)
sqlalchemy.exc.OperationalError: (psycopg2.OperationalError) connection to server at "172.21.0.3", port 5432 failed: Connection refused
	Is the server running on that host and accepting TCP/IP connections?

(Background on this error at: https://sqlalche.me/e/20/e3q8)
2025-09-10 22:20:27.573 ERROR (Recorder) [homeassistant.components.recorder.core] Error during connection setup: (retrying in 3 seconds)
Traceback (most recent call last):
  File "/usr/local/lib/python3.13/site-packages/sqlalchemy/engine/base.py", line 145, in __init__
    self._dbapi_connection = engine.raw_connection()
                             ~~~~~~~~~~~~~~~~~~~~~^^
  File "/usr/local/lib/python3.13/site-packages/sqlalchemy/engine/base.py", line 3297, in raw_connection
    return self.pool.connect()
           ~~~~~~~~~~~~~~~~~^^
  File "/usr/local/lib/python3.13/site-packages/sqlalchemy/pool/base.py", line 449, in connect
    return _ConnectionFairy._checkout(self)
           ~~~~~~~~~~~~~~~~~~~~~~~~~~^^^^^^
  File "/usr/local/lib/python3.13/site-packages/sqlalchemy/pool/base.py", line 1264, in _checkout
    fairy = _ConnectionRecord.checkout(pool)
  File "/usr/local/lib/python3.13/site-packages/sqlalchemy/pool/base.py", line 713, in checkout
    rec = pool._do_get()
  File "/usr/local/lib/python3.13/site-packages/sqlalchemy/pool/impl.py", line 179, in _do_get
    with util.safe_reraise():
         ~~~~~~~~~~~~~~~~~^^
  File "/usr/local/lib/python3.13/site-packages/sqlalchemy/util/langhelpers.py", line 224, in __exit__
    raise exc_value.with_traceback(exc_tb)
  File "/usr/local/lib/python3.13/site-packages/sqlalchemy/pool/impl.py", line 177, in _do_get
    return self._create_connection()
           ~~~~~~~~~~~~~~~~~~~~~~~^^
  File "/usr/local/lib/python3.13/site-packages/sqlalchemy/pool/base.py", line 390, in _create_connection
    return _ConnectionRecord(self)
  File "/usr/local/lib/python3.13/site-packages/sqlalchemy/pool/base.py", line 675, in __init__
    self.__connect()
    ~~~~~~~~~~~~~~^^
  File "/usr/local/lib/python3.13/site-packages/sqlalchemy/pool/base.py", line 901, in __connect
    with util.safe_reraise():
         ~~~~~~~~~~~~~~~~~^^
  File "/usr/local/lib/python3.13/site-packages/sqlalchemy/util/langhelpers.py", line 224, in __exit__
    raise exc_value.with_traceback(exc_tb)
  File "/usr/local/lib/python3.13/site-packages/sqlalchemy/pool/base.py", line 897, in __connect
    self.dbapi_connection = connection = pool._invoke_creator(self)
                                         ~~~~~~~~~~~~~~~~~~~~^^^^^^
  File "/usr/local/lib/python3.13/site-packages/sqlalchemy/engine/create.py", line 646, in connect
    return dialect.connect(*cargs, **cparams)
           ~~~~~~~~~~~~~~~^^^^^^^^^^^^^^^^^^^
  File "/usr/local/lib/python3.13/site-packages/sqlalchemy/engine/default.py", line 625, in connect
    return self.loaded_dbapi.connect(*cargs, **cparams)  # type: ignore[no-any-return]  # NOQA: E501
           ~~~~~~~~~~~~~~~~~~~~~~~~~^^^^^^^^^^^^^^^^^^^
  File "/usr/local/lib/python3.13/site-packages/psycopg2/__init__.py", line 122, in connect
    conn = _connect(dsn, connection_factory=connection_factory, **kwasync)
psycopg2.OperationalError: connection to server at "172.21.0.3", port 5432 failed: Connection refused
	Is the server running on that host and accepting TCP/IP connections?


The above exception was the direct cause of the following exception:

Traceback (most recent call last):
  File "/usr/src/homeassistant/homeassistant/components/recorder/core.py", line 927, in _setup_recorder
    self._setup_connection()
    ~~~~~~~~~~~~~~~~~~~~~~^^
  File "/usr/src/homeassistant/homeassistant/components/recorder/core.py", line 1448, in _setup_connection
    migration.pre_migrate_schema(self.engine)
    ~~~~~~~~~~~~~~~~~~~~~~~~~~~~^^^^^^^^^^^^^
  File "/usr/src/homeassistant/homeassistant/components/recorder/migration.py", line 331, in pre_migrate_schema
    inspector = sqlalchemy.inspect(engine)
  File "/usr/local/lib/python3.13/site-packages/sqlalchemy/inspection.py", line 140, in inspect
    ret = reg(subject)
  File "/usr/local/lib/python3.13/site-packages/sqlalchemy/engine/reflection.py", line 313, in _engine_insp
    return Inspector._construct(Inspector._init_engine, bind)
           ~~~~~~~~~~~~~~~~~~~~^^^^^^^^^^^^^^^^^^^^^^^^^^^^^^
  File "/usr/local/lib/python3.13/site-packages/sqlalchemy/engine/reflection.py", line 246, in _construct
    init(self, bind)
    ~~~~^^^^^^^^^^^^
  File "/usr/local/lib/python3.13/site-packages/sqlalchemy/engine/reflection.py", line 257, in _init_engine
    engine.connect().close()
    ~~~~~~~~~~~~~~^^
  File "/usr/local/lib/python3.13/site-packages/sqlalchemy/engine/base.py", line 3273, in connect
    return self._connection_cls(self)
           ~~~~~~~~~~~~~~~~~~~~^^^^^^
  File "/usr/local/lib/python3.13/site-packages/sqlalchemy/engine/base.py", line 147, in __init__
    Connection._handle_dbapi_exception_noconnection(
    ~~~~~~~~~~~~~~~~~~~~~~~~~~~~~~~~~~~~~~~~~~~~~~~^
        err, dialect, engine
        ^^^^^^^^^^^^^^^^^^^^
    )
    ^
  File "/usr/local/lib/python3.13/site-packages/sqlalchemy/engine/base.py", line 2436, in _handle_dbapi_exception_noconnection
    raise sqlalchemy_exception.with_traceback(exc_info[2]) from e
  File "/usr/local/lib/python3.13/site-packages/sqlalchemy/engine/base.py", line 145, in __init__
    self._dbapi_connection = engine.raw_connection()
                             ~~~~~~~~~~~~~~~~~~~~~^^
  File "/usr/local/lib/python3.13/site-packages/sqlalchemy/engine/base.py", line 3297, in raw_connection
    return self.pool.connect()
           ~~~~~~~~~~~~~~~~~^^
  File "/usr/local/lib/python3.13/site-packages/sqlalchemy/pool/base.py", line 449, in connect
    return _ConnectionFairy._checkout(self)
           ~~~~~~~~~~~~~~~~~~~~~~~~~~^^^^^^
  File "/usr/local/lib/python3.13/site-packages/sqlalchemy/pool/base.py", line 1264, in _checkout
    fairy = _ConnectionRecord.checkout(pool)
  File "/usr/local/lib/python3.13/site-packages/sqlalchemy/pool/base.py", line 713, in checkout
    rec = pool._do_get()
  File "/usr/local/lib/python3.13/site-packages/sqlalchemy/pool/impl.py", line 179, in _do_get
    with util.safe_reraise():
         ~~~~~~~~~~~~~~~~~^^
  File "/usr/local/lib/python3.13/site-packages/sqlalchemy/util/langhelpers.py", line 224, in __exit__
    raise exc_value.with_traceback(exc_tb)
  File "/usr/local/lib/python3.13/site-packages/sqlalchemy/pool/impl.py", line 177, in _do_get
    return self._create_connection()
           ~~~~~~~~~~~~~~~~~~~~~~~^^
  File "/usr/local/lib/python3.13/site-packages/sqlalchemy/pool/base.py", line 390, in _create_connection
    return _ConnectionRecord(self)
  File "/usr/local/lib/python3.13/site-packages/sqlalchemy/pool/base.py", line 675, in __init__
    self.__connect()
    ~~~~~~~~~~~~~~^^
  File "/usr/local/lib/python3.13/site-packages/sqlalchemy/pool/base.py", line 901, in __connect
    with util.safe_reraise():
         ~~~~~~~~~~~~~~~~~^^
  File "/usr/local/lib/python3.13/site-packages/sqlalchemy/util/langhelpers.py", line 224, in __exit__
    raise exc_value.with_traceback(exc_tb)
  File "/usr/local/lib/python3.13/site-packages/sqlalchemy/pool/base.py", line 897, in __connect
    self.dbapi_connection = connection = pool._invoke_creator(self)
                                         ~~~~~~~~~~~~~~~~~~~~^^^^^^
  File "/usr/local/lib/python3.13/site-packages/sqlalchemy/engine/create.py", line 646, in connect
    return dialect.connect(*cargs, **cparams)
           ~~~~~~~~~~~~~~~^^^^^^^^^^^^^^^^^^^
  File "/usr/local/lib/python3.13/site-packages/sqlalchemy/engine/default.py", line 625, in connect
    return self.loaded_dbapi.connect(*cargs, **cparams)  # type: ignore[no-any-return]  # NOQA: E501
           ~~~~~~~~~~~~~~~~~~~~~~~~~^^^^^^^^^^^^^^^^^^^
  File "/usr/local/lib/python3.13/site-packages/psycopg2/__init__.py", line 122, in connect
    conn = _connect(dsn, connection_factory=connection_factory, **kwasync)
sqlalchemy.exc.OperationalError: (psycopg2.OperationalError) connection to server at "172.21.0.3", port 5432 failed: Connection refused
	Is the server running on that host and accepting TCP/IP connections?

(Background on this error at: https://sqlalche.me/e/20/e3q8)
2025-09-10 22:20:30.579 ERROR (Recorder) [homeassistant.components.recorder.core] Error during connection setup: (retrying in 3 seconds)
Traceback (most recent call last):
  File "/usr/local/lib/python3.13/site-packages/sqlalchemy/engine/base.py", line 145, in __init__
    self._dbapi_connection = engine.raw_connection()
                             ~~~~~~~~~~~~~~~~~~~~~^^
  File "/usr/local/lib/python3.13/site-packages/sqlalchemy/engine/base.py", line 3297, in raw_connection
    return self.pool.connect()
           ~~~~~~~~~~~~~~~~~^^
  File "/usr/local/lib/python3.13/site-packages/sqlalchemy/pool/base.py", line 449, in connect
    return _ConnectionFairy._checkout(self)
           ~~~~~~~~~~~~~~~~~~~~~~~~~~^^^^^^
  File "/usr/local/lib/python3.13/site-packages/sqlalchemy/pool/base.py", line 1264, in _checkout
    fairy = _ConnectionRecord.checkout(pool)
  File "/usr/local/lib/python3.13/site-packages/sqlalchemy/pool/base.py", line 713, in checkout
    rec = pool._do_get()
  File "/usr/local/lib/python3.13/site-packages/sqlalchemy/pool/impl.py", line 179, in _do_get
    with util.safe_reraise():
         ~~~~~~~~~~~~~~~~~^^
  File "/usr/local/lib/python3.13/site-packages/sqlalchemy/util/langhelpers.py", line 224, in __exit__
    raise exc_value.with_traceback(exc_tb)
  File "/usr/local/lib/python3.13/site-packages/sqlalchemy/pool/impl.py", line 177, in _do_get
    return self._create_connection()
           ~~~~~~~~~~~~~~~~~~~~~~~^^
  File "/usr/local/lib/python3.13/site-packages/sqlalchemy/pool/base.py", line 390, in _create_connection
    return _ConnectionRecord(self)
  File "/usr/local/lib/python3.13/site-packages/sqlalchemy/pool/base.py", line 675, in __init__
    self.__connect()
    ~~~~~~~~~~~~~~^^
  File "/usr/local/lib/python3.13/site-packages/sqlalchemy/pool/base.py", line 901, in __connect
    with util.safe_reraise():
         ~~~~~~~~~~~~~~~~~^^
  File "/usr/local/lib/python3.13/site-packages/sqlalchemy/util/langhelpers.py", line 224, in __exit__
    raise exc_value.with_traceback(exc_tb)
  File "/usr/local/lib/python3.13/site-packages/sqlalchemy/pool/base.py", line 897, in __connect
    self.dbapi_connection = connection = pool._invoke_creator(self)
                                         ~~~~~~~~~~~~~~~~~~~~^^^^^^
  File "/usr/local/lib/python3.13/site-packages/sqlalchemy/engine/create.py", line 646, in connect
    return dialect.connect(*cargs, **cparams)
           ~~~~~~~~~~~~~~~^^^^^^^^^^^^^^^^^^^
  File "/usr/local/lib/python3.13/site-packages/sqlalchemy/engine/default.py", line 625, in connect
    return self.loaded_dbapi.connect(*cargs, **cparams)  # type: ignore[no-any-return]  # NOQA: E501
           ~~~~~~~~~~~~~~~~~~~~~~~~~^^^^^^^^^^^^^^^^^^^
  File "/usr/local/lib/python3.13/site-packages/psycopg2/__init__.py", line 122, in connect
    conn = _connect(dsn, connection_factory=connection_factory, **kwasync)
psycopg2.OperationalError: connection to server at "172.21.0.3", port 5432 failed: Connection refused
	Is the server running on that host and accepting TCP/IP connections?


The above exception was the direct cause of the following exception:

Traceback (most recent call last):
  File "/usr/src/homeassistant/homeassistant/components/recorder/core.py", line 927, in _setup_recorder
    self._setup_connection()
    ~~~~~~~~~~~~~~~~~~~~~~^^
  File "/usr/src/homeassistant/homeassistant/components/recorder/core.py", line 1448, in _setup_connection
    migration.pre_migrate_schema(self.engine)
    ~~~~~~~~~~~~~~~~~~~~~~~~~~~~^^^^^^^^^^^^^
  File "/usr/src/homeassistant/homeassistant/components/recorder/migration.py", line 331, in pre_migrate_schema
    inspector = sqlalchemy.inspect(engine)
  File "/usr/local/lib/python3.13/site-packages/sqlalchemy/inspection.py", line 140, in inspect
    ret = reg(subject)
  File "/usr/local/lib/python3.13/site-packages/sqlalchemy/engine/reflection.py", line 313, in _engine_insp
    return Inspector._construct(Inspector._init_engine, bind)
           ~~~~~~~~~~~~~~~~~~~~^^^^^^^^^^^^^^^^^^^^^^^^^^^^^^
  File "/usr/local/lib/python3.13/site-packages/sqlalchemy/engine/reflection.py", line 246, in _construct
    init(self, bind)
    ~~~~^^^^^^^^^^^^
  File "/usr/local/lib/python3.13/site-packages/sqlalchemy/engine/reflection.py", line 257, in _init_engine
    engine.connect().close()
    ~~~~~~~~~~~~~~^^
  File "/usr/local/lib/python3.13/site-packages/sqlalchemy/engine/base.py", line 3273, in connect
    return self._connection_cls(self)
           ~~~~~~~~~~~~~~~~~~~~^^^^^^
  File "/usr/local/lib/python3.13/site-packages/sqlalchemy/engine/base.py", line 147, in __init__
    Connection._handle_dbapi_exception_noconnection(
    ~~~~~~~~~~~~~~~~~~~~~~~~~~~~~~~~~~~~~~~~~~~~~~~^
        err, dialect, engine
        ^^^^^^^^^^^^^^^^^^^^
    )
    ^
  File "/usr/local/lib/python3.13/site-packages/sqlalchemy/engine/base.py", line 2436, in _handle_dbapi_exception_noconnection
    raise sqlalchemy_exception.with_traceback(exc_info[2]) from e
  File "/usr/local/lib/python3.13/site-packages/sqlalchemy/engine/base.py", line 145, in __init__
    self._dbapi_connection = engine.raw_connection()
                             ~~~~~~~~~~~~~~~~~~~~~^^
  File "/usr/local/lib/python3.13/site-packages/sqlalchemy/engine/base.py", line 3297, in raw_connection
    return self.pool.connect()
           ~~~~~~~~~~~~~~~~~^^
  File "/usr/local/lib/python3.13/site-packages/sqlalchemy/pool/base.py", line 449, in connect
    return _ConnectionFairy._checkout(self)
           ~~~~~~~~~~~~~~~~~~~~~~~~~~^^^^^^
  File "/usr/local/lib/python3.13/site-packages/sqlalchemy/pool/base.py", line 1264, in _checkout
    fairy = _ConnectionRecord.checkout(pool)
  File "/usr/local/lib/python3.13/site-packages/sqlalchemy/pool/base.py", line 713, in checkout
    rec = pool._do_get()
  File "/usr/local/lib/python3.13/site-packages/sqlalchemy/pool/impl.py", line 179, in _do_get
    with util.safe_reraise():
         ~~~~~~~~~~~~~~~~~^^
  File "/usr/local/lib/python3.13/site-packages/sqlalchemy/util/langhelpers.py", line 224, in __exit__
    raise exc_value.with_traceback(exc_tb)
  File "/usr/local/lib/python3.13/site-packages/sqlalchemy/pool/impl.py", line 177, in _do_get
    return self._create_connection()
           ~~~~~~~~~~~~~~~~~~~~~~~^^
  File "/usr/local/lib/python3.13/site-packages/sqlalchemy/pool/base.py", line 390, in _create_connection
    return _ConnectionRecord(self)
  File "/usr/local/lib/python3.13/site-packages/sqlalchemy/pool/base.py", line 675, in __init__
    self.__connect()
    ~~~~~~~~~~~~~~^^
  File "/usr/local/lib/python3.13/site-packages/sqlalchemy/pool/base.py", line 901, in __connect
    with util.safe_reraise():
         ~~~~~~~~~~~~~~~~~^^
  File "/usr/local/lib/python3.13/site-packages/sqlalchemy/util/langhelpers.py", line 224, in __exit__
    raise exc_value.with_traceback(exc_tb)
  File "/usr/local/lib/python3.13/site-packages/sqlalchemy/pool/base.py", line 897, in __connect
    self.dbapi_connection = connection = pool._invoke_creator(self)
                                         ~~~~~~~~~~~~~~~~~~~~^^^^^^
  File "/usr/local/lib/python3.13/site-packages/sqlalchemy/engine/create.py", line 646, in connect
    return dialect.connect(*cargs, **cparams)
           ~~~~~~~~~~~~~~~^^^^^^^^^^^^^^^^^^^
  File "/usr/local/lib/python3.13/site-packages/sqlalchemy/engine/default.py", line 625, in connect
    return self.loaded_dbapi.connect(*cargs, **cparams)  # type: ignore[no-any-return]  # NOQA: E501
           ~~~~~~~~~~~~~~~~~~~~~~~~~^^^^^^^^^^^^^^^^^^^
  File "/usr/local/lib/python3.13/site-packages/psycopg2/__init__.py", line 122, in connect
    conn = _connect(dsn, connection_factory=connection_factory, **kwasync)
sqlalchemy.exc.OperationalError: (psycopg2.OperationalError) connection to server at "172.21.0.3", port 5432 failed: Connection refused
	Is the server running on that host and accepting TCP/IP connections?

(Background on this error at: https://sqlalche.me/e/20/e3q8)
2025-09-10 22:20:31.529 WARNING (MainThread) [homeassistant.setup] Setup of recorder is taking over 10 seconds.
2025-09-10 22:20:33.585 ERROR (Recorder) [homeassistant.components.recorder.core] Error during connection setup: (retrying in 3 seconds)
Traceback (most recent call last):
  File "/usr/local/lib/python3.13/site-packages/sqlalchemy/engine/base.py", line 145, in __init__
    self._dbapi_connection = engine.raw_connection()
                             ~~~~~~~~~~~~~~~~~~~~~^^
  File "/usr/local/lib/python3.13/site-packages/sqlalchemy/engine/base.py", line 3297, in raw_connection
    return self.pool.connect()
           ~~~~~~~~~~~~~~~~~^^
  File "/usr/local/lib/python3.13/site-packages/sqlalchemy/pool/base.py", line 449, in connect
    return _ConnectionFairy._checkout(self)
           ~~~~~~~~~~~~~~~~~~~~~~~~~~^^^^^^
  File "/usr/local/lib/python3.13/site-packages/sqlalchemy/pool/base.py", line 1264, in _checkout
    fairy = _ConnectionRecord.checkout(pool)
  File "/usr/local/lib/python3.13/site-packages/sqlalchemy/pool/base.py", line 713, in checkout
    rec = pool._do_get()
  File "/usr/local/lib/python3.13/site-packages/sqlalchemy/pool/impl.py", line 179, in _do_get
    with util.safe_reraise():
         ~~~~~~~~~~~~~~~~~^^
  File "/usr/local/lib/python3.13/site-packages/sqlalchemy/util/langhelpers.py", line 224, in __exit__
    raise exc_value.with_traceback(exc_tb)
  File "/usr/local/lib/python3.13/site-packages/sqlalchemy/pool/impl.py", line 177, in _do_get
    return self._create_connection()
           ~~~~~~~~~~~~~~~~~~~~~~~^^
  File "/usr/local/lib/python3.13/site-packages/sqlalchemy/pool/base.py", line 390, in _create_connection
    return _ConnectionRecord(self)
  File "/usr/local/lib/python3.13/site-packages/sqlalchemy/pool/base.py", line 675, in __init__
    self.__connect()
    ~~~~~~~~~~~~~~^^
  File "/usr/local/lib/python3.13/site-packages/sqlalchemy/pool/base.py", line 901, in __connect
    with util.safe_reraise():
         ~~~~~~~~~~~~~~~~~^^
  File "/usr/local/lib/python3.13/site-packages/sqlalchemy/util/langhelpers.py", line 224, in __exit__
    raise exc_value.with_traceback(exc_tb)
  File "/usr/local/lib/python3.13/site-packages/sqlalchemy/pool/base.py", line 897, in __connect
    self.dbapi_connection = connection = pool._invoke_creator(self)
                                         ~~~~~~~~~~~~~~~~~~~~^^^^^^
  File "/usr/local/lib/python3.13/site-packages/sqlalchemy/engine/create.py", line 646, in connect
    return dialect.connect(*cargs, **cparams)
           ~~~~~~~~~~~~~~~^^^^^^^^^^^^^^^^^^^
  File "/usr/local/lib/python3.13/site-packages/sqlalchemy/engine/default.py", line 625, in connect
    return self.loaded_dbapi.connect(*cargs, **cparams)  # type: ignore[no-any-return]  # NOQA: E501
           ~~~~~~~~~~~~~~~~~~~~~~~~~^^^^^^^^^^^^^^^^^^^
  File "/usr/local/lib/python3.13/site-packages/psycopg2/__init__.py", line 122, in connect
    conn = _connect(dsn, connection_factory=connection_factory, **kwasync)
psycopg2.OperationalError: connection to server at "172.21.0.3", port 5432 failed: Connection refused
	Is the server running on that host and accepting TCP/IP connections?


The above exception was the direct cause of the following exception:

Traceback (most recent call last):
  File "/usr/src/homeassistant/homeassistant/components/recorder/core.py", line 927, in _setup_recorder
    self._setup_connection()
    ~~~~~~~~~~~~~~~~~~~~~~^^
  File "/usr/src/homeassistant/homeassistant/components/recorder/core.py", line 1448, in _setup_connection
    migration.pre_migrate_schema(self.engine)
    ~~~~~~~~~~~~~~~~~~~~~~~~~~~~^^^^^^^^^^^^^
  File "/usr/src/homeassistant/homeassistant/components/recorder/migration.py", line 331, in pre_migrate_schema
    inspector = sqlalchemy.inspect(engine)
  File "/usr/local/lib/python3.13/site-packages/sqlalchemy/inspection.py", line 140, in inspect
    ret = reg(subject)
  File "/usr/local/lib/python3.13/site-packages/sqlalchemy/engine/reflection.py", line 313, in _engine_insp
    return Inspector._construct(Inspector._init_engine, bind)
           ~~~~~~~~~~~~~~~~~~~~^^^^^^^^^^^^^^^^^^^^^^^^^^^^^^
  File "/usr/local/lib/python3.13/site-packages/sqlalchemy/engine/reflection.py", line 246, in _construct
    init(self, bind)
    ~~~~^^^^^^^^^^^^
  File "/usr/local/lib/python3.13/site-packages/sqlalchemy/engine/reflection.py", line 257, in _init_engine
    engine.connect().close()
    ~~~~~~~~~~~~~~^^
  File "/usr/local/lib/python3.13/site-packages/sqlalchemy/engine/base.py", line 3273, in connect
    return self._connection_cls(self)
           ~~~~~~~~~~~~~~~~~~~~^^^^^^
  File "/usr/local/lib/python3.13/site-packages/sqlalchemy/engine/base.py", line 147, in __init__
    Connection._handle_dbapi_exception_noconnection(
    ~~~~~~~~~~~~~~~~~~~~~~~~~~~~~~~~~~~~~~~~~~~~~~~^
        err, dialect, engine
        ^^^^^^^^^^^^^^^^^^^^
    )
    ^
  File "/usr/local/lib/python3.13/site-packages/sqlalchemy/engine/base.py", line 2436, in _handle_dbapi_exception_noconnection
    raise sqlalchemy_exception.with_traceback(exc_info[2]) from e
  File "/usr/local/lib/python3.13/site-packages/sqlalchemy/engine/base.py", line 145, in __init__
    self._dbapi_connection = engine.raw_connection()
                             ~~~~~~~~~~~~~~~~~~~~~^^
  File "/usr/local/lib/python3.13/site-packages/sqlalchemy/engine/base.py", line 3297, in raw_connection
    return self.pool.connect()
           ~~~~~~~~~~~~~~~~~^^
  File "/usr/local/lib/python3.13/site-packages/sqlalchemy/pool/base.py", line 449, in connect
    return _ConnectionFairy._checkout(self)
           ~~~~~~~~~~~~~~~~~~~~~~~~~~^^^^^^
  File "/usr/local/lib/python3.13/site-packages/sqlalchemy/pool/base.py", line 1264, in _checkout
    fairy = _ConnectionRecord.checkout(pool)
  File "/usr/local/lib/python3.13/site-packages/sqlalchemy/pool/base.py", line 713, in checkout
    rec = pool._do_get()
  File "/usr/local/lib/python3.13/site-packages/sqlalchemy/pool/impl.py", line 179, in _do_get
    with util.safe_reraise():
         ~~~~~~~~~~~~~~~~~^^
  File "/usr/local/lib/python3.13/site-packages/sqlalchemy/util/langhelpers.py", line 224, in __exit__
    raise exc_value.with_traceback(exc_tb)
  File "/usr/local/lib/python3.13/site-packages/sqlalchemy/pool/impl.py", line 177, in _do_get
    return self._create_connection()
           ~~~~~~~~~~~~~~~~~~~~~~~^^
  File "/usr/local/lib/python3.13/site-packages/sqlalchemy/pool/base.py", line 390, in _create_connection
    return _ConnectionRecord(self)
  File "/usr/local/lib/python3.13/site-packages/sqlalchemy/pool/base.py", line 675, in __init__
    self.__connect()
    ~~~~~~~~~~~~~~^^
  File "/usr/local/lib/python3.13/site-packages/sqlalchemy/pool/base.py", line 901, in __connect
    with util.safe_reraise():
         ~~~~~~~~~~~~~~~~~^^
  File "/usr/local/lib/python3.13/site-packages/sqlalchemy/util/langhelpers.py", line 224, in __exit__
    raise exc_value.with_traceback(exc_tb)
  File "/usr/local/lib/python3.13/site-packages/sqlalchemy/pool/base.py", line 897, in __connect
    self.dbapi_connection = connection = pool._invoke_creator(self)
                                         ~~~~~~~~~~~~~~~~~~~~^^^^^^
  File "/usr/local/lib/python3.13/site-packages/sqlalchemy/engine/create.py", line 646, in connect
    return dialect.connect(*cargs, **cparams)
           ~~~~~~~~~~~~~~~^^^^^^^^^^^^^^^^^^^
  File "/usr/local/lib/python3.13/site-packages/sqlalchemy/engine/default.py", line 625, in connect
    return self.loaded_dbapi.connect(*cargs, **cparams)  # type: ignore[no-any-return]  # NOQA: E501
           ~~~~~~~~~~~~~~~~~~~~~~~~~^^^^^^^^^^^^^^^^^^^
  File "/usr/local/lib/python3.13/site-packages/psycopg2/__init__.py", line 122, in connect
    conn = _connect(dsn, connection_factory=connection_factory, **kwasync)
sqlalchemy.exc.OperationalError: (psycopg2.OperationalError) connection to server at "172.21.0.3", port 5432 failed: Connection refused
	Is the server running on that host and accepting TCP/IP connections?

(Background on this error at: https://sqlalche.me/e/20/e3q8)
2025-09-10 22:20:36.591 ERROR (Recorder) [homeassistant.components.recorder.core] Error during connection setup: (retrying in 3 seconds)
Traceback (most recent call last):
  File "/usr/local/lib/python3.13/site-packages/sqlalchemy/engine/base.py", line 145, in __init__
    self._dbapi_connection = engine.raw_connection()
                             ~~~~~~~~~~~~~~~~~~~~~^^
  File "/usr/local/lib/python3.13/site-packages/sqlalchemy/engine/base.py", line 3297, in raw_connection
    return self.pool.connect()
           ~~~~~~~~~~~~~~~~~^^
  File "/usr/local/lib/python3.13/site-packages/sqlalchemy/pool/base.py", line 449, in connect
    return _ConnectionFairy._checkout(self)
           ~~~~~~~~~~~~~~~~~~~~~~~~~~^^^^^^
  File "/usr/local/lib/python3.13/site-packages/sqlalchemy/pool/base.py", line 1264, in _checkout
    fairy = _ConnectionRecord.checkout(pool)
  File "/usr/local/lib/python3.13/site-packages/sqlalchemy/pool/base.py", line 713, in checkout
    rec = pool._do_get()
  File "/usr/local/lib/python3.13/site-packages/sqlalchemy/pool/impl.py", line 179, in _do_get
    with util.safe_reraise():
         ~~~~~~~~~~~~~~~~~^^
  File "/usr/local/lib/python3.13/site-packages/sqlalchemy/util/langhelpers.py", line 224, in __exit__
    raise exc_value.with_traceback(exc_tb)
  File "/usr/local/lib/python3.13/site-packages/sqlalchemy/pool/impl.py", line 177, in _do_get
    return self._create_connection()
           ~~~~~~~~~~~~~~~~~~~~~~~^^
  File "/usr/local/lib/python3.13/site-packages/sqlalchemy/pool/base.py", line 390, in _create_connection
    return _ConnectionRecord(self)
  File "/usr/local/lib/python3.13/site-packages/sqlalchemy/pool/base.py", line 675, in __init__
    self.__connect()
    ~~~~~~~~~~~~~~^^
  File "/usr/local/lib/python3.13/site-packages/sqlalchemy/pool/base.py", line 901, in __connect
    with util.safe_reraise():
         ~~~~~~~~~~~~~~~~~^^
  File "/usr/local/lib/python3.13/site-packages/sqlalchemy/util/langhelpers.py", line 224, in __exit__
    raise exc_value.with_traceback(exc_tb)
  File "/usr/local/lib/python3.13/site-packages/sqlalchemy/pool/base.py", line 897, in __connect
    self.dbapi_connection = connection = pool._invoke_creator(self)
                                         ~~~~~~~~~~~~~~~~~~~~^^^^^^
  File "/usr/local/lib/python3.13/site-packages/sqlalchemy/engine/create.py", line 646, in connect
    return dialect.connect(*cargs, **cparams)
           ~~~~~~~~~~~~~~~^^^^^^^^^^^^^^^^^^^
  File "/usr/local/lib/python3.13/site-packages/sqlalchemy/engine/default.py", line 625, in connect
    return self.loaded_dbapi.connect(*cargs, **cparams)  # type: ignore[no-any-return]  # NOQA: E501
           ~~~~~~~~~~~~~~~~~~~~~~~~~^^^^^^^^^^^^^^^^^^^
  File "/usr/local/lib/python3.13/site-packages/psycopg2/__init__.py", line 122, in connect
    conn = _connect(dsn, connection_factory=connection_factory, **kwasync)
psycopg2.OperationalError: connection to server at "172.21.0.3", port 5432 failed: Connection refused
	Is the server running on that host and accepting TCP/IP connections?


The above exception was the direct cause of the following exception:

Traceback (most recent call last):
  File "/usr/src/homeassistant/homeassistant/components/recorder/core.py", line 927, in _setup_recorder
    self._setup_connection()
    ~~~~~~~~~~~~~~~~~~~~~~^^
  File "/usr/src/homeassistant/homeassistant/components/recorder/core.py", line 1448, in _setup_connection
    migration.pre_migrate_schema(self.engine)
    ~~~~~~~~~~~~~~~~~~~~~~~~~~~~^^^^^^^^^^^^^
  File "/usr/src/homeassistant/homeassistant/components/recorder/migration.py", line 331, in pre_migrate_schema
    inspector = sqlalchemy.inspect(engine)
  File "/usr/local/lib/python3.13/site-packages/sqlalchemy/inspection.py", line 140, in inspect
    ret = reg(subject)
  File "/usr/local/lib/python3.13/site-packages/sqlalchemy/engine/reflection.py", line 313, in _engine_insp
    return Inspector._construct(Inspector._init_engine, bind)
           ~~~~~~~~~~~~~~~~~~~~^^^^^^^^^^^^^^^^^^^^^^^^^^^^^^
  File "/usr/local/lib/python3.13/site-packages/sqlalchemy/engine/reflection.py", line 246, in _construct
    init(self, bind)
    ~~~~^^^^^^^^^^^^
  File "/usr/local/lib/python3.13/site-packages/sqlalchemy/engine/reflection.py", line 257, in _init_engine
    engine.connect().close()
    ~~~~~~~~~~~~~~^^
  File "/usr/local/lib/python3.13/site-packages/sqlalchemy/engine/base.py", line 3273, in connect
    return self._connection_cls(self)
           ~~~~~~~~~~~~~~~~~~~~^^^^^^
  File "/usr/local/lib/python3.13/site-packages/sqlalchemy/engine/base.py", line 147, in __init__
    Connection._handle_dbapi_exception_noconnection(
    ~~~~~~~~~~~~~~~~~~~~~~~~~~~~~~~~~~~~~~~~~~~~~~~^
        err, dialect, engine
        ^^^^^^^^^^^^^^^^^^^^
    )
    ^
  File "/usr/local/lib/python3.13/site-packages/sqlalchemy/engine/base.py", line 2436, in _handle_dbapi_exception_noconnection
    raise sqlalchemy_exception.with_traceback(exc_info[2]) from e
  File "/usr/local/lib/python3.13/site-packages/sqlalchemy/engine/base.py", line 145, in __init__
    self._dbapi_connection = engine.raw_connection()
                             ~~~~~~~~~~~~~~~~~~~~~^^
  File "/usr/local/lib/python3.13/site-packages/sqlalchemy/engine/base.py", line 3297, in raw_connection
    return self.pool.connect()
           ~~~~~~~~~~~~~~~~~^^
  File "/usr/local/lib/python3.13/site-packages/sqlalchemy/pool/base.py", line 449, in connect
    return _ConnectionFairy._checkout(self)
           ~~~~~~~~~~~~~~~~~~~~~~~~~~^^^^^^
  File "/usr/local/lib/python3.13/site-packages/sqlalchemy/pool/base.py", line 1264, in _checkout
    fairy = _ConnectionRecord.checkout(pool)
  File "/usr/local/lib/python3.13/site-packages/sqlalchemy/pool/base.py", line 713, in checkout
    rec = pool._do_get()
  File "/usr/local/lib/python3.13/site-packages/sqlalchemy/pool/impl.py", line 179, in _do_get
    with util.safe_reraise():
         ~~~~~~~~~~~~~~~~~^^
  File "/usr/local/lib/python3.13/site-packages/sqlalchemy/util/langhelpers.py", line 224, in __exit__
    raise exc_value.with_traceback(exc_tb)
  File "/usr/local/lib/python3.13/site-packages/sqlalchemy/pool/impl.py", line 177, in _do_get
    return self._create_connection()
           ~~~~~~~~~~~~~~~~~~~~~~~^^
  File "/usr/local/lib/python3.13/site-packages/sqlalchemy/pool/base.py", line 390, in _create_connection
    return _ConnectionRecord(self)
  File "/usr/local/lib/python3.13/site-packages/sqlalchemy/pool/base.py", line 675, in __init__
    self.__connect()
    ~~~~~~~~~~~~~~^^
  File "/usr/local/lib/python3.13/site-packages/sqlalchemy/pool/base.py", line 901, in __connect
    with util.safe_reraise():
         ~~~~~~~~~~~~~~~~~^^
  File "/usr/local/lib/python3.13/site-packages/sqlalchemy/util/langhelpers.py", line 224, in __exit__
    raise exc_value.with_traceback(exc_tb)
  File "/usr/local/lib/python3.13/site-packages/sqlalchemy/pool/base.py", line 897, in __connect
    self.dbapi_connection = connection = pool._invoke_creator(self)
                                         ~~~~~~~~~~~~~~~~~~~~^^^^^^
  File "/usr/local/lib/python3.13/site-packages/sqlalchemy/engine/create.py", line 646, in connect
    return dialect.connect(*cargs, **cparams)
           ~~~~~~~~~~~~~~~^^^^^^^^^^^^^^^^^^^
  File "/usr/local/lib/python3.13/site-packages/sqlalchemy/engine/default.py", line 625, in connect
    return self.loaded_dbapi.connect(*cargs, **cparams)  # type: ignore[no-any-return]  # NOQA: E501
           ~~~~~~~~~~~~~~~~~~~~~~~~~^^^^^^^^^^^^^^^^^^^
  File "/usr/local/lib/python3.13/site-packages/psycopg2/__init__.py", line 122, in connect
    conn = _connect(dsn, connection_factory=connection_factory, **kwasync)
sqlalchemy.exc.OperationalError: (psycopg2.OperationalError) connection to server at "172.21.0.3", port 5432 failed: Connection refused
	Is the server running on that host and accepting TCP/IP connections?

(Background on this error at: https://sqlalche.me/e/20/e3q8)
2025-09-10 22:20:39.598 ERROR (Recorder) [homeassistant.components.recorder.core] Error during connection setup: (retrying in 3 seconds)
Traceback (most recent call last):
  File "/usr/local/lib/python3.13/site-packages/sqlalchemy/engine/base.py", line 145, in __init__
    self._dbapi_connection = engine.raw_connection()
                             ~~~~~~~~~~~~~~~~~~~~~^^
  File "/usr/local/lib/python3.13/site-packages/sqlalchemy/engine/base.py", line 3297, in raw_connection
    return self.pool.connect()
           ~~~~~~~~~~~~~~~~~^^
  File "/usr/local/lib/python3.13/site-packages/sqlalchemy/pool/base.py", line 449, in connect
    return _ConnectionFairy._checkout(self)
           ~~~~~~~~~~~~~~~~~~~~~~~~~~^^^^^^
  File "/usr/local/lib/python3.13/site-packages/sqlalchemy/pool/base.py", line 1264, in _checkout
    fairy = _ConnectionRecord.checkout(pool)
  File "/usr/local/lib/python3.13/site-packages/sqlalchemy/pool/base.py", line 713, in checkout
    rec = pool._do_get()
  File "/usr/local/lib/python3.13/site-packages/sqlalchemy/pool/impl.py", line 179, in _do_get
    with util.safe_reraise():
         ~~~~~~~~~~~~~~~~~^^
  File "/usr/local/lib/python3.13/site-packages/sqlalchemy/util/langhelpers.py", line 224, in __exit__
    raise exc_value.with_traceback(exc_tb)
  File "/usr/local/lib/python3.13/site-packages/sqlalchemy/pool/impl.py", line 177, in _do_get
    return self._create_connection()
           ~~~~~~~~~~~~~~~~~~~~~~~^^
  File "/usr/local/lib/python3.13/site-packages/sqlalchemy/pool/base.py", line 390, in _create_connection
    return _ConnectionRecord(self)
  File "/usr/local/lib/python3.13/site-packages/sqlalchemy/pool/base.py", line 675, in __init__
    self.__connect()
    ~~~~~~~~~~~~~~^^
  File "/usr/local/lib/python3.13/site-packages/sqlalchemy/pool/base.py", line 901, in __connect
    with util.safe_reraise():
         ~~~~~~~~~~~~~~~~~^^
  File "/usr/local/lib/python3.13/site-packages/sqlalchemy/util/langhelpers.py", line 224, in __exit__
    raise exc_value.with_traceback(exc_tb)
  File "/usr/local/lib/python3.13/site-packages/sqlalchemy/pool/base.py", line 897, in __connect
    self.dbapi_connection = connection = pool._invoke_creator(self)
                                         ~~~~~~~~~~~~~~~~~~~~^^^^^^
  File "/usr/local/lib/python3.13/site-packages/sqlalchemy/engine/create.py", line 646, in connect
    return dialect.connect(*cargs, **cparams)
           ~~~~~~~~~~~~~~~^^^^^^^^^^^^^^^^^^^
  File "/usr/local/lib/python3.13/site-packages/sqlalchemy/engine/default.py", line 625, in connect
    return self.loaded_dbapi.connect(*cargs, **cparams)  # type: ignore[no-any-return]  # NOQA: E501
           ~~~~~~~~~~~~~~~~~~~~~~~~~^^^^^^^^^^^^^^^^^^^
  File "/usr/local/lib/python3.13/site-packages/psycopg2/__init__.py", line 122, in connect
    conn = _connect(dsn, connection_factory=connection_factory, **kwasync)
psycopg2.OperationalError: connection to server at "172.21.0.3", port 5432 failed: Connection refused
	Is the server running on that host and accepting TCP/IP connections?


The above exception was the direct cause of the following exception:

Traceback (most recent call last):
  File "/usr/src/homeassistant/homeassistant/components/recorder/core.py", line 927, in _setup_recorder
    self._setup_connection()
    ~~~~~~~~~~~~~~~~~~~~~~^^
  File "/usr/src/homeassistant/homeassistant/components/recorder/core.py", line 1448, in _setup_connection
    migration.pre_migrate_schema(self.engine)
    ~~~~~~~~~~~~~~~~~~~~~~~~~~~~^^^^^^^^^^^^^
  File "/usr/src/homeassistant/homeassistant/components/recorder/migration.py", line 331, in pre_migrate_schema
    inspector = sqlalchemy.inspect(engine)
  File "/usr/local/lib/python3.13/site-packages/sqlalchemy/inspection.py", line 140, in inspect
    ret = reg(subject)
  File "/usr/local/lib/python3.13/site-packages/sqlalchemy/engine/reflection.py", line 313, in _engine_insp
    return Inspector._construct(Inspector._init_engine, bind)
           ~~~~~~~~~~~~~~~~~~~~^^^^^^^^^^^^^^^^^^^^^^^^^^^^^^
  File "/usr/local/lib/python3.13/site-packages/sqlalchemy/engine/reflection.py", line 246, in _construct
    init(self, bind)
    ~~~~^^^^^^^^^^^^
  File "/usr/local/lib/python3.13/site-packages/sqlalchemy/engine/reflection.py", line 257, in _init_engine
    engine.connect().close()
    ~~~~~~~~~~~~~~^^
  File "/usr/local/lib/python3.13/site-packages/sqlalchemy/engine/base.py", line 3273, in connect
    return self._connection_cls(self)
           ~~~~~~~~~~~~~~~~~~~~^^^^^^
  File "/usr/local/lib/python3.13/site-packages/sqlalchemy/engine/base.py", line 147, in __init__
    Connection._handle_dbapi_exception_noconnection(
    ~~~~~~~~~~~~~~~~~~~~~~~~~~~~~~~~~~~~~~~~~~~~~~~^
        err, dialect, engine
        ^^^^^^^^^^^^^^^^^^^^
    )
    ^
  File "/usr/local/lib/python3.13/site-packages/sqlalchemy/engine/base.py", line 2436, in _handle_dbapi_exception_noconnection
    raise sqlalchemy_exception.with_traceback(exc_info[2]) from e
  File "/usr/local/lib/python3.13/site-packages/sqlalchemy/engine/base.py", line 145, in __init__
    self._dbapi_connection = engine.raw_connection()
                             ~~~~~~~~~~~~~~~~~~~~~^^
  File "/usr/local/lib/python3.13/site-packages/sqlalchemy/engine/base.py", line 3297, in raw_connection
    return self.pool.connect()
           ~~~~~~~~~~~~~~~~~^^
  File "/usr/local/lib/python3.13/site-packages/sqlalchemy/pool/base.py", line 449, in connect
    return _ConnectionFairy._checkout(self)
           ~~~~~~~~~~~~~~~~~~~~~~~~~~^^^^^^
  File "/usr/local/lib/python3.13/site-packages/sqlalchemy/pool/base.py", line 1264, in _checkout
    fairy = _ConnectionRecord.checkout(pool)
  File "/usr/local/lib/python3.13/site-packages/sqlalchemy/pool/base.py", line 713, in checkout
    rec = pool._do_get()
  File "/usr/local/lib/python3.13/site-packages/sqlalchemy/pool/impl.py", line 179, in _do_get
    with util.safe_reraise():
         ~~~~~~~~~~~~~~~~~^^
  File "/usr/local/lib/python3.13/site-packages/sqlalchemy/util/langhelpers.py", line 224, in __exit__
    raise exc_value.with_traceback(exc_tb)
  File "/usr/local/lib/python3.13/site-packages/sqlalchemy/pool/impl.py", line 177, in _do_get
    return self._create_connection()
           ~~~~~~~~~~~~~~~~~~~~~~~^^
  File "/usr/local/lib/python3.13/site-packages/sqlalchemy/pool/base.py", line 390, in _create_connection
    return _ConnectionRecord(self)
  File "/usr/local/lib/python3.13/site-packages/sqlalchemy/pool/base.py", line 675, in __init__
    self.__connect()
    ~~~~~~~~~~~~~~^^
  File "/usr/local/lib/python3.13/site-packages/sqlalchemy/pool/base.py", line 901, in __connect
    with util.safe_reraise():
         ~~~~~~~~~~~~~~~~~^^
  File "/usr/local/lib/python3.13/site-packages/sqlalchemy/util/langhelpers.py", line 224, in __exit__
    raise exc_value.with_traceback(exc_tb)
  File "/usr/local/lib/python3.13/site-packages/sqlalchemy/pool/base.py", line 897, in __connect
    self.dbapi_connection = connection = pool._invoke_creator(self)
                                         ~~~~~~~~~~~~~~~~~~~~^^^^^^
  File "/usr/local/lib/python3.13/site-packages/sqlalchemy/engine/create.py", line 646, in connect
    return dialect.connect(*cargs, **cparams)
           ~~~~~~~~~~~~~~~^^^^^^^^^^^^^^^^^^^
  File "/usr/local/lib/python3.13/site-packages/sqlalchemy/engine/default.py", line 625, in connect
    return self.loaded_dbapi.connect(*cargs, **cparams)  # type: ignore[no-any-return]  # NOQA: E501
           ~~~~~~~~~~~~~~~~~~~~~~~~~^^^^^^^^^^^^^^^^^^^
  File "/usr/local/lib/python3.13/site-packages/psycopg2/__init__.py", line 122, in connect
    conn = _connect(dsn, connection_factory=connection_factory, **kwasync)
sqlalchemy.exc.OperationalError: (psycopg2.OperationalError) connection to server at "172.21.0.3", port 5432 failed: Connection refused
	Is the server running on that host and accepting TCP/IP connections?

(Background on this error at: https://sqlalche.me/e/20/e3q8)
2025-09-10 22:20:42.605 ERROR (Recorder) [homeassistant.components.recorder.core] Error during connection setup: (retrying in 3 seconds)
Traceback (most recent call last):
  File "/usr/local/lib/python3.13/site-packages/sqlalchemy/engine/base.py", line 145, in __init__
    self._dbapi_connection = engine.raw_connection()
                             ~~~~~~~~~~~~~~~~~~~~~^^
  File "/usr/local/lib/python3.13/site-packages/sqlalchemy/engine/base.py", line 3297, in raw_connection
    return self.pool.connect()
           ~~~~~~~~~~~~~~~~~^^
  File "/usr/local/lib/python3.13/site-packages/sqlalchemy/pool/base.py", line 449, in connect
    return _ConnectionFairy._checkout(self)
           ~~~~~~~~~~~~~~~~~~~~~~~~~~^^^^^^
  File "/usr/local/lib/python3.13/site-packages/sqlalchemy/pool/base.py", line 1264, in _checkout
    fairy = _ConnectionRecord.checkout(pool)
  File "/usr/local/lib/python3.13/site-packages/sqlalchemy/pool/base.py", line 713, in checkout
    rec = pool._do_get()
  File "/usr/local/lib/python3.13/site-packages/sqlalchemy/pool/impl.py", line 179, in _do_get
    with util.safe_reraise():
         ~~~~~~~~~~~~~~~~~^^
  File "/usr/local/lib/python3.13/site-packages/sqlalchemy/util/langhelpers.py", line 224, in __exit__
    raise exc_value.with_traceback(exc_tb)
  File "/usr/local/lib/python3.13/site-packages/sqlalchemy/pool/impl.py", line 177, in _do_get
    return self._create_connection()
           ~~~~~~~~~~~~~~~~~~~~~~~^^
  File "/usr/local/lib/python3.13/site-packages/sqlalchemy/pool/base.py", line 390, in _create_connection
    return _ConnectionRecord(self)
  File "/usr/local/lib/python3.13/site-packages/sqlalchemy/pool/base.py", line 675, in __init__
    self.__connect()
    ~~~~~~~~~~~~~~^^
  File "/usr/local/lib/python3.13/site-packages/sqlalchemy/pool/base.py", line 901, in __connect
    with util.safe_reraise():
         ~~~~~~~~~~~~~~~~~^^
  File "/usr/local/lib/python3.13/site-packages/sqlalchemy/util/langhelpers.py", line 224, in __exit__
    raise exc_value.with_traceback(exc_tb)
  File "/usr/local/lib/python3.13/site-packages/sqlalchemy/pool/base.py", line 897, in __connect
    self.dbapi_connection = connection = pool._invoke_creator(self)
                                         ~~~~~~~~~~~~~~~~~~~~^^^^^^
  File "/usr/local/lib/python3.13/site-packages/sqlalchemy/engine/create.py", line 646, in connect
    return dialect.connect(*cargs, **cparams)
           ~~~~~~~~~~~~~~~^^^^^^^^^^^^^^^^^^^
  File "/usr/local/lib/python3.13/site-packages/sqlalchemy/engine/default.py", line 625, in connect
    return self.loaded_dbapi.connect(*cargs, **cparams)  # type: ignore[no-any-return]  # NOQA: E501
           ~~~~~~~~~~~~~~~~~~~~~~~~~^^^^^^^^^^^^^^^^^^^
  File "/usr/local/lib/python3.13/site-packages/psycopg2/__init__.py", line 122, in connect
    conn = _connect(dsn, connection_factory=connection_factory, **kwasync)
psycopg2.OperationalError: connection to server at "172.21.0.3", port 5432 failed: Connection refused
	Is the server running on that host and accepting TCP/IP connections?


The above exception was the direct cause of the following exception:

Traceback (most recent call last):
  File "/usr/src/homeassistant/homeassistant/components/recorder/core.py", line 927, in _setup_recorder
    self._setup_connection()
    ~~~~~~~~~~~~~~~~~~~~~~^^
  File "/usr/src/homeassistant/homeassistant/components/recorder/core.py", line 1448, in _setup_connection
    migration.pre_migrate_schema(self.engine)
    ~~~~~~~~~~~~~~~~~~~~~~~~~~~~^^^^^^^^^^^^^
  File "/usr/src/homeassistant/homeassistant/components/recorder/migration.py", line 331, in pre_migrate_schema
    inspector = sqlalchemy.inspect(engine)
  File "/usr/local/lib/python3.13/site-packages/sqlalchemy/inspection.py", line 140, in inspect
    ret = reg(subject)
  File "/usr/local/lib/python3.13/site-packages/sqlalchemy/engine/reflection.py", line 313, in _engine_insp
    return Inspector._construct(Inspector._init_engine, bind)
           ~~~~~~~~~~~~~~~~~~~~^^^^^^^^^^^^^^^^^^^^^^^^^^^^^^
  File "/usr/local/lib/python3.13/site-packages/sqlalchemy/engine/reflection.py", line 246, in _construct
    init(self, bind)
    ~~~~^^^^^^^^^^^^
  File "/usr/local/lib/python3.13/site-packages/sqlalchemy/engine/reflection.py", line 257, in _init_engine
    engine.connect().close()
    ~~~~~~~~~~~~~~^^
  File "/usr/local/lib/python3.13/site-packages/sqlalchemy/engine/base.py", line 3273, in connect
    return self._connection_cls(self)
           ~~~~~~~~~~~~~~~~~~~~^^^^^^
  File "/usr/local/lib/python3.13/site-packages/sqlalchemy/engine/base.py", line 147, in __init__
    Connection._handle_dbapi_exception_noconnection(
    ~~~~~~~~~~~~~~~~~~~~~~~~~~~~~~~~~~~~~~~~~~~~~~~^
        err, dialect, engine
        ^^^^^^^^^^^^^^^^^^^^
    )
    ^
  File "/usr/local/lib/python3.13/site-packages/sqlalchemy/engine/base.py", line 2436, in _handle_dbapi_exception_noconnection
    raise sqlalchemy_exception.with_traceback(exc_info[2]) from e
  File "/usr/local/lib/python3.13/site-packages/sqlalchemy/engine/base.py", line 145, in __init__
    self._dbapi_connection = engine.raw_connection()
                             ~~~~~~~~~~~~~~~~~~~~~^^
  File "/usr/local/lib/python3.13/site-packages/sqlalchemy/engine/base.py", line 3297, in raw_connection
    return self.pool.connect()
           ~~~~~~~~~~~~~~~~~^^
  File "/usr/local/lib/python3.13/site-packages/sqlalchemy/pool/base.py", line 449, in connect
    return _ConnectionFairy._checkout(self)
           ~~~~~~~~~~~~~~~~~~~~~~~~~~^^^^^^
  File "/usr/local/lib/python3.13/site-packages/sqlalchemy/pool/base.py", line 1264, in _checkout
    fairy = _ConnectionRecord.checkout(pool)
  File "/usr/local/lib/python3.13/site-packages/sqlalchemy/pool/base.py", line 713, in checkout
    rec = pool._do_get()
  File "/usr/local/lib/python3.13/site-packages/sqlalchemy/pool/impl.py", line 179, in _do_get
    with util.safe_reraise():
         ~~~~~~~~~~~~~~~~~^^
  File "/usr/local/lib/python3.13/site-packages/sqlalchemy/util/langhelpers.py", line 224, in __exit__
    raise exc_value.with_traceback(exc_tb)
  File "/usr/local/lib/python3.13/site-packages/sqlalchemy/pool/impl.py", line 177, in _do_get
    return self._create_connection()
           ~~~~~~~~~~~~~~~~~~~~~~~^^
  File "/usr/local/lib/python3.13/site-packages/sqlalchemy/pool/base.py", line 390, in _create_connection
    return _ConnectionRecord(self)
  File "/usr/local/lib/python3.13/site-packages/sqlalchemy/pool/base.py", line 675, in __init__
    self.__connect()
    ~~~~~~~~~~~~~~^^
  File "/usr/local/lib/python3.13/site-packages/sqlalchemy/pool/base.py", line 901, in __connect
    with util.safe_reraise():
         ~~~~~~~~~~~~~~~~~^^
  File "/usr/local/lib/python3.13/site-packages/sqlalchemy/util/langhelpers.py", line 224, in __exit__
    raise exc_value.with_traceback(exc_tb)
  File "/usr/local/lib/python3.13/site-packages/sqlalchemy/pool/base.py", line 897, in __connect
    self.dbapi_connection = connection = pool._invoke_creator(self)
                                         ~~~~~~~~~~~~~~~~~~~~^^^^^^
  File "/usr/local/lib/python3.13/site-packages/sqlalchemy/engine/create.py", line 646, in connect
    return dialect.connect(*cargs, **cparams)
           ~~~~~~~~~~~~~~~^^^^^^^^^^^^^^^^^^^
  File "/usr/local/lib/python3.13/site-packages/sqlalchemy/engine/default.py", line 625, in connect
    return self.loaded_dbapi.connect(*cargs, **cparams)  # type: ignore[no-any-return]  # NOQA: E501
           ~~~~~~~~~~~~~~~~~~~~~~~~~^^^^^^^^^^^^^^^^^^^
  File "/usr/local/lib/python3.13/site-packages/psycopg2/__init__.py", line 122, in connect
    conn = _connect(dsn, connection_factory=connection_factory, **kwasync)
sqlalchemy.exc.OperationalError: (psycopg2.OperationalError) connection to server at "172.21.0.3", port 5432 failed: Connection refused
	Is the server running on that host and accepting TCP/IP connections?

(Background on this error at: https://sqlalche.me/e/20/e3q8)
2025-09-10 22:20:45.726 ERROR (Recorder) [homeassistant.components.recorder.core] Error during connection setup: (retrying in 3 seconds)
Traceback (most recent call last):
  File "/usr/local/lib/python3.13/site-packages/sqlalchemy/engine/base.py", line 145, in __init__
    self._dbapi_connection = engine.raw_connection()
                             ~~~~~~~~~~~~~~~~~~~~~^^
  File "/usr/local/lib/python3.13/site-packages/sqlalchemy/engine/base.py", line 3297, in raw_connection
    return self.pool.connect()
           ~~~~~~~~~~~~~~~~~^^
  File "/usr/local/lib/python3.13/site-packages/sqlalchemy/pool/base.py", line 449, in connect
    return _ConnectionFairy._checkout(self)
           ~~~~~~~~~~~~~~~~~~~~~~~~~~^^^^^^
  File "/usr/local/lib/python3.13/site-packages/sqlalchemy/pool/base.py", line 1264, in _checkout
    fairy = _ConnectionRecord.checkout(pool)
  File "/usr/local/lib/python3.13/site-packages/sqlalchemy/pool/base.py", line 713, in checkout
    rec = pool._do_get()
  File "/usr/local/lib/python3.13/site-packages/sqlalchemy/pool/impl.py", line 179, in _do_get
    with util.safe_reraise():
         ~~~~~~~~~~~~~~~~~^^
  File "/usr/local/lib/python3.13/site-packages/sqlalchemy/util/langhelpers.py", line 224, in __exit__
    raise exc_value.with_traceback(exc_tb)
  File "/usr/local/lib/python3.13/site-packages/sqlalchemy/pool/impl.py", line 177, in _do_get
    return self._create_connection()
           ~~~~~~~~~~~~~~~~~~~~~~~^^
  File "/usr/local/lib/python3.13/site-packages/sqlalchemy/pool/base.py", line 390, in _create_connection
    return _ConnectionRecord(self)
  File "/usr/local/lib/python3.13/site-packages/sqlalchemy/pool/base.py", line 675, in __init__
    self.__connect()
    ~~~~~~~~~~~~~~^^
  File "/usr/local/lib/python3.13/site-packages/sqlalchemy/pool/base.py", line 901, in __connect
    with util.safe_reraise():
         ~~~~~~~~~~~~~~~~~^^
  File "/usr/local/lib/python3.13/site-packages/sqlalchemy/util/langhelpers.py", line 224, in __exit__
    raise exc_value.with_traceback(exc_tb)
  File "/usr/local/lib/python3.13/site-packages/sqlalchemy/pool/base.py", line 897, in __connect
    self.dbapi_connection = connection = pool._invoke_creator(self)
                                         ~~~~~~~~~~~~~~~~~~~~^^^^^^
  File "/usr/local/lib/python3.13/site-packages/sqlalchemy/engine/create.py", line 646, in connect
    return dialect.connect(*cargs, **cparams)
           ~~~~~~~~~~~~~~~^^^^^^^^^^^^^^^^^^^
  File "/usr/local/lib/python3.13/site-packages/sqlalchemy/engine/default.py", line 625, in connect
    return self.loaded_dbapi.connect(*cargs, **cparams)  # type: ignore[no-any-return]  # NOQA: E501
           ~~~~~~~~~~~~~~~~~~~~~~~~~^^^^^^^^^^^^^^^^^^^
  File "/usr/local/lib/python3.13/site-packages/psycopg2/__init__.py", line 122, in connect
    conn = _connect(dsn, connection_factory=connection_factory, **kwasync)
psycopg2.OperationalError: connection to server at "172.21.0.3", port 5432 failed: Connection refused
	Is the server running on that host and accepting TCP/IP connections?


The above exception was the direct cause of the following exception:

Traceback (most recent call last):
  File "/usr/src/homeassistant/homeassistant/components/recorder/core.py", line 927, in _setup_recorder
    self._setup_connection()
    ~~~~~~~~~~~~~~~~~~~~~~^^
  File "/usr/src/homeassistant/homeassistant/components/recorder/core.py", line 1448, in _setup_connection
    migration.pre_migrate_schema(self.engine)
    ~~~~~~~~~~~~~~~~~~~~~~~~~~~~^^^^^^^^^^^^^
  File "/usr/src/homeassistant/homeassistant/components/recorder/migration.py", line 331, in pre_migrate_schema
    inspector = sqlalchemy.inspect(engine)
  File "/usr/local/lib/python3.13/site-packages/sqlalchemy/inspection.py", line 140, in inspect
    ret = reg(subject)
  File "/usr/local/lib/python3.13/site-packages/sqlalchemy/engine/reflection.py", line 313, in _engine_insp
    return Inspector._construct(Inspector._init_engine, bind)
           ~~~~~~~~~~~~~~~~~~~~^^^^^^^^^^^^^^^^^^^^^^^^^^^^^^
  File "/usr/local/lib/python3.13/site-packages/sqlalchemy/engine/reflection.py", line 246, in _construct
    init(self, bind)
    ~~~~^^^^^^^^^^^^
  File "/usr/local/lib/python3.13/site-packages/sqlalchemy/engine/reflection.py", line 257, in _init_engine
    engine.connect().close()
    ~~~~~~~~~~~~~~^^
  File "/usr/local/lib/python3.13/site-packages/sqlalchemy/engine/base.py", line 3273, in connect
    return self._connection_cls(self)
           ~~~~~~~~~~~~~~~~~~~~^^^^^^
  File "/usr/local/lib/python3.13/site-packages/sqlalchemy/engine/base.py", line 147, in __init__
    Connection._handle_dbapi_exception_noconnection(
    ~~~~~~~~~~~~~~~~~~~~~~~~~~~~~~~~~~~~~~~~~~~~~~~^
        err, dialect, engine
        ^^^^^^^^^^^^^^^^^^^^
    )
    ^
  File "/usr/local/lib/python3.13/site-packages/sqlalchemy/engine/base.py", line 2436, in _handle_dbapi_exception_noconnection
    raise sqlalchemy_exception.with_traceback(exc_info[2]) from e
  File "/usr/local/lib/python3.13/site-packages/sqlalchemy/engine/base.py", line 145, in __init__
    self._dbapi_connection = engine.raw_connection()
                             ~~~~~~~~~~~~~~~~~~~~~^^
  File "/usr/local/lib/python3.13/site-packages/sqlalchemy/engine/base.py", line 3297, in raw_connection
    return self.pool.connect()
           ~~~~~~~~~~~~~~~~~^^
  File "/usr/local/lib/python3.13/site-packages/sqlalchemy/pool/base.py", line 449, in connect
    return _ConnectionFairy._checkout(self)
           ~~~~~~~~~~~~~~~~~~~~~~~~~~^^^^^^
  File "/usr/local/lib/python3.13/site-packages/sqlalchemy/pool/base.py", line 1264, in _checkout
    fairy = _ConnectionRecord.checkout(pool)
  File "/usr/local/lib/python3.13/site-packages/sqlalchemy/pool/base.py", line 713, in checkout
    rec = pool._do_get()
  File "/usr/local/lib/python3.13/site-packages/sqlalchemy/pool/impl.py", line 179, in _do_get
    with util.safe_reraise():
         ~~~~~~~~~~~~~~~~~^^
  File "/usr/local/lib/python3.13/site-packages/sqlalchemy/util/langhelpers.py", line 224, in __exit__
    raise exc_value.with_traceback(exc_tb)
  File "/usr/local/lib/python3.13/site-packages/sqlalchemy/pool/impl.py", line 177, in _do_get
    return self._create_connection()
           ~~~~~~~~~~~~~~~~~~~~~~~^^
  File "/usr/local/lib/python3.13/site-packages/sqlalchemy/pool/base.py", line 390, in _create_connection
    return _ConnectionRecord(self)
  File "/usr/local/lib/python3.13/site-packages/sqlalchemy/pool/base.py", line 675, in __init__
    self.__connect()
    ~~~~~~~~~~~~~~^^
  File "/usr/local/lib/python3.13/site-packages/sqlalchemy/pool/base.py", line 901, in __connect
    with util.safe_reraise():
         ~~~~~~~~~~~~~~~~~^^
  File "/usr/local/lib/python3.13/site-packages/sqlalchemy/util/langhelpers.py", line 224, in __exit__
    raise exc_value.with_traceback(exc_tb)
  File "/usr/local/lib/python3.13/site-packages/sqlalchemy/pool/base.py", line 897, in __connect
    self.dbapi_connection = connection = pool._invoke_creator(self)
                                         ~~~~~~~~~~~~~~~~~~~~^^^^^^
  File "/usr/local/lib/python3.13/site-packages/sqlalchemy/engine/create.py", line 646, in connect
    return dialect.connect(*cargs, **cparams)
           ~~~~~~~~~~~~~~~^^^^^^^^^^^^^^^^^^^
  File "/usr/local/lib/python3.13/site-packages/sqlalchemy/engine/default.py", line 625, in connect
    return self.loaded_dbapi.connect(*cargs, **cparams)  # type: ignore[no-any-return]  # NOQA: E501
           ~~~~~~~~~~~~~~~~~~~~~~~~~^^^^^^^^^^^^^^^^^^^
  File "/usr/local/lib/python3.13/site-packages/psycopg2/__init__.py", line 122, in connect
    conn = _connect(dsn, connection_factory=connection_factory, **kwasync)
sqlalchemy.exc.OperationalError: (psycopg2.OperationalError) connection to server at "172.21.0.3", port 5432 failed: Connection refused
	Is the server running on that host and accepting TCP/IP connections?

(Background on this error at: https://sqlalche.me/e/20/e3q8)
2025-09-10 22:20:48.733 ERROR (Recorder) [homeassistant.components.recorder.core] Error during connection setup: (retrying in 3 seconds)
Traceback (most recent call last):
  File "/usr/local/lib/python3.13/site-packages/sqlalchemy/engine/base.py", line 145, in __init__
    self._dbapi_connection = engine.raw_connection()
                             ~~~~~~~~~~~~~~~~~~~~~^^
  File "/usr/local/lib/python3.13/site-packages/sqlalchemy/engine/base.py", line 3297, in raw_connection
    return self.pool.connect()
           ~~~~~~~~~~~~~~~~~^^
  File "/usr/local/lib/python3.13/site-packages/sqlalchemy/pool/base.py", line 449, in connect
    return _ConnectionFairy._checkout(self)
           ~~~~~~~~~~~~~~~~~~~~~~~~~~^^^^^^
  File "/usr/local/lib/python3.13/site-packages/sqlalchemy/pool/base.py", line 1264, in _checkout
    fairy = _ConnectionRecord.checkout(pool)
  File "/usr/local/lib/python3.13/site-packages/sqlalchemy/pool/base.py", line 713, in checkout
    rec = pool._do_get()
  File "/usr/local/lib/python3.13/site-packages/sqlalchemy/pool/impl.py", line 179, in _do_get
    with util.safe_reraise():
         ~~~~~~~~~~~~~~~~~^^
  File "/usr/local/lib/python3.13/site-packages/sqlalchemy/util/langhelpers.py", line 224, in __exit__
    raise exc_value.with_traceback(exc_tb)
  File "/usr/local/lib/python3.13/site-packages/sqlalchemy/pool/impl.py", line 177, in _do_get
    return self._create_connection()
           ~~~~~~~~~~~~~~~~~~~~~~~^^
  File "/usr/local/lib/python3.13/site-packages/sqlalchemy/pool/base.py", line 390, in _create_connection
    return _ConnectionRecord(self)
  File "/usr/local/lib/python3.13/site-packages/sqlalchemy/pool/base.py", line 675, in __init__
    self.__connect()
    ~~~~~~~~~~~~~~^^
  File "/usr/local/lib/python3.13/site-packages/sqlalchemy/pool/base.py", line 901, in __connect
    with util.safe_reraise():
         ~~~~~~~~~~~~~~~~~^^
  File "/usr/local/lib/python3.13/site-packages/sqlalchemy/util/langhelpers.py", line 224, in __exit__
    raise exc_value.with_traceback(exc_tb)
  File "/usr/local/lib/python3.13/site-packages/sqlalchemy/pool/base.py", line 897, in __connect
    self.dbapi_connection = connection = pool._invoke_creator(self)
                                         ~~~~~~~~~~~~~~~~~~~~^^^^^^
  File "/usr/local/lib/python3.13/site-packages/sqlalchemy/engine/create.py", line 646, in connect
    return dialect.connect(*cargs, **cparams)
           ~~~~~~~~~~~~~~~^^^^^^^^^^^^^^^^^^^
  File "/usr/local/lib/python3.13/site-packages/sqlalchemy/engine/default.py", line 625, in connect
    return self.loaded_dbapi.connect(*cargs, **cparams)  # type: ignore[no-any-return]  # NOQA: E501
           ~~~~~~~~~~~~~~~~~~~~~~~~~^^^^^^^^^^^^^^^^^^^
  File "/usr/local/lib/python3.13/site-packages/psycopg2/__init__.py", line 122, in connect
    conn = _connect(dsn, connection_factory=connection_factory, **kwasync)
psycopg2.OperationalError: connection to server at "172.21.0.3", port 5432 failed: Connection refused
	Is the server running on that host and accepting TCP/IP connections?


The above exception was the direct cause of the following exception:

Traceback (most recent call last):
  File "/usr/src/homeassistant/homeassistant/components/recorder/core.py", line 927, in _setup_recorder
    self._setup_connection()
    ~~~~~~~~~~~~~~~~~~~~~~^^
  File "/usr/src/homeassistant/homeassistant/components/recorder/core.py", line 1448, in _setup_connection
    migration.pre_migrate_schema(self.engine)
    ~~~~~~~~~~~~~~~~~~~~~~~~~~~~^^^^^^^^^^^^^
  File "/usr/src/homeassistant/homeassistant/components/recorder/migration.py", line 331, in pre_migrate_schema
    inspector = sqlalchemy.inspect(engine)
  File "/usr/local/lib/python3.13/site-packages/sqlalchemy/inspection.py", line 140, in inspect
    ret = reg(subject)
  File "/usr/local/lib/python3.13/site-packages/sqlalchemy/engine/reflection.py", line 313, in _engine_insp
    return Inspector._construct(Inspector._init_engine, bind)
           ~~~~~~~~~~~~~~~~~~~~^^^^^^^^^^^^^^^^^^^^^^^^^^^^^^
  File "/usr/local/lib/python3.13/site-packages/sqlalchemy/engine/reflection.py", line 246, in _construct
    init(self, bind)
    ~~~~^^^^^^^^^^^^
  File "/usr/local/lib/python3.13/site-packages/sqlalchemy/engine/reflection.py", line 257, in _init_engine
    engine.connect().close()
    ~~~~~~~~~~~~~~^^
  File "/usr/local/lib/python3.13/site-packages/sqlalchemy/engine/base.py", line 3273, in connect
    return self._connection_cls(self)
           ~~~~~~~~~~~~~~~~~~~~^^^^^^
  File "/usr/local/lib/python3.13/site-packages/sqlalchemy/engine/base.py", line 147, in __init__
    Connection._handle_dbapi_exception_noconnection(
    ~~~~~~~~~~~~~~~~~~~~~~~~~~~~~~~~~~~~~~~~~~~~~~~^
        err, dialect, engine
        ^^^^^^^^^^^^^^^^^^^^
    )
    ^
  File "/usr/local/lib/python3.13/site-packages/sqlalchemy/engine/base.py", line 2436, in _handle_dbapi_exception_noconnection
    raise sqlalchemy_exception.with_traceback(exc_info[2]) from e
  File "/usr/local/lib/python3.13/site-packages/sqlalchemy/engine/base.py", line 145, in __init__
    self._dbapi_connection = engine.raw_connection()
                             ~~~~~~~~~~~~~~~~~~~~~^^
  File "/usr/local/lib/python3.13/site-packages/sqlalchemy/engine/base.py", line 3297, in raw_connection
    return self.pool.connect()
           ~~~~~~~~~~~~~~~~~^^
  File "/usr/local/lib/python3.13/site-packages/sqlalchemy/pool/base.py", line 449, in connect
    return _ConnectionFairy._checkout(self)
           ~~~~~~~~~~~~~~~~~~~~~~~~~~^^^^^^
  File "/usr/local/lib/python3.13/site-packages/sqlalchemy/pool/base.py", line 1264, in _checkout
    fairy = _ConnectionRecord.checkout(pool)
  File "/usr/local/lib/python3.13/site-packages/sqlalchemy/pool/base.py", line 713, in checkout
    rec = pool._do_get()
  File "/usr/local/lib/python3.13/site-packages/sqlalchemy/pool/impl.py", line 179, in _do_get
    with util.safe_reraise():
         ~~~~~~~~~~~~~~~~~^^
  File "/usr/local/lib/python3.13/site-packages/sqlalchemy/util/langhelpers.py", line 224, in __exit__
    raise exc_value.with_traceback(exc_tb)
  File "/usr/local/lib/python3.13/site-packages/sqlalchemy/pool/impl.py", line 177, in _do_get
    return self._create_connection()
           ~~~~~~~~~~~~~~~~~~~~~~~^^
  File "/usr/local/lib/python3.13/site-packages/sqlalchemy/pool/base.py", line 390, in _create_connection
    return _ConnectionRecord(self)
  File "/usr/local/lib/python3.13/site-packages/sqlalchemy/pool/base.py", line 675, in __init__
    self.__connect()
    ~~~~~~~~~~~~~~^^
  File "/usr/local/lib/python3.13/site-packages/sqlalchemy/pool/base.py", line 901, in __connect
    with util.safe_reraise():
         ~~~~~~~~~~~~~~~~~^^
  File "/usr/local/lib/python3.13/site-packages/sqlalchemy/util/langhelpers.py", line 224, in __exit__
    raise exc_value.with_traceback(exc_tb)
  File "/usr/local/lib/python3.13/site-packages/sqlalchemy/pool/base.py", line 897, in __connect
    self.dbapi_connection = connection = pool._invoke_creator(self)
                                         ~~~~~~~~~~~~~~~~~~~~^^^^^^
  File "/usr/local/lib/python3.13/site-packages/sqlalchemy/engine/create.py", line 646, in connect
    return dialect.connect(*cargs, **cparams)
           ~~~~~~~~~~~~~~~^^^^^^^^^^^^^^^^^^^
  File "/usr/local/lib/python3.13/site-packages/sqlalchemy/engine/default.py", line 625, in connect
    return self.loaded_dbapi.connect(*cargs, **cparams)  # type: ignore[no-any-return]  # NOQA: E501
           ~~~~~~~~~~~~~~~~~~~~~~~~~^^^^^^^^^^^^^^^^^^^
  File "/usr/local/lib/python3.13/site-packages/psycopg2/__init__.py", line 122, in connect
    conn = _connect(dsn, connection_factory=connection_factory, **kwasync)
sqlalchemy.exc.OperationalError: (psycopg2.OperationalError) connection to server at "172.21.0.3", port 5432 failed: Connection refused
	Is the server running on that host and accepting TCP/IP connections?

(Background on this error at: https://sqlalche.me/e/20/e3q8)
2025-09-10 22:20:48.738 ERROR (Recorder) [homeassistant.components.recorder.core] Recorder setup failed, recorder shutting down
2025-09-10 22:20:48.739 ERROR (MainThread) [homeassistant.setup] Setup failed for 'recorder': Integration failed to initialize.
2025-09-10 22:20:48.739 INFO (MainThread) [homeassistant.setup] Setup of domain recorder took 27.10 seconds
2025-09-10 22:20:48.739 INFO (MainThread) [homeassistant.bootstrap] Nothing to set up in stage debugger: {'debugpy'}
2025-09-10 22:20:48.739 INFO (MainThread) [homeassistant.bootstrap] Setting up stage zeroconf: {'zeroconf'}; already set up: {}
Dependencies: {}; already set up: {'network', 'http', 'api', 'websocket_api'}
2025-09-10 22:20:48.739 INFO (MainThread) [homeassistant.setup] Setting up zeroconf
2025-09-10 22:20:48.740 INFO (MainThread) [homeassistant.components.zeroconf] Starting Zeroconf broadcast
2025-09-10 22:20:48.741 INFO (MainThread) [homeassistant.setup] Setup of domain zeroconf took 0.00 seconds
2025-09-10 22:20:48.741 INFO (MainThread) [homeassistant.bootstrap] Setting up stage 1: {'ssdp'}; already set up: {}
Dependencies: {}; already set up: {'network', 'http', 'websocket_api'}
2025-09-10 22:20:48.761 INFO (MainThread) [homeassistant.setup] Setting up ssdp
2025-09-10 22:20:48.763 INFO (MainThread) [homeassistant.setup] Setup of domain ssdp took 0.00 seconds
2025-09-10 22:20:48.763 INFO (MainThread) [homeassistant.bootstrap] Setting up stage 2: {'input_text', 'analytics', 'group', 'media_source', 'input_datetime', 'automation', 'input_select', 'script', 'hardware', 'backup', 'history', 'binary_sensor', 'person', 'scene', 'tts', 'mqtt', 'input_number', 'tag', 'input_boolean', 'logbook', 'system_health', 'application_credentials', 'timer', 'schedule', 'recorder', 'zone', 'sonos', 'input_button', 'counter'}; already set up: {'homeassistant', 'api', 'logger', 'frontend', 'network', 'ssdp', 'zeroconf', 'http'}
Dependencies: {'image_upload', 'ffmpeg', 'trace', 'blueprint'}; already set up: {'websocket_api', 'system_log', 'diagnostics', 'api', 'onboarding', 'ssdp', 'search', 'repairs', 'http', 'config', 'auth', 'network', 'file_upload', 'frontend', 'zeroconf', 'device_automation', 'lovelace'}
2025-09-10 22:20:48.763 INFO (MainThread) [homeassistant.setup] Setting up binary_sensor
2025-09-10 22:20:48.764 INFO (MainThread) [homeassistant.setup] Setup of domain binary_sensor took 0.00 seconds
2025-09-10 22:20:48.764 INFO (MainThread) [homeassistant.setup] Setting up scene
2025-09-10 22:20:48.764 INFO (MainThread) [homeassistant.components.scene] Setting up homeassistant.scene
2025-09-10 22:20:48.765 INFO (MainThread) [homeassistant.setup] Setup of domain scene took 0.00 seconds
2025-09-10 22:20:48.765 INFO (MainThread) [homeassistant.setup] Setting up group
2025-09-10 22:20:48.765 INFO (MainThread) [homeassistant.setup] Setup of domain group took 0.00 seconds
2025-09-10 22:20:48.766 INFO (MainThread) [homeassistant.setup] Setting up input_number
2025-09-10 22:20:48.766 INFO (MainThread) [homeassistant.setup] Setup of domain input_number took 0.00 seconds
2025-09-10 22:20:48.766 INFO (MainThread) [homeassistant.setup] Setting up blueprint
2025-09-10 22:20:48.766 INFO (MainThread) [homeassistant.setup] Setup of domain blueprint took 0.00 seconds
2025-09-10 22:20:48.767 INFO (MainThread) [homeassistant.setup] Setting up trace
2025-09-10 22:20:48.767 INFO (MainThread) [homeassistant.setup] Setup of domain trace took 0.00 seconds
2025-09-10 22:20:48.771 ERROR (MainThread) [homeassistant.setup] Unable to set up dependencies of 'logbook'. Setup failed for dependencies: ['recorder']
2025-09-10 22:20:48.772 ERROR (MainThread) [homeassistant.setup] Setup failed for 'logbook': Could not setup dependencies: recorder
2025-09-10 22:20:48.772 INFO (MainThread) [homeassistant.setup] Setting up system_health
2025-09-10 22:20:48.772 INFO (MainThread) [homeassistant.setup] Setup of domain system_health took 0.00 seconds
2025-09-10 22:20:48.772 INFO (MainThread) [homeassistant.setup] Setting up script
2025-09-10 22:20:48.772 INFO (MainThread) [homeassistant.setup] Setup of domain script took 0.00 seconds
2025-09-10 22:20:48.772 INFO (MainThread) [homeassistant.setup] Setting up image_upload
2025-09-10 22:20:48.773 INFO (MainThread) [homeassistant.setup] Setup of domain image_upload took 0.00 seconds
2025-09-10 22:20:48.773 INFO (MainThread) [homeassistant.setup] Setting up backup
2025-09-10 22:20:48.773 ERROR (MainThread) [homeassistant.setup] Unable to set up dependencies of 'history'. Setup failed for dependencies: ['recorder']
2025-09-10 22:20:48.774 ERROR (MainThread) [homeassistant.setup] Setup failed for 'history': Could not setup dependencies: recorder
2025-09-10 22:20:48.774 INFO (MainThread) [homeassistant.setup] Setting up zone
2025-09-10 22:20:48.775 INFO (MainThread) [homeassistant.setup] Setup of domain zone took 0.00 seconds
2025-09-10 22:20:48.775 INFO (MainThread) [homeassistant.setup] Setting up person
2025-09-10 22:20:48.776 INFO (MainThread) [homeassistant.setup] Setup of domain person took 0.00 seconds
2025-09-10 22:20:48.778 INFO (MainThread) [homeassistant.setup] Setup of domain backup took 0.00 seconds
2025-09-10 22:20:48.782 INFO (MainThread) [homeassistant.setup] Setting up ffmpeg
2025-09-10 22:20:48.782 INFO (MainThread) [homeassistant.setup] Setup of domain ffmpeg took 0.00 seconds
2025-09-10 22:20:48.784 INFO (MainThread) [homeassistant.setup] Setting up input_text
2025-09-10 22:20:48.785 INFO (MainThread) [homeassistant.setup] Setup of domain input_text took 0.00 seconds
2025-09-10 22:20:48.794 INFO (MainThread) [homeassistant.setup] Setting up analytics
2025-09-10 22:20:48.795 INFO (MainThread) [homeassistant.setup] Setup of domain analytics took 0.00 seconds
2025-09-10 22:20:48.818 INFO (MainThread) [homeassistant.setup] Setting up mqtt
2025-09-10 22:20:48.819 INFO (MainThread) [homeassistant.setup] Setup of domain mqtt took 0.00 seconds
2025-09-10 22:20:48.823 INFO (MainThread) [homeassistant.setup] Setting up media_source
2025-09-10 22:20:48.824 INFO (MainThread) [homeassistant.setup] Setup of domain media_source took 0.00 seconds
2025-09-10 22:20:48.828 INFO (MainThread) [homeassistant.setup] Setting up tag
2025-09-10 22:20:48.828 INFO (MainThread) [homeassistant.setup] Setup of domain tag took 0.00 seconds
2025-09-10 22:20:48.830 INFO (MainThread) [homeassistant.setup] Setting up input_boolean
2025-09-10 22:20:48.831 INFO (MainThread) [homeassistant.setup] Setup of domain input_boolean took 0.00 seconds
2025-09-10 22:20:48.832 INFO (MainThread) [homeassistant.setup] Setting up input_datetime
2025-09-10 22:20:48.833 INFO (MainThread) [homeassistant.setup] Setup of domain input_datetime took 0.00 seconds
2025-09-10 22:20:48.846 INFO (MainThread) [homeassistant.setup] Setting up input_select
2025-09-10 22:20:48.847 INFO (MainThread) [homeassistant.setup] Setup of domain input_select took 0.00 seconds
2025-09-10 22:20:48.849 INFO (MainThread) [homeassistant.setup] Setting up application_credentials
2025-09-10 22:20:48.850 INFO (MainThread) [homeassistant.setup] Setup of domain application_credentials took 0.00 seconds
2025-09-10 22:20:48.854 INFO (MainThread) [homeassistant.setup] Setting up hardware
2025-09-10 22:20:48.856 INFO (MainThread) [homeassistant.setup] Setting up timer
2025-09-10 22:20:48.857 INFO (MainThread) [homeassistant.setup] Setup of domain timer took 0.00 seconds
2025-09-10 22:20:48.866 INFO (MainThread) [homeassistant.setup] Setting up schedule
2025-09-10 22:20:48.867 INFO (MainThread) [homeassistant.setup] Setup of domain schedule took 0.00 seconds
2025-09-10 22:20:48.874 INFO (MainThread) [homeassistant.setup] Setting up input_button
2025-09-10 22:20:48.875 INFO (MainThread) [homeassistant.setup] Setup of domain input_button took 0.00 seconds
2025-09-10 22:20:48.877 INFO (MainThread) [homeassistant.setup] Setting up counter
2025-09-10 22:20:48.878 INFO (MainThread) [homeassistant.setup] Setup of domain counter took 0.00 seconds
2025-09-10 22:20:48.879 INFO (MainThread) [homeassistant.setup] Setup of domain hardware took 0.02 seconds
2025-09-10 22:20:48.924 INFO (MainThread) [homeassistant.setup] Setting up sonos
2025-09-10 22:20:48.924 INFO (MainThread) [homeassistant.setup] Setup of domain sonos took 0.00 seconds
2025-09-10 22:20:48.926 INFO (MainThread) [homeassistant.setup] Setting up automation
2025-09-10 22:20:48.928 INFO (MainThread) [homeassistant.setup] Setup of domain automation took 0.00 seconds
2025-09-10 22:20:49.082 INFO (MainThread) [homeassistant.setup] Setting up event
2025-09-10 22:20:49.082 INFO (MainThread) [homeassistant.setup] Setup of domain event took 0.00 seconds
2025-09-10 22:20:49.083 INFO (MainThread) [homeassistant.setup] Setting up sensor
2025-09-10 22:20:49.083 INFO (MainThread) [homeassistant.setup] Setup of domain sensor took 0.00 seconds
2025-09-10 22:20:49.088 DEBUG (MainThread) [homeassistant.components.mqtt.client] mqtt: connection opened 24
2025-09-10 22:20:49.088 DEBUG (MainThread) [homeassistant.components.mqtt.client] mqtt: Starting client misc loop
2025-09-10 22:20:49.088 DEBUG (MainThread) [homeassistant.components.mqtt.client] mqtt: register write 24
2025-09-10 22:20:49.089 INFO (MainThread) [homeassistant.components.event] Setting up backup.event
2025-09-10 22:20:49.090 DEBUG (MainThread) [homeassistant.components.mqtt.client] mqtt: unregister write 24
2025-09-10 22:20:49.090 INFO (MainThread) [homeassistant.components.sensor] Setting up backup.sensor
2025-09-10 22:20:49.091 DEBUG (MainThread) [homeassistant.components.mqtt.client] Connected to MQTT server mqtt:1883 (Success)
2025-09-10 22:20:49.100 INFO (MainThread) [homeassistant.setup] Setting up tts
2025-09-10 22:20:49.104 INFO (MainThread) [homeassistant.setup] Setup of domain tts took 0.00 seconds
2025-09-10 22:20:49.458 INFO (MainThread) [homeassistant.setup] Setting up media_player
2025-09-10 22:20:49.554 INFO (MainThread) [homeassistant.setup] Setup of domain media_player took 0.10 seconds
2025-09-10 22:20:49.555 INFO (MainThread) [homeassistant.setup] Setting up number
2025-09-10 22:20:49.555 INFO (MainThread) [homeassistant.setup] Setup of domain number took 0.00 seconds
2025-09-10 22:20:49.555 INFO (MainThread) [homeassistant.setup] Setting up select
2025-09-10 22:20:49.556 INFO (MainThread) [homeassistant.setup] Setup of domain select took 0.00 seconds
2025-09-10 22:20:49.556 INFO (MainThread) [homeassistant.setup] Setting up switch
2025-09-10 22:20:49.557 INFO (MainThread) [homeassistant.setup] Setup of domain switch took 0.00 seconds
2025-09-10 22:20:49.559 INFO (MainThread) [homeassistant.components.binary_sensor] Setting up sonos.binary_sensor
2025-09-10 22:20:49.560 INFO (MainThread) [homeassistant.components.media_player] Setting up sonos.media_player
2025-09-10 22:20:49.562 INFO (MainThread) [homeassistant.components.number] Setting up sonos.number
2025-09-10 22:20:49.562 INFO (MainThread) [homeassistant.components.select] Setting up sonos.select
2025-09-10 22:20:49.563 INFO (MainThread) [homeassistant.components.sensor] Setting up sonos.sensor
2025-09-10 22:20:49.563 INFO (MainThread) [homeassistant.components.switch] Setting up sonos.switch
2025-09-10 22:20:49.592 DEBUG (MainThread) [homeassistant.components.mqtt.client] mqtt: register write 24
2025-09-10 22:20:49.592 DEBUG (MainThread) [homeassistant.components.mqtt.client] Subscribing with mid: 1 to topics with qos: [('homeassistant/alarm_control_panel/+/config', 0)]
2025-09-10 22:20:49.593 DEBUG (MainThread) [homeassistant.components.mqtt.client] mqtt: unregister write 24
2025-09-10 22:20:49.593 DEBUG (MainThread) [homeassistant.components.mqtt.client] mqtt: register write 24
2025-09-10 22:20:49.593 DEBUG (MainThread) [homeassistant.components.mqtt.client] Subscribing with mid: 2 to topics with qos: [('homeassistant/binary_sensor/+/config', 0)]
2025-09-10 22:20:49.593 DEBUG (MainThread) [homeassistant.components.mqtt.client] mqtt: unregister write 24
2025-09-10 22:20:49.594 DEBUG (MainThread) [homeassistant.components.mqtt.client] mqtt: register write 24
2025-09-10 22:20:49.594 DEBUG (MainThread) [homeassistant.components.mqtt.client] Subscribing with mid: 3 to topics with qos: [('homeassistant/button/+/config', 0)]
2025-09-10 22:20:49.594 DEBUG (MainThread) [homeassistant.components.mqtt.client] mqtt: unregister write 24
2025-09-10 22:20:49.594 DEBUG (MainThread) [homeassistant.components.mqtt.client] mqtt: register write 24
2025-09-10 22:20:49.594 DEBUG (MainThread) [homeassistant.components.mqtt.client] Subscribing with mid: 4 to topics with qos: [('homeassistant/camera/+/config', 0)]
2025-09-10 22:20:49.594 DEBUG (MainThread) [homeassistant.components.mqtt.client] mqtt: unregister write 24
2025-09-10 22:20:49.594 DEBUG (MainThread) [homeassistant.components.mqtt.client] mqtt: register write 24
2025-09-10 22:20:49.594 DEBUG (MainThread) [homeassistant.components.mqtt.client] Subscribing with mid: 5 to topics with qos: [('homeassistant/climate/+/config', 0)]
2025-09-10 22:20:49.594 DEBUG (MainThread) [homeassistant.components.mqtt.client] mqtt: unregister write 24
2025-09-10 22:20:49.594 DEBUG (MainThread) [homeassistant.components.mqtt.client] mqtt: register write 24
2025-09-10 22:20:49.594 DEBUG (MainThread) [homeassistant.components.mqtt.client] Subscribing with mid: 6 to topics with qos: [('homeassistant/cover/+/config', 0)]
2025-09-10 22:20:49.594 DEBUG (MainThread) [homeassistant.components.mqtt.client] mqtt: unregister write 24
2025-09-10 22:20:49.595 DEBUG (MainThread) [homeassistant.components.mqtt.client] mqtt: register write 24
2025-09-10 22:20:49.595 DEBUG (MainThread) [homeassistant.components.mqtt.client] Subscribing with mid: 7 to topics with qos: [('homeassistant/device_automation/+/config', 0)]
2025-09-10 22:20:49.595 DEBUG (MainThread) [homeassistant.components.mqtt.client] mqtt: unregister write 24
2025-09-10 22:20:49.595 DEBUG (MainThread) [homeassistant.components.mqtt.client] mqtt: register write 24
2025-09-10 22:20:49.595 DEBUG (MainThread) [homeassistant.components.mqtt.client] Subscribing with mid: 8 to topics with qos: [('homeassistant/device_tracker/+/config', 0)]
2025-09-10 22:20:49.595 DEBUG (MainThread) [homeassistant.components.mqtt.client] mqtt: unregister write 24
2025-09-10 22:20:49.595 DEBUG (MainThread) [homeassistant.components.mqtt.client] mqtt: register write 24
2025-09-10 22:20:49.595 DEBUG (MainThread) [homeassistant.components.mqtt.client] Subscribing with mid: 9 to topics with qos: [('homeassistant/event/+/config', 0)]
2025-09-10 22:20:49.595 DEBUG (MainThread) [homeassistant.components.mqtt.client] mqtt: unregister write 24
2025-09-10 22:20:49.595 DEBUG (MainThread) [homeassistant.components.mqtt.client] mqtt: register write 24
2025-09-10 22:20:49.595 DEBUG (MainThread) [homeassistant.components.mqtt.client] Subscribing with mid: 10 to topics with qos: [('homeassistant/fan/+/config', 0)]
2025-09-10 22:20:49.595 DEBUG (MainThread) [homeassistant.components.mqtt.client] mqtt: unregister write 24
2025-09-10 22:20:49.595 DEBUG (MainThread) [homeassistant.components.mqtt.client] mqtt: register write 24
2025-09-10 22:20:49.595 DEBUG (MainThread) [homeassistant.components.mqtt.client] Subscribing with mid: 11 to topics with qos: [('homeassistant/humidifier/+/config', 0)]
2025-09-10 22:20:49.596 DEBUG (MainThread) [homeassistant.components.mqtt.client] mqtt: unregister write 24
2025-09-10 22:20:49.596 DEBUG (MainThread) [homeassistant.components.mqtt.client] mqtt: register write 24
2025-09-10 22:20:49.596 DEBUG (MainThread) [homeassistant.components.mqtt.client] Subscribing with mid: 12 to topics with qos: [('homeassistant/image/+/config', 0)]
2025-09-10 22:20:49.596 DEBUG (MainThread) [homeassistant.components.mqtt.client] mqtt: unregister write 24
2025-09-10 22:20:49.596 DEBUG (MainThread) [homeassistant.components.mqtt.client] mqtt: register write 24
2025-09-10 22:20:49.596 DEBUG (MainThread) [homeassistant.components.mqtt.client] Subscribing with mid: 13 to topics with qos: [('homeassistant/lawn_mower/+/config', 0)]
2025-09-10 22:20:49.596 DEBUG (MainThread) [homeassistant.components.mqtt.client] mqtt: unregister write 24
2025-09-10 22:20:49.596 DEBUG (MainThread) [homeassistant.components.mqtt.client] mqtt: register write 24
2025-09-10 22:20:49.596 DEBUG (MainThread) [homeassistant.components.mqtt.client] Subscribing with mid: 14 to topics with qos: [('homeassistant/light/+/config', 0)]
2025-09-10 22:20:49.596 DEBUG (MainThread) [homeassistant.components.mqtt.client] mqtt: unregister write 24
2025-09-10 22:20:49.596 DEBUG (MainThread) [homeassistant.components.mqtt.client] mqtt: register write 24
2025-09-10 22:20:49.596 DEBUG (MainThread) [homeassistant.components.mqtt.client] Subscribing with mid: 15 to topics with qos: [('homeassistant/lock/+/config', 0)]
2025-09-10 22:20:49.597 DEBUG (MainThread) [homeassistant.components.mqtt.client] mqtt: unregister write 24
2025-09-10 22:20:49.597 DEBUG (MainThread) [homeassistant.components.mqtt.client] mqtt: register write 24
2025-09-10 22:20:49.597 DEBUG (MainThread) [homeassistant.components.mqtt.client] Subscribing with mid: 16 to topics with qos: [('homeassistant/notify/+/config', 0)]
2025-09-10 22:20:49.597 DEBUG (MainThread) [homeassistant.components.mqtt.client] mqtt: unregister write 24
2025-09-10 22:20:49.597 DEBUG (MainThread) [homeassistant.components.mqtt.client] mqtt: register write 24
2025-09-10 22:20:49.597 DEBUG (MainThread) [homeassistant.components.mqtt.client] Subscribing with mid: 17 to topics with qos: [('homeassistant/number/+/config', 0)]
2025-09-10 22:20:49.597 DEBUG (MainThread) [homeassistant.components.mqtt.client] mqtt: unregister write 24
2025-09-10 22:20:49.598 DEBUG (MainThread) [homeassistant.components.mqtt.client] mqtt: register write 24
2025-09-10 22:20:49.598 DEBUG (MainThread) [homeassistant.components.mqtt.client] Subscribing with mid: 18 to topics with qos: [('homeassistant/scene/+/config', 0)]
2025-09-10 22:20:49.598 DEBUG (MainThread) [homeassistant.components.mqtt.client] mqtt: unregister write 24
2025-09-10 22:20:49.598 DEBUG (MainThread) [homeassistant.components.mqtt.client] mqtt: register write 24
2025-09-10 22:20:49.598 DEBUG (MainThread) [homeassistant.components.mqtt.client] Subscribing with mid: 19 to topics with qos: [('homeassistant/siren/+/config', 0)]
2025-09-10 22:20:49.598 DEBUG (MainThread) [homeassistant.components.mqtt.client] mqtt: unregister write 24
2025-09-10 22:20:49.599 DEBUG (MainThread) [homeassistant.components.mqtt.client] mqtt: register write 24
2025-09-10 22:20:49.599 DEBUG (MainThread) [homeassistant.components.mqtt.client] Subscribing with mid: 20 to topics with qos: [('homeassistant/select/+/config', 0)]
2025-09-10 22:20:49.599 DEBUG (MainThread) [homeassistant.components.mqtt.client] mqtt: unregister write 24
2025-09-10 22:20:49.599 DEBUG (MainThread) [homeassistant.components.mqtt.client] mqtt: register write 24
2025-09-10 22:20:49.599 DEBUG (MainThread) [homeassistant.components.mqtt.client] Subscribing with mid: 21 to topics with qos: [('homeassistant/sensor/+/config', 0)]
2025-09-10 22:20:49.599 DEBUG (MainThread) [homeassistant.components.mqtt.client] mqtt: unregister write 24
2025-09-10 22:20:49.599 DEBUG (MainThread) [homeassistant.components.mqtt.client] mqtt: register write 24
2025-09-10 22:20:49.599 DEBUG (MainThread) [homeassistant.components.mqtt.client] Subscribing with mid: 22 to topics with qos: [('homeassistant/switch/+/config', 0)]
2025-09-10 22:20:49.600 DEBUG (MainThread) [homeassistant.components.mqtt.client] mqtt: unregister write 24
2025-09-10 22:20:49.600 DEBUG (MainThread) [homeassistant.components.mqtt.client] mqtt: register write 24
2025-09-10 22:20:49.600 DEBUG (MainThread) [homeassistant.components.mqtt.client] Subscribing with mid: 23 to topics with qos: [('homeassistant/tag/+/config', 0)]
2025-09-10 22:20:49.600 DEBUG (MainThread) [homeassistant.components.mqtt.client] mqtt: unregister write 24
2025-09-10 22:20:49.600 DEBUG (MainThread) [homeassistant.components.mqtt.client] mqtt: register write 24
2025-09-10 22:20:49.600 DEBUG (MainThread) [homeassistant.components.mqtt.client] Subscribing with mid: 24 to topics with qos: [('homeassistant/text/+/config', 0)]
2025-09-10 22:20:49.601 DEBUG (MainThread) [homeassistant.components.mqtt.client] mqtt: unregister write 24
2025-09-10 22:20:49.601 DEBUG (MainThread) [homeassistant.components.mqtt.client] mqtt: register write 24
2025-09-10 22:20:49.601 DEBUG (MainThread) [homeassistant.components.mqtt.client] Subscribing with mid: 25 to topics with qos: [('homeassistant/update/+/config', 0)]
2025-09-10 22:20:49.602 DEBUG (MainThread) [homeassistant.components.mqtt.client] mqtt: unregister write 24
2025-09-10 22:20:49.602 DEBUG (MainThread) [homeassistant.components.mqtt.client] mqtt: register write 24
2025-09-10 22:20:49.602 DEBUG (MainThread) [homeassistant.components.mqtt.client] Subscribing with mid: 26 to topics with qos: [('homeassistant/vacuum/+/config', 0)]
2025-09-10 22:20:49.602 DEBUG (MainThread) [homeassistant.components.mqtt.client] mqtt: unregister write 24
2025-09-10 22:20:49.602 DEBUG (MainThread) [homeassistant.components.mqtt.client] mqtt: register write 24
2025-09-10 22:20:49.603 DEBUG (MainThread) [homeassistant.components.mqtt.client] Subscribing with mid: 27 to topics with qos: [('homeassistant/valve/+/config', 0)]
2025-09-10 22:20:49.603 DEBUG (MainThread) [homeassistant.components.mqtt.client] mqtt: unregister write 24
2025-09-10 22:20:49.603 DEBUG (MainThread) [homeassistant.components.mqtt.client] mqtt: register write 24
2025-09-10 22:20:49.603 DEBUG (MainThread) [homeassistant.components.mqtt.client] Subscribing with mid: 28 to topics with qos: [('homeassistant/water_heater/+/config', 0)]
2025-09-10 22:20:49.603 DEBUG (MainThread) [homeassistant.components.mqtt.client] mqtt: unregister write 24
2025-09-10 22:20:49.604 DEBUG (MainThread) [homeassistant.components.mqtt.client] mqtt: register write 24
2025-09-10 22:20:49.604 DEBUG (MainThread) [homeassistant.components.mqtt.client] Subscribing with mid: 29 to topics with qos: [('homeassistant/alarm_control_panel/+/+/config', 0)]
2025-09-10 22:20:49.604 DEBUG (MainThread) [homeassistant.components.mqtt.client] mqtt: unregister write 24
2025-09-10 22:20:49.605 DEBUG (MainThread) [homeassistant.components.mqtt.client] mqtt: register write 24
2025-09-10 22:20:49.605 DEBUG (MainThread) [homeassistant.components.mqtt.client] Subscribing with mid: 30 to topics with qos: [('homeassistant/binary_sensor/+/+/config', 0)]
2025-09-10 22:20:49.605 DEBUG (MainThread) [homeassistant.components.mqtt.client] mqtt: unregister write 24
2025-09-10 22:20:49.605 DEBUG (MainThread) [homeassistant.components.mqtt.client] mqtt: register write 24
2025-09-10 22:20:49.605 DEBUG (MainThread) [homeassistant.components.mqtt.client] Subscribing with mid: 31 to topics with qos: [('homeassistant/button/+/+/config', 0)]
2025-09-10 22:20:49.606 DEBUG (MainThread) [homeassistant.components.mqtt.client] mqtt: unregister write 24
2025-09-10 22:20:49.606 DEBUG (MainThread) [homeassistant.components.mqtt.client] mqtt: register write 24
2025-09-10 22:20:49.606 DEBUG (MainThread) [homeassistant.components.mqtt.client] Subscribing with mid: 32 to topics with qos: [('homeassistant/camera/+/+/config', 0)]
2025-09-10 22:20:49.606 DEBUG (MainThread) [homeassistant.components.mqtt.client] mqtt: unregister write 24
2025-09-10 22:20:49.607 DEBUG (MainThread) [homeassistant.components.mqtt.client] mqtt: register write 24
2025-09-10 22:20:49.607 DEBUG (MainThread) [homeassistant.components.mqtt.client] Subscribing with mid: 33 to topics with qos: [('homeassistant/climate/+/+/config', 0)]
2025-09-10 22:20:49.607 DEBUG (MainThread) [homeassistant.components.mqtt.client] mqtt: unregister write 24
2025-09-10 22:20:49.607 DEBUG (MainThread) [homeassistant.components.mqtt.client] mqtt: register write 24
2025-09-10 22:20:49.607 DEBUG (MainThread) [homeassistant.components.mqtt.client] Subscribing with mid: 34 to topics with qos: [('homeassistant/cover/+/+/config', 0)]
2025-09-10 22:20:49.608 DEBUG (MainThread) [homeassistant.components.mqtt.client] mqtt: unregister write 24
2025-09-10 22:20:49.608 DEBUG (MainThread) [homeassistant.components.mqtt.client] mqtt: register write 24
2025-09-10 22:20:49.608 DEBUG (MainThread) [homeassistant.components.mqtt.client] Subscribing with mid: 35 to topics with qos: [('homeassistant/device_automation/+/+/config', 0)]
2025-09-10 22:20:49.608 DEBUG (MainThread) [homeassistant.components.mqtt.client] mqtt: unregister write 24
2025-09-10 22:20:49.608 DEBUG (MainThread) [homeassistant.components.mqtt.client] mqtt: register write 24
2025-09-10 22:20:49.608 DEBUG (MainThread) [homeassistant.components.mqtt.client] Subscribing with mid: 36 to topics with qos: [('homeassistant/device_tracker/+/+/config', 0)]
2025-09-10 22:20:49.608 DEBUG (MainThread) [homeassistant.components.mqtt.client] mqtt: unregister write 24
2025-09-10 22:20:49.609 DEBUG (MainThread) [homeassistant.components.mqtt.client] mqtt: register write 24
2025-09-10 22:20:49.609 DEBUG (MainThread) [homeassistant.components.mqtt.client] Subscribing with mid: 37 to topics with qos: [('homeassistant/event/+/+/config', 0)]
2025-09-10 22:20:49.609 DEBUG (MainThread) [homeassistant.components.mqtt.client] mqtt: unregister write 24
2025-09-10 22:20:49.609 DEBUG (MainThread) [homeassistant.components.mqtt.client] mqtt: register write 24
2025-09-10 22:20:49.609 DEBUG (MainThread) [homeassistant.components.mqtt.client] Subscribing with mid: 38 to topics with qos: [('homeassistant/fan/+/+/config', 0)]
2025-09-10 22:20:49.610 DEBUG (MainThread) [homeassistant.components.mqtt.client] mqtt: unregister write 24
2025-09-10 22:20:49.610 DEBUG (MainThread) [homeassistant.components.mqtt.client] mqtt: register write 24
2025-09-10 22:20:49.610 DEBUG (MainThread) [homeassistant.components.mqtt.client] Subscribing with mid: 39 to topics with qos: [('homeassistant/humidifier/+/+/config', 0)]
2025-09-10 22:20:49.610 DEBUG (MainThread) [homeassistant.components.mqtt.client] mqtt: unregister write 24
2025-09-10 22:20:49.611 DEBUG (MainThread) [homeassistant.components.mqtt.client] mqtt: register write 24
2025-09-10 22:20:49.611 DEBUG (MainThread) [homeassistant.components.mqtt.client] Subscribing with mid: 40 to topics with qos: [('homeassistant/image/+/+/config', 0)]
2025-09-10 22:20:49.611 DEBUG (MainThread) [homeassistant.components.mqtt.client] mqtt: unregister write 24
2025-09-10 22:20:49.611 DEBUG (MainThread) [homeassistant.components.mqtt.client] mqtt: register write 24
2025-09-10 22:20:49.611 DEBUG (MainThread) [homeassistant.components.mqtt.client] Subscribing with mid: 41 to topics with qos: [('homeassistant/lawn_mower/+/+/config', 0)]
2025-09-10 22:20:49.612 DEBUG (MainThread) [homeassistant.components.mqtt.client] mqtt: unregister write 24
2025-09-10 22:20:49.612 DEBUG (MainThread) [homeassistant.components.mqtt.client] mqtt: register write 24
2025-09-10 22:20:49.612 DEBUG (MainThread) [homeassistant.components.mqtt.client] Subscribing with mid: 42 to topics with qos: [('homeassistant/light/+/+/config', 0)]
2025-09-10 22:20:49.612 DEBUG (MainThread) [homeassistant.components.mqtt.client] mqtt: unregister write 24
2025-09-10 22:20:49.612 DEBUG (MainThread) [homeassistant.components.mqtt.client] mqtt: register write 24
2025-09-10 22:20:49.613 DEBUG (MainThread) [homeassistant.components.mqtt.client] Subscribing with mid: 43 to topics with qos: [('homeassistant/lock/+/+/config', 0)]
2025-09-10 22:20:49.613 DEBUG (MainThread) [homeassistant.components.mqtt.client] mqtt: unregister write 24
2025-09-10 22:20:49.613 DEBUG (MainThread) [homeassistant.components.mqtt.client] mqtt: register write 24
2025-09-10 22:20:49.613 DEBUG (MainThread) [homeassistant.components.mqtt.client] Subscribing with mid: 44 to topics with qos: [('homeassistant/notify/+/+/config', 0)]
2025-09-10 22:20:49.613 DEBUG (MainThread) [homeassistant.components.mqtt.client] mqtt: unregister write 24
2025-09-10 22:20:49.614 DEBUG (MainThread) [homeassistant.components.mqtt.client] mqtt: register write 24
2025-09-10 22:20:49.614 DEBUG (MainThread) [homeassistant.components.mqtt.client] Subscribing with mid: 45 to topics with qos: [('homeassistant/number/+/+/config', 0)]
2025-09-10 22:20:49.614 DEBUG (MainThread) [homeassistant.components.mqtt.client] mqtt: unregister write 24
2025-09-10 22:20:49.614 DEBUG (MainThread) [homeassistant.components.mqtt.client] mqtt: register write 24
2025-09-10 22:20:49.614 DEBUG (MainThread) [homeassistant.components.mqtt.client] Subscribing with mid: 46 to topics with qos: [('homeassistant/scene/+/+/config', 0)]
2025-09-10 22:20:49.615 DEBUG (MainThread) [homeassistant.components.mqtt.client] mqtt: unregister write 24
2025-09-10 22:20:49.615 DEBUG (MainThread) [homeassistant.components.mqtt.client] mqtt: register write 24
2025-09-10 22:20:49.615 DEBUG (MainThread) [homeassistant.components.mqtt.client] Subscribing with mid: 47 to topics with qos: [('homeassistant/siren/+/+/config', 0)]
2025-09-10 22:20:49.615 DEBUG (MainThread) [homeassistant.components.mqtt.client] mqtt: unregister write 24
2025-09-10 22:20:49.615 DEBUG (MainThread) [homeassistant.components.mqtt.client] mqtt: register write 24
2025-09-10 22:20:49.615 DEBUG (MainThread) [homeassistant.components.mqtt.client] Subscribing with mid: 48 to topics with qos: [('homeassistant/select/+/+/config', 0)]
2025-09-10 22:20:49.615 DEBUG (MainThread) [homeassistant.components.mqtt.client] mqtt: unregister write 24
2025-09-10 22:20:49.616 DEBUG (MainThread) [homeassistant.components.mqtt.client] mqtt: register write 24
2025-09-10 22:20:49.616 DEBUG (MainThread) [homeassistant.components.mqtt.client] Subscribing with mid: 49 to topics with qos: [('homeassistant/sensor/+/+/config', 0)]
2025-09-10 22:20:49.616 DEBUG (MainThread) [homeassistant.components.mqtt.client] mqtt: unregister write 24
2025-09-10 22:20:49.616 DEBUG (MainThread) [homeassistant.components.mqtt.client] mqtt: register write 24
2025-09-10 22:20:49.616 DEBUG (MainThread) [homeassistant.components.mqtt.client] Subscribing with mid: 50 to topics with qos: [('homeassistant/switch/+/+/config', 0)]
2025-09-10 22:20:49.616 DEBUG (MainThread) [homeassistant.components.mqtt.client] mqtt: unregister write 24
2025-09-10 22:20:49.617 DEBUG (MainThread) [homeassistant.components.mqtt.client] mqtt: register write 24
2025-09-10 22:20:49.617 DEBUG (MainThread) [homeassistant.components.mqtt.client] Subscribing with mid: 51 to topics with qos: [('homeassistant/tag/+/+/config', 0)]
2025-09-10 22:20:49.617 DEBUG (MainThread) [homeassistant.components.mqtt.client] mqtt: unregister write 24
2025-09-10 22:20:49.617 DEBUG (MainThread) [homeassistant.components.mqtt.client] mqtt: register write 24
2025-09-10 22:20:49.617 DEBUG (MainThread) [homeassistant.components.mqtt.client] Subscribing with mid: 52 to topics with qos: [('homeassistant/text/+/+/config', 0)]
2025-09-10 22:20:49.618 DEBUG (MainThread) [homeassistant.components.mqtt.client] mqtt: unregister write 24
2025-09-10 22:20:49.618 DEBUG (MainThread) [homeassistant.components.mqtt.client] mqtt: register write 24
2025-09-10 22:20:49.618 DEBUG (MainThread) [homeassistant.components.mqtt.client] Subscribing with mid: 53 to topics with qos: [('homeassistant/update/+/+/config', 0)]
2025-09-10 22:20:49.618 DEBUG (MainThread) [homeassistant.components.mqtt.client] mqtt: unregister write 24
2025-09-10 22:20:49.619 DEBUG (MainThread) [homeassistant.components.mqtt.client] mqtt: register write 24
2025-09-10 22:20:49.619 DEBUG (MainThread) [homeassistant.components.mqtt.client] Subscribing with mid: 54 to topics with qos: [('homeassistant/vacuum/+/+/config', 0)]
2025-09-10 22:20:49.619 DEBUG (MainThread) [homeassistant.components.mqtt.client] mqtt: unregister write 24
2025-09-10 22:20:49.619 DEBUG (MainThread) [homeassistant.components.mqtt.client] mqtt: register write 24
2025-09-10 22:20:49.619 DEBUG (MainThread) [homeassistant.components.mqtt.client] Subscribing with mid: 55 to topics with qos: [('homeassistant/valve/+/+/config', 0)]
2025-09-10 22:20:49.619 DEBUG (MainThread) [homeassistant.components.mqtt.client] mqtt: unregister write 24
2025-09-10 22:20:49.620 DEBUG (MainThread) [homeassistant.components.mqtt.client] mqtt: register write 24
2025-09-10 22:20:49.620 DEBUG (MainThread) [homeassistant.components.mqtt.client] Subscribing with mid: 56 to topics with qos: [('homeassistant/water_heater/+/+/config', 0)]
2025-09-10 22:20:49.620 DEBUG (MainThread) [homeassistant.components.mqtt.client] mqtt: unregister write 24
2025-09-10 22:20:49.620 DEBUG (MainThread) [homeassistant.components.mqtt.client] mqtt: register write 24
2025-09-10 22:20:49.620 DEBUG (MainThread) [homeassistant.components.mqtt.client] Subscribing with mid: 57 to topics with qos: [('homeassistant/device/+/config', 0)]
2025-09-10 22:20:49.620 DEBUG (MainThread) [homeassistant.components.mqtt.client] mqtt: unregister write 24
2025-09-10 22:20:49.621 DEBUG (MainThread) [homeassistant.components.mqtt.client] mqtt: register write 24
2025-09-10 22:20:49.621 DEBUG (MainThread) [homeassistant.components.mqtt.client] Subscribing with mid: 58 to topics with qos: [('homeassistant/device/+/+/config', 0)]
2025-09-10 22:20:49.621 DEBUG (MainThread) [homeassistant.components.mqtt.client] mqtt: unregister write 24
2025-09-10 22:20:49.621 DEBUG (MainThread) [homeassistant.components.mqtt.client] mqtt: register write 24
2025-09-10 22:20:49.621 DEBUG (MainThread) [homeassistant.components.mqtt.client] Subscribing with mid: 59 to topics with qos: [('drop_connect/discovery/#', 0)]
2025-09-10 22:20:49.622 DEBUG (MainThread) [homeassistant.components.mqtt.client] mqtt: unregister write 24
2025-09-10 22:20:49.622 DEBUG (MainThread) [homeassistant.components.mqtt.client] mqtt: register write 24
2025-09-10 22:20:49.622 DEBUG (MainThread) [homeassistant.components.mqtt.client] Subscribing with mid: 60 to topics with qos: [('dsmr/#', 0)]
2025-09-10 22:20:49.622 DEBUG (MainThread) [homeassistant.components.mqtt.client] mqtt: unregister write 24
2025-09-10 22:20:49.622 DEBUG (MainThread) [homeassistant.components.mqtt.client] mqtt: register write 24
2025-09-10 22:20:49.623 DEBUG (MainThread) [homeassistant.components.mqtt.client] Subscribing with mid: 61 to topics with qos: [('esphome/discover/#', 0)]
2025-09-10 22:20:49.623 DEBUG (MainThread) [homeassistant.components.mqtt.client] mqtt: unregister write 24
2025-09-10 22:20:49.623 DEBUG (MainThread) [homeassistant.components.mqtt.client] mqtt: register write 24
2025-09-10 22:20:49.623 DEBUG (MainThread) [homeassistant.components.mqtt.client] Subscribing with mid: 62 to topics with qos: [('fully/deviceInfo/+', 0)]
2025-09-10 22:20:49.623 DEBUG (MainThread) [homeassistant.components.mqtt.client] mqtt: unregister write 24
2025-09-10 22:20:49.624 DEBUG (MainThread) [homeassistant.components.mqtt.client] mqtt: register write 24
2025-09-10 22:20:49.624 DEBUG (MainThread) [homeassistant.components.mqtt.client] Subscribing with mid: 63 to topics with qos: [('pglab/discovery/#', 0)]
2025-09-10 22:20:49.624 DEBUG (MainThread) [homeassistant.components.mqtt.client] mqtt: unregister write 24
2025-09-10 22:20:49.624 DEBUG (MainThread) [homeassistant.components.mqtt.client] mqtt: register write 24
2025-09-10 22:20:49.624 DEBUG (MainThread) [homeassistant.components.mqtt.client] Subscribing with mid: 64 to topics with qos: [('cloudapp/QBUSMQTTGW/+/state', 0)]
2025-09-10 22:20:49.624 DEBUG (MainThread) [homeassistant.components.mqtt.client] mqtt: unregister write 24
2025-09-10 22:20:49.625 DEBUG (MainThread) [homeassistant.components.mqtt.client] mqtt: register write 24
2025-09-10 22:20:49.625 DEBUG (MainThread) [homeassistant.components.mqtt.client] Subscribing with mid: 65 to topics with qos: [('tasmota/discovery/#', 0)]
2025-09-10 22:20:49.625 DEBUG (MainThread) [homeassistant.components.mqtt.client] mqtt: unregister write 24
2025-09-10 22:20:49.625 DEBUG (MainThread) [homeassistant.components.mqtt.client] mqtt: register write 24
2025-09-10 22:20:49.625 DEBUG (MainThread) [homeassistant.components.mqtt.client] Subscribing with mid: 66 to topics with qos: [('cloudapp/QBUSMQTTGW/config', 0), ('cloudapp/QBUSMQTTGW/state', 0)]
2025-09-10 22:20:49.625 DEBUG (MainThread) [homeassistant.components.mqtt.client] mqtt: unregister write 24
2025-09-10 22:20:59.567 WARNING (MainThread) [homeassistant.components.sonos] Could not get visible Sonos devices from 192.168.1.103: HTTPConnectionPool(host='192.168.1.103', port=1400): Max retries exceeded with url: /xml/DeviceProperties1.xml (Caused by ConnectTimeoutError(<urllib3.connection.HTTPConnection object at 0x7cc44f3938c0>, 'Connection to 192.168.1.103 timed out. (connect timeout=10)'))
2025-09-10 22:21:01.630 WARNING (MainThread) [homeassistant.components.sonos] Subscription to 192.168.1.102 failed, attempting to poll directly
2025-09-10 22:21:03.631 INFO (MainThread) [homeassistant.bootstrap] Home Assistant initialized in 42.72s
2025-09-10 22:21:03.631 INFO (MainThread) [homeassistant.core] Starting Home Assistant 2025.9.1
2025-09-10 22:21:03.639 DEBUG (MainThread) [homeassistant.components.mqtt.trigger] Attaching MQTT trigger for topic: 'alicia/tts/announce', payload: 'None'
2025-09-10 22:21:03.640 INFO (MainThread) [homeassistant.components.automation.sonos_tts_announcement] Initialized trigger Sonos TTS Announcement
2025-09-10 22:21:03.640 DEBUG (MainThread) [homeassistant.components.mqtt.trigger] Attaching MQTT trigger for topic: 'alicia/commands/sonos/group', payload: 'None'
2025-09-10 22:21:03.640 INFO (MainThread) [homeassistant.components.automation.sonos_multi_room_group_control] Initialized trigger Sonos Multi-Room Group Control
2025-09-10 22:21:03.640 DEBUG (MainThread) [homeassistant.components.mqtt.trigger] Attaching MQTT trigger for topic: 'alicia/commands/sonos/volume', payload: 'None'
2025-09-10 22:21:03.640 INFO (MainThread) [homeassistant.components.automation.sonos_volume_control] Initialized trigger Sonos Volume Control
2025-09-10 22:21:03.640 DEBUG (MainThread) [homeassistant.components.mqtt.trigger] Attaching MQTT trigger for topic: 'alicia/commands/sonos/playback', payload: 'None'
2025-09-10 22:21:03.640 INFO (MainThread) [homeassistant.components.automation.sonos_playback_control] Initialized trigger Sonos Playback Control
2025-09-10 22:21:03.640 INFO (MainThread) [homeassistant.components.automation.sonos_status_monitor] Initialized trigger Sonos Status Monitor
2025-09-10 22:21:04.140 DEBUG (MainThread) [homeassistant.components.mqtt.client] mqtt: register write 24
2025-09-10 22:21:04.140 DEBUG (MainThread) [homeassistant.components.mqtt.client] Subscribing with mid: 67 to topics with qos: [('alicia/tts/announce', 0), ('alicia/commands/sonos/group', 0), ('alicia/commands/sonos/volume', 0), ('alicia/commands/sonos/playback', 0)]
2025-09-10 22:21:04.141 DEBUG (MainThread) [homeassistant.components.mqtt.client] mqtt: unregister write 24
2025-09-10 22:21:09.141 DEBUG (MainThread) [homeassistant.components.mqtt.client] mqtt: register write 24
2025-09-10 22:21:09.142 DEBUG (MainThread) [homeassistant.components.mqtt.client] Transmitting message on homeassistant/status: 'online', mid: 68, qos: 0
2025-09-10 22:21:09.142 DEBUG (MainThread) [homeassistant.components.mqtt.client] mqtt: unregister write 24
2025-09-10 22:21:09.142 INFO (MainThread) [homeassistant.components.mqtt.client] MQTT client initialized, birth message sent
2025-09-10 22:21:49.395 DEBUG (MainThread) [homeassistant.components.mqtt.client] mqtt: register write 24
2025-09-10 22:21:49.396 DEBUG (MainThread) [homeassistant.components.mqtt.client] mqtt: unregister write 24
2025-09-10 22:22:49.717 DEBUG (MainThread) [homeassistant.components.mqtt.client] mqtt: register write 24
2025-09-10 22:22:49.718 DEBUG (MainThread) [homeassistant.components.mqtt.client] mqtt: unregister write 24
2025-09-10 22:23:50.034 DEBUG (MainThread) [homeassistant.components.mqtt.client] mqtt: register write 24
2025-09-10 22:23:50.034 DEBUG (MainThread) [homeassistant.components.mqtt.client] mqtt: unregister write 24
2025-09-10 22:24:35.088 ERROR (MainThread) [homeassistant.components.sonos.household_coordinator] Could not refresh SonosFavorites: Error calling SonosFavorites.update_cache on Bedroom: HTTPConnectionPool(host='192.168.1.102', port=1400): Max retries exceeded with url: /MediaServer/ContentDirectory/Control (Caused by ConnectTimeoutError(<urllib3.connection.HTTPConnection object at 0x7cc44f3bd260>, 'Connection to 192.168.1.102 timed out. (connect timeout=9.5)'))
2025-09-10 22:24:50.366 DEBUG (MainThread) [homeassistant.components.mqtt.client] mqtt: register write 24
2025-09-10 22:24:50.367 DEBUG (MainThread) [homeassistant.components.mqtt.client] mqtt: unregister write 24
2025-09-10 22:25:50.687 DEBUG (MainThread) [homeassistant.components.mqtt.client] mqtt: register write 24
2025-09-10 22:25:50.688 DEBUG (MainThread) [homeassistant.components.mqtt.client] mqtt: unregister write 24
